{"version":8,"blockIdVersion":10,"anchorX":0,"anchorY":0,"anchorZ":0,"blocks":[{"x":0,"y":0,"z":0,"name":"Soil_Dirt"},{"x":1,"y":0,"z":0,"name":"Soil_Dirt"},{"x":2,"y":0,"z":0,"name":"Soil_Dirt"},{"x":3,"y":0,"z":0,"name":"Soil_Dirt"},{"x":4,"y":0,"z":0,"name":"Soil_Dirt"},{"x":5,"y":0,"z":0,"name":"Soil_Dirt"},{"x":6,"y":0,"z":0,"name":"Soil_Dirt"},{"x":7,"y":0,"z":0,"name":"Soil_Dirt"},{"x":8,"y":0,"z":0,"name":"Soil_Dirt"},{"x":9,"y":0,"z":0,"name":"Soil_Dirt"},{"x":10,"y":0,"z":0,"name":"Soil_Dirt"},{"x":11,"y":0,"z":0,"name":"Soil_Dirt"},{"x":12,"y":0,"z":0,"name":"Soil_Dirt"},{"x":13,"y":0,"z":0,"name":"Soil_Dirt"},{"x":14,"y":0,"z":0,"name":"Soil_Dirt"},{"x":15,"y":0,"z":0,"name":"Soil_Dirt"},{"x":16,"y":0,"z":0,"name":"Cloth_Block_Wool_Orange"},{"x":0,"y":0,"z":1,"name":"Soil_Dirt"},{"x":1,"y":0,"z":1,"name":"Soil_Dirt"},{"x":2,"y":0,"z":1,"name":"Soil_Dirt"},{"x":3,"y":0,"z":1,"name":"Soil_Dirt"},{"x":4,"y":0,"z":1,"name":"Soil_Dirt"},{"x":5,"y":0,"z":1,"name":"Soil_Dirt"},{"x":6,"y":0,"z":1,"name":"Soil_Dirt"},{"x":7,"y":0,"z":1,"name":"Soil_Dirt"},{"x":8,"y":0,"z":1,"name":"Soil_Dirt"},{"x":9,"y":0,"z":1,"name":"Soil_Dirt"},{"x":10,"y":0,"z":1,"name":"Soil_Dirt"},{"x":11,"y":0,"z":1,"name":"Soil_Dirt"},{"x":12,"y":0,"z":1,"name":"Soil_Dirt"},{"x":13,"y":0,"z":1,"name":"Soil_Dirt"},{"x":14,"y":0,"z":1,"name":"Soil_Dirt"},{"x":15,"y":0,"z":1,"name":"Soil_Dirt"},{"x":16,"y":0,"z":1,"name":"Soil_Dirt"},{"x":0,"y":0,"z":2,"name":"Soil_Dirt"},{"x":1,"y":0,"z":2,"name":"Soil_Dirt"},{"x":2,"y":0,"z":2,"name":"Soil_Dirt"},{"x":3,"y":0,"z":2,"name":"Soil_Grass"},{"x":4,"y":0,"z":2,"name":"Soil_Dirt"},{"x":5,"y":0,"z":2,"name":"Soil_Dirt"},{"x":6,"y":0,"z":2,"name":"Soil_Dirt"},{"x":7,"y":0,"z":2,"name":"Soil_Dirt"},{"x":8,"y":0,"z":2,"name":"Soil_Dirt"},{"x":9,"y":0,"z":2,"name":"Soil_Dirt"},{"x":10,"y":0,"z":2,"name":"Soil_Dirt"},{"x":11,"y":0,"z":2,"name":"Soil_Grass"},{"x":12,"y":0,"z":2,"name":"Soil_Dirt"},{"x":13,"y":0,"z":2,"name":"Soil_Dirt"},{"x":14,"y":0,"z":2,"name":"Soil_Dirt"},{"x":15,"y":0,"z":2,"name":"Soil_Dirt"},{"x":16,"y":0,"z":2,"name":"Soil_Dirt"},{"x":0,"y":0,"z":3,"name":"Soil_Dirt"},{"x":1,"y":0,"z":3,"name":"Soil_Dirt"},{"x":2,"y":0,"z":3,"name":"Soil_Dirt"},{"x":3,"y":0,"z":3,"name":"Soil_Dirt"},{"x":4,"y":0,"z":3,"name":"Soil_Dirt"},{"x":5,"y":0,"z":3,"name":"Soil_Dirt"},{"x":6,"y":0,"z":3,"name":"Soil_Dirt"},{"x":7,"y":0,"z":3,"name":"Soil_Dirt"},{"x":8,"y":0,"z":3,"name":"Soil_Dirt"},{"x":9,"y":0,"z":3,"name":"Soil_Dirt"},{"x":10,"y":0,"z":3,"name":"Soil_Dirt"},{"x":11,"y":0,"z":3,"name":"Soil_Dirt"},{"x":12,"y":0,"z":3,"name":"Soil_Dirt"},{"x":13,"y":0,"z":3,"name":"Soil_Dirt"},{"x":14,"y":0,"z":3,"name":"Soil_Dirt"},{"x":15,"y":0,"z":3,"name":"Soil_Dirt"},{"x":16,"y":0,"z":3,"name":"Soil_Dirt"},{"x":0,"y":0,"z":4,"name":"Soil_Dirt"},{"x":1,"y":0,"z":4,"name":"Soil_Dirt"},{"x":2,"y":0,"z":4,"name":"Soil_Dirt"},{"x":3,"y":0,"z":4,"name":"Soil_Dirt"},{"x":4,"y":0,"z":4,"name":"Soil_Dirt"},{"x":5,"y":0,"z":4,"name":"Soil_Dirt"},{"x":6,"y":0,"z":4,"name":"Soil_Dirt"},{"x":7,"y":0,"z":4,"name":"Soil_Dirt"},{"x":8,"y":0,"z":4,"name":"Soil_Dirt"},{"x":9,"y":0,"z":4,"name":"Soil_Dirt"},{"x":10,"y":0,"z":4,"name":"Soil_Dirt"},{"x":11,"y":0,"z":4,"name":"Soil_Dirt"},{"x":12,"y":0,"z":4,"name":"Soil_Dirt"},{"x":13,"y":0,"z":4,"name":"Soil_Dirt"},{"x":14,"y":0,"z":4,"name":"Soil_Dirt"},{"x":15,"y":0,"z":4,"name":"Soil_Dirt"},{"x":16,"y":0,"z":4,"name":"Soil_Dirt"},{"x":0,"y":0,"z":5,"name":"Soil_Dirt"},{"x":1,"y":0,"z":5,"name":"Soil_Dirt"},{"x":2,"y":0,"z":5,"name":"Soil_Dirt"},{"x":3,"y":0,"z":5,"name":"Soil_Dirt"},{"x":4,"y":0,"z":5,"name":"Soil_Dirt"},{"x":5,"y":0,"z":5,"name":"Soil_Dirt"},{"x":6,"y":0,"z":5,"name":"Soil_Dirt"},{"x":7,"y":0,"z":5,"name":"Soil_Dirt"},{"x":8,"y":0,"z":5,"name":"Soil_Dirt"},{"x":9,"y":0,"z":5,"name":"Soil_Dirt"},{"x":10,"y":0,"z":5,"name":"Soil_Dirt"},{"x":11,"y":0,"z":5,"name":"Soil_Dirt"},{"x":12,"y":0,"z":5,"name":"Soil_Dirt"},{"x":13,"y":0,"z":5,"name":"Soil_Dirt"},{"x":14,"y":0,"z":5,"name":"Soil_Dirt"},{"x":15,"y":0,"z":5,"name":"Soil_Dirt"},{"x":16,"y":0,"z":5,"name":"Soil_Dirt"},{"x":0,"y":0,"z":6,"name":"Soil_Dirt"},{"x":1,"y":0,"z":6,"name":"Soil_Dirt"},{"x":2,"y":0,"z":6,"name":"Soil_Dirt"},{"x":3,"y":0,"z":6,"name":"Soil_Dirt"},{"x":4,"y":0,"z":6,"name":"Soil_Dirt"},{"x":5,"y":0,"z":6,"name":"Soil_Dirt"},{"x":6,"y":0,"z":6,"name":"Soil_Dirt"},{"x":7,"y":0,"z":6,"name":"Soil_Dirt"},{"x":8,"y":0,"z":6,"name":"Soil_Dirt"},{"x":9,"y":0,"z":6,"name":"Soil_Dirt"},{"x":10,"y":0,"z":6,"name":"Soil_Dirt"},{"x":11,"y":0,"z":6,"name":"Soil_Dirt"},{"x":12,"y":0,"z":6,"name":"Soil_Dirt"},{"x":13,"y":0,"z":6,"name":"Soil_Dirt"},{"x":14,"y":0,"z":6,"name":"Soil_Dirt"},{"x":15,"y":0,"z":6,"name":"Soil_Dirt"},{"x":16,"y":0,"z":6,"name":"Soil_Dirt"},{"x":0,"y":0,"z":7,"name":"Soil_Dirt"},{"x":1,"y":0,"z":7,"name":"Soil_Dirt"},{"x":2,"y":0,"z":7,"name":"Soil_Dirt"},{"x":3,"y":0,"z":7,"name":"Soil_Dirt"},{"x":4,"y":0,"z":7,"name":"Soil_Dirt"},{"x":5,"y":0,"z":7,"name":"Soil_Dirt"},{"x":6,"y":0,"z":7,"name":"Soil_Dirt"},{"x":7,"y":0,"z":7,"name":"Soil_Dirt"},{"x":8,"y":0,"z":7,"name":"Soil_Dirt"},{"x":9,"y":0,"z":7,"name":"Soil_Dirt"},{"x":10,"y":0,"z":7,"name":"Soil_Dirt"},{"x":11,"y":0,"z":7,"name":"Soil_Dirt"},{"x":12,"y":0,"z":7,"name":"Soil_Dirt"},{"x":13,"y":0,"z":7,"name":"Soil_Dirt"},{"x":14,"y":0,"z":7,"name":"Soil_Dirt"},{"x":15,"y":0,"z":7,"name":"Soil_Dirt"},{"x":16,"y":0,"z":7,"name":"Soil_Dirt"},{"x":0,"y":0,"z":8,"name":"Soil_Dirt"},{"x":1,"y":0,"z":8,"name":"Soil_Dirt"},{"x":2,"y":0,"z":8,"name":"Soil_Dirt"},{"x":3,"y":0,"z":8,"name":"Soil_Dirt"},{"x":4,"y":0,"z":8,"name":"Soil_Dirt"},{"x":5,"y":0,"z":8,"name":"Soil_Dirt"},{"x":6,"y":0,"z":8,"name":"Soil_Dirt"},{"x":7,"y":0,"z":8,"name":"Soil_Dirt"},{"x":8,"y":0,"z":8,"name":"Soil_Dirt"},{"x":9,"y":0,"z":8,"name":"Soil_Dirt"},{"x":10,"y":0,"z":8,"name":"Soil_Dirt"},{"x":11,"y":0,"z":8,"name":"Soil_Dirt"},{"x":12,"y":0,"z":8,"name":"Soil_Dirt"},{"x":13,"y":0,"z":8,"name":"Soil_Dirt"},{"x":14,"y":0,"z":8,"name":"Soil_Dirt"},{"x":15,"y":0,"z":8,"name":"Soil_Dirt"},{"x":16,"y":0,"z":8,"name":"Soil_Dirt"},{"x":0,"y":0,"z":9,"name":"Soil_Dirt"},{"x":1,"y":0,"z":9,"name":"Soil_Dirt"},{"x":2,"y":0,"z":9,"name":"Soil_Dirt"},{"x":3,"y":0,"z":9,"name":"Soil_Dirt"},{"x":4,"y":0,"z":9,"name":"Soil_Dirt"},{"x":5,"y":0,"z":9,"name":"Soil_Dirt"},{"x":6,"y":0,"z":9,"name":"Soil_Dirt"},{"x":7,"y":0,"z":9,"name":"Soil_Dirt"},{"x":8,"y":0,"z":9,"name":"Soil_Dirt"},{"x":9,"y":0,"z":9,"name":"Soil_Dirt"},{"x":10,"y":0,"z":9,"name":"Soil_Dirt"},{"x":11,"y":0,"z":9,"name":"Soil_Dirt"},{"x":12,"y":0,"z":9,"name":"Soil_Dirt"},{"x":13,"y":0,"z":9,"name":"Soil_Dirt"},{"x":14,"y":0,"z":9,"name":"Soil_Dirt"},{"x":15,"y":0,"z":9,"name":"Soil_Dirt"},{"x":16,"y":0,"z":9,"name":"Soil_Dirt"},{"x":0,"y":0,"z":10,"name":"Soil_Dirt"},{"x":1,"y":0,"z":10,"name":"Soil_Dirt"},{"x":2,"y":0,"z":10,"name":"Soil_Dirt"},{"x":3,"y":0,"z":10,"name":"Soil_Dirt"},{"x":4,"y":0,"z":10,"name":"Soil_Dirt"},{"x":5,"y":0,"z":10,"name":"Soil_Dirt"},{"x":6,"y":0,"z":10,"name":"Soil_Dirt"},{"x":7,"y":0,"z":10,"name":"Soil_Dirt"},{"x":8,"y":0,"z":10,"name":"Soil_Dirt"},{"x":9,"y":0,"z":10,"name":"Soil_Dirt"},{"x":10,"y":0,"z":10,"name":"Soil_Dirt"},{"x":11,"y":0,"z":10,"name":"Soil_Dirt"},{"x":12,"y":0,"z":10,"name":"Soil_Dirt"},{"x":13,"y":0,"z":10,"name":"Soil_Dirt"},{"x":14,"y":0,"z":10,"name":"Soil_Dirt"},{"x":15,"y":0,"z":10,"name":"Soil_Dirt"},{"x":16,"y":0,"z":10,"name":"Soil_Dirt"},{"x":0,"y":0,"z":11,"name":"Soil_Dirt"},{"x":1,"y":0,"z":11,"name":"Soil_Dirt"},{"x":2,"y":0,"z":11,"name":"Soil_Dirt"},{"x":3,"y":0,"z":11,"name":"Soil_Dirt"},{"x":4,"y":0,"z":11,"name":"Soil_Dirt"},{"x":5,"y":0,"z":11,"name":"Soil_Dirt"},{"x":6,"y":0,"z":11,"name":"Soil_Dirt"},{"x":7,"y":0,"z":11,"name":"Soil_Dirt"},{"x":8,"y":0,"z":11,"name":"Soil_Dirt"},{"x":9,"y":0,"z":11,"name":"Soil_Dirt"},{"x":10,"y":0,"z":11,"name":"Soil_Dirt"},{"x":11,"y":0,"z":11,"name":"Soil_Dirt"},{"x":12,"y":0,"z":11,"name":"Soil_Dirt"},{"x":13,"y":0,"z":11,"name":"Soil_Dirt"},{"x":14,"y":0,"z":11,"name":"Soil_Dirt"},{"x":15,"y":0,"z":11,"name":"Soil_Dirt"},{"x":16,"y":0,"z":11,"name":"Soil_Dirt"},{"x":0,"y":0,"z":12,"name":"Soil_Dirt"},{"x":1,"y":0,"z":12,"name":"Soil_Dirt"},{"x":2,"y":0,"z":12,"name":"Soil_Dirt"},{"x":3,"y":0,"z":12,"name":"Soil_Dirt"},{"x":4,"y":0,"z":12,"name":"Soil_Dirt"},{"x":5,"y":0,"z":12,"name":"Soil_Dirt"},{"x":6,"y":0,"z":12,"name":"Soil_Dirt"},{"x":7,"y":0,"z":12,"name":"Soil_Dirt"},{"x":8,"y":0,"z":12,"name":"Soil_Dirt"},{"x":9,"y":0,"z":12,"name":"Soil_Dirt"},{"x":10,"y":0,"z":12,"name":"Soil_Dirt"},{"x":11,"y":0,"z":12,"name":"Soil_Dirt"},{"x":12,"y":0,"z":12,"name":"Soil_Dirt"},{"x":13,"y":0,"z":12,"name":"Soil_Dirt"},{"x":14,"y":0,"z":12,"name":"Soil_Dirt"},{"x":15,"y":0,"z":12,"name":"Soil_Dirt"},{"x":16,"y":0,"z":12,"name":"Soil_Dirt"},{"x":0,"y":0,"z":13,"name":"Soil_Dirt"},{"x":1,"y":0,"z":13,"name":"Soil_Dirt"},{"x":2,"y":0,"z":13,"name":"Soil_Dirt"},{"x":3,"y":0,"z":13,"name":"Soil_Dirt"},{"x":4,"y":0,"z":13,"name":"Soil_Dirt"},{"x":5,"y":0,"z":13,"name":"Soil_Dirt"},{"x":6,"y":0,"z":13,"name":"Soil_Dirt"},{"x":7,"y":0,"z":13,"name":"Soil_Dirt"},{"x":8,"y":0,"z":13,"name":"Soil_Dirt"},{"x":9,"y":0,"z":13,"name":"Soil_Dirt"},{"x":10,"y":0,"z":13,"name":"Soil_Dirt"},{"x":11,"y":0,"z":13,"name":"Soil_Dirt"},{"x":12,"y":0,"z":13,"name":"Soil_Dirt"},{"x":13,"y":0,"z":13,"name":"Soil_Dirt"},{"x":14,"y":0,"z":13,"name":"Soil_Dirt"},{"x":15,"y":0,"z":13,"name":"Soil_Dirt"},{"x":16,"y":0,"z":13,"name":"Soil_Dirt"},{"x":0,"y":0,"z":14,"name":"Soil_Dirt"},{"x":1,"y":0,"z":14,"name":"Soil_Dirt"},{"x":2,"y":0,"z":14,"name":"Soil_Dirt"},{"x":3,"y":0,"z":14,"name":"Soil_Dirt"},{"x":4,"y":0,"z":14,"name":"Soil_Dirt"},{"x":5,"y":0,"z":14,"name":"Soil_Dirt"},{"x":6,"y":0,"z":14,"name":"Soil_Dirt"},{"x":7,"y":0,"z":14,"name":"Soil_Dirt"},{"x":8,"y":0,"z":14,"name":"Soil_Dirt"},{"x":9,"y":0,"z":14,"name":"Soil_Dirt"},{"x":10,"y":0,"z":14,"name":"Soil_Dirt"},{"x":11,"y":0,"z":14,"name":"Soil_Dirt"},{"x":12,"y":0,"z":14,"name":"Soil_Dirt"},{"x":13,"y":0,"z":14,"name":"Soil_Dirt"},{"x":14,"y":0,"z":14,"name":"Soil_Dirt"},{"x":15,"y":0,"z":14,"name":"Soil_Dirt"},{"x":16,"y":0,"z":14,"name":"Soil_Dirt"},{"x":0,"y":0,"z":15,"name":"Soil_Dirt"},{"x":1,"y":0,"z":15,"name":"Soil_Dirt"},{"x":2,"y":0,"z":15,"name":"Soil_Dirt"},{"x":3,"y":0,"z":15,"name":"Soil_Dirt"},{"x":4,"y":0,"z":15,"name":"Soil_Dirt"},{"x":5,"y":0,"z":15,"name":"Soil_Dirt"},{"x":6,"y":0,"z":15,"name":"Soil_Dirt"},{"x":7,"y":0,"z":15,"name":"Soil_Dirt"},{"x":8,"y":0,"z":15,"name":"Soil_Dirt"},{"x":9,"y":0,"z":15,"name":"Soil_Dirt"},{"x":10,"y":0,"z":15,"name":"Soil_Dirt"},{"x":11,"y":0,"z":15,"name":"Soil_Dirt"},{"x":12,"y":0,"z":15,"name":"Soil_Dirt"},{"x":13,"y":0,"z":15,"name":"Soil_Dirt"},{"x":14,"y":0,"z":15,"name":"Soil_Dirt"},{"x":15,"y":0,"z":15,"name":"Soil_Dirt"},{"x":16,"y":0,"z":15,"name":"Soil_Dirt"},{"x":0,"y":0,"z":16,"name":"Soil_Dirt"},{"x":1,"y":0,"z":16,"name":"Soil_Dirt"},{"x":2,"y":0,"z":16,"name":"Soil_Dirt"},{"x":3,"y":0,"z":16,"name":"Soil_Dirt"},{"x":4,"y":0,"z":16,"name":"Soil_Dirt"},{"x":5,"y":0,"z":16,"name":"Soil_Dirt"},{"x":6,"y":0,"z":16,"name":"Soil_Dirt"},{"x":7,"y":0,"z":16,"name":"Soil_Dirt"},{"x":8,"y":0,"z":16,"name":"Soil_Dirt"},{"x":9,"y":0,"z":16,"name":"Soil_Dirt"},{"x":10,"y":0,"z":16,"name":"Soil_Dirt"},{"x":11,"y":0,"z":16,"name":"Soil_Dirt"},{"x":12,"y":0,"z":16,"name":"Soil_Dirt"},{"x":13,"y":0,"z":16,"name":"Soil_Dirt"},{"x":14,"y":0,"z":16,"name":"Soil_Dirt"},{"x":15,"y":0,"z":16,"name":"Soil_Dirt"},{"x":16,"y":0,"z":16,"name":"Soil_Dirt"},{"x":0,"y":0,"z":17,"name":"Soil_Dirt"},{"x":1,"y":0,"z":17,"name":"Soil_Dirt"},{"x":2,"y":0,"z":17,"name":"Soil_Dirt"},{"x":3,"y":0,"z":17,"name":"Soil_Dirt"},{"x":4,"y":0,"z":17,"name":"Soil_Dirt"},{"x":5,"y":0,"z":17,"name":"Soil_Dirt"},{"x":6,"y":0,"z":17,"name":"Soil_Dirt"},{"x":7,"y":0,"z":17,"name":"Soil_Dirt"},{"x":8,"y":0,"z":17,"name":"Soil_Dirt"},{"x":9,"y":0,"z":17,"name":"Soil_Dirt"},{"x":10,"y":0,"z":17,"name":"Soil_Dirt"},{"x":11,"y":0,"z":17,"name":"Soil_Dirt"},{"x":12,"y":0,"z":17,"name":"Soil_Dirt"},{"x":13,"y":0,"z":17,"name":"Soil_Dirt"},{"x":14,"y":0,"z":17,"name":"Soil_Dirt"},{"x":15,"y":0,"z":17,"name":"Soil_Dirt"},{"x":16,"y":0,"z":17,"name":"Soil_Dirt"},{"x":0,"y":0,"z":18,"name":"Soil_Dirt"},{"x":1,"y":0,"z":18,"name":"Soil_Dirt"},{"x":2,"y":0,"z":18,"name":"Soil_Dirt"},{"x":3,"y":0,"z":18,"name":"Soil_Dirt"},{"x":4,"y":0,"z":18,"name":"Soil_Dirt"},{"x":5,"y":0,"z":18,"name":"Soil_Dirt"},{"x":6,"y":0,"z":18,"name":"Soil_Dirt"},{"x":7,"y":0,"z":18,"name":"Soil_Dirt"},{"x":8,"y":0,"z":18,"name":"Soil_Dirt"},{"x":9,"y":0,"z":18,"name":"Soil_Dirt"},{"x":10,"y":0,"z":18,"name":"Soil_Dirt"},{"x":11,"y":0,"z":18,"name":"Soil_Dirt"},{"x":12,"y":0,"z":18,"name":"Soil_Dirt"},{"x":13,"y":0,"z":18,"name":"Soil_Dirt"},{"x":14,"y":0,"z":18,"name":"Soil_Dirt"},{"x":15,"y":0,"z":18,"name":"Soil_Dirt"},{"x":16,"y":0,"z":18,"name":"Soil_Dirt"},{"x":0,"y":0,"z":19,"name":"Soil_Dirt"},{"x":1,"y":0,"z":19,"name":"Soil_Dirt"},{"x":2,"y":0,"z":19,"name":"Soil_Dirt"},{"x":3,"y":0,"z":19,"name":"Soil_Dirt"},{"x":4,"y":0,"z":19,"name":"Soil_Dirt"},{"x":5,"y":0,"z":19,"name":"Soil_Dirt"},{"x":6,"y":0,"z":19,"name":"Soil_Dirt"},{"x":7,"y":0,"z":19,"name":"Soil_Dirt"},{"x":8,"y":0,"z":19,"name":"Soil_Dirt"},{"x":9,"y":0,"z":19,"name":"Soil_Dirt"},{"x":10,"y":0,"z":19,"name":"Soil_Dirt"},{"x":11,"y":0,"z":19,"name":"Soil_Dirt"},{"x":12,"y":0,"z":19,"name":"Soil_Dirt"},{"x":13,"y":0,"z":19,"name":"Soil_Dirt"},{"x":14,"y":0,"z":19,"name":"Soil_Dirt"},{"x":15,"y":0,"z":19,"name":"Soil_Dirt"},{"x":16,"y":0,"z":19,"name":"Soil_Dirt"},{"x":0,"y":0,"z":20,"name":"Soil_Dirt"},{"x":1,"y":0,"z":20,"name":"Soil_Dirt"},{"x":2,"y":0,"z":20,"name":"Soil_Dirt"},{"x":3,"y":0,"z":20,"name":"Soil_Dirt"},{"x":4,"y":0,"z":20,"name":"Soil_Dirt"},{"x":5,"y":0,"z":20,"name":"Soil_Dirt"},{"x":6,"y":0,"z":20,"name":"Soil_Dirt"},{"x":7,"y":0,"z":20,"name":"Soil_Dirt"},{"x":8,"y":0,"z":20,"name":"Soil_Dirt"},{"x":9,"y":0,"z":20,"name":"Soil_Dirt"},{"x":10,"y":0,"z":20,"name":"Soil_Dirt"},{"x":11,"y":0,"z":20,"name":"Soil_Dirt"},{"x":12,"y":0,"z":20,"name":"Soil_Dirt"},{"x":13,"y":0,"z":20,"name":"Soil_Dirt"},{"x":14,"y":0,"z":20,"name":"Soil_Dirt"},{"x":15,"y":0,"z":20,"name":"Soil_Dirt"},{"x":16,"y":0,"z":20,"name":"Soil_Dirt"},{"x":0,"y":0,"z":21,"name":"Soil_Dirt"},{"x":1,"y":0,"z":21,"name":"Soil_Dirt"},{"x":2,"y":0,"z":21,"name":"Soil_Dirt"},{"x":3,"y":0,"z":21,"name":"Soil_Dirt"},{"x":4,"y":0,"z":21,"name":"Soil_Dirt"},{"x":5,"y":0,"z":21,"name":"Soil_Dirt"},{"x":6,"y":0,"z":21,"name":"Soil_Dirt"},{"x":7,"y":0,"z":21,"name":"Soil_Dirt"},{"x":8,"y":0,"z":21,"name":"Soil_Dirt"},{"x":9,"y":0,"z":21,"name":"Soil_Dirt"},{"x":10,"y":0,"z":21,"name":"Soil_Dirt"},{"x":11,"y":0,"z":21,"name":"Soil_Dirt"},{"x":12,"y":0,"z":21,"name":"Soil_Dirt"},{"x":13,"y":0,"z":21,"name":"Soil_Dirt"},{"x":14,"y":0,"z":21,"name":"Soil_Dirt"},{"x":15,"y":0,"z":21,"name":"Soil_Dirt"},{"x":16,"y":0,"z":21,"name":"Soil_Dirt"},{"x":0,"y":0,"z":22,"name":"Soil_Dirt"},{"x":1,"y":0,"z":22,"name":"Soil_Dirt"},{"x":2,"y":0,"z":22,"name":"Soil_Dirt"},{"x":3,"y":0,"z":22,"name":"Soil_Dirt"},{"x":4,"y":0,"z":22,"name":"Soil_Dirt"},{"x":5,"y":0,"z":22,"name":"Soil_Dirt"},{"x":6,"y":0,"z":22,"name":"Soil_Dirt"},{"x":7,"y":0,"z":22,"name":"Soil_Dirt"},{"x":8,"y":0,"z":22,"name":"Soil_Dirt"},{"x":9,"y":0,"z":22,"name":"Soil_Dirt"},{"x":10,"y":0,"z":22,"name":"Soil_Dirt"},{"x":11,"y":0,"z":22,"name":"Soil_Dirt"},{"x":12,"y":0,"z":22,"name":"Soil_Dirt"},{"x":13,"y":0,"z":22,"name":"Soil_Dirt"},{"x":14,"y":0,"z":22,"name":"Soil_Dirt"},{"x":15,"y":0,"z":22,"name":"Soil_Dirt"},{"x":16,"y":0,"z":22,"name":"Soil_Dirt"},{"x":0,"y":1,"z":0,"name":"Soil_Grass"},{"x":1,"y":1,"z":0,"name":"Soil_Grass"},{"x":2,"y":1,"z":0,"name":"Soil_Grass"},{"x":3,"y":1,"z":0,"name":"Soil_Grass"},{"x":4,"y":1,"z":0,"name":"Soil_Dirt"},{"x":5,"y":1,"z":0,"name":"Soil_Dirt"},{"x":6,"y":1,"z":0,"name":"Soil_Pathway"},{"x":7,"y":1,"z":0,"name":"Soil_Pathway"},{"x":8,"y":1,"z":0,"name":"Soil_Pathway"},{"x":9,"y":1,"z":0,"name":"Soil_Grass"},{"x":10,"y":1,"z":0,"name":"Soil_Dirt"},{"x":11,"y":1,"z":0,"name":"Soil_Grass"},{"x":12,"y":1,"z":0,"name":"Soil_Grass"},{"x":13,"y":1,"z":0,"name":"Rock_Stone_Cobble_Stairs","rotation":2},{"x":14,"y":1,"z":0,"name":"Soil_Grass"},{"x":15,"y":1,"z":0,"name":"Soil_Grass"},{"x":0,"y":1,"z":1,"name":"Soil_Grass"},{"x":1,"y":1,"z":1,"name":"Soil_Grass"},{"x":2,"y":1,"z":1,"name":"Soil_Grass"},{"x":3,"y":1,"z":1,"name":"Soil_Grass"},{"x":4,"y":1,"z":1,"name":"Rock_Stone_Cobble_Mossy"},{"x":5,"y":1,"z":1,"name":"Soil_Grass"},{"x":6,"y":1,"z":1,"name":"Soil_Dirt"},{"x":7,"y":1,"z":1,"name":"Soil_Pathway"},{"x":8,"y":1,"z":1,"name":"Soil_Pathway"},{"x":9,"y":1,"z":1,"name":"Soil_Grass"},{"x":10,"y":1,"z":1,"name":"Rock_Stone_Cobble_Mossy"},{"x":11,"y":1,"z":1,"name":"Rock_Stone_Cobble_Mossy"},{"x":12,"y":1,"z":1,"name":"Soil_Grass"},{"x":13,"y":1,"z":1,"name":"Soil_Dirt"},{"x":14,"y":1,"z":1,"name":"Rock_Stone_Cobble_Stairs","rotation":1},{"x":15,"y":1,"z":1,"name":"Soil_Grass"},{"x":16,"y":1,"z":1,"name":"Soil_Grass"},{"x":0,"y":1,"z":2,"name":"Soil_Dirt"},{"x":1,"y":1,"z":2,"name":"Soil_Grass"},{"x":2,"y":1,"z":2,"name":"Soil_Dirt"},{"x":3,"y":1,"z":2,"name":"Rock_Stone_Cobble_Mossy_Half","rotation":8},{"x":4,"y":1,"z":2,"name":"Soil_Grass"},{"x":5,"y":1,"z":2,"name":"Soil_Grass"},{"x":6,"y":1,"z":2,"name":"Soil_Grass"},{"x":7,"y":1,"z":2,"name":"Soil_Pathway"},{"x":8,"y":1,"z":2,"name":"Soil_Pathway"},{"x":9,"y":1,"z":2,"name":"Soil_Dirt"},{"x":10,"y":1,"z":2,"name":"Soil_Dirt"},{"x":11,"y":1,"z":2,"name":"Rock_Stone_Cobble_Mossy_Half","rotation":8},{"x":12,"y":1,"z":2,"name":"Soil_Grass"},{"x":13,"y":1,"z":2,"name":"Soil_Grass"},{"x":14,"y":1,"z":2,"name":"Soil_Grass"},{"x":15,"y":1,"z":2,"name":"Soil_Grass"},{"x":16,"y":1,"z":2,"name":"Soil_Grass"},{"x":0,"y":1,"z":3,"name":"Soil_Grass"},{"x":1,"y":1,"z":3,"name":"Soil_Grass"},{"x":2,"y":1,"z":3,"name":"Soil_Dirt"},{"x":3,"y":1,"z":3,"name":"Soil_Dirt"},{"x":4,"y":1,"z":3,"name":"Soil_Grass"},{"x":5,"y":1,"z":3,"name":"Soil_Dirt"},{"x":6,"y":1,"z":3,"name":"Soil_Dirt_Burnt"},{"x":7,"y":1,"z":3,"name":"Soil_Dirt"},{"x":8,"y":1,"z":3,"name":"Soil_Dirt"},{"x":9,"y":1,"z":3,"name":"Soil_Dirt"},{"x":10,"y":1,"z":3,"name":"Soil_Dirt"},{"x":11,"y":1,"z":3,"name":"Soil_Dirt"},{"x":12,"y":1,"z":3,"name":"Soil_Grass"},{"x":13,"y":1,"z":3,"name":"Soil_Dirt"},{"x":14,"y":1,"z":3,"name":"Soil_Dirt"},{"x":15,"y":1,"z":3,"name":"Soil_Dirt_Burnt"},{"x":16,"y":1,"z":3,"name":"Soil_Grass"},{"x":0,"y":1,"z":4,"name":"Soil_Dirt"},{"x":1,"y":1,"z":4,"name":"Soil_Dirt_Burnt"},{"x":2,"y":1,"z":4,"name":"Wood_Oak_Trunk","rotation":2},{"x":3,"y":1,"z":4,"name":"Soil_Dirt"},{"x":4,"y":1,"z":4,"name":"Soil_Grass"},{"x":5,"y":1,"z":4,"name":"Soil_Dirt_Burnt"},{"x":6,"y":1,"z":4,"name":"Wood_Oak_Trunk","rotation":2},{"x":7,"y":1,"z":4,"name":"Wood_Darkwood_Stairs","rotation":8},{"x":8,"y":1,"z":4,"name":"Soil_Dirt"},{"x":9,"y":1,"z":4,"name":"Wood_Darkwood_Stairs","rotation":8},{"x":10,"y":1,"z":4,"name":"Wood_Oak_Trunk","rotation":2},{"x":11,"y":1,"z":4,"name":"Soil_Dirt"},{"x":12,"y":1,"z":4,"name":"Soil_Dirt"},{"x":13,"y":1,"z":4,"name":"Soil_Dirt_Burnt"},{"x":14,"y":1,"z":4,"name":"Wood_Oak_Trunk","rotation":2},{"x":15,"y":1,"z":4,"name":"Soil_Dirt"},{"x":16,"y":1,"z":4,"name":"Soil_Grass"},{"x":0,"y":1,"z":5,"name":"Soil_Grass"},{"x":1,"y":1,"z":5,"name":"Wood_Oak_Trunk","rotation":2},{"x":2,"y":1,"z":5,"name":"Wood_Oak_Trunk","rotation":2},{"x":3,"y":1,"z":5,"name":"Cloth_Block_Wool_Cyan"},{"x":4,"y":1,"z":5,"name":"Cloth_Block_Wool_White"},{"x":5,"y":1,"z":5,"name":"Cloth_Block_Wool_Cyan"},{"x":6,"y":1,"z":5,"name":"Wood_Oak_Trunk","rotation":2},{"x":7,"y":1,"z":5,"name":"Cloth_Block_Wool_Cyan"},{"x":8,"y":1,"z":5,"name":"Cloth_Block_Wool_White"},{"x":9,"y":1,"z":5,"name":"Cloth_Block_Wool_Cyan"},{"x":10,"y":1,"z":5,"name":"Wood_Oak_Trunk","rotation":2},{"x":11,"y":1,"z":5,"name":"Cloth_Block_Wool_Cyan"},{"x":12,"y":1,"z":5,"name":"Cloth_Block_Wool_White"},{"x":13,"y":1,"z":5,"name":"Cloth_Block_Wool_Cyan"},{"x":14,"y":1,"z":5,"name":"Wood_Oak_Trunk","rotation":2},{"x":15,"y":1,"z":5,"name":"Wood_Oak_Trunk","rotation":2},{"x":16,"y":1,"z":5,"name":"Soil_Dirt"},{"x":0,"y":1,"z":6,"name":"Soil_Dirt"},{"x":1,"y":1,"z":6,"name":"Soil_Dirt"},{"x":2,"y":1,"z":6,"name":"Cloth_Block_Wool_Cyan"},{"x":3,"y":1,"z":6,"name":"Wood_Darkwood_Planks"},{"x":4,"y":1,"z":6,"name":"Wood_Darkwood_Planks"},{"x":5,"y":1,"z":6,"name":"Wood_Darkwood_Planks"},{"x":6,"y":1,"z":6,"name":"Wood_Darkwood_Planks"},{"x":7,"y":1,"z":6,"name":"Wood_Darkwood_Planks"},{"x":8,"y":1,"z":6,"name":"Wood_Darkwood_Planks"},{"x":9,"y":1,"z":6,"name":"Wood_Darkwood_Planks"},{"x":10,"y":1,"z":6,"name":"Wood_Darkwood_Planks"},{"x":11,"y":1,"z":6,"name":"Wood_Darkwood_Planks"},{"x":12,"y":1,"z":6,"name":"Wood_Darkwood_Planks"},{"x":13,"y":1,"z":6,"name":"Wood_Darkwood_Planks"},{"x":14,"y":1,"z":6,"name":"Cloth_Block_Wool_Cyan"},{"x":15,"y":1,"z":6,"name":"Soil_Dirt"},{"x":16,"y":1,"z":6,"name":"Soil_Dirt_Burnt"},{"x":0,"y":1,"z":7,"name":"Soil_Grass"},{"x":1,"y":1,"z":7,"name":"Soil_Grass"},{"x":2,"y":1,"z":7,"name":"Cloth_Block_Wool_White"},{"x":3,"y":1,"z":7,"name":"Wood_Darkwood_Planks"},{"x":4,"y":1,"z":7,"name":"Wood_Darkwood_Planks"},{"x":5,"y":1,"z":7,"name":"Wood_Darkwood_Planks"},{"x":6,"y":1,"z":7,"name":"Wood_Darkwood_Planks"},{"x":7,"y":1,"z":7,"name":"Wood_Darkwood_Planks"},{"x":8,"y":1,"z":7,"name":"Wood_Darkwood_Planks"},{"x":9,"y":1,"z":7,"name":"Wood_Darkwood_Planks"},{"x":10,"y":1,"z":7,"name":"Wood_Darkwood_Planks"},{"x":11,"y":1,"z":7,"name":"Wood_Darkwood_Planks"},{"x":12,"y":1,"z":7,"name":"Wood_Darkwood_Planks"},{"x":13,"y":1,"z":7,"name":"Wood_Darkwood_Planks"},{"x":14,"y":1,"z":7,"name":"Cloth_Block_Wool_White"},{"x":15,"y":1,"z":7,"name":"Soil_Dirt"},{"x":16,"y":1,"z":7,"name":"Soil_Dirt"},{"x":0,"y":1,"z":8,"name":"Soil_Dirt"},{"x":1,"y":1,"z":8,"name":"Soil_Grass"},{"x":2,"y":1,"z":8,"name":"Cloth_Block_Wool_Cyan"},{"x":3,"y":1,"z":8,"name":"Wood_Darkwood_Planks"},{"x":4,"y":1,"z":8,"name":"Wood_Darkwood_Planks"},{"x":5,"y":1,"z":8,"name":"Wood_Darkwood_Planks"},{"x":6,"y":1,"z":8,"name":"Wood_Darkwood_Planks"},{"x":7,"y":1,"z":8,"name":"Wood_Darkwood_Planks"},{"x":8,"y":1,"z":8,"name":"Wood_Darkwood_Planks"},{"x":9,"y":1,"z":8,"name":"Wood_Darkwood_Planks"},{"x":10,"y":1,"z":8,"name":"Wood_Darkwood_Planks"},{"x":11,"y":1,"z":8,"name":"Wood_Darkwood_Planks"},{"x":12,"y":1,"z":8,"name":"Wood_Darkwood_Planks"},{"x":13,"y":1,"z":8,"name":"Wood_Darkwood_Planks"},{"x":14,"y":1,"z":8,"name":"Cloth_Block_Wool_Cyan"},{"x":15,"y":1,"z":8,"name":"Soil_Dirt_Burnt"},{"x":16,"y":1,"z":8,"name":"Soil_Dirt"},{"x":0,"y":1,"z":9,"name":"Soil_Grass"},{"x":1,"y":1,"z":9,"name":"Wood_Oak_Trunk","rotation":2},{"x":2,"y":1,"z":9,"name":"Wood_Oak_Trunk","rotation":2},{"x":3,"y":1,"z":9,"name":"Wood_Darkwood_Planks"},{"x":4,"y":1,"z":9,"name":"Wood_Darkwood_Planks"},{"x":5,"y":1,"z":9,"name":"Wood_Darkwood_Planks"},{"x":6,"y":1,"z":9,"name":"Wood_Darkwood_Planks"},{"x":7,"y":1,"z":9,"name":"Wood_Darkwood_Planks"},{"x":8,"y":1,"z":9,"name":"Wood_Darkwood_Planks"},{"x":9,"y":1,"z":9,"name":"Wood_Darkwood_Planks"},{"x":10,"y":1,"z":9,"name":"Wood_Darkwood_Planks"},{"x":11,"y":1,"z":9,"name":"Wood_Darkwood_Planks"},{"x":12,"y":1,"z":9,"name":"Wood_Darkwood_Planks"},{"x":13,"y":1,"z":9,"name":"Wood_Darkwood_Planks"},{"x":14,"y":1,"z":9,"name":"Wood_Oak_Trunk","rotation":2},{"x":15,"y":1,"z":9,"name":"Wood_Oak_Trunk","rotation":2},{"x":16,"y":1,"z":9,"name":"Soil_Dirt_Burnt"},{"x":0,"y":1,"z":10,"name":"Soil_Grass"},{"x":1,"y":1,"z":10,"name":"Soil_Dirt"},{"x":2,"y":1,"z":10,"name":"Cloth_Block_Wool_Cyan"},{"x":3,"y":1,"z":10,"name":"Wood_Darkwood_Planks"},{"x":4,"y":1,"z":10,"name":"Wood_Darkwood_Planks"},{"x":5,"y":1,"z":10,"name":"Wood_Darkwood_Planks"},{"x":6,"y":1,"z":10,"name":"Wood_Darkwood_Planks"},{"x":7,"y":1,"z":10,"name":"Wood_Darkwood_Planks"},{"x":8,"y":1,"z":10,"name":"Wood_Darkwood_Planks"},{"x":9,"y":1,"z":10,"name":"Wood_Darkwood_Planks"},{"x":10,"y":1,"z":10,"name":"Wood_Darkwood_Planks"},{"x":11,"y":1,"z":10,"name":"Wood_Darkwood_Planks"},{"x":12,"y":1,"z":10,"name":"Wood_Darkwood_Planks"},{"x":13,"y":1,"z":10,"name":"Wood_Darkwood_Planks"},{"x":14,"y":1,"z":10,"name":"Cloth_Block_Wool_Cyan"},{"x":15,"y":1,"z":10,"name":"Soil_Dirt"},{"x":16,"y":1,"z":10,"name":"Soil_Dirt"},{"x":0,"y":1,"z":11,"name":"Soil_Dirt"},{"x":1,"y":1,"z":11,"name":"Soil_Dirt_Burnt"},{"x":2,"y":1,"z":11,"name":"Cloth_Block_Wool_White"},{"x":3,"y":1,"z":11,"name":"Wood_Darkwood_Planks"},{"x":4,"y":1,"z":11,"name":"Wood_Darkwood_Planks"},{"x":5,"y":1,"z":11,"name":"Wood_Darkwood_Planks"},{"x":6,"y":1,"z":11,"name":"Wood_Darkwood_Planks"},{"x":7,"y":1,"z":11,"name":"Wood_Darkwood_Planks"},{"x":8,"y":1,"z":11,"name":"Wood_Darkwood_Planks"},{"x":9,"y":1,"z":11,"name":"Wood_Darkwood_Planks"},{"x":10,"y":1,"z":11,"name":"Wood_Darkwood_Planks"},{"x":11,"y":1,"z":11,"name":"Wood_Darkwood_Planks"},{"x":12,"y":1,"z":11,"name":"Wood_Darkwood_Planks"},{"x":13,"y":1,"z":11,"name":"Wood_Darkwood_Planks"},{"x":14,"y":1,"z":11,"name":"Cloth_Block_Wool_White"},{"x":15,"y":1,"z":11,"name":"Soil_Dirt"},{"x":16,"y":1,"z":11,"name":"Soil_Dirt"},{"x":0,"y":1,"z":12,"name":"Soil_Dirt_Burnt"},{"x":1,"y":1,"z":12,"name":"Soil_Dirt"},{"x":2,"y":1,"z":12,"name":"Cloth_Block_Wool_Cyan"},{"x":3,"y":1,"z":12,"name":"Wood_Darkwood_Planks"},{"x":4,"y":1,"z":12,"name":"Wood_Darkwood_Planks"},{"x":5,"y":1,"z":12,"name":"Wood_Darkwood_Planks"},{"x":6,"y":1,"z":12,"name":"Wood_Darkwood_Planks"},{"x":7,"y":1,"z":12,"name":"Wood_Darkwood_Planks"},{"x":8,"y":1,"z":12,"name":"Wood_Darkwood_Planks"},{"x":9,"y":1,"z":12,"name":"Wood_Darkwood_Planks"},{"x":10,"y":1,"z":12,"name":"Wood_Darkwood_Planks"},{"x":11,"y":1,"z":12,"name":"Wood_Darkwood_Planks"},{"x":12,"y":1,"z":12,"name":"Wood_Darkwood_Planks"},{"x":13,"y":1,"z":12,"name":"Wood_Darkwood_Planks"},{"x":14,"y":1,"z":12,"name":"Cloth_Block_Wool_Cyan"},{"x":15,"y":1,"z":12,"name":"Soil_Grass"},{"x":16,"y":1,"z":12,"name":"Soil_Grass"},{"x":0,"y":1,"z":13,"name":"Soil_Grass"},{"x":1,"y":1,"z":13,"name":"Wood_Oak_Trunk","rotation":2},{"x":2,"y":1,"z":13,"name":"Wood_Oak_Trunk","rotation":2},{"x":3,"y":1,"z":13,"name":"Wood_Darkwood_Planks"},{"x":4,"y":1,"z":13,"name":"Wood_Darkwood_Planks"},{"x":5,"y":1,"z":13,"name":"Wood_Darkwood_Planks"},{"x":6,"y":1,"z":13,"name":"Wood_Darkwood_Planks"},{"x":7,"y":1,"z":13,"name":"Wood_Darkwood_Planks"},{"x":8,"y":1,"z":13,"name":"Wood_Darkwood_Planks"},{"x":9,"y":1,"z":13,"name":"Wood_Darkwood_Planks"},{"x":10,"y":1,"z":13,"name":"Wood_Darkwood_Planks"},{"x":11,"y":1,"z":13,"name":"Wood_Darkwood_Planks"},{"x":12,"y":1,"z":13,"name":"Wood_Darkwood_Planks"},{"x":13,"y":1,"z":13,"name":"Wood_Darkwood_Planks"},{"x":14,"y":1,"z":13,"name":"Wood_Oak_Trunk","rotation":2},{"x":15,"y":1,"z":13,"name":"Wood_Oak_Trunk","rotation":2},{"x":16,"y":1,"z":13,"name":"Soil_Dirt_Burnt"},{"x":0,"y":1,"z":14,"name":"Soil_Grass"},{"x":1,"y":1,"z":14,"name":"Soil_Grass"},{"x":2,"y":1,"z":14,"name":"Cloth_Block_Wool_Cyan"},{"x":3,"y":1,"z":14,"name":"Wood_Darkwood_Planks"},{"x":4,"y":1,"z":14,"name":"Wood_Darkwood_Planks"},{"x":5,"y":1,"z":14,"name":"Wood_Darkwood_Planks"},{"x":6,"y":1,"z":14,"name":"Wood_Darkwood_Planks"},{"x":7,"y":1,"z":14,"name":"Wood_Darkwood_Planks"},{"x":8,"y":1,"z":14,"name":"Wood_Darkwood_Planks"},{"x":9,"y":1,"z":14,"name":"Wood_Darkwood_Planks"},{"x":10,"y":1,"z":14,"name":"Wood_Darkwood_Planks"},{"x":11,"y":1,"z":14,"name":"Wood_Darkwood_Planks"},{"x":12,"y":1,"z":14,"name":"Wood_Darkwood_Planks"},{"x":13,"y":1,"z":14,"name":"Wood_Darkwood_Planks"},{"x":14,"y":1,"z":14,"name":"Cloth_Block_Wool_Cyan"},{"x":15,"y":1,"z":14,"name":"Soil_Dirt"},{"x":16,"y":1,"z":14,"name":"Soil_Dirt"},{"x":0,"y":1,"z":15,"name":"Soil_Dirt"},{"x":1,"y":1,"z":15,"name":"Soil_Grass"},{"x":2,"y":1,"z":15,"name":"Cloth_Block_Wool_White"},{"x":3,"y":1,"z":15,"name":"Wood_Darkwood_Planks"},{"x":4,"y":1,"z":15,"name":"Wood_Darkwood_Planks"},{"x":5,"y":1,"z":15,"name":"Wood_Darkwood_Planks"},{"x":6,"y":1,"z":15,"name":"Wood_Darkwood_Planks"},{"x":7,"y":1,"z":15,"name":"Wood_Darkwood_Planks"},{"x":8,"y":1,"z":15,"name":"Wood_Darkwood_Planks"},{"x":9,"y":1,"z":15,"name":"Wood_Darkwood_Planks"},{"x":10,"y":1,"z":15,"name":"Wood_Darkwood_Planks"},{"x":11,"y":1,"z":15,"name":"Wood_Darkwood_Planks"},{"x":12,"y":1,"z":15,"name":"Wood_Darkwood_Planks"},{"x":13,"y":1,"z":15,"name":"Wood_Darkwood_Planks"},{"x":14,"y":1,"z":15,"name":"Cloth_Block_Wool_White"},{"x":15,"y":1,"z":15,"name":"Soil_Dirt"},{"x":16,"y":1,"z":15,"name":"Soil_Dirt_Burnt"},{"x":0,"y":1,"z":16,"name":"Soil_Dirt"},{"x":1,"y":1,"z":16,"name":"Soil_Dirt"},{"x":2,"y":1,"z":16,"name":"Cloth_Block_Wool_Cyan"},{"x":3,"y":1,"z":16,"name":"Wood_Darkwood_Planks"},{"x":4,"y":1,"z":16,"name":"Wood_Darkwood_Planks"},{"x":5,"y":1,"z":16,"name":"Wood_Darkwood_Planks"},{"x":6,"y":1,"z":16,"name":"Wood_Darkwood_Planks"},{"x":7,"y":1,"z":16,"name":"Wood_Darkwood_Planks"},{"x":8,"y":1,"z":16,"name":"Wood_Darkwood_Planks"},{"x":9,"y":1,"z":16,"name":"Wood_Darkwood_Planks"},{"x":10,"y":1,"z":16,"name":"Wood_Darkwood_Planks"},{"x":11,"y":1,"z":16,"name":"Wood_Darkwood_Planks"},{"x":12,"y":1,"z":16,"name":"Wood_Darkwood_Planks"},{"x":13,"y":1,"z":16,"name":"Wood_Darkwood_Planks"},{"x":14,"y":1,"z":16,"name":"Cloth_Block_Wool_Cyan"},{"x":15,"y":1,"z":16,"name":"Soil_Dirt_Burnt"},{"x":16,"y":1,"z":16,"name":"Soil_Dirt"},{"x":0,"y":1,"z":17,"name":"Soil_Grass"},{"x":1,"y":1,"z":17,"name":"Wood_Oak_Trunk","rotation":2},{"x":2,"y":1,"z":17,"name":"Wood_Oak_Trunk","rotation":2},{"x":3,"y":1,"z":17,"name":"Cloth_Block_Wool_Cyan"},{"x":4,"y":1,"z":17,"name":"Cloth_Block_Wool_White"},{"x":5,"y":1,"z":17,"name":"Cloth_Block_Wool_Cyan"},{"x":6,"y":1,"z":17,"name":"Wood_Oak_Trunk","rotation":2},{"x":7,"y":1,"z":17,"name":"Cloth_Block_Wool_Cyan"},{"x":8,"y":1,"z":17,"name":"Cloth_Block_Wool_White"},{"x":9,"y":1,"z":17,"name":"Cloth_Block_Wool_Cyan"},{"x":10,"y":1,"z":17,"name":"Wood_Oak_Trunk","rotation":2},{"x":11,"y":1,"z":17,"name":"Cloth_Block_Wool_Cyan"},{"x":12,"y":1,"z":17,"name":"Cloth_Block_Wool_White"},{"x":13,"y":1,"z":17,"name":"Cloth_Block_Wool_Cyan"},{"x":14,"y":1,"z":17,"name":"Wood_Oak_Trunk","rotation":2},{"x":15,"y":1,"z":17,"name":"Wood_Oak_Trunk","rotation":2},{"x":16,"y":1,"z":17,"name":"Soil_Dirt_Burnt"},{"x":0,"y":1,"z":18,"name":"Soil_Dirt_Burnt"},{"x":1,"y":1,"z":18,"name":"Soil_Grass"},{"x":2,"y":1,"z":18,"name":"Wood_Oak_Trunk","rotation":2},{"x":3,"y":1,"z":18,"name":"Soil_Dirt_Burnt"},{"x":4,"y":1,"z":18,"name":"Soil_Grass"},{"x":5,"y":1,"z":18,"name":"Soil_Dirt"},{"x":6,"y":1,"z":18,"name":"Soil_Dirt"},{"x":7,"y":1,"z":18,"name":"Soil_Grass"},{"x":8,"y":1,"z":18,"name":"Soil_Grass"},{"x":9,"y":1,"z":18,"name":"Soil_Dirt"},{"x":10,"y":1,"z":18,"name":"Wood_Oak_Trunk","rotation":2},{"x":11,"y":1,"z":18,"name":"Soil_Dirt_Burnt"},{"x":12,"y":1,"z":18,"name":"Soil_Dirt"},{"x":13,"y":1,"z":18,"name":"Soil_Dirt"},{"x":14,"y":1,"z":18,"name":"Wood_Oak_Trunk","rotation":2},{"x":15,"y":1,"z":18,"name":"Soil_Grass"},{"x":16,"y":1,"z":18,"name":"Soil_Dirt"},{"x":0,"y":1,"z":19,"name":"Soil_Dirt"},{"x":1,"y":1,"z":19,"name":"Soil_Dirt"},{"x":2,"y":1,"z":19,"name":"Soil_Dirt_Burnt"},{"x":3,"y":1,"z":19,"name":"Soil_Grass"},{"x":4,"y":1,"z":19,"name":"Soil_Dirt"},{"x":5,"y":1,"z":19,"name":"Soil_Dirt_Burnt"},{"x":6,"y":1,"z":19,"name":"Soil_Dirt"},{"x":7,"y":1,"z":19,"name":"Soil_Dirt"},{"x":8,"y":1,"z":19,"name":"Soil_Grass"},{"x":9,"y":1,"z":19,"name":"Soil_Dirt"},{"x":10,"y":1,"z":19,"name":"Soil_Dirt_Burnt"},{"x":11,"y":1,"z":19,"name":"Soil_Dirt"},{"x":12,"y":1,"z":19,"name":"Soil_Grass"},{"x":13,"y":1,"z":19,"name":"Soil_Dirt"},{"x":14,"y":1,"z":19,"name":"Soil_Dirt"},{"x":15,"y":1,"z":19,"name":"Soil_Dirt"},{"x":16,"y":1,"z":19,"name":"Soil_Grass"},{"x":0,"y":1,"z":20,"name":"Soil_Grass"},{"x":1,"y":1,"z":20,"name":"Soil_Grass"},{"x":2,"y":1,"z":20,"name":"Soil_Dirt"},{"x":3,"y":1,"z":20,"name":"Soil_Grass"},{"x":4,"y":1,"z":20,"name":"Soil_Dirt"},{"x":5,"y":1,"z":20,"name":"Soil_Grass"},{"x":6,"y":1,"z":20,"name":"Soil_Grass"},{"x":7,"y":1,"z":20,"name":"Soil_Grass"},{"x":8,"y":1,"z":20,"name":"Soil_Grass"},{"x":9,"y":1,"z":20,"name":"Soil_Dirt_Burnt"},{"x":10,"y":1,"z":20,"name":"Soil_Grass"},{"x":11,"y":1,"z":20,"name":"Soil_Dirt"},{"x":12,"y":1,"z":20,"name":"Soil_Dirt_Burnt"},{"x":13,"y":1,"z":20,"name":"Soil_Grass"},{"x":14,"y":1,"z":20,"name":"Soil_Dirt_Burnt"},{"x":15,"y":1,"z":20,"name":"Soil_Grass"},{"x":16,"y":1,"z":20,"name":"Soil_Dirt_Burnt"},{"x":0,"y":1,"z":21,"name":"Soil_Grass"},{"x":1,"y":1,"z":21,"name":"Soil_Grass"},{"x":2,"y":1,"z":21,"name":"Soil_Grass"},{"x":3,"y":1,"z":21,"name":"Soil_Dirt"},{"x":4,"y":1,"z":21,"name":"Soil_Grass"},{"x":5,"y":1,"z":21,"name":"Soil_Grass"},{"x":6,"y":1,"z":21,"name":"Soil_Grass"},{"x":7,"y":1,"z":21,"name":"Soil_Dirt_Burnt"},{"x":8,"y":1,"z":21,"name":"Soil_Dirt_Burnt"},{"x":9,"y":1,"z":21,"name":"Soil_Grass"},{"x":10,"y":1,"z":21,"name":"Soil_Grass"},{"x":11,"y":1,"z":21,"name":"Soil_Grass"},{"x":12,"y":1,"z":21,"name":"Soil_Grass"},{"x":13,"y":1,"z":21,"name":"Soil_Grass"},{"x":14,"y":1,"z":21,"name":"Soil_Grass"},{"x":15,"y":1,"z":21,"name":"Soil_Grass"},{"x":16,"y":1,"z":21,"name":"Soil_Grass"},{"x":0,"y":1,"z":22,"name":"Soil_Grass"},{"x":1,"y":1,"z":22,"name":"Soil_Grass"},{"x":2,"y":1,"z":22,"name":"Soil_Grass"},{"x":3,"y":1,"z":22,"name":"Soil_Grass"},{"x":4,"y":1,"z":22,"name":"Soil_Grass"},{"x":5,"y":1,"z":22,"name":"Soil_Grass"},{"x":6,"y":1,"z":22,"name":"Soil_Grass"},{"x":7,"y":1,"z":22,"name":"Soil_Grass"},{"x":8,"y":1,"z":22,"name":"Soil_Grass"},{"x":9,"y":1,"z":22,"name":"Soil_Grass"},{"x":10,"y":1,"z":22,"name":"Soil_Grass"},{"x":11,"y":1,"z":22,"name":"Soil_Grass"},{"x":12,"y":1,"z":22,"name":"Soil_Grass"},{"x":13,"y":1,"z":22,"name":"Soil_Grass"},{"x":14,"y":1,"z":22,"name":"Soil_Grass"},{"x":15,"y":1,"z":22,"name":"Soil_Grass"},{"x":16,"y":1,"z":22,"name":"Soil_Grass"},{"x":0,"y":2,"z":0,"name":"Plant_Flower_Common_White2"},{"x":1,"y":2,"z":0,"name":"Plant_Grass_Sharp"},{"x":2,"y":2,"z":0,"name":"Plant_Grass_Sharp"},{"x":12,"y":2,"z":0,"name":"Plant_Grass_Sharp"},{"x":0,"y":2,"z":1,"name":"Plant_Grass_Sharp"},{"x":2,"y":2,"z":1,"name":"Plant_Crop_Mana1"},{"x":3,"y":2,"z":1,"name":"Plant_Grass_Sharp"},{"x":9,"y":2,"z":1,"name":"Plant_Grass_Sharp"},{"x":13,"y":2,"z":1,"name":"Rock_Stone_Cobble_Mossy_Half","rotation":0},{"x":15,"y":2,"z":1,"name":"Plant_Grass_Sharp"},{"x":16,"y":2,"z":1,"name":"Plant_Grass_Sharp"},{"x":1,"y":2,"z":2,"name":"Plant_Grass_Sharp"},{"x":14,"y":2,"z":2,"name":"*Plant_Crop_Berry_Block_State_Definitions_StageFinal"},{"x":16,"y":2,"z":2,"name":"Plant_Grass_Sharp"},{"x":2,"y":2,"z":3,"name":"Plant_Leaves_Beech","support":15},{"x":6,"y":2,"z":3,"name":"*Plant_Crop_Berry_Block_State_Definitions_StageFinal"},{"x":12,"y":2,"z":3,"name":"*Plant_Crop_Berry_Block_State_Definitions_StageFinal"},{"x":13,"y":2,"z":3,"name":"Plant_Leaves_Beech","support":15},{"x":14,"y":2,"z":3,"name":"Plant_Grass_Sharp_Wild"},{"x":1,"y":2,"z":4,"name":"Plant_Flower_Tall_Pink"},{"x":2,"y":2,"z":4,"name":"Wood_Oak_Trunk","rotation":2},{"x":3,"y":2,"z":4,"name":"Plant_Leaves_Beech","support":15},{"x":4,"y":2,"z":4,"name":"Plant_Grass_Sharp_Wild"},{"x":5,"y":2,"z":4,"name":"*Plant_Crop_Berry_Block_State_Definitions_StageFinal"},{"x":6,"y":2,"z":4,"name":"Wood_Oak_Trunk","rotation":2},{"x":7,"y":2,"z":4,"name":"Wood_Darkwood_Stairs","rotation":2},{"x":8,"y":2,"z":4,"name":"Wood_Darkwood_Stairs","rotation":2},{"x":9,"y":2,"z":4,"name":"Wood_Darkwood_Stairs","rotation":2},{"x":10,"y":2,"z":4,"name":"Wood_Oak_Trunk","rotation":2},{"x":11,"y":2,"z":4,"name":"Plant_Grass_Sharp_Wild"},{"x":12,"y":2,"z":4,"name":"Plant_Leaves_Beech","support":15},{"x":13,"y":2,"z":4,"name":"Plant_Leaves_Beech","support":15},{"x":14,"y":2,"z":4,"name":"Wood_Oak_Trunk","rotation":2},{"x":15,"y":2,"z":4,"name":"Plant_Leaves_Beech","support":15},{"x":16,"y":2,"z":4,"name":"Plant_Flower_Common_White2"},{"x":0,"y":2,"z":5,"name":"*Plant_Crop_Berry_Block_State_Definitions_StageFinal"},{"x":1,"y":2,"z":5,"name":"Wood_Oak_Trunk","rotation":2},{"x":2,"y":2,"z":5,"name":"Wood_Oak_Trunk","rotation":2},{"x":3,"y":2,"z":5,"name":"Rock_Stone_Brick"},{"x":4,"y":2,"z":5,"name":"Rock_Stone_Brick"},{"x":5,"y":2,"z":5,"name":"Rock_Stone_Brick"},{"x":6,"y":2,"z":5,"name":"Wood_Oak_Trunk","rotation":2},{"x":7,"y":2,"z":5,"name":"Wood_Darkwood_Planks"},{"x":8,"y":2,"z":5,"name":"Wood_Darkwood_Planks"},{"x":9,"y":2,"z":5,"name":"Wood_Darkwood_Planks"},{"x":10,"y":2,"z":5,"name":"Wood_Oak_Trunk","rotation":2},{"x":11,"y":2,"z":5,"name":"Rock_Stone_Brick"},{"x":12,"y":2,"z":5,"name":"Rock_Stone_Brick"},{"x":13,"y":2,"z":5,"name":"Rock_Stone_Brick"},{"x":14,"y":2,"z":5,"name":"Wood_Oak_Trunk","rotation":2},{"x":15,"y":2,"z":5,"name":"Wood_Oak_Trunk","rotation":2},{"x":1,"y":2,"z":6,"name":"Plant_Flower_Tall_Pink"},{"x":2,"y":2,"z":6,"name":"Rock_Stone_Brick"},{"x":3,"y":2,"z":6,"name":"Wood_Darkwood_Planks"},{"x":4,"y":2,"z":6,"name":"Wood_Darkwood_Planks"},{"x":5,"y":2,"z":6,"name":"Wood_Darkwood_Planks"},{"x":6,"y":2,"z":6,"name":"Wood_Darkwood_Planks"},{"x":7,"y":2,"z":6,"name":"Wood_Darkwood_Planks"},{"x":8,"y":2,"z":6,"name":"Wood_Darkwood_Planks"},{"x":9,"y":2,"z":6,"name":"Wood_Darkwood_Planks"},{"x":10,"y":2,"z":6,"name":"Wood_Darkwood_Planks"},{"x":11,"y":2,"z":6,"name":"Wood_Darkwood_Planks"},{"x":12,"y":2,"z":6,"name":"Wood_Darkwood_Planks"},{"x":13,"y":2,"z":6,"name":"Wood_Darkwood_Planks"},{"x":14,"y":2,"z":6,"name":"Rock_Stone_Brick"},{"x":1,"y":2,"z":7,"name":"Plant_Leaves_Beech","support":15},{"x":2,"y":2,"z":7,"name":"Rock_Stone_Brick"},{"x":3,"y":2,"z":7,"name":"Wood_Darkwood_Planks"},{"x":4,"y":2,"z":7,"name":"Wood_Darkwood_Planks"},{"x":5,"y":2,"z":7,"name":"Wood_Darkwood_Planks"},{"x":6,"y":2,"z":7,"name":"Wood_Darkwood_Planks"},{"x":7,"y":2,"z":7,"name":"Wood_Darkwood_Planks"},{"x":8,"y":2,"z":7,"name":"Wood_Darkwood_Planks"},{"x":9,"y":2,"z":7,"name":"Wood_Darkwood_Planks"},{"x":10,"y":2,"z":7,"name":"Wood_Darkwood_Planks"},{"x":11,"y":2,"z":7,"name":"Wood_Darkwood_Planks"},{"x":12,"y":2,"z":7,"name":"Wood_Darkwood_Planks"},{"x":13,"y":2,"z":7,"name":"Wood_Darkwood_Planks"},{"x":14,"y":2,"z":7,"name":"Rock_Stone_Brick"},{"x":0,"y":2,"z":8,"name":"Plant_Bush_Green"},{"x":1,"y":2,"z":8,"name":"Plant_Leaves_Beech","support":15},{"x":2,"y":2,"z":8,"name":"Rock_Stone_Brick"},{"x":3,"y":2,"z":8,"name":"Wood_Darkwood_Planks"},{"x":4,"y":2,"z":8,"name":"Wood_Darkwood_Planks"},{"x":5,"y":2,"z":8,"name":"Wood_Darkwood_Planks"},{"x":6,"y":2,"z":8,"name":"Wood_Darkwood_Planks"},{"x":7,"y":2,"z":8,"name":"Wood_Darkwood_Planks"},{"x":8,"y":2,"z":8,"name":"Wood_Darkwood_Planks"},{"x":9,"y":2,"z":8,"name":"Wood_Darkwood_Planks"},{"x":10,"y":2,"z":8,"name":"Wood_Darkwood_Planks"},{"x":11,"y":2,"z":8,"name":"Wood_Darkwood_Planks"},{"x":12,"y":2,"z":8,"name":"Wood_Darkwood_Planks"},{"x":13,"y":2,"z":8,"name":"Wood_Darkwood_Planks"},{"x":14,"y":2,"z":8,"name":"Rock_Stone_Brick"},{"x":15,"y":2,"z":8,"name":"Plant_Grass_Sharp_Wild"},{"x":0,"y":2,"z":9,"name":"Plant_Leaves_Beech","support":15},{"x":1,"y":2,"z":9,"name":"Wood_Oak_Trunk","rotation":2},{"x":2,"y":2,"z":9,"name":"Wood_Oak_Trunk","rotation":2},{"x":3,"y":2,"z":9,"name":"Wood_Darkwood_Planks"},{"x":4,"y":2,"z":9,"name":"Wood_Darkwood_Planks"},{"x":5,"y":2,"z":9,"name":"Wood_Darkwood_Planks"},{"x":6,"y":2,"z":9,"name":"Wood_Darkwood_Planks"},{"x":7,"y":2,"z":9,"name":"Wood_Darkwood_Planks"},{"x":8,"y":2,"z":9,"name":"Wood_Darkwood_Planks"},{"x":9,"y":2,"z":9,"name":"Wood_Darkwood_Planks"},{"x":10,"y":2,"z":9,"name":"Wood_Darkwood_Planks"},{"x":11,"y":2,"z":9,"name":"Wood_Darkwood_Planks"},{"x":12,"y":2,"z":9,"name":"Wood_Darkwood_Planks"},{"x":13,"y":2,"z":9,"name":"Wood_Darkwood_Planks"},{"x":14,"y":2,"z":9,"name":"Wood_Oak_Trunk","rotation":2},{"x":15,"y":2,"z":9,"name":"Wood_Oak_Trunk","rotation":2},{"x":16,"y":2,"z":9,"name":"Plant_Leaves_Beech","support":15},{"x":1,"y":2,"z":10,"name":"Plant_Grass_Sharp_Wild"},{"x":2,"y":2,"z":10,"name":"Rock_Stone_Brick"},{"x":3,"y":2,"z":10,"name":"Wood_Darkwood_Planks"},{"x":4,"y":2,"z":10,"name":"Wood_Darkwood_Planks"},{"x":5,"y":2,"z":10,"name":"Wood_Darkwood_Planks"},{"x":6,"y":2,"z":10,"name":"Wood_Darkwood_Planks"},{"x":7,"y":2,"z":10,"name":"Wood_Darkwood_Planks"},{"x":8,"y":2,"z":10,"name":"Wood_Darkwood_Planks"},{"x":9,"y":2,"z":10,"name":"Wood_Darkwood_Planks"},{"x":10,"y":2,"z":10,"name":"Wood_Darkwood_Planks"},{"x":11,"y":2,"z":10,"name":"Wood_Darkwood_Planks"},{"x":12,"y":2,"z":10,"name":"Wood_Darkwood_Planks"},{"x":13,"y":2,"z":10,"name":"Wood_Darkwood_Planks"},{"x":14,"y":2,"z":10,"name":"Rock_Stone_Brick"},{"x":15,"y":2,"z":10,"name":"Plant_Leaves_Beech","support":15},{"x":1,"y":2,"z":11,"name":"*Plant_Crop_Berry_Block_State_Definitions_StageFinal"},{"x":2,"y":2,"z":11,"name":"Rock_Stone_Brick"},{"x":3,"y":2,"z":11,"name":"Wood_Darkwood_Planks"},{"x":4,"y":2,"z":11,"name":"Wood_Darkwood_Planks"},{"x":5,"y":2,"z":11,"name":"Wood_Darkwood_Planks"},{"x":6,"y":2,"z":11,"name":"Wood_Darkwood_Planks"},{"x":7,"y":2,"z":11,"name":"Wood_Darkwood_Planks"},{"x":8,"y":2,"z":11,"name":"Wood_Darkwood_Planks"},{"x":9,"y":2,"z":11,"name":"Wood_Darkwood_Planks"},{"x":10,"y":2,"z":11,"name":"Wood_Darkwood_Planks"},{"x":11,"y":2,"z":11,"name":"Wood_Darkwood_Planks"},{"x":12,"y":2,"z":11,"name":"Wood_Darkwood_Planks"},{"x":13,"y":2,"z":11,"name":"Wood_Darkwood_Planks"},{"x":14,"y":2,"z":11,"name":"Rock_Stone_Brick"},{"x":2,"y":2,"z":12,"name":"Rock_Stone_Brick"},{"x":3,"y":2,"z":12,"name":"Wood_Darkwood_Planks"},{"x":4,"y":2,"z":12,"name":"Wood_Darkwood_Planks"},{"x":5,"y":2,"z":12,"name":"Wood_Darkwood_Planks"},{"x":6,"y":2,"z":12,"name":"Wood_Darkwood_Planks"},{"x":7,"y":2,"z":12,"name":"Wood_Darkwood_Planks"},{"x":8,"y":2,"z":12,"name":"Wood_Darkwood_Planks"},{"x":9,"y":2,"z":12,"name":"Wood_Darkwood_Planks"},{"x":10,"y":2,"z":12,"name":"Wood_Darkwood_Planks"},{"x":11,"y":2,"z":12,"name":"Wood_Darkwood_Planks"},{"x":12,"y":2,"z":12,"name":"Wood_Darkwood_Planks"},{"x":13,"y":2,"z":12,"name":"Wood_Darkwood_Planks"},{"x":14,"y":2,"z":12,"name":"Rock_Stone_Brick"},{"x":15,"y":2,"z":12,"name":"Plant_Bush_Green"},{"x":0,"y":2,"z":13,"name":"Plant_Leaves_Beech","support":15},{"x":1,"y":2,"z":13,"name":"Wood_Oak_Trunk","rotation":2},{"x":2,"y":2,"z":13,"name":"Wood_Oak_Trunk","rotation":2},{"x":3,"y":2,"z":13,"name":"Wood_Darkwood_Planks"},{"x":4,"y":2,"z":13,"name":"Wood_Darkwood_Planks"},{"x":5,"y":2,"z":13,"name":"Wood_Darkwood_Planks"},{"x":6,"y":2,"z":13,"name":"Wood_Darkwood_Planks"},{"x":7,"y":2,"z":13,"name":"Wood_Darkwood_Planks"},{"x":8,"y":2,"z":13,"name":"Wood_Darkwood_Planks"},{"x":9,"y":2,"z":13,"name":"Wood_Darkwood_Planks"},{"x":10,"y":2,"z":13,"name":"Wood_Darkwood_Planks"},{"x":11,"y":2,"z":13,"name":"Wood_Darkwood_Planks"},{"x":12,"y":2,"z":13,"name":"Wood_Darkwood_Planks"},{"x":13,"y":2,"z":13,"name":"Wood_Darkwood_Planks"},{"x":14,"y":2,"z":13,"name":"Wood_Oak_Trunk","rotation":2},{"x":15,"y":2,"z":13,"name":"Wood_Oak_Trunk","rotation":2},{"x":0,"y":2,"z":14,"name":"Plant_Flower_Tall_Pink"},{"x":1,"y":2,"z":14,"name":"Plant_Leaves_Beech","support":15},{"x":2,"y":2,"z":14,"name":"Rock_Stone_Brick"},{"x":3,"y":2,"z":14,"name":"Wood_Darkwood_Planks"},{"x":4,"y":2,"z":14,"name":"Wood_Darkwood_Planks"},{"x":5,"y":2,"z":14,"name":"Wood_Darkwood_Planks"},{"x":6,"y":2,"z":14,"name":"Wood_Darkwood_Planks"},{"x":7,"y":2,"z":14,"name":"Wood_Darkwood_Planks"},{"x":8,"y":2,"z":14,"name":"Wood_Darkwood_Planks"},{"x":9,"y":2,"z":14,"name":"Wood_Darkwood_Planks"},{"x":10,"y":2,"z":14,"name":"Wood_Darkwood_Planks"},{"x":11,"y":2,"z":14,"name":"Wood_Darkwood_Planks"},{"x":12,"y":2,"z":14,"name":"Wood_Darkwood_Planks"},{"x":13,"y":2,"z":14,"name":"Wood_Darkwood_Planks"},{"x":14,"y":2,"z":14,"name":"Rock_Stone_Brick"},{"x":1,"y":2,"z":15,"name":"Plant_Flower_Tall_Pink"},{"x":2,"y":2,"z":15,"name":"Rock_Stone_Brick"},{"x":3,"y":2,"z":15,"name":"Wood_Darkwood_Planks"},{"x":4,"y":2,"z":15,"name":"Wood_Darkwood_Planks"},{"x":5,"y":2,"z":15,"name":"Wood_Darkwood_Planks"},{"x":6,"y":2,"z":15,"name":"Wood_Darkwood_Planks"},{"x":7,"y":2,"z":15,"name":"Wood_Darkwood_Planks"},{"x":8,"y":2,"z":15,"name":"Wood_Darkwood_Planks"},{"x":9,"y":2,"z":15,"name":"Wood_Darkwood_Planks"},{"x":10,"y":2,"z":15,"name":"Wood_Darkwood_Planks"},{"x":11,"y":2,"z":15,"name":"Wood_Darkwood_Planks"},{"x":12,"y":2,"z":15,"name":"Wood_Darkwood_Planks"},{"x":13,"y":2,"z":15,"name":"Wood_Darkwood_Planks"},{"x":14,"y":2,"z":15,"name":"Rock_Stone_Brick"},{"x":15,"y":2,"z":15,"name":"Plant_Flower_Tall_Pink"},{"x":1,"y":2,"z":16,"name":"*Plant_Crop_Berry_Block_State_Definitions_StageFinal"},{"x":2,"y":2,"z":16,"name":"Rock_Stone_Brick"},{"x":3,"y":2,"z":16,"name":"Wood_Darkwood_Planks"},{"x":4,"y":2,"z":16,"name":"Wood_Darkwood_Planks"},{"x":5,"y":2,"z":16,"name":"Wood_Darkwood_Planks"},{"x":6,"y":2,"z":16,"name":"Wood_Darkwood_Planks"},{"x":7,"y":2,"z":16,"name":"Wood_Darkwood_Planks"},{"x":8,"y":2,"z":16,"name":"Wood_Darkwood_Planks"},{"x":9,"y":2,"z":16,"name":"Wood_Darkwood_Planks"},{"x":10,"y":2,"z":16,"name":"Wood_Darkwood_Planks"},{"x":11,"y":2,"z":16,"name":"Wood_Darkwood_Planks"},{"x":12,"y":2,"z":16,"name":"Wood_Darkwood_Planks"},{"x":13,"y":2,"z":16,"name":"Wood_Darkwood_Planks"},{"x":14,"y":2,"z":16,"name":"Rock_Stone_Brick"},{"x":15,"y":2,"z":16,"name":"Plant_Leaves_Beech","support":15},{"x":1,"y":2,"z":17,"name":"Wood_Oak_Trunk","rotation":2},{"x":2,"y":2,"z":17,"name":"Wood_Oak_Trunk","rotation":2},{"x":3,"y":2,"z":17,"name":"Rock_Stone_Brick"},{"x":4,"y":2,"z":17,"name":"Rock_Stone_Brick"},{"x":5,"y":2,"z":17,"name":"Rock_Stone_Brick"},{"x":6,"y":2,"z":17,"name":"Wood_Oak_Trunk","rotation":2},{"x":7,"y":2,"z":17,"name":"Rock_Stone_Brick"},{"x":8,"y":2,"z":17,"name":"Rock_Stone_Brick"},{"x":9,"y":2,"z":17,"name":"Rock_Stone_Brick"},{"x":10,"y":2,"z":17,"name":"Wood_Oak_Trunk","rotation":2},{"x":11,"y":2,"z":17,"name":"Rock_Stone_Brick"},{"x":12,"y":2,"z":17,"name":"Rock_Stone_Brick"},{"x":13,"y":2,"z":17,"name":"Rock_Stone_Brick"},{"x":14,"y":2,"z":17,"name":"Wood_Oak_Trunk","rotation":2},{"x":15,"y":2,"z":17,"name":"Wood_Oak_Trunk","rotation":2},{"x":16,"y":2,"z":17,"name":"Plant_Leaves_Beech","support":15},{"x":1,"y":2,"z":18,"name":"*Plant_Crop_Berry_Block_State_Definitions_StageFinal"},{"x":2,"y":2,"z":18,"name":"Wood_Oak_Trunk","rotation":2},{"x":3,"y":2,"z":18,"name":"Plant_Leaves_Beech","support":15},{"x":4,"y":2,"z":18,"name":"Plant_Flower_Tall_Pink"},{"x":6,"y":2,"z":18,"name":"Wood_Oak_Trunk","rotation":2},{"x":7,"y":2,"z":18,"name":"Plant_Leaves_Beech","support":15},{"x":9,"y":2,"z":18,"name":"Plant_Flower_Tall_Pink"},{"x":10,"y":2,"z":18,"name":"Wood_Oak_Trunk","rotation":2},{"x":11,"y":2,"z":18,"name":"Plant_Grass_Sharp_Wild"},{"x":12,"y":2,"z":18,"name":"*Plant_Crop_Berry_Block_State_Definitions_StageFinal"},{"x":14,"y":2,"z":18,"name":"Wood_Oak_Trunk","rotation":2},{"x":15,"y":2,"z":18,"name":"Plant_Leaves_Beech","support":15},{"x":2,"y":2,"z":19,"name":"Plant_Grass_Sharp_Wild"},{"x":6,"y":2,"z":19,"name":"Plant_Leaves_Beech","support":15},{"x":7,"y":2,"z":19,"name":"Plant_Grass_Sharp_Wild"},{"x":10,"y":2,"z":19,"name":"*Plant_Crop_Berry_Block_State_Definitions_StageFinal"},{"x":16,"y":2,"z":19,"name":"Plant_Grass_Sharp"},{"x":0,"y":2,"z":20,"name":"Plant_Grass_Sharp_Wild"},{"x":1,"y":2,"z":20,"name":"Plant_Grass_Sharp_Wild"},{"x":3,"y":2,"z":20,"name":"Plant_Grass_Sharp"},{"x":5,"y":2,"z":20,"name":"Plant_Grass_Sharp"},{"x":6,"y":2,"z":20,"name":"*Plant_Crop_Berry_Block_State_Definitions_StageFinal"},{"x":10,"y":2,"z":20,"name":"Plant_Grass_Sharp"},{"x":13,"y":2,"z":20,"name":"Plant_Grass_Sharp"},{"x":15,"y":2,"z":20,"name":"Plant_Flower_Flax_Yellow"},{"x":0,"y":2,"z":21,"name":"Plant_Grass_Sharp_Wild"},{"x":1,"y":2,"z":21,"name":"Plant_Grass_Sharp"},{"x":2,"y":2,"z":21,"name":"Plant_Grass_Sharp"},{"x":4,"y":2,"z":21,"name":"Plant_Grass_Sharp"},{"x":5,"y":2,"z":21,"name":"Plant_Grass_Sharp_Wild"},{"x":6,"y":2,"z":21,"name":"Plant_Grass_Sharp"},{"x":9,"y":2,"z":21,"name":"Plant_Grass_Sharp"},{"x":10,"y":2,"z":21,"name":"Plant_Grass_Sharp_Wild"},{"x":11,"y":2,"z":21,"name":"Plant_Grass_Sharp"},{"x":12,"y":2,"z":21,"name":"Plant_Grass_Sharp_Wild"},{"x":14,"y":2,"z":21,"name":"Plant_Grass_Sharp"},{"x":15,"y":2,"z":21,"name":"Plant_Grass_Sharp_Wild"},{"x":16,"y":2,"z":21,"name":"Plant_Grass_Sharp_Wild"},{"x":0,"y":2,"z":22,"name":"Plant_Flower_Common_Cyan2"},{"x":2,"y":2,"z":22,"name":"Plant_Grass_Sharp"},{"x":3,"y":2,"z":22,"name":"Plant_Grass_Sharp"},{"x":4,"y":2,"z":22,"name":"Plant_Grass_Sharp_Wild"},{"x":5,"y":2,"z":22,"name":"Plant_Grass_Sharp_Wild"},{"x":6,"y":2,"z":22,"name":"Plant_Grass_Sharp"},{"x":8,"y":2,"z":22,"name":"Plant_Grass_Sharp"},{"x":9,"y":2,"z":22,"name":"Plant_Grass_Sharp"},{"x":10,"y":2,"z":22,"name":"Plant_Grass_Sharp"},{"x":11,"y":2,"z":22,"name":"Plant_Grass_Sharp"},{"x":12,"y":2,"z":22,"name":"Plant_Grass_Sharp"},{"x":13,"y":2,"z":22,"name":"Plant_Grass_Sharp"},{"x":14,"y":2,"z":22,"name":"Plant_Grass_Sharp"},{"x":15,"y":2,"z":22,"name":"Plant_Grass_Sharp"},{"x":2,"y":3,"z":4,"name":"Wood_Oak_Trunk","rotation":2},{"x":6,"y":3,"z":4,"name":"Wood_Oak_Trunk","rotation":2},{"x":10,"y":3,"z":4,"name":"Wood_Oak_Trunk","rotation":2},{"x":13,"y":3,"z":4,"name":"Plant_Leaves_Beech","support":15},{"x":14,"y":3,"z":4,"name":"Wood_Oak_Trunk","rotation":2},{"x":1,"y":3,"z":5,"name":"Wood_Oak_Trunk","rotation":2},{"x":2,"y":3,"z":5,"name":"Wood_Oak_Trunk","rotation":2},{"x":3,"y":3,"z":5,"name":"Rock_Stone_Brick_Stairs","rotation":8},{"x":4,"y":3,"z":5,"name":"Rock_Stone_Brick_Stairs","rotation":8},{"x":5,"y":3,"z":5,"name":"Rock_Stone_Brick_Stairs","rotation":8},{"x":6,"y":3,"z":5,"name":"Wood_Oak_Trunk","rotation":2},{"x":7,"y":3,"z":5,"name":"*Furniture_Crude_Trapdoor_State_Definitions_OpenDoorOut","rotation":1},{"x":9,"y":3,"z":5,"name":"*Furniture_Crude_Trapdoor_State_Definitions_OpenDoorOut","rotation":3},{"x":10,"y":3,"z":5,"name":"Wood_Oak_Trunk","rotation":2},{"x":11,"y":3,"z":5,"name":"Rock_Stone_Brick_Stairs","rotation":8},{"x":12,"y":3,"z":5,"name":"Rock_Stone_Brick_Stairs","rotation":8},{"x":13,"y":3,"z":5,"name":"Rock_Stone_Brick_Stairs","rotation":8},{"x":14,"y":3,"z":5,"name":"Wood_Oak_Trunk","rotation":2},{"x":15,"y":3,"z":5,"name":"Wood_Oak_Trunk","rotation":2},{"x":2,"y":3,"z":6,"name":"Rock_Stone_Brick_Stairs","rotation":9},{"x":3,"y":3,"z":6,"name":"Wood_Beech_Trunk_Full","rotation":2},{"x":4,"y":3,"z":6,"name":"Wood_Ash_Trunk","rotation":2},{"x":5,"y":3,"z":6,"name":"Wood_Beech_Trunk_Full","rotation":2},{"x":6,"y":3,"z":6,"name":"Wood_Redwood_Ornate"},{"x":7,"y":3,"z":6,"name":"*Furniture_Tavern_Trapdoor_State_Definitions_OpenDoorOut","rotation":0},{"x":8,"y":3,"z":6,"name":"*Furniture_Village_Door_State_Definitions_CloseDoorOut"},{"x":9,"y":3,"z":6,"name":"*Furniture_Tavern_Trapdoor_State_Definitions_OpenDoorOut","rotation":0},{"x":10,"y":3,"z":6,"name":"Wood_Redwood_Ornate"},{"x":11,"y":3,"z":6,"name":"Wood_Beech_Trunk_Full","rotation":2},{"x":12,"y":3,"z":6,"name":"Wood_Ash_Trunk","rotation":2},{"x":13,"y":3,"z":6,"name":"Wood_Beech_Trunk_Full","rotation":2},{"x":14,"y":3,"z":6,"name":"Rock_Stone_Brick_Stairs","rotation":11},{"x":2,"y":3,"z":7,"name":"Rock_Stone_Brick_Stairs","rotation":9},{"x":3,"y":3,"z":7,"name":"Wood_Ash_Trunk","rotation":2},{"x":5,"y":3,"z":7,"name":"Furniture_Crude_Chest_Small"},{"x":11,"y":3,"z":7,"name":"Rock_Ledge_Brick_Wall"},{"x":13,"y":3,"z":7,"name":"Wood_Ash_Trunk","rotation":2},{"x":14,"y":3,"z":7,"name":"Rock_Stone_Brick_Stairs","rotation":11},{"x":1,"y":3,"z":8,"name":"Plant_Leaves_Beech","support":15},{"x":2,"y":3,"z":8,"name":"Rock_Stone_Brick_Stairs","rotation":9},{"x":3,"y":3,"z":8,"name":"Wood_Beech_Trunk_Full","rotation":2},{"x":4,"y":3,"z":8,"name":"Wood_Ash_Trunk","rotation":2},{"x":5,"y":3,"z":8,"name":"Wood_Hardwood_Stairs","rotation":1},{"x":11,"y":3,"z":8,"name":"Wood_Hardwood_Stairs","rotation":3},{"x":12,"y":3,"z":8,"name":"Wood_Ash_Trunk","rotation":2},{"x":13,"y":3,"z":8,"name":"Wood_Beech_Trunk_Full","rotation":2},{"x":14,"y":3,"z":8,"name":"Rock_Stone_Brick_Stairs","rotation":11},{"x":1,"y":3,"z":9,"name":"Wood_Oak_Trunk","rotation":2},{"x":2,"y":3,"z":9,"name":"Wood_Oak_Trunk","rotation":2},{"x":3,"y":3,"z":9,"name":"Wood_Ash_Trunk","rotation":2},{"x":5,"y":3,"z":9,"name":"Wood_Drywood_Decorative","rotation":3},{"x":11,"y":3,"z":9,"name":"Furniture_Tavern_Planter"},{"x":13,"y":3,"z":9,"name":"Wood_Ash_Trunk","rotation":2},{"x":14,"y":3,"z":9,"name":"Wood_Oak_Trunk","rotation":2},{"x":15,"y":3,"z":9,"name":"Wood_Oak_Trunk","rotation":2},{"x":2,"y":3,"z":10,"name":"Rock_Stone_Brick_Stairs","rotation":9},{"x":3,"y":3,"z":10,"name":"Wood_Beech_Trunk_Full","rotation":2},{"x":4,"y":3,"z":10,"name":"Wood_Ash_Trunk","rotation":2},{"x":5,"y":3,"z":10,"name":"Wood_Hardwood_Stairs","rotation":1},{"x":11,"y":3,"z":10,"name":"Wood_Hardwood_Stairs","rotation":3},{"x":12,"y":3,"z":10,"name":"Wood_Ash_Trunk","rotation":2},{"x":13,"y":3,"z":10,"name":"Wood_Beech_Trunk_Full","rotation":2},{"x":14,"y":3,"z":10,"name":"Rock_Stone_Brick_Stairs","rotation":11},{"x":2,"y":3,"z":11,"name":"Rock_Stone_Brick_Stairs","rotation":9},{"x":3,"y":3,"z":11,"name":"Wood_Ash_Trunk","rotation":2},{"x":5,"y":3,"z":11,"name":"Rock_Basalt_Brick_Decorative"},{"x":11,"y":3,"z":11,"name":"Wood_Lightwood_Ornate"},{"x":13,"y":3,"z":11,"name":"Wood_Ash_Trunk","rotation":2},{"x":14,"y":3,"z":11,"name":"Rock_Stone_Brick_Stairs","rotation":11},{"x":2,"y":3,"z":12,"name":"Rock_Stone_Brick_Stairs","rotation":9},{"x":3,"y":3,"z":12,"name":"Wood_Beech_Trunk_Full","rotation":2},{"x":4,"y":3,"z":12,"name":"Wood_Ash_Trunk","rotation":2},{"x":5,"y":3,"z":12,"name":"Wood_Hardwood_Stairs","rotation":1},{"x":11,"y":3,"z":12,"name":"Wood_Hardwood_Stairs","rotation":3},{"x":12,"y":3,"z":12,"name":"Wood_Ash_Trunk","rotation":2},{"x":13,"y":3,"z":12,"name":"Wood_Beech_Trunk_Full","rotation":2},{"x":14,"y":3,"z":12,"name":"Rock_Stone_Brick_Stairs","rotation":11},{"x":1,"y":3,"z":13,"name":"Wood_Oak_Trunk","rotation":2},{"x":2,"y":3,"z":13,"name":"Wood_Oak_Trunk","rotation":2},{"x":3,"y":3,"z":13,"name":"Wood_Ash_Trunk","rotation":2},{"x":5,"y":3,"z":13,"name":"Wood_Drywood_Decorative","rotation":3},{"x":11,"y":3,"z":13,"name":"Wood_Drywood_Decorative","rotation":3},{"x":13,"y":3,"z":13,"name":"Wood_Ash_Trunk","rotation":2},{"x":14,"y":3,"z":13,"name":"Wood_Oak_Trunk","rotation":2},{"x":15,"y":3,"z":13,"name":"Wood_Oak_Trunk","rotation":2},{"x":2,"y":3,"z":14,"name":"Rock_Stone_Brick_Stairs","rotation":9},{"x":3,"y":3,"z":14,"name":"Wood_Beech_Trunk_Full","rotation":2},{"x":4,"y":3,"z":14,"name":"Wood_Ash_Trunk","rotation":2},{"x":5,"y":3,"z":14,"name":"Wood_Hardwood_Stairs","rotation":1},{"x":11,"y":3,"z":14,"name":"Wood_Hardwood_Stairs","rotation":3},{"x":12,"y":3,"z":14,"name":"Wood_Ash_Trunk","rotation":2},{"x":13,"y":3,"z":14,"name":"Wood_Beech_Trunk_Full","rotation":2},{"x":14,"y":3,"z":14,"name":"Rock_Stone_Brick_Stairs","rotation":11},{"x":2,"y":3,"z":15,"name":"Rock_Stone_Brick_Stairs","rotation":9},{"x":3,"y":3,"z":15,"name":"Wood_Ash_Trunk","rotation":2},{"x":5,"y":3,"z":15,"name":"Wood_Lightwood_Ornate"},{"x":11,"y":3,"z":15,"name":"Rock_Stone_Brick_Smooth_Half"},{"x":13,"y":3,"z":15,"name":"Wood_Ash_Trunk","rotation":2},{"x":14,"y":3,"z":15,"name":"Rock_Stone_Brick_Stairs","rotation":11},{"x":2,"y":3,"z":16,"name":"Rock_Stone_Brick_Stairs","rotation":9},{"x":3,"y":3,"z":16,"name":"Wood_Beech_Trunk_Full","rotation":2},{"x":4,"y":3,"z":16,"name":"Wood_Ash_Trunk","rotation":2},{"x":5,"y":3,"z":16,"name":"Wood_Beech_Trunk_Full","rotation":2},{"x":6,"y":3,"z":16,"name":"Wood_Redwood_Ornate"},{"x":7,"y":3,"z":16,"name":"Furniture_Ancient_Crate"},{"x":8,"y":3,"z":16,"name":"Rock_Slate_Cobble_Wall"},{"x":9,"y":3,"z":16,"name":"Furniture_Ancient_Crate"},{"x":10,"y":3,"z":16,"name":"Wood_Redwood_Ornate"},{"x":11,"y":3,"z":16,"name":"Wood_Beech_Trunk_Full","rotation":2},{"x":12,"y":3,"z":16,"name":"Wood_Ash_Trunk","rotation":2},{"x":13,"y":3,"z":16,"name":"Wood_Beech_Trunk_Full","rotation":2},{"x":14,"y":3,"z":16,"name":"Rock_Stone_Brick_Stairs","rotation":11},{"x":1,"y":3,"z":17,"name":"Wood_Oak_Trunk","rotation":2},{"x":2,"y":3,"z":17,"name":"Wood_Oak_Trunk","rotation":2},{"x":3,"y":3,"z":17,"name":"Rock_Stone_Brick_Stairs","rotation":10},{"x":4,"y":3,"z":17,"name":"Rock_Stone_Brick_Stairs","rotation":10},{"x":5,"y":3,"z":17,"name":"Rock_Stone_Brick_Stairs","rotation":10},{"x":6,"y":3,"z":17,"name":"Wood_Oak_Trunk","rotation":2},{"x":7,"y":3,"z":17,"name":"Rock_Stone_Brick_Stairs","rotation":10},{"x":8,"y":3,"z":17,"name":"Rock_Stone_Brick_Stairs","rotation":10},{"x":9,"y":3,"z":17,"name":"Rock_Stone_Brick_Stairs","rotation":10},{"x":10,"y":3,"z":17,"name":"Wood_Oak_Trunk","rotation":2},{"x":11,"y":3,"z":17,"name":"Rock_Stone_Brick_Stairs","rotation":10},{"x":12,"y":3,"z":17,"name":"Rock_Stone_Brick_Stairs","rotation":10},{"x":13,"y":3,"z":17,"name":"Rock_Stone_Brick_Stairs","rotation":10},{"x":14,"y":3,"z":17,"name":"Wood_Oak_Trunk","rotation":2},{"x":15,"y":3,"z":17,"name":"Wood_Oak_Trunk","rotation":2},{"x":16,"y":3,"z":17,"name":"Plant_Leaves_Beech","support":15},{"x":2,"y":3,"z":18,"name":"Wood_Oak_Trunk","rotation":2},{"x":6,"y":3,"z":18,"name":"Wood_Oak_Trunk","rotation":2},{"x":10,"y":3,"z":18,"name":"Wood_Oak_Trunk","rotation":2},{"x":14,"y":3,"z":18,"name":"Wood_Oak_Trunk","rotation":2},{"x":2,"y":4,"z":4,"name":"Wood_Hardwood_Stairs","rotation":2},{"x":6,"y":4,"z":4,"name":"Wood_Hardwood_Stairs","rotation":2},{"x":10,"y":4,"z":4,"name":"Wood_Hardwood_Stairs","rotation":2},{"x":14,"y":4,"z":4,"name":"Wood_Hardwood_Stairs","rotation":2},{"x":1,"y":4,"z":5,"name":"Wood_Hardwood_Stairs","rotation":3},{"x":2,"y":4,"z":5,"name":"Wood_Oak_Trunk","rotation":2},{"x":3,"y":4,"z":5,"name":"*Furniture_Crude_Trapdoor_State_Definitions_OpenDoorOut","rotation":1},{"x":5,"y":4,"z":5,"name":"*Furniture_Crude_Trapdoor_State_Definitions_OpenDoorOut","rotation":3},{"x":6,"y":4,"z":5,"name":"Wood_Oak_Trunk","rotation":2},{"x":7,"y":4,"z":5,"name":"*Furniture_Crude_Trapdoor_State_Definitions_OpenDoorOut","rotation":1},{"x":9,"y":4,"z":5,"name":"*Furniture_Crude_Trapdoor_State_Definitions_OpenDoorOut","rotation":3},{"x":10,"y":4,"z":5,"name":"Wood_Oak_Trunk","rotation":2},{"x":11,"y":4,"z":5,"name":"*Furniture_Crude_Trapdoor_State_Definitions_OpenDoorOut","rotation":1},{"x":13,"y":4,"z":5,"name":"*Furniture_Crude_Trapdoor_State_Definitions_OpenDoorOut","rotation":3},{"x":14,"y":4,"z":5,"name":"Wood_Oak_Trunk","rotation":2},{"x":15,"y":4,"z":5,"name":"Wood_Hardwood_Stairs","rotation":1},{"x":2,"y":4,"z":6,"name":"*Furniture_Crude_Trapdoor_State_Definitions_OpenDoorOut","rotation":0},{"x":3,"y":4,"z":6,"name":"Wood_Beech_Trunk_Full","rotation":2},{"x":4,"y":4,"z":6,"name":"Wood_Ash_Trunk","rotation":2},{"x":5,"y":4,"z":6,"name":"Wood_Beech_Trunk_Full","rotation":2},{"x":6,"y":4,"z":6,"name":"Furniture_Village_Pot"},{"x":7,"y":4,"z":6,"name":"*Furniture_Tavern_Trapdoor_State_Definitions_OpenDoorOut","rotation":0},{"x":8,"y":4,"z":6,"name":"*Furniture_Village_Door_State_Definitions_CloseDoorOut","filler":1024},{"x":9,"y":4,"z":6,"name":"*Furniture_Tavern_Trapdoor_State_Definitions_OpenDoorOut","rotation":0},{"x":10,"y":4,"z":6,"name":"Furniture_Village_Pot"},{"x":11,"y":4,"z":6,"name":"Wood_Beech_Trunk_Full","rotation":2},{"x":12,"y":4,"z":6,"name":"Wood_Ash_Trunk","rotation":2},{"x":13,"y":4,"z":6,"name":"Wood_Beech_Trunk_Full","rotation":2},{"x":14,"y":4,"z":6,"name":"*Furniture_Crude_Trapdoor_State_Definitions_OpenDoorOut","rotation":0},{"x":3,"y":4,"z":7,"name":"Wood_Ash_Trunk","rotation":2},{"x":5,"y":4,"z":7,"name":"*Furniture_Crude_Trapdoor_State_Definitions_CloseDoorOut","rotation":1},{"x":11,"y":4,"z":7,"name":"*Furniture_Crude_Trapdoor_State_Definitions_CloseDoorOut","rotation":3},{"x":13,"y":4,"z":7,"name":"Wood_Ash_Trunk","rotation":2},{"x":2,"y":4,"z":8,"name":"*Furniture_Crude_Trapdoor_State_Definitions_OpenDoorOut","rotation":2},{"x":3,"y":4,"z":8,"name":"Wood_Beech_Trunk_Full","rotation":2},{"x":4,"y":4,"z":8,"name":"Wood_Hardwood_Planks_Half","rotation":0},{"x":5,"y":4,"z":8,"name":"Wood_Hardwood_Stairs","rotation":11},{"x":11,"y":4,"z":8,"name":"Wood_Hardwood_Stairs","rotation":9},{"x":12,"y":4,"z":8,"name":"Wood_Hardwood_Planks_Half","rotation":0},{"x":13,"y":4,"z":8,"name":"Wood_Beech_Trunk_Full","rotation":2},{"x":14,"y":4,"z":8,"name":"*Furniture_Crude_Trapdoor_State_Definitions_OpenDoorOut","rotation":2},{"x":1,"y":4,"z":9,"name":"Wood_Hardwood_Stairs","rotation":3},{"x":2,"y":4,"z":9,"name":"Wood_Oak_Trunk","rotation":2},{"x":3,"y":4,"z":9,"name":"Wood_Ash_Trunk","rotation":2},{"x":5,"y":4,"z":9,"name":"*Furniture_Crude_Trapdoor_State_Definitions_CloseDoorOut","rotation":1},{"x":11,"y":4,"z":9,"name":"*Furniture_Crude_Trapdoor_State_Definitions_CloseDoorOut","rotation":3},{"x":13,"y":4,"z":9,"name":"Wood_Ash_Trunk","rotation":2},{"x":14,"y":4,"z":9,"name":"Wood_Oak_Trunk","rotation":2},{"x":15,"y":4,"z":9,"name":"Wood_Hardwood_Stairs","rotation":1},{"x":2,"y":4,"z":10,"name":"*Furniture_Crude_Trapdoor_State_Definitions_OpenDoorOut","rotation":0},{"x":3,"y":4,"z":10,"name":"Wood_Beech_Trunk_Full","rotation":2},{"x":4,"y":4,"z":10,"name":"Wood_Hardwood_Planks_Half","rotation":0},{"x":5,"y":4,"z":10,"name":"Wood_Hardwood_Stairs","rotation":11},{"x":11,"y":4,"z":10,"name":"Wood_Hardwood_Stairs","rotation":9},{"x":12,"y":4,"z":10,"name":"Wood_Hardwood_Planks_Half","rotation":0},{"x":13,"y":4,"z":10,"name":"Wood_Beech_Trunk_Full","rotation":2},{"x":14,"y":4,"z":10,"name":"*Furniture_Crude_Trapdoor_State_Definitions_OpenDoorOut","rotation":0},{"x":3,"y":4,"z":11,"name":"Wood_Ash_Trunk","rotation":2},{"x":5,"y":4,"z":11,"name":"*Furniture_Crude_Trapdoor_State_Definitions_CloseDoorOut","rotation":1},{"x":11,"y":4,"z":11,"name":"*Furniture_Crude_Trapdoor_State_Definitions_CloseDoorOut","rotation":3},{"x":13,"y":4,"z":11,"name":"Wood_Ash_Trunk","rotation":2},{"x":2,"y":4,"z":12,"name":"*Furniture_Crude_Trapdoor_State_Definitions_OpenDoorOut","rotation":2},{"x":3,"y":4,"z":12,"name":"Wood_Beech_Trunk_Full","rotation":2},{"x":4,"y":4,"z":12,"name":"Wood_Hardwood_Planks_Half","rotation":0},{"x":5,"y":4,"z":12,"name":"Wood_Hardwood_Stairs","rotation":11},{"x":11,"y":4,"z":12,"name":"Wood_Hardwood_Stairs","rotation":9},{"x":12,"y":4,"z":12,"name":"Wood_Hardwood_Planks_Half","rotation":0},{"x":13,"y":4,"z":12,"name":"Wood_Beech_Trunk_Full","rotation":2},{"x":14,"y":4,"z":12,"name":"*Furniture_Crude_Trapdoor_State_Definitions_OpenDoorOut","rotation":2},{"x":1,"y":4,"z":13,"name":"Wood_Hardwood_Stairs","rotation":3},{"x":2,"y":4,"z":13,"name":"Wood_Oak_Trunk","rotation":2},{"x":3,"y":4,"z":13,"name":"Wood_Ash_Trunk","rotation":2},{"x":5,"y":4,"z":13,"name":"*Furniture_Crude_Trapdoor_State_Definitions_CloseDoorOut","rotation":1},{"x":11,"y":4,"z":13,"name":"*Furniture_Crude_Trapdoor_State_Definitions_CloseDoorOut","rotation":3},{"x":13,"y":4,"z":13,"name":"Wood_Ash_Trunk","rotation":2},{"x":14,"y":4,"z":13,"name":"Wood_Oak_Trunk","rotation":2},{"x":15,"y":4,"z":13,"name":"Wood_Hardwood_Stairs","rotation":1},{"x":2,"y":4,"z":14,"name":"*Furniture_Crude_Trapdoor_State_Definitions_OpenDoorOut","rotation":0},{"x":3,"y":4,"z":14,"name":"Wood_Beech_Trunk_Full","rotation":2},{"x":4,"y":4,"z":14,"name":"Wood_Hardwood_Planks_Half","rotation":0},{"x":5,"y":4,"z":14,"name":"Wood_Hardwood_Stairs","rotation":11},{"x":11,"y":4,"z":14,"name":"Wood_Hardwood_Stairs","rotation":9},{"x":12,"y":4,"z":14,"name":"Wood_Hardwood_Planks_Half","rotation":0},{"x":13,"y":4,"z":14,"name":"Wood_Beech_Trunk_Full","rotation":2},{"x":14,"y":4,"z":14,"name":"*Furniture_Crude_Trapdoor_State_Definitions_OpenDoorOut","rotation":0},{"x":3,"y":4,"z":15,"name":"Wood_Ash_Trunk","rotation":2},{"x":5,"y":4,"z":15,"name":"*Furniture_Crude_Trapdoor_State_Definitions_CloseDoorOut","rotation":1},{"x":11,"y":4,"z":15,"name":"*Furniture_Crude_Trapdoor_State_Definitions_CloseDoorOut","rotation":3},{"x":13,"y":4,"z":15,"name":"Wood_Ash_Trunk","rotation":2},{"x":2,"y":4,"z":16,"name":"*Furniture_Crude_Trapdoor_State_Definitions_OpenDoorOut","rotation":2},{"x":3,"y":4,"z":16,"name":"Wood_Beech_Trunk_Full","rotation":2},{"x":4,"y":4,"z":16,"name":"Wood_Ash_Trunk","rotation":2},{"x":5,"y":4,"z":16,"name":"Wood_Beech_Trunk_Full","rotation":2},{"x":6,"y":4,"z":16,"name":"Furniture_Village_Pot"},{"x":7,"y":4,"z":16,"name":"Furniture_Village_Chest_Small","rotation":2,"components":{"Components":{"container":{"AllowViewing":true,"Custom":false,"ItemContainer":{"Capacity":27,"Items":{}}}}}},{"x":8,"y":4,"z":16,"name":"Furniture_Village_Chest_Small","rotation":2,"components":{"Components":{"container":{"AllowViewing":true,"Custom":false,"ItemContainer":{"Capacity":27,"Items":{}}}}}},{"x":9,"y":4,"z":16,"name":"Furniture_Village_Chest_Small","rotation":2,"components":{"Components":{"container":{"AllowViewing":true,"Custom":false,"ItemContainer":{"Capacity":27,"Items":{}}}}}},{"x":10,"y":4,"z":16,"name":"Furniture_Village_Pot"},{"x":11,"y":4,"z":16,"name":"Wood_Beech_Trunk_Full","rotation":2},{"x":12,"y":4,"z":16,"name":"Wood_Ash_Trunk","rotation":2},{"x":13,"y":4,"z":16,"name":"Wood_Beech_Trunk_Full","rotation":2},{"x":14,"y":4,"z":16,"name":"*Furniture_Crude_Trapdoor_State_Definitions_OpenDoorOut","rotation":2},{"x":1,"y":4,"z":17,"name":"Wood_Hardwood_Stairs","rotation":3},{"x":2,"y":4,"z":17,"name":"Wood_Oak_Trunk","rotation":2},{"x":3,"y":4,"z":17,"name":"*Furniture_Crude_Trapdoor_State_Definitions_OpenDoorOut","rotation":1},{"x":5,"y":4,"z":17,"name":"*Furniture_Crude_Trapdoor_State_Definitions_OpenDoorOut","rotation":3},{"x":6,"y":4,"z":17,"name":"Wood_Oak_Trunk","rotation":2},{"x":8,"y":4,"z":17,"name":"Rock_Ice_Permafrost"},{"x":10,"y":4,"z":17,"name":"Wood_Oak_Trunk","rotation":2},{"x":11,"y":4,"z":17,"name":"*Furniture_Crude_Trapdoor_State_Definitions_OpenDoorOut","rotation":1},{"x":13,"y":4,"z":17,"name":"*Furniture_Crude_Trapdoor_State_Definitions_OpenDoorOut","rotation":3},{"x":14,"y":4,"z":17,"name":"Wood_Oak_Trunk","rotation":2},{"x":15,"y":4,"z":17,"name":"Wood_Hardwood_Stairs","rotation":1},{"x":2,"y":4,"z":18,"name":"Wood_Hardwood_Stairs","rotation":0},{"x":6,"y":4,"z":18,"name":"Wood_Hardwood_Stairs","rotation":0},{"x":10,"y":4,"z":18,"name":"Wood_Hardwood_Stairs","rotation":0},{"x":14,"y":4,"z":18,"name":"Wood_Hardwood_Stairs","rotation":0},{"x":15,"y":4,"z":22,"name":"Plant_Leaves_Beech","support":15},{"x":16,"y":4,"z":22,"name":"Plant_Leaves_Beech","support":15},{"x":2,"y":5,"z":5,"name":"Wood_Oak_Trunk","rotation":2},{"x":3,"y":5,"z":5,"name":"*Furniture_Crude_Trapdoor_State_Definitions_OpenDoorOut","rotation":1},{"x":5,"y":5,"z":5,"name":"*Furniture_Crude_Trapdoor_State_Definitions_OpenDoorOut","rotation":3},{"x":6,"y":5,"z":5,"name":"Wood_Oak_Trunk","rotation":2},{"x":7,"y":5,"z":5,"name":"*Furniture_Crude_Trapdoor_State_Definitions_OpenDoorOut","rotation":1},{"x":9,"y":5,"z":5,"name":"*Furniture_Crude_Trapdoor_State_Definitions_OpenDoorOut","rotation":3},{"x":10,"y":5,"z":5,"name":"Wood_Oak_Trunk","rotation":2},{"x":11,"y":5,"z":5,"name":"*Furniture_Crude_Trapdoor_State_Definitions_OpenDoorOut","rotation":1},{"x":13,"y":5,"z":5,"name":"*Furniture_Crude_Trapdoor_State_Definitions_OpenDoorOut","rotation":3},{"x":14,"y":5,"z":5,"name":"Wood_Oak_Trunk","rotation":2},{"x":2,"y":5,"z":6,"name":"*Furniture_Crude_Trapdoor_State_Definitions_OpenDoorOut","rotation":0},{"x":3,"y":5,"z":6,"name":"Wood_Beech_Trunk_Full","rotation":2},{"x":4,"y":5,"z":6,"name":"Wood_Ash_Trunk","rotation":2},{"x":5,"y":5,"z":6,"name":"Wood_Beech_Trunk_Full","rotation":2},{"x":6,"y":5,"z":6,"name":"Plant_Leaves_Beech","support":15},{"x":7,"y":5,"z":6,"name":"*Furniture_Tavern_Trapdoor_State_Definitions_OpenDoorOut","rotation":0},{"x":8,"y":5,"z":6,"name":"*Furniture_Tavern_Trapdoor_State_Definitions_OpenDoorOut","rotation":0},{"x":9,"y":5,"z":6,"name":"*Furniture_Tavern_Trapdoor_State_Definitions_OpenDoorOut","rotation":0},{"x":10,"y":5,"z":6,"name":"Plant_Leaves_Beech","support":15},{"x":11,"y":5,"z":6,"name":"Wood_Beech_Trunk_Full","rotation":2},{"x":12,"y":5,"z":6,"name":"Wood_Ash_Trunk","rotation":2},{"x":13,"y":5,"z":6,"name":"Wood_Beech_Trunk_Full","rotation":2},{"x":14,"y":5,"z":6,"name":"*Furniture_Crude_Trapdoor_State_Definitions_OpenDoorOut","rotation":0},{"x":3,"y":5,"z":7,"name":"Wood_Ash_Trunk","rotation":2},{"x":5,"y":5,"z":7,"name":"Wood_Ash_Trunk","rotation":4},{"x":11,"y":5,"z":7,"name":"Wood_Ash_Trunk","rotation":4},{"x":13,"y":5,"z":7,"name":"Wood_Ash_Trunk","rotation":2},{"x":2,"y":5,"z":8,"name":"*Furniture_Crude_Trapdoor_State_Definitions_OpenDoorOut","rotation":2},{"x":3,"y":5,"z":8,"name":"Wood_Beech_Trunk_Full","rotation":2},{"x":4,"y":5,"z":8,"name":"Wood_Ash_Trunk","rotation":2},{"x":5,"y":5,"z":8,"name":"Wood_Beech_Trunk_Full","rotation":2},{"x":11,"y":5,"z":8,"name":"Wood_Beech_Trunk_Full","rotation":2},{"x":12,"y":5,"z":8,"name":"Wood_Ash_Trunk","rotation":2},{"x":13,"y":5,"z":8,"name":"Wood_Beech_Trunk_Full","rotation":2},{"x":14,"y":5,"z":8,"name":"*Furniture_Crude_Trapdoor_State_Definitions_OpenDoorOut","rotation":2},{"x":2,"y":5,"z":9,"name":"Wood_Oak_Trunk","rotation":2},{"x":3,"y":5,"z":9,"name":"Wood_Ash_Trunk","rotation":2},{"x":5,"y":5,"z":9,"name":"Wood_Ash_Trunk","rotation":4},{"x":11,"y":5,"z":9,"name":"Wood_Ash_Trunk","rotation":4},{"x":13,"y":5,"z":9,"name":"Wood_Ash_Trunk","rotation":2},{"x":14,"y":5,"z":9,"name":"Wood_Oak_Trunk","rotation":2},{"x":2,"y":5,"z":10,"name":"*Furniture_Crude_Trapdoor_State_Definitions_OpenDoorOut","rotation":0},{"x":3,"y":5,"z":10,"name":"Wood_Beech_Trunk_Full","rotation":2},{"x":4,"y":5,"z":10,"name":"Wood_Ash_Trunk","rotation":2},{"x":5,"y":5,"z":10,"name":"Wood_Beech_Trunk_Full","rotation":2},{"x":11,"y":5,"z":10,"name":"Wood_Beech_Trunk_Full","rotation":2},{"x":12,"y":5,"z":10,"name":"Wood_Ash_Trunk","rotation":2},{"x":13,"y":5,"z":10,"name":"Wood_Beech_Trunk_Full","rotation":2},{"x":14,"y":5,"z":10,"name":"*Furniture_Crude_Trapdoor_State_Definitions_OpenDoorOut","rotation":0},{"x":3,"y":5,"z":11,"name":"Wood_Ash_Trunk","rotation":2},{"x":5,"y":5,"z":11,"name":"Wood_Ash_Trunk","rotation":4},{"x":11,"y":5,"z":11,"name":"Wood_Ash_Trunk","rotation":4},{"x":13,"y":5,"z":11,"name":"Wood_Ash_Trunk","rotation":2},{"x":2,"y":5,"z":12,"name":"*Furniture_Crude_Trapdoor_State_Definitions_OpenDoorOut","rotation":2},{"x":3,"y":5,"z":12,"name":"Wood_Beech_Trunk_Full","rotation":2},{"x":4,"y":5,"z":12,"name":"Wood_Ash_Trunk","rotation":2},{"x":5,"y":5,"z":12,"name":"Wood_Beech_Trunk_Full","rotation":2},{"x":11,"y":5,"z":12,"name":"Wood_Beech_Trunk_Full","rotation":2},{"x":12,"y":5,"z":12,"name":"Wood_Ash_Trunk","rotation":2},{"x":13,"y":5,"z":12,"name":"Wood_Beech_Trunk_Full","rotation":2},{"x":14,"y":5,"z":12,"name":"*Furniture_Crude_Trapdoor_State_Definitions_OpenDoorOut","rotation":2},{"x":2,"y":5,"z":13,"name":"Wood_Oak_Trunk","rotation":2},{"x":3,"y":5,"z":13,"name":"Wood_Ash_Trunk","rotation":2},{"x":5,"y":5,"z":13,"name":"Wood_Ash_Trunk","rotation":4},{"x":11,"y":5,"z":13,"name":"Wood_Ash_Trunk","rotation":4},{"x":13,"y":5,"z":13,"name":"Wood_Ash_Trunk","rotation":2},{"x":14,"y":5,"z":13,"name":"Wood_Oak_Trunk","rotation":2},{"x":2,"y":5,"z":14,"name":"*Furniture_Crude_Trapdoor_State_Definitions_OpenDoorOut","rotation":0},{"x":3,"y":5,"z":14,"name":"Wood_Beech_Trunk_Full","rotation":2},{"x":4,"y":5,"z":14,"name":"Wood_Ash_Trunk","rotation":2},{"x":5,"y":5,"z":14,"name":"Wood_Beech_Trunk_Full","rotation":2},{"x":11,"y":5,"z":14,"name":"Wood_Beech_Trunk_Full","rotation":2},{"x":12,"y":5,"z":14,"name":"Wood_Ash_Trunk","rotation":2},{"x":13,"y":5,"z":14,"name":"Wood_Beech_Trunk_Full","rotation":2},{"x":14,"y":5,"z":14,"name":"*Furniture_Crude_Trapdoor_State_Definitions_OpenDoorOut","rotation":0},{"x":3,"y":5,"z":15,"name":"Wood_Ash_Trunk","rotation":2},{"x":5,"y":5,"z":15,"name":"Wood_Ash_Trunk","rotation":4},{"x":11,"y":5,"z":15,"name":"Wood_Ash_Trunk","rotation":4},{"x":13,"y":5,"z":15,"name":"Wood_Ash_Trunk","rotation":2},{"x":2,"y":5,"z":16,"name":"*Furniture_Crude_Trapdoor_State_Definitions_OpenDoorOut","rotation":2},{"x":3,"y":5,"z":16,"name":"Wood_Beech_Trunk_Full","rotation":2},{"x":4,"y":5,"z":16,"name":"Wood_Ash_Trunk","rotation":2},{"x":5,"y":5,"z":16,"name":"Wood_Beech_Trunk_Full","rotation":2},{"x":6,"y":5,"z":16,"name":"Plant_Leaves_Beech","support":15},{"x":10,"y":5,"z":16,"name":"Plant_Leaves_Beech","support":15},{"x":11,"y":5,"z":16,"name":"Wood_Beech_Trunk_Full","rotation":2},{"x":12,"y":5,"z":16,"name":"Wood_Ash_Trunk","rotation":2},{"x":13,"y":5,"z":16,"name":"Wood_Beech_Trunk_Full","rotation":2},{"x":14,"y":5,"z":16,"name":"*Furniture_Crude_Trapdoor_State_Definitions_OpenDoorOut","rotation":2},{"x":2,"y":5,"z":17,"name":"Wood_Oak_Trunk","rotation":2},{"x":3,"y":5,"z":17,"name":"*Furniture_Crude_Trapdoor_State_Definitions_OpenDoorOut","rotation":1},{"x":5,"y":5,"z":17,"name":"*Furniture_Crude_Trapdoor_State_Definitions_OpenDoorOut","rotation":3},{"x":6,"y":5,"z":17,"name":"Wood_Oak_Trunk","rotation":2},{"x":8,"y":5,"z":17,"name":"Rock_Ice_Permafrost"},{"x":10,"y":5,"z":17,"name":"Wood_Oak_Trunk","rotation":2},{"x":11,"y":5,"z":17,"name":"*Furniture_Crude_Trapdoor_State_Definitions_OpenDoorOut","rotation":1},{"x":13,"y":5,"z":17,"name":"*Furniture_Crude_Trapdoor_State_Definitions_OpenDoorOut","rotation":3},{"x":14,"y":5,"z":17,"name":"Wood_Oak_Trunk","rotation":2},{"x":16,"y":5,"z":22,"name":"Plant_Leaves_Beech","support":15},{"x":6,"y":6,"z":3,"name":"Deco_Lantern_Ceiling"},{"x":10,"y":6,"z":3,"name":"Deco_Lantern_Ceiling"},{"x":6,"y":6,"z":4,"name":"Wood_Hardwood_Stairs","rotation":8},{"x":7,"y":6,"z":4,"name":"Furniture_Crude_Trapdoor","rotation":2},{"x":8,"y":6,"z":4,"name":"Furniture_Crude_Trapdoor","rotation":2},{"x":9,"y":6,"z":4,"name":"Furniture_Crude_Trapdoor","rotation":2},{"x":10,"y":6,"z":4,"name":"Wood_Hardwood_Stairs","rotation":8},{"x":2,"y":6,"z":5,"name":"Wood_Oak_Trunk","rotation":2},{"x":3,"y":6,"z":5,"name":"*Furniture_Crude_Trapdoor_State_Definitions_OpenDoorOut","rotation":1},{"x":5,"y":6,"z":5,"name":"*Furniture_Crude_Trapdoor_State_Definitions_OpenDoorOut","rotation":3},{"x":6,"y":6,"z":5,"name":"Wood_Oak_Trunk","rotation":2},{"x":7,"y":6,"z":5,"name":"Wood_Hardwood_Stairs","rotation":11},{"x":8,"y":6,"z":5,"name":"Furniture_Crude_Trapdoor","rotation":0},{"x":9,"y":6,"z":5,"name":"Wood_Hardwood_Stairs","rotation":9},{"x":10,"y":6,"z":5,"name":"Wood_Oak_Trunk","rotation":2},{"x":11,"y":6,"z":5,"name":"*Furniture_Crude_Trapdoor_State_Definitions_OpenDoorOut","rotation":1},{"x":13,"y":6,"z":5,"name":"*Furniture_Crude_Trapdoor_State_Definitions_OpenDoorOut","rotation":3},{"x":14,"y":6,"z":5,"name":"Wood_Oak_Trunk","rotation":2},{"x":2,"y":6,"z":6,"name":"*Furniture_Crude_Trapdoor_State_Definitions_OpenDoorOut","rotation":0},{"x":3,"y":6,"z":6,"name":"Wood_Beech_Trunk_Full","rotation":2},{"x":4,"y":6,"z":6,"name":"Wood_Ash_Trunk","rotation":2},{"x":5,"y":6,"z":6,"name":"Wood_Beech_Trunk_Full","rotation":2},{"x":6,"y":6,"z":6,"name":"Plant_Leaves_Beech","support":15},{"x":7,"y":6,"z":6,"name":"*Furniture_Tavern_Trapdoor_State_Definitions_OpenDoorOut","rotation":0},{"x":8,"y":6,"z":6,"name":"*Furniture_Tavern_Trapdoor_State_Definitions_OpenDoorOut","rotation":0},{"x":9,"y":6,"z":6,"name":"*Furniture_Tavern_Trapdoor_State_Definitions_OpenDoorOut","rotation":0},{"x":10,"y":6,"z":6,"name":"Plant_Leaves_Beech","support":15},{"x":11,"y":6,"z":6,"name":"Wood_Beech_Trunk_Full","rotation":2},{"x":12,"y":6,"z":6,"name":"Wood_Ash_Trunk","rotation":2},{"x":13,"y":6,"z":6,"name":"Wood_Beech_Trunk_Full","rotation":2},{"x":14,"y":6,"z":6,"name":"*Furniture_Crude_Trapdoor_State_Definitions_OpenDoorOut","rotation":0},{"x":3,"y":6,"z":7,"name":"Wood_Ash_Trunk","rotation":2},{"x":5,"y":6,"z":7,"name":"Wood_Hardwood_Fence","rotation":1},{"x":11,"y":6,"z":7,"name":"Wood_Hardwood_Fence","rotation":1},{"x":13,"y":6,"z":7,"name":"Wood_Ash_Trunk","rotation":2},{"x":2,"y":6,"z":8,"name":"*Furniture_Crude_Trapdoor_State_Definitions_OpenDoorOut","rotation":2},{"x":3,"y":6,"z":8,"name":"Wood_Beech_Trunk_Full","rotation":2},{"x":4,"y":6,"z":8,"name":"Wood_Ash_Trunk","rotation":2},{"x":5,"y":6,"z":8,"name":"Wood_Beech_Trunk_Full","rotation":2},{"x":11,"y":6,"z":8,"name":"Wood_Beech_Trunk_Full","rotation":2},{"x":12,"y":6,"z":8,"name":"Wood_Ash_Trunk","rotation":2},{"x":13,"y":6,"z":8,"name":"Wood_Beech_Trunk_Full","rotation":2},{"x":14,"y":6,"z":8,"name":"*Furniture_Crude_Trapdoor_State_Definitions_OpenDoorOut","rotation":2},{"x":2,"y":6,"z":9,"name":"Wood_Oak_Trunk","rotation":2},{"x":3,"y":6,"z":9,"name":"Wood_Ash_Trunk","rotation":2},{"x":5,"y":6,"z":9,"name":"Wood_Hardwood_Fence","rotation":1},{"x":11,"y":6,"z":9,"name":"Wood_Hardwood_Fence","rotation":1},{"x":13,"y":6,"z":9,"name":"Wood_Ash_Trunk","rotation":2},{"x":14,"y":6,"z":9,"name":"Wood_Oak_Trunk","rotation":2},{"x":2,"y":6,"z":10,"name":"*Furniture_Crude_Trapdoor_State_Definitions_OpenDoorOut","rotation":0},{"x":3,"y":6,"z":10,"name":"Wood_Beech_Trunk_Full","rotation":2},{"x":4,"y":6,"z":10,"name":"Wood_Ash_Trunk","rotation":2},{"x":5,"y":6,"z":10,"name":"Wood_Beech_Trunk_Full","rotation":2},{"x":11,"y":6,"z":10,"name":"Wood_Beech_Trunk_Full","rotation":2},{"x":12,"y":6,"z":10,"name":"Wood_Ash_Trunk","rotation":2},{"x":13,"y":6,"z":10,"name":"Wood_Beech_Trunk_Full","rotation":2},{"x":14,"y":6,"z":10,"name":"*Furniture_Crude_Trapdoor_State_Definitions_OpenDoorOut","rotation":0},{"x":3,"y":6,"z":11,"name":"Wood_Ash_Trunk","rotation":2},{"x":5,"y":6,"z":11,"name":"Wood_Hardwood_Fence","rotation":1},{"x":11,"y":6,"z":11,"name":"Wood_Hardwood_Fence","rotation":1},{"x":13,"y":6,"z":11,"name":"Wood_Ash_Trunk","rotation":2},{"x":2,"y":6,"z":12,"name":"*Furniture_Crude_Trapdoor_State_Definitions_OpenDoorOut","rotation":2},{"x":3,"y":6,"z":12,"name":"Wood_Beech_Trunk_Full","rotation":2},{"x":4,"y":6,"z":12,"name":"Wood_Ash_Trunk","rotation":2},{"x":5,"y":6,"z":12,"name":"Wood_Beech_Trunk_Full","rotation":2},{"x":11,"y":6,"z":12,"name":"Wood_Beech_Trunk_Full","rotation":2},{"x":12,"y":6,"z":12,"name":"Wood_Ash_Trunk","rotation":2},{"x":13,"y":6,"z":12,"name":"Wood_Beech_Trunk_Full","rotation":2},{"x":14,"y":6,"z":12,"name":"*Furniture_Crude_Trapdoor_State_Definitions_OpenDoorOut","rotation":2},{"x":2,"y":6,"z":13,"name":"Wood_Oak_Trunk","rotation":2},{"x":3,"y":6,"z":13,"name":"Wood_Ash_Trunk","rotation":2},{"x":5,"y":6,"z":13,"name":"Wood_Hardwood_Fence","rotation":1},{"x":11,"y":6,"z":13,"name":"Wood_Hardwood_Fence","rotation":1},{"x":13,"y":6,"z":13,"name":"Wood_Ash_Trunk","rotation":2},{"x":14,"y":6,"z":13,"name":"Wood_Oak_Trunk","rotation":2},{"x":2,"y":6,"z":14,"name":"*Furniture_Crude_Trapdoor_State_Definitions_OpenDoorOut","rotation":0},{"x":3,"y":6,"z":14,"name":"Wood_Beech_Trunk_Full","rotation":2},{"x":4,"y":6,"z":14,"name":"Wood_Ash_Trunk","rotation":2},{"x":5,"y":6,"z":14,"name":"Wood_Beech_Trunk_Full","rotation":2},{"x":11,"y":6,"z":14,"name":"Wood_Beech_Trunk_Full","rotation":2},{"x":12,"y":6,"z":14,"name":"Wood_Ash_Trunk","rotation":2},{"x":13,"y":6,"z":14,"name":"Wood_Beech_Trunk_Full","rotation":2},{"x":14,"y":6,"z":14,"name":"*Furniture_Crude_Trapdoor_State_Definitions_OpenDoorOut","rotation":0},{"x":3,"y":6,"z":15,"name":"Wood_Ash_Trunk","rotation":2},{"x":5,"y":6,"z":15,"name":"Wood_Hardwood_Fence","rotation":1},{"x":11,"y":6,"z":15,"name":"Wood_Hardwood_Fence","rotation":1},{"x":13,"y":6,"z":15,"name":"Wood_Ash_Trunk","rotation":2},{"x":2,"y":6,"z":16,"name":"*Furniture_Crude_Trapdoor_State_Definitions_OpenDoorOut","rotation":2},{"x":3,"y":6,"z":16,"name":"Wood_Beech_Trunk_Full","rotation":2},{"x":4,"y":6,"z":16,"name":"Wood_Ash_Trunk","rotation":2},{"x":5,"y":6,"z":16,"name":"Wood_Beech_Trunk_Full","rotation":2},{"x":6,"y":6,"z":16,"name":"Plant_Leaves_Beech","support":15},{"x":10,"y":6,"z":16,"name":"Plant_Leaves_Beech","support":15},{"x":11,"y":6,"z":16,"name":"Wood_Beech_Trunk_Full","rotation":2},{"x":12,"y":6,"z":16,"name":"Wood_Ash_Trunk","rotation":2},{"x":13,"y":6,"z":16,"name":"Wood_Beech_Trunk_Full","rotation":2},{"x":14,"y":6,"z":16,"name":"*Furniture_Crude_Trapdoor_State_Definitions_OpenDoorOut","rotation":2},{"x":2,"y":6,"z":17,"name":"Wood_Oak_Trunk","rotation":2},{"x":3,"y":6,"z":17,"name":"*Furniture_Crude_Trapdoor_State_Definitions_OpenDoorOut","rotation":1},{"x":5,"y":6,"z":17,"name":"*Furniture_Crude_Trapdoor_State_Definitions_OpenDoorOut","rotation":3},{"x":6,"y":6,"z":17,"name":"Wood_Oak_Trunk","rotation":2},{"x":8,"y":6,"z":17,"name":"Rock_Ice_Permafrost"},{"x":10,"y":6,"z":17,"name":"Wood_Oak_Trunk","rotation":2},{"x":11,"y":6,"z":17,"name":"*Furniture_Crude_Trapdoor_State_Definitions_OpenDoorOut","rotation":1},{"x":13,"y":6,"z":17,"name":"*Furniture_Crude_Trapdoor_State_Definitions_OpenDoorOut","rotation":3},{"x":14,"y":6,"z":17,"name":"Wood_Oak_Trunk","rotation":2},{"x":6,"y":6,"z":18,"name":"Wood_Hardwood_Stairs","rotation":10},{"x":7,"y":6,"z":18,"name":"Furniture_Crude_Trapdoor","rotation":0},{"x":8,"y":6,"z":18,"name":"Furniture_Crude_Trapdoor","rotation":0},{"x":9,"y":6,"z":18,"name":"Furniture_Crude_Trapdoor","rotation":0},{"x":10,"y":6,"z":18,"name":"Wood_Hardwood_Stairs","rotation":10},{"x":6,"y":6,"z":19,"name":"Deco_Lantern_Ceiling"},{"x":10,"y":6,"z":19,"name":"Deco_Lantern_Ceiling"},{"x":6,"y":7,"z":3,"name":"Deco_Iron_Chain_Small","rotation":2},{"x":10,"y":7,"z":3,"name":"Deco_Iron_Chain_Small","rotation":2},{"x":2,"y":7,"z":4,"name":"Wood_Hardwood_Stairs","rotation":8},{"x":3,"y":7,"z":4,"name":"Furniture_Crude_Trapdoor","rotation":2},{"x":4,"y":7,"z":4,"name":"Furniture_Crude_Trapdoor","rotation":2},{"x":5,"y":7,"z":4,"name":"Furniture_Crude_Trapdoor","rotation":2},{"x":6,"y":7,"z":4,"name":"Wood_Oak_Trunk","rotation":2},{"x":7,"y":7,"z":4,"name":"Furniture_Crude_Brazier"},{"x":8,"y":7,"z":4,"name":"Furniture_Crude_Brazier"},{"x":9,"y":7,"z":4,"name":"Furniture_Crude_Brazier"},{"x":10,"y":7,"z":4,"name":"Wood_Oak_Trunk","rotation":2},{"x":11,"y":7,"z":4,"name":"*Furniture_Crude_Trapdoor_State_Definitions_CloseDoorOut","rotation":3},{"x":12,"y":7,"z":4,"name":"*Furniture_Crude_Trapdoor_State_Definitions_CloseDoorOut","rotation":3},{"x":13,"y":7,"z":4,"name":"*Furniture_Crude_Trapdoor_State_Definitions_CloseDoorOut","rotation":3},{"x":14,"y":7,"z":4,"name":"Wood_Hardwood_Stairs","rotation":8},{"x":1,"y":7,"z":5,"name":"Wood_Hardwood_Stairs","rotation":9},{"x":2,"y":7,"z":5,"name":"Wood_Oak_Trunk","rotation":2},{"x":3,"y":7,"z":5,"name":"Wood_Hardwood_Stairs","rotation":11},{"x":4,"y":7,"z":5,"name":"Furniture_Crude_Trapdoor","rotation":0},{"x":5,"y":7,"z":5,"name":"Wood_Hardwood_Stairs","rotation":9},{"x":6,"y":7,"z":5,"name":"Wood_Oak_Trunk","rotation":2},{"x":7,"y":7,"z":5,"name":"Wood_Oak_Trunk","rotation":5},{"x":8,"y":7,"z":5,"name":"Wood_Oak_Trunk","rotation":5},{"x":9,"y":7,"z":5,"name":"Wood_Oak_Trunk","rotation":5},{"x":10,"y":7,"z":5,"name":"Wood_Oak_Trunk","rotation":2},{"x":11,"y":7,"z":5,"name":"Wood_Hardwood_Stairs","rotation":11},{"x":12,"y":7,"z":5,"name":"*Furniture_Crude_Trapdoor_State_Definitions_CloseDoorOut","rotation":1},{"x":13,"y":7,"z":5,"name":"Wood_Hardwood_Stairs","rotation":9},{"x":14,"y":7,"z":5,"name":"Wood_Oak_Trunk","rotation":2},{"x":15,"y":7,"z":5,"name":"Wood_Hardwood_Stairs","rotation":11},{"x":1,"y":7,"z":6,"name":"*Furniture_Crude_Trapdoor_State_Definitions_CloseDoorOut","rotation":3},{"x":2,"y":7,"z":6,"name":"Wood_Hardwood_Stairs","rotation":10},{"x":3,"y":7,"z":6,"name":"Wood_Beech_Trunk_Full","rotation":2},{"x":4,"y":7,"z":6,"name":"Wood_Ash_Trunk","rotation":2},{"x":5,"y":7,"z":6,"name":"Wood_Beech_Trunk_Full","rotation":2},{"x":6,"y":7,"z":6,"name":"Wood_Darkwood_Planks_Half","rotation":8},{"x":7,"y":7,"z":6,"name":"Furniture_Tavern_Trapdoor","rotation":0},{"x":8,"y":7,"z":6,"name":"Wood_Darkwood_Planks_Half","rotation":8},{"x":9,"y":7,"z":6,"name":"Furniture_Tavern_Trapdoor","rotation":0},{"x":10,"y":7,"z":6,"name":"Wood_Darkwood_Planks_Half","rotation":8},{"x":11,"y":7,"z":6,"name":"Wood_Beech_Trunk_Full","rotation":2},{"x":12,"y":7,"z":6,"name":"Wood_Ash_Trunk","rotation":2},{"x":13,"y":7,"z":6,"name":"Wood_Beech_Trunk_Full","rotation":2},{"x":14,"y":7,"z":6,"name":"Wood_Hardwood_Stairs","rotation":10},{"x":15,"y":7,"z":6,"name":"*Furniture_Crude_Trapdoor_State_Definitions_CloseDoorOut","rotation":1},{"x":1,"y":7,"z":7,"name":"*Furniture_Crude_Trapdoor_State_Definitions_CloseDoorOut","rotation":3},{"x":2,"y":7,"z":7,"name":"*Furniture_Crude_Trapdoor_State_Definitions_CloseDoorOut","rotation":1},{"x":3,"y":7,"z":7,"name":"Wood_Ash_Trunk","rotation":2},{"x":4,"y":7,"z":7,"name":"*Furniture_Crude_Trapdoor_State_Definitions_CloseDoorOut","rotation":3},{"x":5,"y":7,"z":7,"name":"Wood_Ash_Trunk","rotation":4},{"x":6,"y":7,"z":7,"name":"*Furniture_Tavern_Trapdoor_State_Definitions_CloseDoorOut","rotation":1},{"x":10,"y":7,"z":7,"name":"*Furniture_Tavern_Trapdoor_State_Definitions_CloseDoorOut","rotation":3},{"x":11,"y":7,"z":7,"name":"Wood_Ash_Trunk","rotation":4},{"x":12,"y":7,"z":7,"name":"*Furniture_Crude_Trapdoor_State_Definitions_CloseDoorOut","rotation":3},{"x":13,"y":7,"z":7,"name":"Wood_Ash_Trunk","rotation":2},{"x":14,"y":7,"z":7,"name":"*Furniture_Crude_Trapdoor_State_Definitions_CloseDoorOut","rotation":1},{"x":15,"y":7,"z":7,"name":"*Furniture_Crude_Trapdoor_State_Definitions_CloseDoorOut","rotation":1},{"x":1,"y":7,"z":8,"name":"*Furniture_Crude_Trapdoor_State_Definitions_CloseDoorOut","rotation":3},{"x":2,"y":7,"z":8,"name":"Wood_Hardwood_Stairs","rotation":8},{"x":3,"y":7,"z":8,"name":"Wood_Beech_Trunk_Full","rotation":2},{"x":4,"y":7,"z":8,"name":"Wood_Ash_Trunk","rotation":2},{"x":5,"y":7,"z":8,"name":"Wood_Beech_Trunk_Full","rotation":2},{"x":6,"y":7,"z":8,"name":"Wood_Darkwood_Planks_Half","rotation":8},{"x":10,"y":7,"z":8,"name":"Wood_Darkwood_Planks_Half","rotation":8},{"x":11,"y":7,"z":8,"name":"Wood_Beech_Trunk_Full","rotation":2},{"x":12,"y":7,"z":8,"name":"Wood_Ash_Trunk","rotation":2},{"x":13,"y":7,"z":8,"name":"Wood_Beech_Trunk_Full","rotation":2},{"x":14,"y":7,"z":8,"name":"Wood_Hardwood_Stairs","rotation":8},{"x":15,"y":7,"z":8,"name":"*Furniture_Crude_Trapdoor_State_Definitions_CloseDoorOut","rotation":1},{"x":1,"y":7,"z":9,"name":"Wood_Hardwood_Stairs","rotation":9},{"x":2,"y":7,"z":9,"name":"Wood_Oak_Trunk","rotation":2},{"x":3,"y":7,"z":9,"name":"Wood_Ash_Trunk","rotation":2},{"x":4,"y":7,"z":9,"name":"*Furniture_Crude_Trapdoor_State_Definitions_CloseDoorOut","rotation":3},{"x":5,"y":7,"z":9,"name":"Wood_Ash_Trunk","rotation":4},{"x":6,"y":7,"z":9,"name":"*Furniture_Tavern_Trapdoor_State_Definitions_CloseDoorOut","rotation":1},{"x":10,"y":7,"z":9,"name":"*Furniture_Tavern_Trapdoor_State_Definitions_CloseDoorOut","rotation":3},{"x":11,"y":7,"z":9,"name":"Wood_Ash_Trunk","rotation":4},{"x":12,"y":7,"z":9,"name":"*Furniture_Crude_Trapdoor_State_Definitions_CloseDoorOut","rotation":3},{"x":13,"y":7,"z":9,"name":"Wood_Ash_Trunk","rotation":2},{"x":14,"y":7,"z":9,"name":"Wood_Oak_Trunk","rotation":2},{"x":15,"y":7,"z":9,"name":"Wood_Hardwood_Stairs","rotation":11},{"x":1,"y":7,"z":10,"name":"*Furniture_Crude_Trapdoor_State_Definitions_CloseDoorOut","rotation":3},{"x":2,"y":7,"z":10,"name":"Wood_Hardwood_Stairs","rotation":10},{"x":3,"y":7,"z":10,"name":"Wood_Beech_Trunk_Full","rotation":2},{"x":4,"y":7,"z":10,"name":"Wood_Ash_Trunk","rotation":2},{"x":5,"y":7,"z":10,"name":"Wood_Beech_Trunk_Full","rotation":2},{"x":6,"y":7,"z":10,"name":"Wood_Darkwood_Planks_Half","rotation":8},{"x":10,"y":7,"z":10,"name":"Wood_Darkwood_Planks_Half","rotation":8},{"x":11,"y":7,"z":10,"name":"Wood_Beech_Trunk_Full","rotation":2},{"x":12,"y":7,"z":10,"name":"Wood_Ash_Trunk","rotation":2},{"x":13,"y":7,"z":10,"name":"Wood_Beech_Trunk_Full","rotation":2},{"x":14,"y":7,"z":10,"name":"Wood_Hardwood_Stairs","rotation":10},{"x":15,"y":7,"z":10,"name":"*Furniture_Crude_Trapdoor_State_Definitions_CloseDoorOut","rotation":1},{"x":1,"y":7,"z":11,"name":"*Furniture_Crude_Trapdoor_State_Definitions_CloseDoorOut","rotation":3},{"x":2,"y":7,"z":11,"name":"*Furniture_Crude_Trapdoor_State_Definitions_CloseDoorOut","rotation":1},{"x":3,"y":7,"z":11,"name":"Wood_Ash_Trunk","rotation":2},{"x":5,"y":7,"z":11,"name":"Wood_Ash_Trunk","rotation":4},{"x":6,"y":7,"z":11,"name":"*Furniture_Tavern_Trapdoor_State_Definitions_CloseDoorOut","rotation":1},{"x":10,"y":7,"z":11,"name":"*Furniture_Tavern_Trapdoor_State_Definitions_CloseDoorOut","rotation":3},{"x":11,"y":7,"z":11,"name":"Wood_Ash_Trunk","rotation":4},{"x":12,"y":7,"z":11,"name":"*Furniture_Crude_Trapdoor_State_Definitions_CloseDoorOut","rotation":3},{"x":13,"y":7,"z":11,"name":"Wood_Ash_Trunk","rotation":2},{"x":14,"y":7,"z":11,"name":"*Furniture_Crude_Trapdoor_State_Definitions_CloseDoorOut","rotation":1},{"x":15,"y":7,"z":11,"name":"*Furniture_Crude_Trapdoor_State_Definitions_CloseDoorOut","rotation":1},{"x":1,"y":7,"z":12,"name":"*Furniture_Crude_Trapdoor_State_Definitions_CloseDoorOut","rotation":3},{"x":2,"y":7,"z":12,"name":"Wood_Hardwood_Stairs","rotation":8},{"x":3,"y":7,"z":12,"name":"Wood_Beech_Trunk_Full","rotation":2},{"x":4,"y":7,"z":12,"name":"Wood_Ash_Trunk","rotation":2},{"x":5,"y":7,"z":12,"name":"Wood_Beech_Trunk_Full","rotation":2},{"x":6,"y":7,"z":12,"name":"Wood_Darkwood_Planks_Half","rotation":8},{"x":10,"y":7,"z":12,"name":"Wood_Darkwood_Planks_Half","rotation":8},{"x":11,"y":7,"z":12,"name":"Wood_Beech_Trunk_Full","rotation":2},{"x":12,"y":7,"z":12,"name":"Wood_Ash_Trunk","rotation":2},{"x":13,"y":7,"z":12,"name":"Wood_Beech_Trunk_Full","rotation":2},{"x":14,"y":7,"z":12,"name":"Wood_Hardwood_Stairs","rotation":8},{"x":15,"y":7,"z":12,"name":"*Furniture_Crude_Trapdoor_State_Definitions_CloseDoorOut","rotation":1},{"x":1,"y":7,"z":13,"name":"Wood_Hardwood_Stairs","rotation":9},{"x":2,"y":7,"z":13,"name":"Wood_Oak_Trunk","rotation":2},{"x":3,"y":7,"z":13,"name":"Wood_Ash_Trunk","rotation":2},{"x":4,"y":7,"z":13,"name":"*Furniture_Crude_Trapdoor_State_Definitions_CloseDoorOut","rotation":3},{"x":5,"y":7,"z":13,"name":"Wood_Ash_Trunk","rotation":4},{"x":6,"y":7,"z":13,"name":"*Furniture_Tavern_Trapdoor_State_Definitions_CloseDoorOut","rotation":1},{"x":10,"y":7,"z":13,"name":"*Furniture_Tavern_Trapdoor_State_Definitions_CloseDoorOut","rotation":3},{"x":11,"y":7,"z":13,"name":"Wood_Ash_Trunk","rotation":4},{"x":12,"y":7,"z":13,"name":"*Furniture_Crude_Trapdoor_State_Definitions_CloseDoorOut","rotation":3},{"x":13,"y":7,"z":13,"name":"Wood_Ash_Trunk","rotation":2},{"x":14,"y":7,"z":13,"name":"Wood_Oak_Trunk","rotation":2},{"x":15,"y":7,"z":13,"name":"Wood_Hardwood_Stairs","rotation":11},{"x":1,"y":7,"z":14,"name":"*Furniture_Crude_Trapdoor_State_Definitions_CloseDoorOut","rotation":3},{"x":2,"y":7,"z":14,"name":"Wood_Hardwood_Stairs","rotation":10},{"x":3,"y":7,"z":14,"name":"Wood_Beech_Trunk_Full","rotation":2},{"x":4,"y":7,"z":14,"name":"Wood_Ash_Trunk","rotation":2},{"x":5,"y":7,"z":14,"name":"Wood_Beech_Trunk_Full","rotation":2},{"x":6,"y":7,"z":14,"name":"Wood_Darkwood_Planks_Half","rotation":8},{"x":10,"y":7,"z":14,"name":"Wood_Darkwood_Planks_Half","rotation":8},{"x":11,"y":7,"z":14,"name":"Wood_Beech_Trunk_Full","rotation":2},{"x":12,"y":7,"z":14,"name":"Wood_Ash_Trunk","rotation":2},{"x":13,"y":7,"z":14,"name":"Wood_Beech_Trunk_Full","rotation":2},{"x":14,"y":7,"z":14,"name":"Wood_Hardwood_Stairs","rotation":10},{"x":15,"y":7,"z":14,"name":"*Furniture_Crude_Trapdoor_State_Definitions_CloseDoorOut","rotation":1},{"x":1,"y":7,"z":15,"name":"*Furniture_Crude_Trapdoor_State_Definitions_CloseDoorOut","rotation":3},{"x":2,"y":7,"z":15,"name":"*Furniture_Crude_Trapdoor_State_Definitions_CloseDoorOut","rotation":1},{"x":3,"y":7,"z":15,"name":"Wood_Ash_Trunk","rotation":2},{"x":4,"y":7,"z":15,"name":"*Furniture_Crude_Trapdoor_State_Definitions_CloseDoorOut","rotation":3},{"x":5,"y":7,"z":15,"name":"Wood_Ash_Trunk","rotation":4},{"x":6,"y":7,"z":15,"name":"*Furniture_Tavern_Trapdoor_State_Definitions_CloseDoorOut","rotation":1},{"x":10,"y":7,"z":15,"name":"*Furniture_Tavern_Trapdoor_State_Definitions_CloseDoorOut","rotation":3},{"x":11,"y":7,"z":15,"name":"Wood_Ash_Trunk","rotation":4},{"x":12,"y":7,"z":15,"name":"*Furniture_Crude_Trapdoor_State_Definitions_CloseDoorOut","rotation":1},{"x":13,"y":7,"z":15,"name":"Wood_Ash_Trunk","rotation":2},{"x":14,"y":7,"z":15,"name":"*Furniture_Crude_Trapdoor_State_Definitions_CloseDoorOut","rotation":1},{"x":15,"y":7,"z":15,"name":"*Furniture_Crude_Trapdoor_State_Definitions_CloseDoorOut","rotation":1},{"x":1,"y":7,"z":16,"name":"*Furniture_Crude_Trapdoor_State_Definitions_CloseDoorOut","rotation":3},{"x":2,"y":7,"z":16,"name":"Wood_Hardwood_Stairs","rotation":8},{"x":3,"y":7,"z":16,"name":"Wood_Beech_Trunk_Full","rotation":2},{"x":4,"y":7,"z":16,"name":"Wood_Ash_Trunk","rotation":2},{"x":5,"y":7,"z":16,"name":"Wood_Beech_Trunk_Full","rotation":2},{"x":6,"y":7,"z":16,"name":"Wood_Darkwood_Planks_Half","rotation":8},{"x":7,"y":7,"z":16,"name":"Furniture_Tavern_Trapdoor","rotation":2},{"x":8,"y":7,"z":16,"name":"Wood_Darkwood_Planks_Half","rotation":8},{"x":9,"y":7,"z":16,"name":"Furniture_Tavern_Trapdoor","rotation":2},{"x":10,"y":7,"z":16,"name":"Wood_Darkwood_Planks_Half","rotation":8},{"x":11,"y":7,"z":16,"name":"Wood_Beech_Trunk_Full","rotation":2},{"x":12,"y":7,"z":16,"name":"Wood_Ash_Trunk","rotation":2},{"x":13,"y":7,"z":16,"name":"Wood_Beech_Trunk_Full","rotation":2},{"x":14,"y":7,"z":16,"name":"Wood_Hardwood_Stairs","rotation":8},{"x":15,"y":7,"z":16,"name":"*Furniture_Crude_Trapdoor_State_Definitions_CloseDoorOut","rotation":1},{"x":1,"y":7,"z":17,"name":"Wood_Hardwood_Stairs","rotation":9},{"x":2,"y":7,"z":17,"name":"Wood_Oak_Trunk","rotation":2},{"x":3,"y":7,"z":17,"name":"Wood_Hardwood_Stairs","rotation":11},{"x":4,"y":7,"z":17,"name":"Furniture_Crude_Trapdoor","rotation":0},{"x":5,"y":7,"z":17,"name":"Wood_Hardwood_Stairs","rotation":9},{"x":6,"y":7,"z":17,"name":"Wood_Oak_Trunk","rotation":2},{"x":7,"y":7,"z":17,"name":"Wood_Oak_Trunk","rotation":5},{"x":8,"y":7,"z":17,"name":"Wood_Oak_Trunk","rotation":5},{"x":9,"y":7,"z":17,"name":"Wood_Oak_Trunk","rotation":5},{"x":10,"y":7,"z":17,"name":"Wood_Oak_Trunk","rotation":2},{"x":11,"y":7,"z":17,"name":"Wood_Hardwood_Stairs","rotation":11},{"x":12,"y":7,"z":17,"name":"Furniture_Crude_Trapdoor","rotation":0},{"x":13,"y":7,"z":17,"name":"Wood_Hardwood_Stairs","rotation":9},{"x":14,"y":7,"z":17,"name":"Wood_Oak_Trunk","rotation":2},{"x":15,"y":7,"z":17,"name":"Wood_Hardwood_Stairs","rotation":11},{"x":2,"y":7,"z":18,"name":"Wood_Hardwood_Stairs","rotation":10},{"x":3,"y":7,"z":18,"name":"Furniture_Crude_Trapdoor","rotation":0},{"x":4,"y":7,"z":18,"name":"Furniture_Crude_Trapdoor","rotation":0},{"x":5,"y":7,"z":18,"name":"Furniture_Crude_Trapdoor","rotation":0},{"x":6,"y":7,"z":18,"name":"Wood_Oak_Trunk","rotation":2},{"x":7,"y":7,"z":18,"name":"Furniture_Crude_Brazier"},{"x":8,"y":7,"z":18,"name":"Furniture_Crude_Brazier"},{"x":9,"y":7,"z":18,"name":"Furniture_Crude_Brazier"},{"x":10,"y":7,"z":18,"name":"Wood_Oak_Trunk","rotation":2},{"x":11,"y":7,"z":18,"name":"Furniture_Crude_Trapdoor","rotation":0},{"x":12,"y":7,"z":18,"name":"Furniture_Crude_Trapdoor","rotation":0},{"x":13,"y":7,"z":18,"name":"Furniture_Crude_Trapdoor","rotation":0},{"x":14,"y":7,"z":18,"name":"Wood_Hardwood_Stairs","rotation":10},{"x":6,"y":7,"z":19,"name":"Deco_Iron_Chain_Small","rotation":2},{"x":10,"y":7,"z":19,"name":"Deco_Iron_Chain_Small","rotation":2},{"x":6,"y":8,"z":3,"name":"Wood_Hardwood_Fence","rotation":1},{"x":10,"y":8,"z":3,"name":"Wood_Hardwood_Fence","rotation":1},{"x":2,"y":8,"z":4,"name":"Wood_Oak_Trunk","rotation":2},{"x":3,"y":8,"z":4,"name":"Furniture_Crude_Brazier"},{"x":4,"y":8,"z":4,"name":"Furniture_Crude_Brazier"},{"x":5,"y":8,"z":4,"name":"Furniture_Crude_Brazier"},{"x":6,"y":8,"z":4,"name":"Wood_Oak_Trunk","rotation":2},{"x":10,"y":8,"z":4,"name":"Wood_Oak_Trunk","rotation":2},{"x":11,"y":8,"z":4,"name":"Furniture_Crude_Brazier"},{"x":12,"y":8,"z":4,"name":"Furniture_Crude_Brazier"},{"x":13,"y":8,"z":4,"name":"Furniture_Crude_Brazier"},{"x":14,"y":8,"z":4,"name":"Wood_Oak_Trunk","rotation":2},{"x":1,"y":8,"z":5,"name":"Wood_Oak_Trunk","rotation":2},{"x":2,"y":8,"z":5,"name":"Wood_Oak_Trunk","rotation":2},{"x":3,"y":8,"z":5,"name":"Wood_Oak_Trunk","rotation":5},{"x":4,"y":8,"z":5,"name":"Wood_Oak_Trunk","rotation":5},{"x":5,"y":8,"z":5,"name":"Wood_Oak_Trunk","rotation":5},{"x":6,"y":8,"z":5,"name":"Wood_Oak_Trunk","rotation":2},{"x":7,"y":8,"z":5,"name":"Wood_Hardwood_Stairs","rotation":8},{"x":8,"y":8,"z":5,"name":"Wood_Hardwood_Stairs","rotation":8},{"x":9,"y":8,"z":5,"name":"Wood_Hardwood_Stairs","rotation":8},{"x":10,"y":8,"z":5,"name":"Wood_Oak_Trunk","rotation":2},{"x":11,"y":8,"z":5,"name":"Wood_Oak_Trunk","rotation":5},{"x":12,"y":8,"z":5,"name":"Wood_Oak_Trunk","rotation":5},{"x":13,"y":8,"z":5,"name":"Wood_Oak_Trunk","rotation":5},{"x":14,"y":8,"z":5,"name":"Wood_Oak_Trunk","rotation":2},{"x":15,"y":8,"z":5,"name":"Wood_Oak_Trunk","rotation":2},{"x":1,"y":8,"z":6,"name":"Furniture_Crude_Brazier"},{"x":2,"y":8,"z":6,"name":"Wood_Oak_Trunk","rotation":4},{"x":3,"y":8,"z":6,"name":"Wood_Beech_Trunk_Full","rotation":2},{"x":4,"y":8,"z":6,"name":"Wood_Ash_Trunk","rotation":2},{"x":5,"y":8,"z":6,"name":"Wood_Beech_Trunk_Full","rotation":2},{"x":6,"y":8,"z":6,"name":"Wood_Oak_Trunk","rotation":4},{"x":7,"y":8,"z":6,"name":"Rock_Ledge_Brick_Wall"},{"x":8,"y":8,"z":6,"name":"Wood_Drywood_Planks"},{"x":9,"y":8,"z":6,"name":"Rock_Slate_Cobble_Wall"},{"x":10,"y":8,"z":6,"name":"Wood_Oak_Trunk","rotation":4},{"x":11,"y":8,"z":6,"name":"Wood_Beech_Trunk_Full","rotation":2},{"x":12,"y":8,"z":6,"name":"Wood_Ash_Trunk","rotation":2},{"x":13,"y":8,"z":6,"name":"Wood_Beech_Trunk_Full","rotation":2},{"x":14,"y":8,"z":6,"name":"Wood_Oak_Trunk","rotation":4},{"x":15,"y":8,"z":6,"name":"Furniture_Crude_Brazier"},{"x":1,"y":8,"z":7,"name":"Furniture_Crude_Brazier"},{"x":2,"y":8,"z":7,"name":"Wood_Oak_Trunk","rotation":4},{"x":3,"y":8,"z":7,"name":"Wood_Ash_Trunk","rotation":2},{"x":4,"y":8,"z":7,"name":"Rock_Crystal_Yellow_Block"},{"x":6,"y":8,"z":7,"name":"Wood_Oak_Trunk","rotation":4},{"x":10,"y":8,"z":7,"name":"Wood_Oak_Trunk","rotation":4},{"x":12,"y":8,"z":7,"name":"Rock_Crystal_Yellow_Block"},{"x":13,"y":8,"z":7,"name":"Wood_Ash_Trunk","rotation":2},{"x":14,"y":8,"z":7,"name":"Wood_Oak_Trunk","rotation":4},{"x":15,"y":8,"z":7,"name":"Furniture_Crude_Brazier"},{"x":1,"y":8,"z":8,"name":"Furniture_Crude_Brazier"},{"x":2,"y":8,"z":8,"name":"Wood_Oak_Trunk","rotation":4},{"x":3,"y":8,"z":8,"name":"Wood_Beech_Trunk_Full","rotation":2},{"x":4,"y":8,"z":8,"name":"Wood_Ash_Trunk","rotation":2},{"x":5,"y":8,"z":8,"name":"Wood_Ash_Trunk","rotation":5},{"x":6,"y":8,"z":8,"name":"Wood_Oak_Trunk","rotation":4},{"x":10,"y":8,"z":8,"name":"Wood_Oak_Trunk","rotation":4},{"x":11,"y":8,"z":8,"name":"Wood_Ash_Trunk","rotation":5},{"x":12,"y":8,"z":8,"name":"Wood_Ash_Trunk","rotation":5},{"x":13,"y":8,"z":8,"name":"Wood_Beech_Trunk_Full","rotation":2},{"x":14,"y":8,"z":8,"name":"Wood_Oak_Trunk","rotation":4},{"x":15,"y":8,"z":8,"name":"Furniture_Crude_Brazier"},{"x":1,"y":8,"z":9,"name":"Wood_Oak_Trunk","rotation":2},{"x":2,"y":8,"z":9,"name":"Wood_Oak_Trunk","rotation":2},{"x":3,"y":8,"z":9,"name":"Wood_Ash_Trunk","rotation":2},{"x":4,"y":8,"z":9,"name":"Rock_Crystal_Yellow_Block"},{"x":6,"y":8,"z":9,"name":"Wood_Oak_Trunk","rotation":4},{"x":10,"y":8,"z":9,"name":"Wood_Oak_Trunk","rotation":4},{"x":12,"y":8,"z":9,"name":"Rock_Crystal_Yellow_Block"},{"x":13,"y":8,"z":9,"name":"Wood_Ash_Trunk","rotation":2},{"x":14,"y":8,"z":9,"name":"Wood_Oak_Trunk","rotation":2},{"x":15,"y":8,"z":9,"name":"Wood_Oak_Trunk","rotation":2},{"x":1,"y":8,"z":10,"name":"Furniture_Crude_Brazier"},{"x":2,"y":8,"z":10,"name":"Wood_Oak_Trunk","rotation":4},{"x":3,"y":8,"z":10,"name":"Wood_Beech_Trunk_Full","rotation":2},{"x":4,"y":8,"z":10,"name":"Wood_Ash_Trunk","rotation":2},