{
  "version": 8,
  "blockIdVersion": 10,
  "anchorX": 0,
  "anchorY": 0,
  "anchorZ": 0,
  "blocks": [
    {
      "x": 0,
      "y": 0,
      "z": 0,
      "name": "Soil_Dirt"
    },
    {
      "x": 1,
      "y": 0,
      "z": 0,
      "name": "Soil_Dirt"
    },
    {
      "x": 2,
      "y": 0,
      "z": 0,
      "name": "Soil_Dirt"
    },
    {
      "x": 3,
      "y": 0,
      "z": 0,
      "name": "Soil_Dirt"
    },
    {
      "x": 4,
      "y": 0,
      "z": 0,
      "name": "Soil_Dirt"
    },
    {
      "x": 5,
      "y": 0,
      "z": 0,
      "name": "Soil_Dirt"
    },
    {
      "x": 6,
      "y": 0,
      "z": 0,
      "name": "Soil_Dirt"
    },
    {
      "x": 7,
      "y": 0,
      "z": 0,
      "name": "Soil_Dirt"
    },
    {
      "x": 8,
      "y": 0,
      "z": 0,
      "name": "Soil_Dirt"
    },
    {
      "x": 9,
      "y": 0,
      "z": 0,
      "name": "Soil_Dirt"
    },
    {
      "x": 10,
      "y": 0,
      "z": 0,
      "name": "Soil_Dirt"
    },
    {
      "x": 11,
      "y": 0,
      "z": 0,
      "name": "Soil_Dirt"
    },
    {
      "x": 12,
      "y": 0,
      "z": 0,
      "name": "Soil_Dirt"
    },
    {
      "x": 13,
      "y": 0,
      "z": 0,
      "name": "Soil_Dirt"
    },
    {
      "x": 14,
      "y": 0,
      "z": 0,
      "name": "Soil_Dirt"
    },
    {
      "x": 15,
      "y": 0,
      "z": 0,
      "name": "Soil_Dirt"
    },
    {
      "x": 16,
      "y": 0,
      "z": 0,
      "name": "Rock_Stone_Brick"
    },
    {
      "x": 0,
      "y": 0,
      "z": 1,
      "name": "Soil_Dirt"
    },
    {
      "x": 1,
      "y": 0,
      "z": 1,
      "name": "Soil_Dirt"
    },
    {
      "x": 2,
      "y": 0,
      "z": 1,
      "name": "Soil_Dirt"
    },
    {
      "x": 3,
      "y": 0,
      "z": 1,
      "name": "Soil_Dirt"
    },
    {
      "x": 4,
      "y": 0,
      "z": 1,
      "name": "Soil_Dirt"
    },
    {
      "x": 5,
      "y": 0,
      "z": 1,
      "name": "Soil_Dirt"
    },
    {
      "x": 6,
      "y": 0,
      "z": 1,
      "name": "Soil_Dirt"
    },
    {
      "x": 7,
      "y": 0,
      "z": 1,
      "name": "Soil_Dirt"
    },
    {
      "x": 8,
      "y": 0,
      "z": 1,
      "name": "Soil_Dirt"
    },
    {
      "x": 9,
      "y": 0,
      "z": 1,
      "name": "Soil_Dirt"
    },
    {
      "x": 10,
      "y": 0,
      "z": 1,
      "name": "Soil_Dirt"
    },
    {
      "x": 11,
      "y": 0,
      "z": 1,
      "name": "Soil_Dirt"
    },
    {
      "x": 12,
      "y": 0,
      "z": 1,
      "name": "Soil_Dirt"
    },
    {
      "x": 13,
      "y": 0,
      "z": 1,
      "name": "Soil_Dirt"
    },
    {
      "x": 14,
      "y": 0,
      "z": 1,
      "name": "Soil_Dirt"
    },
    {
      "x": 15,
      "y": 0,
      "z": 1,
      "name": "Soil_Dirt"
    },
    {
      "x": 16,
      "y": 0,
      "z": 1,
      "name": "Soil_Dirt"
    },
    {
      "x": 0,
      "y": 0,
      "z": 2,
      "name": "Soil_Dirt"
    },
    {
      "x": 1,
      "y": 0,
      "z": 2,
      "name": "Soil_Dirt"
    },
    {
      "x": 2,
      "y": 0,
      "z": 2,
      "name": "Soil_Dirt"
    },
    {
      "x": 3,
      "y": 0,
      "z": 2,
      "name": "Soil_Grass"
    },
    {
      "x": 4,
      "y": 0,
      "z": 2,
      "name": "Soil_Dirt"
    },
    {
      "x": 5,
      "y": 0,
      "z": 2,
      "name": "Soil_Dirt"
    },
    {
      "x": 6,
      "y": 0,
      "z": 2,
      "name": "Soil_Dirt"
    },
    {
      "x": 7,
      "y": 0,
      "z": 2,
      "name": "Soil_Dirt"
    },
    {
      "x": 8,
      "y": 0,
      "z": 2,
      "name": "Soil_Dirt"
    },
    {
      "x": 9,
      "y": 0,
      "z": 2,
      "name": "Soil_Dirt"
    },
    {
      "x": 10,
      "y": 0,
      "z": 2,
      "name": "Soil_Dirt"
    },
    {
      "x": 11,
      "y": 0,
      "z": 2,
      "name": "Soil_Grass"
    },
    {
      "x": 12,
      "y": 0,
      "z": 2,
      "name": "Soil_Dirt"
    },
    {
      "x": 13,
      "y": 0,
      "z": 2,
      "name": "Soil_Dirt"
    },
    {
      "x": 14,
      "y": 0,
      "z": 2,
      "name": "Soil_Dirt"
    },
    {
      "x": 15,
      "y": 0,
      "z": 2,
      "name": "Soil_Dirt"
    },
    {
      "x": 16,
      "y": 0,
      "z": 2,
      "name": "Soil_Dirt"
    },
    {
      "x": 0,
      "y": 0,
      "z": 3,
      "name": "Soil_Dirt"
    },
    {
      "x": 1,
      "y": 0,
      "z": 3,
      "name": "Soil_Dirt"
    },
    {
      "x": 2,
      "y": 0,
      "z": 3,
      "name": "Soil_Dirt"
    },
    {
      "x": 3,
      "y": 0,
      "z": 3,
      "name": "Soil_Dirt"
    },
    {
      "x": 4,
      "y": 0,
      "z": 3,
      "name": "Soil_Dirt"
    },
    {
      "x": 5,
      "y": 0,
      "z": 3,
      "name": "Soil_Dirt"
    },
    {
      "x": 6,
      "y": 0,
      "z": 3,
      "name": "Soil_Dirt"
    },
    {
      "x": 7,
      "y": 0,
      "z": 3,
      "name": "Soil_Dirt"
    },
    {
      "x": 8,
      "y": 0,
      "z": 3,
      "name": "Soil_Dirt"
    },
    {
      "x": 9,
      "y": 0,
      "z": 3,
      "name": "Soil_Dirt"
    },
    {
      "x": 10,
      "y": 0,
      "z": 3,
      "name": "Soil_Dirt"
    },
    {
      "x": 11,
      "y": 0,
      "z": 3,
      "name": "Soil_Dirt"
    },
    {
      "x": 12,
      "y": 0,
      "z": 3,
      "name": "Soil_Dirt"
    },
    {
      "x": 13,
      "y": 0,
      "z": 3,
      "name": "Soil_Dirt"
    },
    {
      "x": 14,
      "y": 0,
      "z": 3,
      "name": "Soil_Dirt"
    },
    {
      "x": 15,
      "y": 0,
      "z": 3,
      "name": "Soil_Dirt"
    },
    {
      "x": 16,
      "y": 0,
      "z": 3,
      "name": "Soil_Dirt"
    },
    {
      "x": 0,
      "y": 0,
      "z": 4,
      "name": "Soil_Dirt"
    },
    {
      "x": 1,
      "y": 0,
      "z": 4,
      "name": "Soil_Dirt"
    },
    {
      "x": 2,
      "y": 0,
      "z": 4,
      "name": "Soil_Dirt"
    },
    {
      "x": 3,
      "y": 0,
      "z": 4,
      "name": "Soil_Dirt"
    },
    {
      "x": 4,
      "y": 0,
      "z": 4,
      "name": "Soil_Dirt"
    },
    {
      "x": 5,
      "y": 0,
      "z": 4,
      "name": "Soil_Dirt"
    },
    {
      "x": 6,
      "y": 0,
      "z": 4,
      "name": "Soil_Dirt"
    },
    {
      "x": 7,
      "y": 0,
      "z": 4,
      "name": "Soil_Dirt"
    },
    {
      "x": 8,
      "y": 0,
      "z": 4,
      "name": "Soil_Dirt"
    },
    {
      "x": 9,
      "y": 0,
      "z": 4,
      "name": "Soil_Dirt"
    },
    {
      "x": 10,
      "y": 0,
      "z": 4,
      "name": "Soil_Dirt"
    },
    {
      "x": 11,
      "y": 0,
      "z": 4,
      "name": "Soil_Dirt"
    },
    {
      "x": 12,
      "y": 0,
      "z": 4,
      "name": "Soil_Dirt"
    },
    {
      "x": 13,
      "y": 0,
      "z": 4,
      "name": "Soil_Dirt"
    },
    {
      "x": 14,
      "y": 0,
      "z": 4,
      "name": "Soil_Dirt"
    },
    {
      "x": 15,
      "y": 0,
      "z": 4,
      "name": "Soil_Dirt"
    },
    {
      "x": 16,
      "y": 0,
      "z": 4,
      "name": "Soil_Dirt"
    },
    {
      "x": 0,
      "y": 0,
      "z": 5,
      "name": "Soil_Dirt"
    },
    {
      "x": 1,
      "y": 0,
      "z": 5,
      "name": "Soil_Dirt"
    },
    {
      "x": 2,
      "y": 0,
      "z": 5,
      "name": "Soil_Dirt"
    },
    {
      "x": 3,
      "y": 0,
      "z": 5,
      "name": "Soil_Dirt"
    },
    {
      "x": 4,
      "y": 0,
      "z": 5,
      "name": "Soil_Dirt"
    },
    {
      "x": 5,
      "y": 0,
      "z": 5,
      "name": "Soil_Dirt"
    },
    {
      "x": 6,
      "y": 0,
      "z": 5,
      "name": "Soil_Dirt"
    },
    {
      "x": 7,
      "y": 0,
      "z": 5,
      "name": "Soil_Dirt"
    },
    {
      "x": 8,
      "y": 0,
      "z": 5,
      "name": "Soil_Dirt"
    },
    {
      "x": 9,
      "y": 0,
      "z": 5,
      "name": "Soil_Dirt"
    },
    {
      "x": 10,
      "y": 0,
      "z": 5,
      "name": "Soil_Dirt"
    },
    {
      "x": 11,
      "y": 0,
      "z": 5,
      "name": "Soil_Dirt"
    },
    {
      "x": 12,
      "y": 0,
      "z": 5,
      "name": "Soil_Dirt"
    },
    {
      "x": 13,
      "y": 0,
      "z": 5,
      "name": "Soil_Dirt"
    },
    {
      "x": 14,
      "y": 0,
      "z": 5,
      "name": "Soil_Dirt"
    },
    {
      "x": 15,
      "y": 0,
      "z": 5,
      "name": "Soil_Dirt"
    },
    {
      "x": 16,
      "y": 0,
      "z": 5,
      "name": "Soil_Dirt"
    },
    {
      "x": 0,
      "y": 0,
      "z": 6,
      "name": "Soil_Dirt"
    },
    {
      "x": 1,
      "y": 0,
      "z": 6,
      "name": "Soil_Dirt"
    },
    {
      "x": 2,
      "y": 0,
      "z": 6,
      "name": "Soil_Dirt"
    },
    {
      "x": 3,
      "y": 0,
      "z": 6,
      "name": "Soil_Dirt"
    },
    {
      "x": 4,
      "y": 0,
      "z": 6,
      "name": "Soil_Dirt"
    },
    {
      "x": 5,
      "y": 0,
      "z": 6,
      "name": "Soil_Dirt"
    },
    {
      "x": 6,
      "y": 0,
      "z": 6,
      "name": "Soil_Dirt"
    },
    {
      "x": 7,
      "y": 0,
      "z": 6,
      "name": "Soil_Dirt"
    },
    {
      "x": 8,
      "y": 0,
      "z": 6,
      "name": "Soil_Dirt"
    },
    {
      "x": 9,
      "y": 0,
      "z": 6,
      "name": "Soil_Dirt"
    },
    {
      "x": 10,
      "y": 0,
      "z": 6,
      "name": "Soil_Dirt"
    },
    {
      "x": 11,
      "y": 0,
      "z": 6,
      "name": "Soil_Dirt"
    },
    {
      "x": 12,
      "y": 0,
      "z": 6,
      "name": "Soil_Dirt"
    },
    {
      "x": 13,
      "y": 0,
      "z": 6,
      "name": "Soil_Dirt"
    },
    {
      "x": 14,
      "y": 0,
      "z": 6,
      "name": "Soil_Dirt"
    },
    {
      "x": 15,
      "y": 0,
      "z": 6,
      "name": "Soil_Dirt"
    },
    {
      "x": 16,
      "y": 0,
      "z": 6,
      "name": "Soil_Dirt"
    },
    {
      "x": 0,
      "y": 0,
      "z": 7,
      "name": "Soil_Dirt"
    },
    {
      "x": 1,
      "y": 0,
      "z": 7,
      "name": "Soil_Dirt"
    },
    {
      "x": 2,
      "y": 0,
      "z": 7,
      "name": "Soil_Dirt"
    },
    {
      "x": 3,
      "y": 0,
      "z": 7,
      "name": "Soil_Dirt"
    },
    {
      "x": 4,
      "y": 0,
      "z": 7,
      "name": "Soil_Dirt"
    },
    {
      "x": 5,
      "y": 0,
      "z": 7,
      "name": "Soil_Dirt"
    },
    {
      "x": 6,
      "y": 0,
      "z": 7,
      "name": "Soil_Dirt"
    },
    {
      "x": 7,
      "y": 0,
      "z": 7,
      "name": "Soil_Dirt"
    },
    {
      "x": 8,
      "y": 0,
      "z": 7,
      "name": "Soil_Dirt"
    },
    {
      "x": 9,
      "y": 0,
      "z": 7,
      "name": "Soil_Dirt"
    },
    {
      "x": 10,
      "y": 0,
      "z": 7,
      "name": "Soil_Dirt"
    },
    {
      "x": 11,
      "y": 0,
      "z": 7,
      "name": "Soil_Dirt"
    },
    {
      "x": 12,
      "y": 0,
      "z": 7,
      "name": "Soil_Dirt"
    },
    {
      "x": 13,
      "y": 0,
      "z": 7,
      "name": "Soil_Dirt"
    },
    {
      "x": 14,
      "y": 0,
      "z": 7,
      "name": "Soil_Dirt"
    },
    {
      "x": 15,
      "y": 0,
      "z": 7,
      "name": "Soil_Dirt"
    },
    {
      "x": 16,
      "y": 0,
      "z": 7,
      "name": "Soil_Dirt"
    },
    {
      "x": 0,
      "y": 0,
      "z": 8,
      "name": "Soil_Dirt"
    },
    {
      "x": 1,
      "y": 0,
      "z": 8,
      "name": "Soil_Dirt"
    },
    {
      "x": 2,
      "y": 0,
      "z": 8,
      "name": "Soil_Dirt"
    },
    {
      "x": 3,
      "y": 0,
      "z": 8,
      "name": "Soil_Dirt"
    },
    {
      "x": 4,
      "y": 0,
      "z": 8,
      "name": "Soil_Dirt"
    },
    {
      "x": 5,
      "y": 0,
      "z": 8,
      "name": "Soil_Dirt"
    },
    {
      "x": 6,
      "y": 0,
      "z": 8,
      "name": "Soil_Dirt"
    },
    {
      "x": 7,
      "y": 0,
      "z": 8,
      "name": "Soil_Dirt"
    },
    {
      "x": 8,
      "y": 0,
      "z": 8,
      "name": "Soil_Dirt"
    },
    {
      "x": 9,
      "y": 0,
      "z": 8,
      "name": "Soil_Dirt"
    },
    {
      "x": 10,
      "y": 0,
      "z": 8,
      "name": "Soil_Dirt"
    },
    {
      "x": 11,
      "y": 0,
      "z": 8,
      "name": "Soil_Dirt"
    },
    {
      "x": 12,
      "y": 0,
      "z": 8,
      "name": "Soil_Dirt"
    },
    {
      "x": 13,
      "y": 0,
      "z": 8,
      "name": "Soil_Dirt"
    },
    {
      "x": 14,
      "y": 0,
      "z": 8,
      "name": "Soil_Dirt"
    },
    {
      "x": 15,
      "y": 0,
      "z": 8,
      "name": "Soil_Dirt"
    },
    {
      "x": 16,
      "y": 0,
      "z": 8,
      "name": "Soil_Dirt"
    },
    {
      "x": 0,
      "y": 0,
      "z": 9,
      "name": "Soil_Dirt"
    },
    {
      "x": 1,
      "y": 0,
      "z": 9,
      "name": "Soil_Dirt"
    },
    {
      "x": 2,
      "y": 0,
      "z": 9,
      "name": "Soil_Dirt"
    },
    {
      "x": 3,
      "y": 0,
      "z": 9,
      "name": "Soil_Dirt"
    },
    {
      "x": 4,
      "y": 0,
      "z": 9,
      "name": "Soil_Dirt"
    },
    {
      "x": 5,
      "y": 0,
      "z": 9,
      "name": "Soil_Dirt"
    },
    {
      "x": 6,
      "y": 0,
      "z": 9,
      "name": "Soil_Dirt"
    },
    {
      "x": 7,
      "y": 0,
      "z": 9,
      "name": "Soil_Dirt"
    },
    {
      "x": 8,
      "y": 0,
      "z": 9,
      "name": "Soil_Dirt"
    },
    {
      "x": 9,
      "y": 0,
      "z": 9,
      "name": "Soil_Dirt"
    },
    {
      "x": 10,
      "y": 0,
      "z": 9,
      "name": "Soil_Dirt"
    },
    {
      "x": 11,
      "y": 0,
      "z": 9,
      "name": "Soil_Dirt"
    },
    {
      "x": 12,
      "y": 0,
      "z": 9,
      "name": "Soil_Dirt"
    },
    {
      "x": 13,
      "y": 0,
      "z": 9,
      "name": "Soil_Dirt"
    },
    {
      "x": 14,
      "y": 0,
      "z": 9,
      "name": "Soil_Dirt"
    },
    {
      "x": 15,
      "y": 0,
      "z": 9,
      "name": "Soil_Dirt"
    },
    {
      "x": 16,
      "y": 0,
      "z": 9,
      "name": "Soil_Dirt"
    },
    {
      "x": 0,
      "y": 0,
      "z": 10,
      "name": "Soil_Dirt"
    },
    {
      "x": 1,
      "y": 0,
      "z": 10,
      "name": "Soil_Dirt"
    },
    {
      "x": 2,
      "y": 0,
      "z": 10,
      "name": "Soil_Dirt"
    },
    {
      "x": 3,
      "y": 0,
      "z": 10,
      "name": "Soil_Dirt"
    },
    {
      "x": 4,
      "y": 0,
      "z": 10,
      "name": "Soil_Dirt"
    },
    {
      "x": 5,
      "y": 0,
      "z": 10,
      "name": "Soil_Dirt"
    },
    {
      "x": 6,
      "y": 0,
      "z": 10,
      "name": "Soil_Dirt"
    },
    {
      "x": 7,
      "y": 0,
      "z": 10,
      "name": "Soil_Dirt"
    },
    {
      "x": 8,
      "y": 0,
      "z": 10,
      "name": "Soil_Dirt"
    },
    {
      "x": 9,
      "y": 0,
      "z": 10,
      "name": "Soil_Dirt"
    },
    {
      "x": 10,
      "y": 0,
      "z": 10,
      "name": "Soil_Dirt"
    },
    {
      "x": 11,
      "y": 0,
      "z": 10,
      "name": "Soil_Dirt"
    },
    {
      "x": 12,
      "y": 0,
      "z": 10,
      "name": "Soil_Dirt"
    },
    {
      "x": 13,
      "y": 0,
      "z": 10,
      "name": "Soil_Dirt"
    },
    {
      "x": 14,
      "y": 0,
      "z": 10,
      "name": "Soil_Dirt"
    },
    {
      "x": 15,
      "y": 0,
      "z": 10,
      "name": "Soil_Dirt"
    },
    {
      "x": 16,
      "y": 0,
      "z": 10,
      "name": "Soil_Dirt"
    },
    {
      "x": 0,
      "y": 0,
      "z": 11,
      "name": "Soil_Dirt"
    },
    {
      "x": 1,
      "y": 0,
      "z": 11,
      "name": "Soil_Dirt"
    },
    {
      "x": 2,
      "y": 0,
      "z": 11,
      "name": "Soil_Dirt"
    },
    {
      "x": 3,
      "y": 0,
      "z": 11,
      "name": "Soil_Dirt"
    },
    {
      "x": 4,
      "y": 0,
      "z": 11,
      "name": "Soil_Dirt"
    },
    {
      "x": 5,
      "y": 0,
      "z": 11,
      "name": "Soil_Dirt"
    },
    {
      "x": 6,
      "y": 0,
      "z": 11,
      "name": "Soil_Dirt"
    },
    {
      "x": 7,
      "y": 0,
      "z": 11,
      "name": "Soil_Dirt"
    },
    {
      "x": 8,
      "y": 0,
      "z": 11,
      "name": "Soil_Dirt"
    },
    {
      "x": 9,
      "y": 0,
      "z": 11,
      "name": "Soil_Dirt"
    },
    {
      "x": 10,
      "y": 0,
      "z": 11,
      "name": "Soil_Dirt"
    },
    {
      "x": 11,
      "y": 0,
      "z": 11,
      "name": "Soil_Dirt"
    },
    {
      "x": 12,
      "y": 0,
      "z": 11,
      "name": "Soil_Dirt"
    },
    {
      "x": 13,
      "y": 0,
      "z": 11,
      "name": "Soil_Dirt"
    },
    {
      "x": 14,
      "y": 0,
      "z": 11,
      "name": "Soil_Dirt"
    },
    {
      "x": 15,
      "y": 0,
      "z": 11,
      "name": "Soil_Dirt"
    },
    {
      "x": 16,
      "y": 0,
      "z": 11,
      "name": "Soil_Dirt"
    },
    {
      "x": 0,
      "y": 0,
      "z": 12,
      "name": "Soil_Dirt"
    },
    {
      "x": 1,
      "y": 0,
      "z": 12,
      "name": "Soil_Dirt"
    },
    {
      "x": 2,
      "y": 0,
      "z": 12,
      "name": "Soil_Dirt"
    },
    {
      "x": 3,
      "y": 0,
      "z": 12,
      "name": "Soil_Dirt"
    },
    {
      "x": 4,
      "y": 0,
      "z": 12,
      "name": "Soil_Dirt"
    },
    {
      "x": 5,
      "y": 0,
      "z": 12,
      "name": "Soil_Dirt"
    },
    {
      "x": 6,
      "y": 0,
      "z": 12,
      "name": "Soil_Dirt"
    },
    {
      "x": 7,
      "y": 0,
      "z": 12,
      "name": "Soil_Dirt"
    },
    {
      "x": 8,
      "y": 0,
      "z": 12,
      "name": "Soil_Dirt"
    },
    {
      "x": 9,
      "y": 0,
      "z": 12,
      "name": "Soil_Dirt"
    },
    {
      "x": 10,
      "y": 0,
      "z": 12,
      "name": "Soil_Dirt"
    },
    {
      "x": 11,
      "y": 0,
      "z": 12,
      "name": "Soil_Dirt"
    },
    {
      "x": 12,
      "y": 0,
      "z": 12,
      "name": "Soil_Dirt"
    },
    {
      "x": 13,
      "y": 0,
      "z": 12,
      "name": "Soil_Dirt"
    },
    {
      "x": 14,
      "y": 0,
      "z": 12,
      "name": "Soil_Dirt"
    },
    {
      "x": 15,
      "y": 0,
      "z": 12,
      "name": "Soil_Dirt"
    },
    {
      "x": 16,
      "y": 0,
      "z": 12,
      "name": "Soil_Dirt"
    },
    {
      "x": 0,
      "y": 0,
      "z": 13,
      "name": "Soil_Dirt"
    },
    {
      "x": 1,
      "y": 0,
      "z": 13,
      "name": "Soil_Dirt"
    },
    {
      "x": 2,
      "y": 0,
      "z": 13,
      "name": "Soil_Dirt"
    },
    {
      "x": 3,
      "y": 0,
      "z": 13,
      "name": "Soil_Dirt"
    },
    {
      "x": 4,
      "y": 0,
      "z": 13,
      "name": "Soil_Dirt"
    },
    {
      "x": 5,
      "y": 0,
      "z": 13,
      "name": "Soil_Dirt"
    },
    {
      "x": 6,
      "y": 0,
      "z": 13,
      "name": "Soil_Dirt"
    },
    {
      "x": 7,
      "y": 0,
      "z": 13,
      "name": "Soil_Dirt"
    },
    {
      "x": 8,
      "y": 0,
      "z": 13,
      "name": "Soil_Dirt"
    },
    {
      "x": 9,
      "y": 0,
      "z": 13,
      "name": "Soil_Dirt"
    },
    {
      "x": 10,
      "y": 0,
      "z": 13,
      "name": "Soil_Dirt"
    },
    {
      "x": 11,
      "y": 0,
      "z": 13,
      "name": "Soil_Dirt"
    },
    {
      "x": 12,
      "y": 0,
      "z": 13,
      "name": "Soil_Dirt"
    },
    {
      "x": 13,
      "y": 0,
      "z": 13,
      "name": "Soil_Dirt"
    },
    {
      "x": 14,
      "y": 0,
      "z": 13,
      "name": "Soil_Dirt"
    },
    {
      "x": 15,
      "y": 0,
      "z": 13,
      "name": "Soil_Dirt"
    },
    {
      "x": 16,
      "y": 0,
      "z": 13,
      "name": "Soil_Dirt"
    },
    {
      "x": 0,
      "y": 0,
      "z": 14,
      "name": "Soil_Dirt"
    },
    {
      "x": 1,
      "y": 0,
      "z": 14,
      "name": "Soil_Dirt"
    },
    {
      "x": 2,
      "y": 0,
      "z": 14,
      "name": "Soil_Dirt"
    },
    {
      "x": 3,
      "y": 0,
      "z": 14,
      "name": "Soil_Dirt"
    },
    {
      "x": 4,
      "y": 0,
      "z": 14,
      "name": "Soil_Dirt"
    },
    {
      "x": 5,
      "y": 0,
      "z": 14,
      "name": "Soil_Dirt"
    },
    {
      "x": 6,
      "y": 0,
      "z": 14,
      "name": "Soil_Dirt"
    },
    {
      "x": 7,
      "y": 0,
      "z": 14,
      "name": "Soil_Dirt"
    },
    {
      "x": 8,
      "y": 0,
      "z": 14,
      "name": "Soil_Dirt"
    },
    {
      "x": 9,
      "y": 0,
      "z": 14,
      "name": "Soil_Dirt"
    },
    {
      "x": 10,
      "y": 0,
      "z": 14,
      "name": "Soil_Dirt"
    },
    {
      "x": 11,
      "y": 0,
      "z": 14,
      "name": "Soil_Dirt"
    },
    {
      "x": 12,
      "y": 0,
      "z": 14,
      "name": "Soil_Dirt"
    },
    {
      "x": 13,
      "y": 0,
      "z": 14,
      "name": "Soil_Dirt"
    },
    {
      "x": 14,
      "y": 0,
      "z": 14,
      "name": "Soil_Dirt"
    },
    {
      "x": 15,
      "y": 0,
      "z": 14,
      "name": "Soil_Dirt"
    },
    {
      "x": 16,
      "y": 0,
      "z": 14,
      "name": "Soil_Dirt"
    },
    {
      "x": 0,
      "y": 0,
      "z": 15,
      "name": "Soil_Dirt"
    },
    {
      "x": 1,
      "y": 0,
      "z": 15,
      "name": "Soil_Dirt"
    },
    {
      "x": 2,
      "y": 0,
      "z": 15,
      "name": "Soil_Dirt"
    },
    {
      "x": 3,
      "y": 0,
      "z": 15,
      "name": "Soil_Dirt"
    },
    {
      "x": 4,
      "y": 0,
      "z": 15,
      "name": "Soil_Dirt"
    },
    {
      "x": 5,
      "y": 0,
      "z": 15,
      "name": "Soil_Dirt"
    },
    {
      "x": 6,
      "y": 0,
      "z": 15,
      "name": "Soil_Dirt"
    },
    {
      "x": 7,
      "y": 0,
      "z": 15,
      "name": "Soil_Dirt"
    },
    {
      "x": 8,
      "y": 0,
      "z": 15,
      "name": "Soil_Dirt"
    },
    {
      "x": 9,
      "y": 0,
      "z": 15,
      "name": "Soil_Dirt"
    },
    {
      "x": 10,
      "y": 0,
      "z": 15,
      "name": "Soil_Dirt"
    },
    {
      "x": 11,
      "y": 0,
      "z": 15,
      "name": "Soil_Dirt"
    },
    {
      "x": 12,
      "y": 0,
      "z": 15,
      "name": "Soil_Dirt"
    },
    {
      "x": 13,
      "y": 0,
      "z": 15,
      "name": "Soil_Dirt"
    },
    {
      "x": 14,
      "y": 0,
      "z": 15,
      "name": "Soil_Dirt"
    },
    {
      "x": 15,
      "y": 0,
      "z": 15,
      "name": "Soil_Dirt"
    },
    {
      "x": 16,
      "y": 0,
      "z": 15,
      "name": "Soil_Dirt"
    },
    {
      "x": 0,
      "y": 0,
      "z": 16,
      "name": "Soil_Dirt"
    },
    {
      "x": 1,
      "y": 0,
      "z": 16,
      "name": "Soil_Dirt"
    },
    {
      "x": 2,
      "y": 0,
      "z": 16,
      "name": "Soil_Dirt"
    },
    {
      "x": 3,
      "y": 0,
      "z": 16,
      "name": "Soil_Dirt"
    },
    {
      "x": 4,
      "y": 0,
      "z": 16,
      "name": "Soil_Dirt"
    },
    {
      "x": 5,
      "y": 0,
      "z": 16,
      "name": "Soil_Dirt"
    },
    {
      "x": 6,
      "y": 0,
      "z": 16,
      "name": "Soil_Dirt"
    },
    {
      "x": 7,
      "y": 0,
      "z": 16,
      "name": "Soil_Dirt"
    },
    {
      "x": 8,
      "y": 0,
      "z": 16,
      "name": "Soil_Dirt"
    },
    {
      "x": 9,
      "y": 0,
      "z": 16,
      "name": "Soil_Dirt"
    },
    {
      "x": 10,
      "y": 0,
      "z": 16,
      "name": "Soil_Dirt"
    },
    {
      "x": 11,
      "y": 0,
      "z": 16,
      "name": "Soil_Dirt"
    },
    {
      "x": 12,
      "y": 0,
      "z": 16,
      "name": "Soil_Dirt"
    },
    {
      "x": 13,
      "y": 0,
      "z": 16,
      "name": "Soil_Dirt"
    },
    {
      "x": 14,
      "y": 0,
      "z": 16,
      "name": "Soil_Dirt"
    },
    {
      "x": 15,
      "y": 0,
      "z": 16,
      "name": "Soil_Dirt"
    },
    {
      "x": 16,
      "y": 0,
      "z": 16,
      "name": "Soil_Dirt"
    },
    {
      "x": 0,
      "y": 0,
      "z": 17,
      "name": "Soil_Dirt"
    },
    {
      "x": 1,
      "y": 0,
      "z": 17,
      "name": "Soil_Dirt"
    },
    {
      "x": 2,
      "y": 0,
      "z": 17,
      "name": "Soil_Dirt"
    },
    {
      "x": 3,
      "y": 0,
      "z": 17,
      "name": "Soil_Dirt"
    },
    {
      "x": 4,
      "y": 0,
      "z": 17,
      "name": "Soil_Dirt"
    },
    {
      "x": 5,
      "y": 0,
      "z": 17,
      "name": "Soil_Dirt"
    },
    {
      "x": 6,
      "y": 0,
      "z": 17,
      "name": "Soil_Dirt"
    },
    {
      "x": 7,
      "y": 0,
      "z": 17,
      "name": "Soil_Dirt"
    },
    {
      "x": 8,
      "y": 0,
      "z": 17,
      "name": "Soil_Dirt"
    },
    {
      "x": 9,
      "y": 0,
      "z": 17,
      "name": "Soil_Dirt"
    },
    {
      "x": 10,
      "y": 0,
      "z": 17,
      "name": "Soil_Dirt"
    },
    {
      "x": 11,
      "y": 0,
      "z": 17,
      "name": "Soil_Dirt"
    },
    {
      "x": 12,
      "y": 0,
      "z": 17,
      "name": "Soil_Dirt"
    },
    {
      "x": 13,
      "y": 0,
      "z": 17,
      "name": "Soil_Dirt"
    },
    {
      "x": 14,
      "y": 0,
      "z": 17,
      "name": "Soil_Dirt"
    },
    {
      "x": 15,
      "y": 0,
      "z": 17,
      "name": "Soil_Dirt"
    },
    {
      "x": 16,
      "y": 0,
      "z": 17,
      "name": "Soil_Dirt"
    },
    {
      "x": 0,
      "y": 0,
      "z": 18,
      "name": "Soil_Dirt"
    },
    {
      "x": 1,
      "y": 0,
      "z": 18,
      "name": "Soil_Dirt"
    },
    {
      "x": 2,
      "y": 0,
      "z": 18,
      "name": "Soil_Dirt"
    },
    {
      "x": 3,
      "y": 0,
      "z": 18,
      "name": "Soil_Dirt"
    },
    {
      "x": 4,
      "y": 0,
      "z": 18,
      "name": "Soil_Dirt"
    },
    {
      "x": 5,
      "y": 0,
      "z": 18,
      "name": "Soil_Dirt"
    },
    {
      "x": 6,
      "y": 0,
      "z": 18,
      "name": "Soil_Dirt"
    },
    {
      "x": 7,
      "y": 0,
      "z": 18,
      "name": "Soil_Dirt"
    },
    {
      "x": 8,
      "y": 0,
      "z": 18,
      "name": "Soil_Dirt"
    },
    {
      "x": 9,
      "y": 0,
      "z": 18,
      "name": "Soil_Dirt"
    },
    {
      "x": 10,
      "y": 0,
      "z": 18,
      "name": "Soil_Dirt"
    },
    {
      "x": 11,
      "y": 0,
      "z": 18,
      "name": "Soil_Dirt"
    },
    {
      "x": 12,
      "y": 0,
      "z": 18,
      "name": "Soil_Dirt"
    },
    {
      "x": 13,
      "y": 0,
      "z": 18,
      "name": "Soil_Dirt"
    },
    {
      "x": 14,
      "y": 0,
      "z": 18,
      "name": "Soil_Dirt"
    },
    {
      "x": 15,
      "y": 0,
      "z": 18,
      "name": "Soil_Dirt"
    },
    {
      "x": 16,
      "y": 0,
      "z": 18,
      "name": "Soil_Dirt"
    },
    {
      "x": 0,
      "y": 0,
      "z": 19,
      "name": "Soil_Dirt"
    },
    {
      "x": 1,
      "y": 0,
      "z": 19,
      "name": "Soil_Dirt"
    },
    {
      "x": 2,
      "y": 0,
      "z": 19,
      "name": "Soil_Dirt"
    },
    {
      "x": 3,
      "y": 0,
      "z": 19,
      "name": "Soil_Dirt"
    },
    {
      "x": 4,
      "y": 0,
      "z": 19,
      "name": "Soil_Dirt"
    },
    {
      "x": 5,
      "y": 0,
      "z": 19,
      "name": "Soil_Dirt"
    },
    {
      "x": 6,
      "y": 0,
      "z": 19,
      "name": "Soil_Dirt"
    },
    {
      "x": 7,
      "y": 0,
      "z": 19,
      "name": "Soil_Dirt"
    },
    {
      "x": 8,
      "y": 0,
      "z": 19,
      "name": "Soil_Dirt"
    },
    {
      "x": 9,
      "y": 0,
      "z": 19,
      "name": "Soil_Dirt"
    },
    {
      "x": 10,
      "y": 0,
      "z": 19,
      "name": "Soil_Dirt"
    },
    {
      "x": 11,
      "y": 0,
      "z": 19,
      "name": "Soil_Dirt"
    },
    {
      "x": 12,
      "y": 0,
      "z": 19,
      "name": "Soil_Dirt"
    },
    {
      "x": 13,
      "y": 0,
      "z": 19,
      "name": "Soil_Dirt"
    },
    {
      "x": 14,
      "y": 0,
      "z": 19,
      "name": "Soil_Dirt"
    },
    {
      "x": 15,
      "y": 0,
      "z": 19,
      "name": "Soil_Dirt"
    },
    {
      "x": 16,
      "y": 0,
      "z": 19,
      "name": "Soil_Dirt"
    },
    {
      "x": 0,
      "y": 0,
      "z": 20,
      "name": "Soil_Dirt"
    },
    {
      "x": 1,
      "y": 0,
      "z": 20,
      "name": "Soil_Dirt"
    },
    {
      "x": 2,
      "y": 0,
      "z": 20,
      "name": "Soil_Dirt"
    },
    {
      "x": 3,
      "y": 0,
      "z": 20,
      "name": "Soil_Dirt"
    },
    {
      "x": 4,
      "y": 0,
      "z": 20,
      "name": "Soil_Dirt"
    },
    {
      "x": 5,
      "y": 0,
      "z": 20,
      "name": "Soil_Dirt"
    },
    {
      "x": 6,
      "y": 0,
      "z": 20,
      "name": "Soil_Dirt"
    },
    {
      "x": 7,
      "y": 0,
      "z": 20,
      "name": "Soil_Dirt"
    },
    {
      "x": 8,
      "y": 0,
      "z": 20,
      "name": "Soil_Dirt"
    },
    {
      "x": 9,
      "y": 0,
      "z": 20,
      "name": "Soil_Dirt"
    },
    {
      "x": 10,
      "y": 0,
      "z": 20,
      "name": "Soil_Dirt"
    },
    {
      "x": 11,
      "y": 0,
      "z": 20,
      "name": "Soil_Dirt"
    },
    {
      "x": 12,
      "y": 0,
      "z": 20,
      "name": "Soil_Dirt"
    },
    {
      "x": 13,
      "y": 0,
      "z": 20,
      "name": "Soil_Dirt"
    },
    {
      "x": 14,
      "y": 0,
      "z": 20,
      "name": "Soil_Dirt"
    },
    {
      "x": 15,
      "y": 0,
      "z": 20,
      "name": "Soil_Dirt"
    },
    {
      "x": 16,
      "y": 0,
      "z": 20,
      "name": "Soil_Dirt"
    },
    {
      "x": 0,
      "y": 0,
      "z": 21,
      "name": "Soil_Dirt"
    },
    {
      "x": 1,
      "y": 0,
      "z": 21,
      "name": "Soil_Dirt"
    },
    {
      "x": 2,
      "y": 0,
      "z": 21,
      "name": "Soil_Dirt"
    },
    {
      "x": 3,
      "y": 0,
      "z": 21,
      "name": "Soil_Dirt"
    },
    {
      "x": 4,
      "y": 0,
      "z": 21,
      "name": "Soil_Dirt"
    },
    {
      "x": 5,
      "y": 0,
      "z": 21,
      "name": "Soil_Dirt"
    },
    {
      "x": 6,
      "y": 0,
      "z": 21,
      "name": "Soil_Dirt"
    },
    {
      "x": 7,
      "y": 0,
      "z": 21,
      "name": "Soil_Dirt"
    },
    {
      "x": 8,
      "y": 0,
      "z": 21,
      "name": "Soil_Dirt"
    },
    {
      "x": 9,
      "y": 0,
      "z": 21,
      "name": "Soil_Dirt"
    },
    {
      "x": 10,
      "y": 0,
      "z": 21,
      "name": "Soil_Dirt"
    },
    {
      "x": 11,
      "y": 0,
      "z": 21,
      "name": "Soil_Dirt"
    },
    {
      "x": 12,
      "y": 0,
      "z": 21,
      "name": "Soil_Dirt"
    },
    {
      "x": 13,
      "y": 0,
      "z": 21,
      "name": "Soil_Dirt"
    },
    {
      "x": 14,
      "y": 0,
      "z": 21,
      "name": "Soil_Dirt"
    },
    {
      "x": 15,
      "y": 0,
      "z": 21,
      "name": "Soil_Dirt"
    },
    {
      "x": 16,
      "y": 0,
      "z": 21,
      "name": "Soil_Dirt"
    },
    {
      "x": 0,
      "y": 0,
      "z": 22,
      "name": "Soil_Dirt"
    },
    {
      "x": 1,
      "y": 0,
      "z": 22,
      "name": "Soil_Dirt"
    },
    {
      "x": 2,
      "y": 0,
      "z": 22,
      "name": "Soil_Dirt"
    },
    {
      "x": 3,
      "y": 0,
      "z": 22,
      "name": "Soil_Dirt"
    },
    {
      "x": 4,
      "y": 0,
      "z": 22,
      "name": "Soil_Dirt"
    },
    {
      "x": 5,
      "y": 0,
      "z": 22,
      "name": "Soil_Dirt"
    },
    {
      "x": 6,
      "y": 0,
      "z": 22,
      "name": "Soil_Dirt"
    },
    {
      "x": 7,
      "y": 0,
      "z": 22,
      "name": "Soil_Dirt"
    },
    {
      "x": 8,
      "y": 0,
      "z": 22,
      "name": "Soil_Dirt"
    },
    {
      "x": 9,
      "y": 0,
      "z": 22,
      "name": "Soil_Dirt"
    },
    {
      "x": 10,
      "y": 0,
      "z": 22,
      "name": "Soil_Dirt"
    },
    {
      "x": 11,
      "y": 0,
      "z": 22,
      "name": "Soil_Dirt"
    },
    {
      "x": 12,
      "y": 0,
      "z": 22,
      "name": "Soil_Dirt"
    },
    {
      "x": 13,
      "y": 0,
      "z": 22,
      "name": "Soil_Dirt"
    },
    {
      "x": 14,
      "y": 0,
      "z": 22,
      "name": "Soil_Dirt"
    },
    {
      "x": 15,
      "y": 0,
      "z": 22,
      "name": "Soil_Dirt"
    },
    {
      "x": 16,
      "y": 0,
      "z": 22,
      "name": "Soil_Dirt"
    },
    {
      "x": 0,
      "y": 1,
      "z": 0,
      "name": "Soil_Grass"
    },
    {
      "x": 1,
      "y": 1,
      "z": 0,
      "name": "Soil_Grass"
    },
    {
      "x": 2,
      "y": 1,
      "z": 0,
      "name": "Soil_Grass"
    },
    {
      "x": 3,
      "y": 1,
      "z": 0,
      "name": "Soil_Grass"
    },
    {
      "x": 4,
      "y": 1,
      "z": 0,
      "name": "Soil_Dirt"
    },
    {
      "x": 5,
      "y": 1,
      "z": 0,
      "name": "Soil_Dirt"
    },
    {
      "x": 6,
      "y": 1,
      "z": 0,
      "name": "Soil_Dirt"
    },
    {
      "x": 7,
      "y": 1,
      "z": 0,
      "name": "Soil_Dirt"
    },
    {
      "x": 8,
      "y": 1,
      "z": 0,
      "name": "Soil_Dirt"
    },
    {
      "x": 9,
      "y": 1,
      "z": 0,
      "name": "Soil_Grass"
    },
    {
      "x": 10,
      "y": 1,
      "z": 0,
      "name": "Soil_Dirt"
    },
    {
      "x": 11,
      "y": 1,
      "z": 0,
      "name": "Soil_Grass"
    },
    {
      "x": 12,
      "y": 1,
      "z": 0,
      "name": "Soil_Grass"
    },
    {
      "x": 14,
      "y": 1,
      "z": 0,
      "name": "Soil_Grass"
    },
    {
      "x": 15,
      "y": 1,
      "z": 0,
      "name": "Soil_Grass"
    },
    {
      "x": 0,
      "y": 1,
      "z": 1,
      "name": "Soil_Grass"
    },
    {
      "x": 1,
      "y": 1,
      "z": 1,
      "name": "Soil_Grass"
    },
    {
      "x": 2,
      "y": 1,
      "z": 1,
      "name": "Soil_Grass"
    },
    {
      "x": 3,
      "y": 1,
      "z": 1,
      "name": "Soil_Grass"
    },
    {
      "x": 4,
      "y": 1,
      "z": 1,
      "name": "Rock_Stone_Brick"
    },
    {
      "x": 5,
      "y": 1,
      "z": 1,
      "name": "Soil_Grass"
    },
    {
      "x": 6,
      "y": 1,
      "z": 1,
      "name": "Soil_Dirt"
    },
    {
      "x": 7,
      "y": 1,
      "z": 1,
      "name": "Soil_Dirt"
    },
    {
      "x": 8,
      "y": 1,
      "z": 1,
      "name": "Soil_Dirt"
    },
    {
      "x": 9,
      "y": 1,
      "z": 1,
      "name": "Soil_Grass"
    },
    {
      "x": 10,
      "y": 1,
      "z": 1,
      "name": "Rock_Stone_Brick"
    },
    {
      "x": 11,
      "y": 1,
      "z": 1,
      "name": "Rock_Stone_Brick"
    },
    {
      "x": 12,
      "y": 1,
      "z": 1,
      "name": "Soil_Grass"
    },
    {
      "x": 13,
      "y": 1,
      "z": 1,
      "name": "Soil_Dirt"
    },
    {
      "x": 15,
      "y": 1,
      "z": 1,
      "name": "Soil_Grass"
    },
    {
      "x": 16,
      "y": 1,
      "z": 1,
      "name": "Soil_Grass"
    },
    {
      "x": 0,
      "y": 1,
      "z": 2,
      "name": "Soil_Dirt"
    },
    {
      "x": 1,
      "y": 1,
      "z": 2,
      "name": "Soil_Grass"
    },
    {
      "x": 2,
      "y": 1,
      "z": 2,
      "name": "Soil_Dirt"
    },
    {
      "x": 3,
      "y": 1,
      "z": 2,
      "name": "Rock_Stone_Brick"
    },
    {
      "x": 4,
      "y": 1,
      "z": 2,
      "name": "Soil_Grass"
    },
    {
      "x": 5,
      "y": 1,
      "z": 2,
      "name": "Soil_Grass"
    },
    {
      "x": 6,
      "y": 1,
      "z": 2,
      "name": "Soil_Grass"
    },
    {
      "x": 7,
      "y": 1,
      "z": 2,
      "name": "Soil_Dirt"
    },
    {
      "x": 8,
      "y": 1,
      "z": 2,
      "name": "Soil_Dirt"
    },
    {
      "x": 9,
      "y": 1,
      "z": 2,
      "name": "Soil_Dirt"
    },
    {
      "x": 10,
      "y": 1,
      "z": 2,
      "name": "Soil_Dirt"
    },
    {
      "x": 11,
      "y": 1,
      "z": 2,
      "name": "Rock_Stone_Brick"
    },
    {
      "x": 12,
      "y": 1,
      "z": 2,
      "name": "Soil_Grass"
    },
    {
      "x": 13,
      "y": 1,
      "z": 2,
      "name": "Soil_Grass"
    },
    {
      "x": 14,
      "y": 1,
      "z": 2,
      "name": "Soil_Grass"
    },
    {
      "x": 15,
      "y": 1,
      "z": 2,
      "name": "Soil_Grass"
    },
    {
      "x": 16,
      "y": 1,
      "z": 2,
      "name": "Soil_Grass"
    },
    {
      "x": 0,
      "y": 1,
      "z": 3,
      "name": "Soil_Grass"
    },
    {
      "x": 1,
      "y": 1,
      "z": 3,
      "name": "Soil_Grass"
    },
    {
      "x": 2,
      "y": 1,
      "z": 3,
      "name": "Soil_Dirt"
    },
    {
      "x": 3,
      "y": 1,
      "z": 3,
      "name": "Soil_Dirt"
    },
    {
      "x": 4,
      "y": 1,
      "z": 3,
      "name": "Soil_Grass"
    },
    {
      "x": 5,
      "y": 1,
      "z": 3,
      "name": "Soil_Dirt"
    },
    {
      "x": 6,
      "y": 1,
      "z": 3,
      "name": "Soil_Podzol"
    },
    {
      "x": 7,
      "y": 1,
      "z": 3,
      "name": "Soil_Dirt"
    },
    {
      "x": 8,
      "y": 1,
      "z": 3,
      "name": "Soil_Dirt"
    },
    {
      "x": 9,
      "y": 1,
      "z": 3,
      "name": "Soil_Dirt"
    },
    {
      "x": 10,
      "y": 1,
      "z": 3,
      "name": "Soil_Dirt"
    },
    {
      "x": 11,
      "y": 1,
      "z": 3,
      "name": "Soil_Dirt"
    },
    {
      "x": 12,
      "y": 1,
      "z": 3,
      "name": "Soil_Grass"
    },
    {
      "x": 13,
      "y": 1,
      "z": 3,
      "name": "Soil_Dirt"
    },
    {
      "x": 14,
      "y": 1,
      "z": 3,
      "name": "Soil_Dirt"
    },
    {
      "x": 15,
      "y": 1,
      "z": 3,
      "name": "Soil_Podzol"
    },
    {
      "x": 16,
      "y": 1,
      "z": 3,
      "name": "Soil_Grass"
    },
    {
      "x": 0,
      "y": 1,
      "z": 4,
      "name": "Soil_Dirt"
    },
    {
      "x": 1,
      "y": 1,
      "z": 4,
      "name": "Soil_Podzol"
    },
    {
      "x": 2,
      "y": 1,
      "z": 4,
      "name": "Wood_Oak_Trunk"
    },
    {
      "x": 3,
      "y": 1,
      "z": 4,
      "name": "Soil_Dirt"
    },
    {
      "x": 4,
      "y": 1,
      "z": 4,
      "name": "Soil_Grass"
    },
    {
      "x": 5,
      "y": 1,
      "z": 4,
      "name": "Soil_Podzol"
    },
    {
      "x": 6,
      "y": 1,
      "z": 4,
      "name": "Wood_Oak_Trunk"
    },
    {
      "x": 8,
      "y": 1,
      "z": 4,
      "name": "Soil_Dirt"
    },
    {
      "x": 10,
      "y": 1,
      "z": 4,
      "name": "Wood_Oak_Trunk"
    },
    {
      "x": 11,
      "y": 1,
      "z": 4,
      "name": "Soil_Dirt"
    },
    {
      "x": 12,
      "y": 1,
      "z": 4,
      "name": "Soil_Dirt"
    },
    {
      "x": 13,
      "y": 1,
      "z": 4,
      "name": "Soil_Podzol"
    },
    {
      "x": 14,
      "y": 1,
      "z": 4,
      "name": "Wood_Oak_Trunk"
    },
    {
      "x": 15,
      "y": 1,
      "z": 4,
      "name": "Soil_Dirt"
    },
    {
      "x": 16,
      "y": 1,
      "z": 4,
      "name": "Soil_Grass"
    },
    {
      "x": 0,
      "y": 1,
      "z": 5,
      "name": "Soil_Grass"
    },
    {
      "x": 1,
      "y": 1,
      "z": 5,
      "name": "Wood_Oak_Trunk"
    },
    {
      "x": 2,
      "y": 1,
      "z": 5,
      "name": "Wood_Oak_Trunk"
    },
    {
      "x": 3,
      "y": 1,
      "z": 5,
      "name": "Rock_Stone_Brick"
    },
    {
      "x": 4,
      "y": 1,
      "z": 5,
      "name": "Rock_Stone_Brick_Smooth"
    },
    {
      "x": 5,
      "y": 1,
      "z": 5,
      "name": "Rock_Stone_Brick"
    },
    {
      "x": 6,
      "y": 1,
      "z": 5,
      "name": "Wood_Oak_Trunk"
    },
    {
      "x": 7,
      "y": 1,
      "z": 5,
      "name": "Rock_Stone_Brick"
    },
    {
      "x": 8,
      "y": 1,
      "z": 5,
      "name": "Rock_Stone_Brick_Smooth"
    },
    {
      "x": 9,
      "y": 1,
      "z": 5,
      "name": "Rock_Stone_Brick"
    },
    {
      "x": 10,
      "y": 1,
      "z": 5,
      "name": "Wood_Oak_Trunk"
    },
    {
      "x": 11,
      "y": 1,
      "z": 5,
      "name": "Rock_Stone_Brick"
    },
    {
      "x": 12,
      "y": 1,
      "z": 5,
      "name": "Rock_Stone_Brick_Smooth"
    },
    {
      "x": 13,
      "y": 1,
      "z": 5,
      "name": "Rock_Stone_Brick"
    },
    {
      "x": 14,
      "y": 1,
      "z": 5,
      "name": "Wood_Oak_Trunk"
    },
    {
      "x": 15,
      "y": 1,
      "z": 5,
      "name": "Wood_Oak_Trunk"
    },
    {
      "x": 16,
      "y": 1,
      "z": 5,
      "name": "Soil_Dirt"
    },
    {
      "x": 0,
      "y": 1,
      "z": 6,
      "name": "Soil_Dirt"
    },
    {
      "x": 1,
      "y": 1,
      "z": 6,
      "name": "Soil_Dirt"
    },
    {
      "x": 2,
      "y": 1,
      "z": 6,
      "name": "Rock_Stone_Brick"
    },
    {
      "x": 3,
      "y": 1,
      "z": 6,
      "name": "Wood_Oak_Planks"
    },
    {
      "x": 4,
      "y": 1,
      "z": 6,
      "name": "Wood_Oak_Planks"
    },
    {
      "x": 5,
      "y": 1,
      "z": 6,
      "name": "Wood_Oak_Planks"
    },
    {
      "x": 6,
      "y": 1,
      "z": 6,
      "name": "Wood_Oak_Planks"
    },
    {
      "x": 7,
      "y": 1,
      "z": 6,
      "name": "Wood_Oak_Planks"
    },
    {
      "x": 8,
      "y": 1,
      "z": 6,
      "name": "Wood_Oak_Planks"
    },
    {
      "x": 9,
      "y": 1,
      "z": 6,
      "name": "Wood_Oak_Planks"
    },
    {
      "x": 10,
      "y": 1,
      "z": 6,
      "name": "Wood_Oak_Planks"
    },
    {
      "x": 11,
      "y": 1,
      "z": 6,
      "name": "Wood_Oak_Planks"
    },
    {
      "x": 12,
      "y": 1,
      "z": 6,
      "name": "Wood_Oak_Planks"
    },
    {
      "x": 13,
      "y": 1,
      "z": 6,
      "name": "Wood_Oak_Planks"
    },
    {
      "x": 14,
      "y": 1,
      "z": 6,
      "name": "Rock_Stone_Brick"
    },
    {
      "x": 15,
      "y": 1,
      "z": 6,
      "name": "Soil_Dirt"
    },
    {
      "x": 16,
      "y": 1,
      "z": 6,
      "name": "Soil_Podzol"
    },
    {
      "x": 0,
      "y": 1,
      "z": 7,
      "name": "Soil_Grass"
    },
    {
      "x": 1,
      "y": 1,
      "z": 7,
      "name": "Soil_Grass"
    },
    {
      "x": 2,
      "y": 1,
      "z": 7,
      "name": "Rock_Stone_Brick_Smooth"
    },
    {
      "x": 3,
      "y": 1,
      "z": 7,
      "name": "Wood_Oak_Planks"
    },
    {
      "x": 4,
      "y": 1,
      "z": 7,
      "name": "Wood_Oak_Planks"
    },
    {
      "x": 5,
      "y": 1,
      "z": 7,
      "name": "Wood_Oak_Planks"
    },
    {
      "x": 6,
      "y": 1,
      "z": 7,
      "name": "Wood_Oak_Planks"
    },
    {
      "x": 7,
      "y": 1,
      "z": 7,
      "name": "Wood_Oak_Planks"
    },
    {
      "x": 8,
      "y": 1,
      "z": 7,
      "name": "Wood_Oak_Planks"
    },
    {
      "x": 9,
      "y": 1,
      "z": 7,
      "name": "Wood_Oak_Planks"
    },
    {
      "x": 10,
      "y": 1,
      "z": 7,
      "name": "Wood_Oak_Planks"
    },
    {
      "x": 11,
      "y": 1,
      "z": 7,
      "name": "Wood_Oak_Planks"
    },
    {
      "x": 12,
      "y": 1,
      "z": 7,
      "name": "Wood_Oak_Planks"
    },
    {
      "x": 13,
      "y": 1,
      "z": 7,
      "name": "Wood_Oak_Planks"
    },
    {
      "x": 14,
      "y": 1,
      "z": 7,
      "name": "Rock_Stone_Brick_Smooth"
    },
    {
      "x": 15,
      "y": 1,
      "z": 7,
      "name": "Soil_Dirt"
    },
    {
      "x": 16,
      "y": 1,
      "z": 7,
      "name": "Soil_Dirt"
    },
    {
      "x": 0,
      "y": 1,
      "z": 8,
      "name": "Soil_Dirt"
    },
    {
      "x": 1,
      "y": 1,
      "z": 8,
      "name": "Soil_Grass"
    },
    {
      "x": 2,
      "y": 1,
      "z": 8,
      "name": "Rock_Stone_Brick"
    },
    {
      "x": 3,
      "y": 1,
      "z": 8,
      "name": "Wood_Oak_Planks"
    },
    {
      "x": 4,
      "y": 1,
      "z": 8,
      "name": "Wood_Oak_Planks"
    },
    {
      "x": 5,
      "y": 1,
      "z": 8,
      "name": "Wood_Oak_Planks"
    },
    {
      "x": 6,
      "y": 1,
      "z": 8,
      "name": "Wood_Oak_Planks"
    },
    {
      "x": 7,
      "y": 1,
      "z": 8,
      "name": "Wood_Oak_Planks"
    },
    {
      "x": 8,
      "y": 1,
      "z": 8,
      "name": "Wood_Oak_Planks"
    },
    {
      "x": 9,
      "y": 1,
      "z": 8,
      "name": "Wood_Oak_Planks"
    },
    {
      "x": 10,
      "y": 1,
      "z": 8,
      "name": "Wood_Oak_Planks"
    },
    {
      "x": 11,
      "y": 1,
      "z": 8,
      "name": "Wood_Oak_Planks"
    },
    {
      "x": 12,
      "y": 1,
      "z": 8,
      "name": "Wood_Oak_Planks"
    },
    {
      "x": 13,
      "y": 1,
      "z": 8,
      "name": "Wood_Oak_Planks"
    },
    {
      "x": 14,
      "y": 1,
      "z": 8,
      "name": "Rock_Stone_Brick"
    },
    {
      "x": 15,
      "y": 1,
      "z": 8,
      "name": "Soil_Podzol"
    },
    {
      "x": 16,
      "y": 1,
      "z": 8,
      "name": "Soil_Dirt"
    },
    {
      "x": 0,
      "y": 1,
      "z": 9,
      "name": "Soil_Grass"
    },
    {
      "x": 1,
      "y": 1,
      "z": 9,
      "name": "Wood_Oak_Trunk"
    },
    {
      "x": 2,
      "y": 1,
      "z": 9,
      "name": "Wood_Oak_Trunk"
    },
    {
      "x": 3,
      "y": 1,
      "z": 9,
      "name": "Wood_Oak_Planks"
    },
    {
      "x": 4,
      "y": 1,
      "z": 9,
      "name": "Wood_Oak_Planks"
    },
    {
      "x": 5,
      "y": 1,
      "z": 9,
      "name": "Wood_Oak_Planks"
    },
    {
      "x": 6,
      "y": 1,
      "z": 9,
      "name": "Wood_Oak_Planks"
    },
    {
      "x": 7,
      "y": 1,
      "z": 9,
      "name": "Wood_Oak_Planks"
    },
    {
      "x": 8,
      "y": 1,
      "z": 9,
      "name": "Wood_Oak_Planks"
    },
    {
      "x": 9,
      "y": 1,
      "z": 9,
      "name": "Wood_Oak_Planks"
    },
    {
      "x": 10,
      "y": 1,
      "z": 9,
      "name": "Wood_Oak_Planks"
    },
    {
      "x": 11,
      "y": 1,
      "z": 9,
      "name": "Wood_Oak_Planks"
    },
    {
      "x": 12,
      "y": 1,
      "z": 9,
      "name": "Wood_Oak_Planks"
    },
    {
      "x": 13,
      "y": 1,
      "z": 9,
      "name": "Wood_Oak_Planks"
    },
    {
      "x": 14,
      "y": 1,
      "z": 9,
      "name": "Wood_Oak_Trunk"
    },
    {
      "x": 15,
      "y": 1,
      "z": 9,
      "name": "Wood_Oak_Trunk"
    },
    {
      "x": 16,
      "y": 1,
      "z": 9,
      "name": "Soil_Podzol"
    },
    {
      "x": 0,
      "y": 1,
      "z": 10,
      "name": "Soil_Grass"
    },
    {
      "x": 1,
      "y": 1,
      "z": 10,
      "name": "Soil_Dirt"
    },
    {
      "x": 2,
      "y": 1,
      "z": 10,
      "name": "Rock_Stone_Brick"
    },
    {
      "x": 3,
      "y": 1,
      "z": 10,
      "name": "Wood_Oak_Planks"
    },
    {
      "x": 4,
      "y": 1,
      "z": 10,
      "name": "Wood_Oak_Planks"
    },
    {
      "x": 5,
      "y": 1,
      "z": 10,
      "name": "Wood_Oak_Planks"
    },
    {
      "x": 6,
      "y": 1,
      "z": 10,
      "name": "Wood_Oak_Planks"
    },
    {
      "x": 7,
      "y": 1,
      "z": 10,
      "name": "Wood_Oak_Planks"
    },
    {
      "x": 8,
      "y": 1,
      "z": 10,
      "name": "Wood_Oak_Planks"
    },
    {
      "x": 9,
      "y": 1,
      "z": 10,
      "name": "Wood_Oak_Planks"
    },
    {
      "x": 10,
      "y": 1,
      "z": 10,
      "name": "Wood_Oak_Planks"
    },
    {
      "x": 11,
      "y": 1,
      "z": 10,
      "name": "Wood_Oak_Planks"
    },
    {
      "x": 12,
      "y": 1,
      "z": 10,
      "name": "Wood_Oak_Planks"
    },
    {
      "x": 13,
      "y": 1,
      "z": 10,
      "name": "Wood_Oak_Planks"
    },
    {
      "x": 14,
      "y": 1,
      "z": 10,
      "name": "Rock_Stone_Brick"
    },
    {
      "x": 15,
      "y": 1,
      "z": 10,
      "name": "Soil_Dirt"
    },
    {
      "x": 16,
      "y": 1,
      "z": 10,
      "name": "Soil_Dirt"
    },
    {
      "x": 0,
      "y": 1,
      "z": 11,
      "name": "Soil_Dirt"
    },
    {
      "x": 1,
      "y": 1,
      "z": 11,
      "name": "Soil_Podzol"
    },
    {
      "x": 2,
      "y": 1,
      "z": 11,
      "name": "Rock_Stone_Brick_Smooth"
    },
    {
      "x": 3,
      "y": 1,
      "z": 11,
      "name": "Wood_Oak_Planks"
    },
    {
      "x": 4,
      "y": 1,
      "z": 11,
      "name": "Wood_Oak_Planks"
    },
    {
      "x": 5,
      "y": 1,
      "z": 11,
      "name": "Wood_Oak_Planks"
    },
    {
      "x": 6,
      "y": 1,
      "z": 11,
      "name": "Wood_Oak_Planks"
    },
    {
      "x": 7,
      "y": 1,
      "z": 11,
      "name": "Wood_Oak_Planks"
    },
    {
      "x": 8,
      "y": 1,
      "z": 11,
      "name": "Wood_Oak_Planks"
    },
    {
      "x": 9,
      "y": 1,
      "z": 11,
      "name": "Wood_Oak_Planks"
    },
    {
      "x": 10,
      "y": 1,
      "z": 11,
      "name": "Wood_Oak_Planks"
    },
    {
      "x": 11,
      "y": 1,
      "z": 11,
      "name": "Wood_Oak_Planks"
    },
    {
      "x": 12,
      "y": 1,
      "z": 11,
      "name": "Wood_Oak_Planks"
    },
    {
      "x": 13,
      "y": 1,
      "z": 11,
      "name": "Wood_Oak_Planks"
    },
    {
      "x": 14,
      "y": 1,
      "z": 11,
      "name": "Rock_Stone_Brick_Smooth"
    },
    {
      "x": 15,
      "y": 1,
      "z": 11,
      "name": "Soil_Dirt"
    },
    {
      "x": 16,
      "y": 1,
      "z": 11,
      "name": "Soil_Dirt"
    },
    {
      "x": 0,
      "y": 1,
      "z": 12,
      "name": "Soil_Podzol"
    },
    {
      "x": 1,
      "y": 1,
      "z": 12,
      "name": "Soil_Dirt"
    },
    {
      "x": 2,
      "y": 1,
      "z": 12,
      "name": "Rock_Stone_Brick"
    },
    {
      "x": 3,
      "y": 1,
      "z": 12,
      "name": "Wood_Oak_Planks"
    },
    {
      "x": 4,
      "y": 1,
      "z": 12,
      "name": "Wood_Oak_Planks"
    },
    {
      "x": 5,
      "y": 1,
      "z": 12,
      "name": "Wood_Oak_Planks"
    },
    {
      "x": 6,
      "y": 1,
      "z": 12,
      "name": "Wood_Oak_Planks"
    },
    {
      "x": 7,
      "y": 1,
      "z": 12,
      "name": "Wood_Oak_Planks"
    },
    {
      "x": 8,
      "y": 1,
      "z": 12,
      "name": "Wood_Oak_Planks"
    },
    {
      "x": 9,
      "y": 1,
      "z": 12,
      "name": "Wood_Oak_Planks"
    },
    {
      "x": 10,
      "y": 1,
      "z": 12,
      "name": "Wood_Oak_Planks"
    },
    {
      "x": 11,
      "y": 1,
      "z": 12,
      "name": "Wood_Oak_Planks"
    },
    {
      "x": 12,
      "y": 1,
      "z": 12,
      "name": "Wood_Oak_Planks"
    },
    {
      "x": 13,
      "y": 1,
      "z": 12,
      "name": "Wood_Oak_Planks"
    },
    {
      "x": 14,
      "y": 1,
      "z": 12,
      "name": "Rock_Stone_Brick"
    },
    {
      "x": 15,
      "y": 1,
      "z": 12,
      "name": "Soil_Grass"
    },
    {
      "x": 16,
      "y": 1,
      "z": 12,
      "name": "Soil_Grass"
    },
    {
      "x": 0,
      "y": 1,
      "z": 13,
      "name": "Soil_Grass"
    },
    {
      "x": 1,
      "y": 1,
      "z": 13,
      "name": "Wood_Oak_Trunk"
    },
    {
      "x": 2,
      "y": 1,
      "z": 13,
      "name": "Wood_Oak_Trunk"
    },
    {
      "x": 3,
      "y": 1,
      "z": 13,
      "name": "Wood_Oak_Planks"
    },
    {
      "x": 4,
      "y": 1,
      "z": 13,
      "name": "Wood_Oak_Planks"
    },
    {
      "x": 5,
      "y": 1,
      "z": 13,
      "name": "Wood_Oak_Planks"
    },
    {
      "x": 6,
      "y": 1,
      "z": 13,
      "name": "Wood_Oak_Planks"
    },
    {
      "x": 7,
      "y": 1,
      "z": 13,
      "name": "Wood_Oak_Planks"
    },
    {
      "x": 8,
      "y": 1,
      "z": 13,
      "name": "Wood_Oak_Planks"
    },
    {
      "x": 9,
      "y": 1,
      "z": 13,
      "name": "Wood_Oak_Planks"
    },
    {
      "x": 10,
      "y": 1,
      "z": 13,
      "name": "Wood_Oak_Planks"
    },
    {
      "x": 11,
      "y": 1,
      "z": 13,
      "name": "Wood_Oak_Planks"
    },
    {
      "x": 12,
      "y": 1,
      "z": 13,
      "name": "Wood_Oak_Planks"
    },
    {
      "x": 13,
      "y": 1,
      "z": 13,
      "name": "Wood_Oak_Planks"
    },
    {
      "x": 14,
      "y": 1,
      "z": 13,
      "name": "Wood_Oak_Trunk"
    },
    {
      "x": 15,
      "y": 1,
      "z": 13,
      "name": "Wood_Oak_Trunk"
    },
    {
      "x": 16,
      "y": 1,
      "z": 13,
      "name": "Soil_Podzol"
    },
    {
      "x": 0,
      "y": 1,
      "z": 14,
      "name": "Soil_Grass"
    },
    {
      "x": 1,
      "y": 1,
      "z": 14,
      "name": "Soil_Grass"
    },
    {
      "x": 2,
      "y": 1,
      "z": 14,
      "name": "Rock_Stone_Brick"
    },
    {
      "x": 3,
      "y": 1,
      "z": 14,
      "name": "Wood_Oak_Planks"
    },
    {
      "x": 4,
      "y": 1,
      "z": 14,
      "name": "Wood_Oak_Planks"
    },
    {
      "x": 5,
      "y": 1,
      "z": 14,
      "name": "Wood_Oak_Planks"
    },
    {
      "x": 6,
      "y": 1,
      "z": 14,
      "name": "Wood_Oak_Planks"
    },
    {
      "x": 7,
      "y": 1,
      "z": 14,
      "name": "Wood_Oak_Planks"
    },
    {
      "x": 8,
      "y": 1,
      "z": 14,
      "name": "Wood_Oak_Planks"
    },
    {
      "x": 9,
      "y": 1,
      "z": 14,
      "name": "Wood_Oak_Planks"
    },
    {
      "x": 10,
      "y": 1,
      "z": 14,
      "name": "Wood_Oak_Planks"
    },
    {
      "x": 11,
      "y": 1,
      "z": 14,
      "name": "Wood_Oak_Planks"
    },
    {
      "x": 12,
      "y": 1,
      "z": 14,
      "name": "Wood_Oak_Planks"
    },
    {
      "x": 13,
      "y": 1,
      "z": 14,
      "name": "Wood_Oak_Planks"
    },
    {
      "x": 14,
      "y": 1,
      "z": 14,
      "name": "Rock_Stone_Brick"
    },
    {
      "x": 15,
      "y": 1,
      "z": 14,
      "name": "Soil_Dirt"
    },
    {
      "x": 16,
      "y": 1,
      "z": 14,
      "name": "Soil_Dirt"
    },
    {
      "x": 0,
      "y": 1,
      "z": 15,
      "name": "Soil_Dirt"
    },
    {
      "x": 1,
      "y": 1,
      "z": 15,
      "name": "Soil_Grass"
    },
    {
      "x": 2,
      "y": 1,
      "z": 15,
      "name": "Rock_Stone_Brick_Smooth"
    },
    {
      "x": 3,
      "y": 1,
      "z": 15,
      "name": "Wood_Oak_Planks"
    },
    {
      "x": 4,
      "y": 1,
      "z": 15,
      "name": "Wood_Oak_Planks"
    },
    {
      "x": 5,
      "y": 1,
      "z": 15,
      "name": "Wood_Oak_Planks"
    },
    {
      "x": 6,
      "y": 1,
      "z": 15,
      "name": "Wood_Oak_Planks"
    },
    {
      "x": 7,
      "y": 1,
      "z": 15,
      "name": "Wood_Oak_Planks"
    },
    {
      "x": 8,
      "y": 1,
      "z": 15,
      "name": "Wood_Oak_Planks"
    },
    {
      "x": 9,
      "y": 1,
      "z": 15,
      "name": "Wood_Oak_Planks"
    },
    {
      "x": 10,
      "y": 1,
      "z": 15,
      "name": "Wood_Oak_Planks"
    },
    {
      "x": 11,
      "y": 1,
      "z": 15,
      "name": "Wood_Oak_Planks"
    },
    {
      "x": 12,
      "y": 1,
      "z": 15,
      "name": "Wood_Oak_Planks"
    },
    {
      "x": 13,
      "y": 1,
      "z": 15,
      "name": "Wood_Oak_Planks"
    },
    {
      "x": 14,
      "y": 1,
      "z": 15,
      "name": "Rock_Stone_Brick_Smooth"
    },
    {
      "x": 15,
      "y": 1,
      "z": 15,
      "name": "Soil_Dirt"
    },
    {
      "x": 16,
      "y": 1,
      "z": 15,
      "name": "Soil_Podzol"
    },
    {
      "x": 0,
      "y": 1,
      "z": 16,
      "name": "Soil_Dirt"
    },
    {
      "x": 1,
      "y": 1,
      "z": 16,
      "name": "Soil_Dirt"
    },
    {
      "x": 2,
      "y": 1,
      "z": 16,
      "name": "Rock_Stone_Brick"
    },
    {
      "x": 3,
      "y": 1,
      "z": 16,
      "name": "Wood_Oak_Planks"
    },
    {
      "x": 4,
      "y": 1,
      "z": 16,
      "name": "Wood_Oak_Planks"
    },
    {
      "x": 5,
      "y": 1,
      "z": 16,
      "name": "Wood_Oak_Planks"
    },
    {
      "x": 6,
      "y": 1,
      "z": 16,
      "name": "Wood_Oak_Planks"
    },
    {
      "x": 7,
      "y": 1,
      "z": 16,
      "name": "Wood_Oak_Planks"
    },
    {
      "x": 8,
      "y": 1,
      "z": 16,
      "name": "Wood_Oak_Planks"
    },
    {
      "x": 9,
      "y": 1,
      "z": 16,
      "name": "Wood_Oak_Planks"
    },
    {
      "x": 10,
      "y": 1,
      "z": 16,
      "name": "Wood_Oak_Planks"
    },
    {
      "x": 11,
      "y": 1,
      "z": 16,
      "name": "Wood_Oak_Planks"
    },
    {
      "x": 12,
      "y": 1,
      "z": 16,
      "name": "Wood_Oak_Planks"
    },
    {
      "x": 13,
      "y": 1,
      "z": 16,
      "name": "Wood_Oak_Planks"
    },
    {
      "x": 14,
      "y": 1,
      "z": 16,
      "name": "Rock_Stone_Brick"
    },
    {
      "x": 15,
      "y": 1,
      "z": 16,
      "name": "Soil_Podzol"
    },
    {
      "x": 16,
      "y": 1,
      "z": 16,
      "name": "Soil_Dirt"
    },
    {
      "x": 0,
      "y": 1,
      "z": 17,
      "name": "Soil_Grass"
    },
    {
      "x": 1,
      "y": 1,
      "z": 17,
      "name": "Wood_Oak_Trunk"
    },
    {
      "x": 2,
      "y": 1,
      "z": 17,
      "name": "Wood_Oak_Trunk"
    },
    {
      "x": 3,
      "y": 1,
      "z": 17,
      "name": "Rock_Stone_Brick"
    },
    {
      "x": 4,
      "y": 1,
      "z": 17,
      "name": "Rock_Stone_Brick_Smooth"
    },
    {
      "x": 5,
      "y": 1,
      "z": 17,
      "name": "Rock_Stone_Brick"
    },
    {
      "x": 6,
      "y": 1,
      "z": 17,
      "name": "Wood_Oak_Trunk"
    },
    {
      "x": 7,
      "y": 1,
      "z": 17,
      "name": "Rock_Stone_Brick"
    },
    {
      "x": 8,
      "y": 1,
      "z": 17,
      "name": "Rock_Stone_Brick_Smooth"
    },
    {
      "x": 9,
      "y": 1,
      "z": 17,
      "name": "Rock_Stone_Brick"
    },
    {
      "x": 10,
      "y": 1,
      "z": 17,
      "name": "Wood_Oak_Trunk"
    },
    {
      "x": 11,
      "y": 1,
      "z": 17,
      "name": "Rock_Stone_Brick"
    },
    {
      "x": 12,
      "y": 1,
      "z": 17,
      "name": "Rock_Stone_Brick_Smooth"
    },
    {
      "x": 13,
      "y": 1,
      "z": 17,
      "name": "Rock_Stone_Brick"
    },
    {
      "x": 14,
      "y": 1,
      "z": 17,
      "name": "Wood_Oak_Trunk"
    },
    {
      "x": 15,
      "y": 1,
      "z": 17,
      "name": "Wood_Oak_Trunk"
    },
    {
      "x": 16,
      "y": 1,
      "z": 17,
      "name": "Soil_Podzol"
    },
    {
      "x": 0,
      "y": 1,
      "z": 18,
      "name": "Soil_Podzol"
    },
    {
      "x": 1,
      "y": 1,
      "z": 18,
      "name": "Soil_Grass"
    },
    {
      "x": 2,
      "y": 1,
      "z": 18,
      "name": "Wood_Oak_Trunk"
    },
    {
      "x": 3,
      "y": 1,
      "z": 18,
      "name": "Soil_Podzol"
    },
    {
      "x": 4,
      "y": 1,
      "z": 18,
      "name": "Soil_Grass"
    },
    {
      "x": 5,
      "y": 1,
      "z": 18,
      "name": "Soil_Dirt"
    },
    {
      "x": 6,
      "y": 1,
      "z": 18,
      "name": "Soil_Dirt"
    },
    {
      "x": 7,
      "y": 1,
      "z": 18,
      "name": "Soil_Grass"
    },
    {
      "x": 8,
      "y": 1,
      "z": 18,
      "name": "Soil_Grass"
    },
    {
      "x": 9,
      "y": 1,
      "z": 18,
      "name": "Soil_Dirt"
    },
    {
      "x": 10,
      "y": 1,
      "z": 18,
      "name": "Wood_Oak_Trunk"
    },
    {
      "x": 11,
      "y": 1,
      "z": 18,
      "name": "Soil_Podzol"
    },
    {
      "x": 12,
      "y": 1,
      "z": 18,
      "name": "Soil_Dirt"
    },
    {
      "x": 13,
      "y": 1,
      "z": 18,
      "name": "Soil_Dirt"
    },
    {
      "x": 14,
      "y": 1,
      "z": 18,
      "name": "Wood_Oak_Trunk"
    },
    {
      "x": 15,
      "y": 1,
      "z": 18,
      "name": "Soil_Grass"
    },
    {
      "x": 16,
      "y": 1,
      "z": 18,
      "name": "Soil_Dirt"
    },
    {
      "x": 0,
      "y": 1,
      "z": 19,
      "name": "Soil_Dirt"
    },
    {
      "x": 1,
      "y": 1,
      "z": 19,
      "name": "Soil_Dirt"
    },
    {
      "x": 2,
      "y": 1,
      "z": 19,
      "name": "Soil_Podzol"
    },
    {
      "x": 3,
      "y": 1,
      "z": 19,
      "name": "Soil_Grass"
    },
    {
      "x": 4,
      "y": 1,
      "z": 19,
      "name": "Soil_Dirt"
    },
    {
      "x": 5,
      "y": 1,
      "z": 19,
      "name": "Soil_Podzol"
    },
    {
      "x": 6,
      "y": 1,
      "z": 19,
      "name": "Soil_Dirt"
    },
    {
      "x": 7,
      "y": 1,
      "z": 19,
      "name": "Soil_Dirt"
    },
    {
      "x": 8,
      "y": 1,
      "z": 19,
      "name": "Soil_Grass"
    },
    {
      "x": 9,
      "y": 1,
      "z": 19,
      "name": "Soil_Dirt"
    },
    {
      "x": 10,
      "y": 1,
      "z": 19,
      "name": "Soil_Podzol"
    },
    {
      "x": 11,
      "y": 1,
      "z": 19,
      "name": "Soil_Dirt"
    },
    {
      "x": 12,
      "y": 1,
      "z": 19,
      "name": "Soil_Grass"
    },
    {
      "x": 13,
      "y": 1,
      "z": 19,
      "name": "Soil_Dirt"
    },
    {
      "x": 14,
      "y": 1,
      "z": 19,
      "name": "Soil_Dirt"
    },
    {
      "x": 15,
      "y": 1,
      "z": 19,
      "name": "Soil_Dirt"
    },
    {
      "x": 16,
      "y": 1,
      "z": 19,
      "name": "Soil_Grass"
    },
    {
      "x": 0,
      "y": 1,
      "z": 20,
      "name": "Soil_Grass"
    },
    {
      "x": 1,
      "y": 1,
      "z": 20,
      "name": "Soil_Grass"
    },
    {
      "x": 2,
      "y": 1,
      "z": 20,
      "name": "Soil_Dirt"
    },
    {
      "x": 3,
      "y": 1,
      "z": 20,
      "name": "Soil_Grass"
    },
    {
      "x": 4,
      "y": 1,
      "z": 20,
      "name": "Soil_Dirt"
    },
    {
      "x": 5,
      "y": 1,
      "z": 20,
      "name": "Soil_Grass"
    },
    {
      "x": 6,
      "y": 1,
      "z": 20,
      "name": "Soil_Grass"
    },
    {
      "x": 7,
      "y": 1,
      "z": 20,
      "name": "Soil_Grass"
    },
    {
      "x": 8,
      "y": 1,
      "z": 20,
      "name": "Soil_Grass"
    },
    {
      "x": 9,
      "y": 1,
      "z": 20,
      "name": "Soil_Podzol"
    },
    {
      "x": 10,
      "y": 1,
      "z": 20,
      "name": "Soil_Grass"
    },
    {
      "x": 11,
      "y": 1,
      "z": 20,
      "name": "Soil_Dirt"
    },
    {
      "x": 12,
      "y": 1,
      "z": 20,
      "name": "Soil_Podzol"
    },
    {
      "x": 13,
      "y": 1,
      "z": 20,
      "name": "Soil_Grass"
    },
    {
      "x": 14,
      "y": 1,
      "z": 20,
      "name": "Soil_Podzol"
    },
    {
      "x": 15,
      "y": 1,
      "z": 20,
      "name": "Soil_Grass"
    },
    {
      "x": 16,
      "y": 1,
      "z": 20,
      "name": "Soil_Podzol"
    },
    {
      "x": 0,
      "y": 1,
      "z": 21,
      "name": "Soil_Grass"
    },
    {
      "x": 1,
      "y": 1,
      "z": 21,
      "name": "Soil_Grass"
    },
    {
      "x": 2,
      "y": 1,
      "z": 21,
      "name": "Soil_Grass"
    },
    {
      "x": 3,
      "y": 1,
      "z": 21,
      "name": "Soil_Dirt"
    },
    {
      "x": 4,
      "y": 1,
      "z": 21,
      "name": "Soil_Grass"
    },
    {
      "x": 5,
      "y": 1,
      "z": 21,
      "name": "Soil_Grass"
    },
    {
      "x": 6,
      "y": 1,
      "z": 21,
      "name": "Soil_Grass"
    },
    {
      "x": 7,
      "y": 1,
      "z": 21,
      "name": "Soil_Podzol"
    },
    {
      "x": 8,
      "y": 1,
      "z": 21,
      "name": "Soil_Podzol"
    },
    {
      "x": 9,
      "y": 1,
      "z": 21,
      "name": "Soil_Grass"
    },
    {
      "x": 10,
      "y": 1,
      "z": 21,
      "name": "Soil_Grass"
    },
    {
      "x": 11,
      "y": 1,
      "z": 21,
      "name": "Soil_Grass"
    },
    {
      "x": 12,
      "y": 1,
      "z": 21,
      "name": "Soil_Grass"
    },
    {
      "x": 13,
      "y": 1,
      "z": 21,
      "name": "Soil_Grass"
    },
    {
      "x": 14,
      "y": 1,
      "z": 21,
      "name": "Soil_Grass"
    },
    {
      "x": 15,
      "y": 1,
      "z": 21,
      "name": "Soil_Grass"
    },
    {
      "x": 16,
      "y": 1,
      "z": 21,
      "name": "Soil_Grass"
    },
    {
      "x": 0,
      "y": 1,
      "z": 22,
      "name": "Soil_Grass"
    },
    {
      "x": 1,
      "y": 1,
      "z": 22,
      "name": "Soil_Grass"
    },
    {
      "x": 2,
      "y": 1,
      "z": 22,
      "name": "Soil_Grass"
    },
    {
      "x": 3,
      "y": 1,
      "z": 22,
      "name": "Soil_Grass"
    },
    {
      "x": 4,
      "y": 1,
      "z": 22,
      "name": "Soil_Grass"
    },
    {
      "x": 5,
      "y": 1,
      "z": 22,
      "name": "Soil_Grass"
    },
    {
      "x": 6,
      "y": 1,
      "z": 22,
      "name": "Soil_Grass"
    },
    {
      "x": 7,
      "y": 1,
      "z": 22,
      "name": "Soil_Grass"
    },
    {
      "x": 8,
      "y": 1,
      "z": 22,
      "name": "Soil_Grass"
    },
    {
      "x": 9,
      "y": 1,
      "z": 22,
      "name": "Soil_Grass"
    },
    {
      "x": 10,
      "y": 1,
      "z": 22,
      "name": "Soil_Grass"
    },
    {
      "x": 11,
      "y": 1,
      "z": 22,
      "name": "Soil_Grass"
    },
    {
      "x": 12,
      "y": 1,
      "z": 22,
      "name": "Soil_Grass"
    },
    {
      "x": 13,
      "y": 1,
      "z": 22,
      "name": "Soil_Grass"
    },
    {
      "x": 14,
      "y": 1,
      "z": 22,
      "name": "Soil_Grass"
    },
    {
      "x": 15,
      "y": 1,
      "z": 22,
      "name": "Soil_Grass"
    },
    {
      "x": 16,
      "y": 1,
      "z": 22,
      "name": "Soil_Grass"
    },
    {
      "x": 1,
      "y": 2,
      "z": 0,
      "name": "Plant_Grass_Sharp"
    },
    {
      "x": 2,
      "y": 2,
      "z": 0,
      "name": "Plant_Grass_Sharp"
    },
    {
      "x": 12,
      "y": 2,
      "z": 0,
      "name": "Plant_Grass_Sharp"
    },
    {
      "x": 0,
      "y": 2,
      "z": 1,
      "name": "Plant_Grass_Sharp"
    },
    {
      "x": 3,
      "y": 2,
      "z": 1,
      "name": "Plant_Grass_Sharp"
    },
    {
      "x": 9,
      "y": 2,
      "z": 1,
      "name": "Plant_Grass_Sharp"
    },
    {
      "x": 13,
      "y": 2,
      "z": 1,
      "name": "Rock_Stone_Brick"
    },
    {
      "x": 15,
      "y": 2,
      "z": 1,
      "name": "Plant_Grass_Sharp"
    },
    {
      "x": 16,
      "y": 2,
      "z": 1,
      "name": "Plant_Grass_Sharp"
    },
    {
      "x": 1,
      "y": 2,
      "z": 2,
      "name": "Plant_Grass_Sharp"
    },
    {
      "x": 16,
      "y": 2,
      "z": 2,
      "name": "Plant_Grass_Sharp"
    },
    {
      "x": 2,
      "y": 2,
      "z": 3,
      "name": "Plant_Leaves_Oak"
    },
    {
      "x": 13,
      "y": 2,
      "z": 3,
      "name": "Plant_Leaves_Oak"
    },
    {
      "x": 14,
      "y": 2,
      "z": 3,
      "name": "Plant_Grass_Sharp"
    },
    {
      "x": 2,
      "y": 2,
      "z": 4,
      "name": "Wood_Oak_Trunk"
    },
    {
      "x": 3,
      "y": 2,
      "z": 4,
      "name": "Plant_Leaves_Oak"
    },
    {
      "x": 4,
      "y": 2,
      "z": 4,
      "name": "Plant_Grass_Sharp"
    },
    {
      "x": 6,
      "y": 2,
      "z": 4,
      "name": "Wood_Oak_Trunk"
    },
    {
      "x": 10,
      "y": 2,
      "z": 4,
      "name": "Wood_Oak_Trunk"
    },
    {
      "x": 11,
      "y": 2,
      "z": 4,
      "name": "Plant_Grass_Sharp"
    },
    {
      "x": 12,
      "y": 2,
      "z": 4,
      "name": "Plant_Leaves_Oak"
    },
    {
      "x": 13,
      "y": 2,
      "z": 4,
      "name": "Plant_Leaves_Oak"
    },
    {
      "x": 14,
      "y": 2,
      "z": 4,
      "name": "Wood_Oak_Trunk"
    },
    {
      "x": 15,
      "y": 2,
      "z": 4,
      "name": "Plant_Leaves_Oak"
    },
    {
      "x": 1,
      "y": 2,
      "z": 5,
      "name": "Wood_Oak_Trunk"
    },
    {
      "x": 2,
      "y": 2,
      "z": 5,
      "name": "Wood_Oak_Trunk"
    },
    {
      "x": 3,
      "y": 2,
      "z": 5,
      "name": "Rock_Stone_Brick"
    },
    {
      "x": 4,
      "y": 2,
      "z": 5,
      "name": "Rock_Stone_Brick"
    },
    {
      "x": 5,
      "y": 2,
      "z": 5,
      "name": "Rock_Stone_Brick"
    },
    {
      "x": 6,
      "y": 2,
      "z": 5,
      "name": "Wood_Oak_Trunk"
    },
    {
      "x": 7,
      "y": 2,
      "z": 5,
      "name": "Wood_Oak_Planks"
    },
    {
      "x": 8,
      "y": 2,
      "z": 5,
      "name": "Wood_Oak_Planks"
    },
    {
      "x": 9,
      "y": 2,
      "z": 5,
      "name": "Wood_Oak_Planks"
    },
    {
      "x": 10,
      "y": 2,
      "z": 5,
      "name": "Wood_Oak_Trunk"
    },
    {
      "x": 11,
      "y": 2,
      "z": 5,
      "name": "Rock_Stone_Brick"
    },
    {
      "x": 12,
      "y": 2,
      "z": 5,
      "name": "Rock_Stone_Brick"
    },
    {
      "x": 13,
      "y": 2,
      "z": 5,
      "name": "Rock_Stone_Brick"
    },
    {
      "x": 14,
      "y": 2,
      "z": 5,
      "name": "Wood_Oak_Trunk"
    },
    {
      "x": 15,
      "y": 2,
      "z": 5,
      "name": "Wood_Oak_Trunk"
    },
    {
      "x": 2,
      "y": 2,
      "z": 6,
      "name": "Rock_Stone_Brick"
    },
    {
      "x": 3,
      "y": 2,
      "z": 6,
      "name": "Wood_Oak_Planks"
    },
    {
      "x": 4,
      "y": 2,
      "z": 6,
      "name": "Wood_Oak_Planks"
    },
    {
      "x": 5,
      "y": 2,
      "z": 6,
      "name": "Wood_Oak_Planks"
    },
    {
      "x": 6,
      "y": 2,
      "z": 6,
      "name": "Wood_Oak_Planks"
    },
    {
      "x": 7,
      "y": 2,
      "z": 6,
      "name": "Wood_Oak_Planks"
    },
    {
      "x": 8,
      "y": 2,
      "z": 6,
      "name": "Wood_Oak_Planks"
    },
    {
      "x": 9,
      "y": 2,
      "z": 6,
      "name": "Wood_Oak_Planks"
    },
    {
      "x": 10,
      "y": 2,
      "z": 6,
      "name": "Wood_Oak_Planks"
    },
    {
      "x": 11,
      "y": 2,
      "z": 6,
      "name": "Wood_Oak_Planks"
    },
    {
      "x": 12,
      "y": 2,
      "z": 6,
      "name": "Wood_Oak_Planks"
    },
    {
      "x": 13,
      "y": 2,
      "z": 6,
      "name": "Wood_Oak_Planks"
    },
    {
      "x": 14,
      "y": 2,
      "z": 6,
      "name": "Rock_Stone_Brick"
    },
    {
      "x": 1,
      "y": 2,
      "z": 7,
      "name": "Plant_Leaves_Oak"
    },
    {
      "x": 2,
      "y": 2,
      "z": 7,
      "name": "Rock_Stone_Brick"
    },
    {
      "x": 3,
      "y": 2,
      "z": 7,
      "name": "Wood_Oak_Planks"
    },
    {
      "x": 4,
      "y": 2,
      "z": 7,
      "name": "Wood_Oak_Planks"
    },
    {
      "x": 5,
      "y": 2,
      "z": 7,
      "name": "Wood_Oak_Planks"
    },
    {
      "x": 6,
      "y": 2,
      "z": 7,
      "name": "Wood_Oak_Planks"
    },
    {
      "x": 7,
      "y": 2,
      "z": 7,
      "name": "Wood_Oak_Planks"
    },
    {
      "x": 8,
      "y": 2,
      "z": 7,
      "name": "Wood_Oak_Planks"
    },
    {
      "x": 9,
      "y": 2,
      "z": 7,
      "name": "Wood_Oak_Planks"
    },
    {
      "x": 10,
      "y": 2,
      "z": 7,
      "name": "Wood_Oak_Planks"
    },
    {
      "x": 11,
      "y": 2,
      "z": 7,
      "name": "Wood_Oak_Planks"
    },
    {
      "x": 12,
      "y": 2,
      "z": 7,
      "name": "Wood_Oak_Planks"
    },
    {
      "x": 13,
      "y": 2,
      "z": 7,
      "name": "Wood_Oak_Planks"
    },
    {
      "x": 14,
      "y": 2,
      "z": 7,
      "name": "Rock_Stone_Brick"
    },
    {
      "x": 0,
      "y": 2,
      "z": 8,
      "name": "Plant_Grass_Sharp"
    },
    {
      "x": 1,
      "y": 2,
      "z": 8,
      "name": "Plant_Leaves_Oak"
    },
    {
      "x": 2,
      "y": 2,
      "z": 8,
      "name": "Rock_Stone_Brick"
    },
    {
      "x": 3,
      "y": 2,
      "z": 8,
      "name": "Wood_Oak_Planks"
    },
    {
      "x": 4,
      "y": 2,
      "z": 8,
      "name": "Wood_Oak_Planks"
    },
    {
      "x": 5,
      "y": 2,
      "z": 8,
      "name": "Wood_Oak_Planks"
    },
    {
      "x": 6,
      "y": 2,
      "z": 8,
      "name": "Wood_Oak_Planks"
    },
    {
      "x": 7,
      "y": 2,
      "z": 8,
      "name": "Wood_Oak_Planks"
    },
    {
      "x": 8,
      "y": 2,
      "z": 8,
      "name": "Wood_Oak_Planks"
    },
    {
      "x": 9,
      "y": 2,
      "z": 8,
      "name": "Wood_Oak_Planks"
    },
    {
      "x": 10,
      "y": 2,
      "z": 8,
      "name": "Wood_Oak_Planks"
    },
    {
      "x": 11,
      "y": 2,
      "z": 8,
      "name": "Wood_Oak_Planks"
    },
    {
      "x": 12,
      "y": 2,
      "z": 8,
      "name": "Wood_Oak_Planks"
    },
    {
      "x": 13,
      "y": 2,
      "z": 8,
      "name": "Wood_Oak_Planks"
    },
    {
      "x": 14,
      "y": 2,
      "z": 8,
      "name": "Rock_Stone_Brick"
    },
    {
      "x": 15,
      "y": 2,
      "z": 8,
      "name": "Plant_Grass_Sharp"
    },
    {
      "x": 0,
      "y": 2,
      "z": 9,
      "name": "Plant_Leaves_Oak"
    },
    {
      "x": 1,
      "y": 2,
      "z": 9,
      "name": "Wood_Oak_Trunk"
    },
    {
      "x": 2,
      "y": 2,
      "z": 9,
      "name": "Wood_Oak_Trunk"
    },
    {
      "x": 3,
      "y": 2,
      "z": 9,
      "name": "Wood_Oak_Planks"
    },
    {
      "x": 4,
      "y": 2,
      "z": 9,
      "name": "Wood_Oak_Planks"
    },
    {
      "x": 5,
      "y": 2,
      "z": 9,
      "name": "Wood_Oak_Planks"
    },
    {
      "x": 6,
      "y": 2,
      "z": 9,
      "name": "Wood_Oak_Planks"
    },
    {
      "x": 7,
      "y": 2,
      "z": 9,
      "name": "Wood_Oak_Planks"
    },
    {
      "x": 8,
      "y": 2,
      "z": 9,
      "name": "Wood_Oak_Planks"
    },
    {
      "x": 9,
      "y": 2,
      "z": 9,
      "name": "Wood_Oak_Planks"
    },
    {
      "x": 10,
      "y": 2,
      "z": 9,
      "name": "Wood_Oak_Planks"
    },
    {
      "x": 11,
      "y": 2,
      "z": 9,
      "name": "Wood_Oak_Planks"
    },
    {
      "x": 12,
      "y": 2,
      "z": 9,
      "name": "Wood_Oak_Planks"
    },
    {
      "x": 13,
      "y": 2,
      "z": 9,
      "name": "Wood_Oak_Planks"
    },
    {
      "x": 14,
      "y": 2,
      "z": 9,
      "name": "Wood_Oak_Trunk"
    },
    {
      "x": 15,
      "y": 2,
      "z": 9,
      "name": "Wood_Oak_Trunk"
    },
    {
      "x": 16,
      "y": 2,
      "z": 9,
      "name": "Plant_Leaves_Oak"
    },
    {
      "x": 1,
      "y": 2,
      "z": 10,
      "name": "Plant_Grass_Sharp"
    },
    {
      "x": 2,
      "y": 2,
      "z": 10,
      "name": "Rock_Stone_Brick"
    },
    {
      "x": 3,
      "y": 2,
      "z": 10,
      "name": "Wood_Oak_Planks"
    },
    {
      "x": 4,
      "y": 2,
      "z": 10,
      "name": "Wood_Oak_Planks"
    },
    {
      "x": 5,
      "y": 2,
      "z": 10,
      "name": "Wood_Oak_Planks"
    },
    {
      "x": 6,
      "y": 2,
      "z": 10,
      "name": "Wood_Oak_Planks"
    },
    {
      "x": 7,
      "y": 2,
      "z": 10,
      "name": "Wood_Oak_Planks"
    },
    {
      "x": 8,
      "y": 2,
      "z": 10,
      "name": "Wood_Oak_Planks"
    },
    {
      "x": 9,
      "y": 2,
      "z": 10,
      "name": "Wood_Oak_Planks"
    },
    {
      "x": 10,
      "y": 2,
      "z": 10,
      "name": "Wood_Oak_Planks"
    },
    {
      "x": 11,
      "y": 2,
      "z": 10,
      "name": "Wood_Oak_Planks"
    },
    {
      "x": 12,
      "y": 2,
      "z": 10,
      "name": "Wood_Oak_Planks"
    },
    {
      "x": 13,
      "y": 2,
      "z": 10,
      "name": "Wood_Oak_Planks"
    },
    {
      "x": 14,
      "y": 2,
      "z": 10,
      "name": "Rock_Stone_Brick"
    },
    {
      "x": 15,
      "y": 2,
      "z": 10,
      "name": "Plant_Leaves_Oak"
    },
    {
      "x": 2,
      "y": 2,
      "z": 11,
      "name": "Rock_Stone_Brick"
    },
    {
      "x": 3,
      "y": 2,
      "z": 11,
      "name": "Wood_Oak_Planks"
    },
    {
      "x": 4,
      "y": 2,
      "z": 11,
      "name": "Wood_Oak_Planks"
    },
    {
      "x": 5,
      "y": 2,
      "z": 11,
      "name": "Wood_Oak_Planks"
    },
    {
      "x": 6,
      "y": 2,
      "z": 11,
      "name": "Wood_Oak_Planks"
    },
    {
      "x": 7,
      "y": 2,
      "z": 11,
      "name": "Wood_Oak_Planks"
    },
    {
      "x": 8,
      "y": 2,
      "z": 11,
      "name": "Wood_Oak_Planks"
    },
    {
      "x": 9,
      "y": 2,
      "z": 11,
      "name": "Wood_Oak_Planks"
    },
    {
      "x": 10,
      "y": 2,
      "z": 11,
      "name": "Wood_Oak_Planks"
    },
    {
      "x": 11,
      "y": 2,
      "z": 11,
      "name": "Wood_Oak_Planks"
    },
    {
      "x": 12,
      "y": 2,
      "z": 11,
      "name": "Wood_Oak_Planks"
    },
    {
      "x": 13,
      "y": 2,
      "z": 11,
      "name": "Wood_Oak_Planks"
    },
    {
      "x": 14,
      "y": 2,
      "z": 11,
      "name": "Rock_Stone_Brick"
    },
    {
      "x": 2,
      "y": 2,
      "z": 12,
      "name": "Rock_Stone_Brick"
    },
    {
      "x": 3,
      "y": 2,
      "z": 12,
      "name": "Wood_Oak_Planks"
    },
    {
      "x": 4,
      "y": 2,
      "z": 12,
      "name": "Wood_Oak_Planks"
    },
    {
      "x": 5,
      "y": 2,
      "z": 12,
      "name": "Wood_Oak_Planks"
    },
    {
      "x": 6,
      "y": 2,
      "z": 12,
      "name": "Wood_Oak_Planks"
    },
    {
      "x": 7,
      "y": 2,
      "z": 12,
      "name": "Wood_Oak_Planks"
    },
    {
      "x": 8,
      "y": 2,
      "z": 12,
      "name": "Wood_Oak_Planks"
    },
    {
      "x": 9,
      "y": 2,
      "z": 12,
      "name": "Wood_Oak_Planks"
    },
    {
      "x": 10,
      "y": 2,
      "z": 12,
      "name": "Wood_Oak_Planks"
    },
    {
      "x": 11,
      "y": 2,
      "z": 12,
      "name": "Wood_Oak_Planks"
    },
    {
      "x": 12,
      "y": 2,
      "z": 12,
      "name": "Wood_Oak_Planks"
    },
    {
      "x": 13,
      "y": 2,
      "z": 12,
      "name": "Wood_Oak_Planks"
    },
    {
      "x": 14,
      "y": 2,
      "z": 12,
      "name": "Rock_Stone_Brick"
    },
    {
      "x": 15,
      "y": 2,
      "z": 12,
      "name": "Plant_Grass_Sharp"
    },
    {
      "x": 0,
      "y": 2,
      "z": 13,
      "name": "Plant_Leaves_Oak"
    },
    {
      "x": 1,
      "y": 2,
      "z": 13,
      "name": "Wood_Oak_Trunk"
    },
    {
      "x": 2,
      "y": 2,
      "z": 13,
      "name": "Wood_Oak_Trunk"
    },
    {
      "x": 3,
      "y": 2,
      "z": 13,
      "name": "Wood_Oak_Planks"
    },
    {
      "x": 4,
      "y": 2,
      "z": 13,
      "name": "Wood_Oak_Planks"
    },
    {
      "x": 5,
      "y": 2,
      "z": 13,
      "name": "Wood_Oak_Planks"
    },
    {
      "x": 6,
      "y": 2,
      "z": 13,
      "name": "Wood_Oak_Planks"
    },
    {
      "x": 7,
      "y": 2,
      "z": 13,
      "name": "Wood_Oak_Planks"
    },
    {
      "x": 8,
      "y": 2,
      "z": 13,
      "name": "Wood_Oak_Planks"
    },
    {
      "x": 9,
      "y": 2,
      "z": 13,
      "name": "Wood_Oak_Planks"
    },
    {
      "x": 10,
      "y": 2,
      "z": 13,
      "name": "Wood_Oak_Planks"
    },
    {
      "x": 11,
      "y": 2,
      "z": 13,
      "name": "Wood_Oak_Planks"
    },
    {
      "x": 12,
      "y": 2,
      "z": 13,
      "name": "Wood_Oak_Planks"
    },
    {
      "x": 13,
      "y": 2,
      "z": 13,
      "name": "Wood_Oak_Planks"
    },
    {
      "x": 14,
      "y": 2,
      "z": 13,
      "name": "Wood_Oak_Trunk"
    },
    {
      "x": 15,
      "y": 2,
      "z": 13,
      "name": "Wood_Oak_Trunk"
    },
    {
      "x": 1,
      "y": 2,
      "z": 14,
      "name": "Plant_Leaves_Oak"
    },
    {
      "x": 2,
      "y": 2,
      "z": 14,
      "name": "Rock_Stone_Brick"
    },
    {
      "x": 3,
      "y": 2,
      "z": 14,
      "name": "Wood_Oak_Planks"
    },
    {
      "x": 4,
      "y": 2,
      "z": 14,
      "name": "Wood_Oak_Planks"
    },
    {
      "x": 5,
      "y": 2,
      "z": 14,
      "name": "Wood_Oak_Planks"
    },
    {
      "x": 6,
      "y": 2,
      "z": 14,
      "name": "Wood_Oak_Planks"
    },
    {
      "x": 7,
      "y": 2,
      "z": 14,
      "name": "Wood_Oak_Planks"
    },
    {
      "x": 8,
      "y": 2,
      "z": 14,
      "name": "Wood_Oak_Planks"
    },
    {
      "x": 9,
      "y": 2,
      "z": 14,
      "name": "Wood_Oak_Planks"
    },
    {
      "x": 10,
      "y": 2,
      "z": 14,
      "name": "Wood_Oak_Planks"
    },
    {
      "x": 11,
      "y": 2,
      "z": 14,
      "name": "Wood_Oak_Planks"
    },
    {
      "x": 12,
      "y": 2,
      "z": 14,
      "name": "Wood_Oak_Planks"
    },
    {
      "x": 13,
      "y": 2,
      "z": 14,
      "name": "Wood_Oak_Planks"
    },
    {
      "x": 14,
      "y": 2,
      "z": 14,
      "name": "Rock_Stone_Brick"
    },
    {
      "x": 2,
      "y": 2,
      "z": 15,
      "name": "Rock_Stone_Brick"
    },
    {
      "x": 3,
      "y": 2,
      "z": 15,
      "name": "Wood_Oak_Planks"
    },
    {
      "x": 4,
      "y": 2,
      "z": 15,
      "name": "Wood_Oak_Planks"
    },
    {
      "x": 5,
      "y": 2,
      "z": 15,
      "name": "Wood_Oak_Planks"
    },
    {
      "x": 6,
      "y": 2,
      "z": 15,
      "name": "Wood_Oak_Planks"
    },
    {
      "x": 7,
      "y": 2,
      "z": 15,
      "name": "Wood_Oak_Planks"
    },
    {
      "x": 8,
      "y": 2,
      "z": 15,
      "name": "Wood_Oak_Planks"
    },
    {
      "x": 9,
      "y": 2,
      "z": 15,
      "name": "Wood_Oak_Planks"
    },
    {
      "x": 10,
      "y": 2,
      "z": 15,
      "name": "Wood_Oak_Planks"
    },
    {
      "x": 11,
      "y": 2,
      "z": 15,
      "name": "Wood_Oak_Planks"
    },
    {
      "x": 12,
      "y": 2,
      "z": 15,
      "name": "Wood_Oak_Planks"
    },
    {
      "x": 13,
      "y": 2,
      "z": 15,
      "name": "Wood_Oak_Planks"
    },
    {
      "x": 14,
      "y": 2,
      "z": 15,
      "name": "Rock_Stone_Brick"
    },
    {
      "x": 2,
      "y": 2,
      "z": 16,
      "name": "Rock_Stone_Brick"
    },
    {
      "x": 3,
      "y": 2,
      "z": 16,
      "name": "Wood_Oak_Planks"
    },
    {
      "x": 4,
      "y": 2,
      "z": 16,
      "name": "Wood_Oak_Planks"
    },
    {
      "x": 5,
      "y": 2,
      "z": 16,
      "name": "Wood_Oak_Planks"
    },
    {
      "x": 6,
      "y": 2,
      "z": 16,
      "name": "Wood_Oak_Planks"
    },
    {
      "x": 7,
      "y": 2,
      "z": 16,
      "name": "Wood_Oak_Planks"
    },
    {
      "x": 8,
      "y": 2,
      "z": 16,
      "name": "Wood_Oak_Planks"
    },
    {
      "x": 9,
      "y": 2,
      "z": 16,
      "name": "Wood_Oak_Planks"
    },
    {
      "x": 10,
      "y": 2,
      "z": 16,
      "name": "Wood_Oak_Planks"
    },
    {
      "x": 11,
      "y": 2,
      "z": 16,
      "name": "Wood_Oak_Planks"
    },
    {
      "x": 12,
      "y": 2,
      "z": 16,
      "name": "Wood_Oak_Planks"
    },
    {
      "x": 13,
      "y": 2,
      "z": 16,
      "name": "Wood_Oak_Planks"
    },
    {
      "x": 14,
      "y": 2,
      "z": 16,
      "name": "Rock_Stone_Brick"
    },
    {
      "x": 15,
      "y": 2,
      "z": 16,
      "name": "Plant_Leaves_Oak"
    },
    {
      "x": 1,
      "y": 2,
      "z": 17,
      "name": "Wood_Oak_Trunk"
    },
    {
      "x": 2,
      "y": 2,
      "z": 17,
      "name": "Wood_Oak_Trunk"
    },
    {
      "x": 3,
      "y": 2,
      "z": 17,
      "name": "Rock_Stone_Brick"
    },
    {
      "x": 4,
      "y": 2,
      "z": 17,
      "name": "Rock_Stone_Brick"
    },
    {
      "x": 5,
      "y": 2,
      "z": 17,
      "name": "Rock_Stone_Brick"
    },
    {
      "x": 6,
      "y": 2,
      "z": 17,
      "name": "Wood_Oak_Trunk"
    },
    {
      "x": 7,
      "y": 2,
      "z": 17,
      "name": "Rock_Stone_Brick"
    },
    {
      "x": 8,
      "y": 2,
      "z": 17,
      "name": "Rock_Stone_Brick"
    },
    {
      "x": 9,
      "y": 2,
      "z": 17,
      "name": "Rock_Stone_Brick"
    },
    {
      "x": 10,
      "y": 2,
      "z": 17,
      "name": "Wood_Oak_Trunk"
    },
    {
      "x": 11,
      "y": 2,
      "z": 17,
      "name": "Rock_Stone_Brick"
    },
    {
      "x": 12,
      "y": 2,
      "z": 17,
      "name": "Rock_Stone_Brick"
    },
    {
      "x": 13,
      "y": 2,
      "z": 17,
      "name": "Rock_Stone_Brick"
    },
    {
      "x": 14,
      "y": 2,
      "z": 17,
      "name": "Wood_Oak_Trunk"
    },
    {
      "x": 15,
      "y": 2,
      "z": 17,
      "name": "Wood_Oak_Trunk"
    },
    {
      "x": 16,
      "y": 2,
      "z": 17,
      "name": "Plant_Leaves_Oak"
    },
    {
      "x": 2,
      "y": 2,
      "z": 18,
      "name": "Wood_Oak_Trunk"
    },
    {
      "x": 3,
      "y": 2,
      "z": 18,
      "name": "Plant_Leaves_Oak"
    },
    {
      "x": 6,
      "y": 2,
      "z": 18,
      "name": "Wood_Oak_Trunk"
    },
    {
      "x": 7,
      "y": 2,
      "z": 18,
      "name": "Plant_Leaves_Oak"
    },
    {
      "x": 10,
      "y": 2,
      "z": 18,
      "name": "Wood_Oak_Trunk"
    },
    {
      "x": 11,
      "y": 2,
      "z": 18,
      "name": "Plant_Grass_Sharp"
    },
    {
      "x": 14,
      "y": 2,
      "z": 18,
      "name": "Wood_Oak_Trunk"
    },
    {
      "x": 15,
      "y": 2,
      "z": 18,
      "name": "Plant_Leaves_Oak"
    },
    {
      "x": 2,
      "y": 2,
      "z": 19,
      "name": "Plant_Grass_Sharp"
    },
    {
      "x": 6,
      "y": 2,
      "z": 19,
      "name": "Plant_Leaves_Oak"
    },
    {
      "x": 7,
      "y": 2,
      "z": 19,
      "name": "Plant_Grass_Sharp"
    },
    {
      "x": 16,
      "y": 2,
      "z": 19,
      "name": "Plant_Grass_Sharp"
    },
    {
      "x": 0,
      "y": 2,
      "z": 20,
      "name": "Plant_Grass_Sharp"
    },
    {
      "x": 1,
      "y": 2,
      "z": 20,
      "name": "Plant_Grass_Sharp"
    },
    {
      "x": 3,
      "y": 2,
      "z": 20,
      "name": "Plant_Grass_Sharp"
    },
    {
      "x": 5,
      "y": 2,
      "z": 20,
      "name": "Plant_Grass_Sharp"
    },
    {
      "x": 10,
      "y": 2,
      "z": 20,
      "name": "Plant_Grass_Sharp"
    },
    {
      "x": 13,
      "y": 2,
      "z": 20,
      "name": "Plant_Grass_Sharp"
    },
    {
      "x": 0,
      "y": 2,
      "z": 21,
      "name": "Plant_Grass_Sharp"
    },
    {
      "x": 1,
      "y": 2,
      "z": 21,
      "name": "Plant_Grass_Sharp"
    },
    {
      "x": 2,
      "y": 2,
      "z": 21,
      "name": "Plant_Grass_Sharp"
    },
    {
      "x": 4,
      "y": 2,
      "z": 21,
      "name": "Plant_Grass_Sharp"
    },
    {
      "x": 5,
      "y": 2,
      "z": 21,
      "name": "Plant_Grass_Sharp"
    },
    {
      "x": 6,
      "y": 2,
      "z": 21,
      "name": "Plant_Grass_Sharp"
    },
    {
      "x": 9,
      "y": 2,
      "z": 21,
      "name": "Plant_Grass_Sharp"
    },
    {
      "x": 10,
      "y": 2,
      "z": 21,
      "name": "Plant_Grass_Sharp"
    },
    {
      "x": 11,
      "y": 2,
      "z": 21,
      "name": "Plant_Grass_Sharp"
    },
    {
      "x": 12,
      "y": 2,
      "z": 21,
      "name": "Plant_Grass_Sharp"
    },
    {
      "x": 14,
      "y": 2,
      "z": 21,
      "name": "Plant_Grass_Sharp"
    },
    {
      "x": 15,
      "y": 2,
      "z": 21,
      "name": "Plant_Grass_Sharp"
    },
    {
      "x": 16,
      "y": 2,
      "z": 21,
      "name": "Plant_Grass_Sharp"
    },
    {
      "x": 2,
      "y": 2,
      "z": 22,
      "name": "Plant_Grass_Sharp"
    },
    {
      "x": 3,
      "y": 2,
      "z": 22,
      "name": "Plant_Grass_Sharp"
    },
    {
      "x": 4,
      "y": 2,
      "z": 22,
      "name": "Plant_Grass_Sharp"
    },
    {
      "x": 5,
      "y": 2,
      "z": 22,
      "name": "Plant_Grass_Sharp"
    },
    {
      "x": 6,
      "y": 2,
      "z": 22,
      "name": "Plant_Grass_Sharp"
    },
    {
      "x": 8,
      "y": 2,
      "z": 22,
      "name": "Plant_Grass_Sharp"
    },
    {
      "x": 9,
      "y": 2,
      "z": 22,
      "name": "Plant_Grass_Sharp"
    },
    {
      "x": 10,
      "y": 2,
      "z": 22,
      "name": "Plant_Grass_Sharp"
    },
    {
      "x": 11,
      "y": 2,
      "z": 22,
      "name": "Plant_Grass_Sharp"
    },
    {
      "x": 12,
      "y": 2,
      "z": 22,
      "name": "Plant_Grass_Sharp"
    },
    {
      "x": 13,
      "y": 2,
      "z": 22,
      "name": "Plant_Grass_Sharp"
    },
    {
      "x": 14,
      "y": 2,
      "z": 22,
      "name": "Plant_Grass_Sharp"
    },
    {
      "x": 15,
      "y": 2,
      "z": 22,
      "name": "Plant_Grass_Sharp"
    },
    {
      "x": 14,
      "y": 3,
      "z": 3,
      "name": "Plant_Grass_Sharp"
    },
    {
      "x": 2,
      "y": 3,
      "z": 4,
      "name": "Wood_Oak_Trunk"
    },
    {
      "x": 4,
      "y": 3,
      "z": 4,
      "name": "Plant_Grass_Sharp"
    },
    {
      "x": 6,
      "y": 3,
      "z": 4,
      "name": "Wood_Oak_Trunk"
    },
    {
      "x": 10,
      "y": 3,
      "z": 4,
      "name": "Wood_Oak_Trunk"
    },
    {
      "x": 11,
      "y": 3,
      "z": 4,
      "name": "Plant_Grass_Sharp"
    },
    {
      "x": 13,
      "y": 3,
      "z": 4,
      "name": "Plant_Leaves_Oak"
    },
    {
      "x": 14,
      "y": 3,
      "z": 4,
      "name": "Wood_Oak_Trunk"
    },
    {
      "x": 1,
      "y": 3,
      "z": 5,
      "name": "Wood_Oak_Trunk"
    },
    {
      "x": 2,
      "y": 3,
      "z": 5,
      "name": "Wood_Oak_Trunk"
    },
    {
      "x": 6,
      "y": 3,
      "z": 5,
      "name": "Wood_Oak_Trunk"
    },
    {
      "x": 7,
      "y": 3,
      "z": 5,
      "name": "Wood_Pine_Planks"
    },
    {
      "x": 9,
      "y": 3,
      "z": 5,
      "name": "Wood_Pine_Planks"
    },
    {
      "x": 10,
      "y": 3,
      "z": 5,
      "name": "Wood_Oak_Trunk"
    },
    {
      "x": 14,
      "y": 3,
      "z": 5,
      "name": "Wood_Oak_Trunk"
    },
    {
      "x": 15,
      "y": 3,
      "z": 5,
      "name": "Wood_Oak_Trunk"
    },
    {
      "x": 3,
      "y": 3,
      "z": 6,
      "name": "Wood_Pine_Trunk"
    },
    {
      "x": 4,
      "y": 3,
      "z": 6,
      "name": "Wood_Pine_Trunk"
    },
    {
      "x": 5,
      "y": 3,
      "z": 6,
      "name": "Wood_Pine_Trunk"
    },
    {
      "x": 6,
      "y": 3,
      "z": 6,
      "name": "Wood_Oak_Planks"
    },
    {
      "x": 7,
      "y": 3,
      "z": 6,
      "name": "Rock_Stone_Brick"
    },
    {
      "x": 8,
      "y": 3,
      "z": 6,
      "name": "Wood_Oak_Planks"
    },
    {
      "x": 9,
      "y": 3,
      "z": 6,
      "name": "Rock_Stone_Brick"
    },
    {
      "x": 10,
      "y": 3,
      "z": 6,
      "name": "Wood_Oak_Planks"
    },
    {
      "x": 11,
      "y": 3,
      "z": 6,
      "name": "Wood_Pine_Trunk"
    },
    {
      "x": 12,
      "y": 3,
      "z": 6,
      "name": "Wood_Pine_Trunk"
    },
    {
      "x": 13,
      "y": 3,
      "z": 6,
      "name": "Wood_Pine_Trunk"
    },
    {
      "x": 3,
      "y": 3,
      "z": 7,
      "name": "Wood_Pine_Trunk"
    },
    {
      "x": 5,
      "y": 3,
      "z": 7,
      "name": "Wood_Oak_Planks"
    },
    {
      "x": 11,
      "y": 3,
      "z": 7,
      "name": "Rock_Stone"
    },
    {
      "x": 13,
      "y": 3,
      "z": 7,
      "name": "Wood_Pine_Trunk"
    },
    {
      "x": 0,
      "y": 3,
      "z": 8,
      "name": "Plant_Grass_Sharp"
    },
    {
      "x": 1,
      "y": 3,
      "z": 8,
      "name": "Plant_Leaves_Oak"
    },
    {
      "x": 3,
      "y": 3,
      "z": 8,
      "name": "Wood_Pine_Trunk"
    },
    {
      "x": 4,
      "y": 3,
      "z": 8,
      "name": "Wood_Pine_Trunk"
    },
    {
      "x": 12,
      "y": 3,
      "z": 8,
      "name": "Wood_Pine_Trunk"
    },
    {
      "x": 13,
      "y": 3,
      "z": 8,
      "name": "Wood_Pine_Trunk"
    },
    {
      "x": 15,
      "y": 3,
      "z": 8,
      "name": "Plant_Grass_Sharp"
    },
    {
      "x": 1,
      "y": 3,
      "z": 9,
      "name": "Wood_Oak_Trunk"
    },
    {
      "x": 2,
      "y": 3,
      "z": 9,
      "name": "Wood_Oak_Trunk"
    },
    {
      "x": 3,
      "y": 3,
      "z": 9,
      "name": "Wood_Pine_Trunk"
    },
    {
      "x": 5,
      "y": 3,
      "z": 9,
      "name": "Wood_Oak_Planks"
    },
    {
      "x": 11,
      "y": 3,
      "z": 9,
      "name": "Wood_Oak_Planks"
    },
    {
      "x": 13,
      "y": 3,
      "z": 9,
      "name": "Wood_Pine_Trunk"
    },
    {
      "x": 14,
      "y": 3,
      "z": 9,
      "name": "Wood_Oak_Trunk"
    },
    {
      "x": 15,
      "y": 3,
      "z": 9,
      "name": "Wood_Oak_Trunk"
    },
    {
      "x": 1,
      "y": 3,
      "z": 10,
      "name": "Plant_Grass_Sharp"
    },
    {
      "x": 3,
      "y": 3,
      "z": 10,
      "name": "Wood_Pine_Trunk"
    },
    {
      "x": 4,
      "y": 3,
      "z": 10,
      "name": "Wood_Pine_Trunk"
    },
    {
      "x": 12,
      "y": 3,
      "z": 10,
      "name": "Wood_Pine_Trunk"
    },
    {
      "x": 13,
      "y": 3,
      "z": 10,
      "name": "Wood_Pine_Trunk"
    },
    {
      "x": 3,
      "y": 3,
      "z": 11,
      "name": "Wood_Pine_Trunk"
    },
    {
      "x": 5,
      "y": 3,
      "z": 11,
      "name": "Rock_Stone"
    },
    {
      "x": 11,
      "y": 3,
      "z": 11,
      "name": "Wood_Oak_Planks"
    },
    {
      "x": 13,
      "y": 3,
      "z": 11,
      "name": "Wood_Pine_Trunk"
    },
    {
      "x": 3,
      "y": 3,
      "z": 12,
      "name": "Wood_Pine_Trunk"
    },
    {
      "x": 4,
      "y": 3,
      "z": 12,
      "name": "Wood_Pine_Trunk"
    },
    {
      "x": 12,
      "y": 3,
      "z": 12,
      "name": "Wood_Pine_Trunk"
    },
    {
      "x": 13,
      "y": 3,
      "z": 12,
      "name": "Wood_Pine_Trunk"
    },
    {
      "x": 15,
      "y": 3,
      "z": 12,
      "name": "Plant_Grass_Sharp"
    },
    {
      "x": 1,
      "y": 3,
      "z": 13,
      "name": "Wood_Oak_Trunk"
    },
    {
      "x": 2,
      "y": 3,
      "z": 13,
      "name": "Wood_Oak_Trunk"
    },
    {
      "x": 3,
      "y": 3,
      "z": 13,
      "name": "Wood_Pine_Trunk"
    },
    {
      "x": 5,
      "y": 3,
      "z": 13,
      "name": "Wood_Oak_Planks"
    },
    {
      "x": 11,
      "y": 3,
      "z": 13,
      "name": "Wood_Oak_Planks"
    },
    {
      "x": 13,
      "y": 3,
      "z": 13,
      "name": "Wood_Pine_Trunk"
    },
    {
      "x": 14,
      "y": 3,
      "z": 13,
      "name": "Wood_Oak_Trunk"
    },
    {
      "x": 15,
      "y": 3,
      "z": 13,
      "name": "Wood_Oak_Trunk"
    },
    {
      "x": 3,
      "y": 3,
      "z": 14,
      "name": "Wood_Pine_Trunk"
    },
    {
      "x": 4,
      "y": 3,
      "z": 14,
      "name": "Wood_Pine_Trunk"
    },
    {
      "x": 12,
      "y": 3,
      "z": 14,
      "name": "Wood_Pine_Trunk"
    },
    {
      "x": 13,
      "y": 3,
      "z": 14,
      "name": "Wood_Pine_Trunk"
    },
    {
      "x": 3,
      "y": 3,
      "z": 15,
      "name": "Wood_Pine_Trunk"
    },
    {
      "x": 5,
      "y": 3,
      "z": 15,
      "name": "Wood_Oak_Planks"
    },
    {
      "x": 11,
      "y": 3,
      "z": 15,
      "name": "Rock_Stone"
    },
    {
      "x": 13,
      "y": 3,
      "z": 15,
      "name": "Wood_Pine_Trunk"
    },
    {
      "x": 3,
      "y": 3,
      "z": 16,
      "name": "Wood_Pine_Trunk"
    },
    {
      "x": 4,
      "y": 3,
      "z": 16,
      "name": "Wood_Pine_Trunk"
    },
    {
      "x": 5,
      "y": 3,
      "z": 16,
      "name": "Wood_Pine_Trunk"
    },
    {
      "x": 6,
      "y": 3,
      "z": 16,
      "name": "Wood_Oak_Planks"
    },
    {
      "x": 7,
      "y": 3,
      "z": 16,
      "name": "Wood_Oak_Planks"
    },
    {
      "x": 8,
      "y": 3,
      "z": 16,
      "name": "Rock_Stone"
    },
    {
      "x": 9,
      "y": 3,
      "z": 16,
      "name": "Wood_Oak_Planks"
    },
    {
      "x": 10,
      "y": 3,
      "z": 16,
      "name": "Wood_Oak_Planks"
    },
    {
      "x": 11,
      "y": 3,
      "z": 16,
      "name": "Wood_Pine_Trunk"
    },
    {
      "x": 12,
      "y": 3,
      "z": 16,
      "name": "Wood_Pine_Trunk"
    },
    {
      "x": 13,
      "y": 3,
      "z": 16,
      "name": "Wood_Pine_Trunk"
    },
    {
      "x": 1,
      "y": 3,
      "z": 17,
      "name": "Wood_Oak_Trunk"
    },
    {
      "x": 2,
      "y": 3,
      "z": 17,
      "name": "Wood_Oak_Trunk"
    },
    {
      "x": 6,
      "y": 3,
      "z": 17,
      "name": "Wood_Oak_Trunk"
    },
    {
      "x": 10,
      "y": 3,
      "z": 17,
      "name": "Wood_Oak_Trunk"
    },
    {
      "x": 14,
      "y": 3,
      "z": 17,
      "name": "Wood_Oak_Trunk"
    },
    {
      "x": 15,
      "y": 3,
      "z": 17,
      "name": "Wood_Oak_Trunk"
    },
    {
      "x": 16,
      "y": 3,
      "z": 17,
      "name": "Plant_Leaves_Oak"
    },
    {
      "x": 2,
      "y": 3,
      "z": 18,
      "name": "Wood_Oak_Trunk"
    },
    {
      "x": 6,
      "y": 3,
      "z": 18,
      "name": "Wood_Oak_Trunk"
    },
    {
      "x": 10,
      "y": 3,
      "z": 18,
      "name": "Wood_Oak_Trunk"
    },
    {
      "x": 11,
      "y": 3,
      "z": 18,
      "name": "Plant_Grass_Sharp"
    },
    {
      "x": 14,
      "y": 3,
      "z": 18,
      "name": "Wood_Oak_Trunk"
    },
    {
      "x": 2,
      "y": 3,
      "z": 19,
      "name": "Plant_Grass_Sharp"
    },
    {
      "x": 7,
      "y": 3,
      "z": 19,
      "name": "Plant_Grass_Sharp"
    },
    {
      "x": 0,
      "y": 3,
      "z": 20,
      "name": "Plant_Grass_Sharp"
    },
    {
      "x": 1,
      "y": 3,
      "z": 20,
      "name": "Plant_Grass_Sharp"
    },
    {
      "x": 0,
      "y": 3,
      "z": 21,
      "name": "Plant_Grass_Sharp"
    },
    {
      "x": 5,
      "y": 3,
      "z": 21,
      "name": "Plant_Grass_Sharp"
    },
    {
      "x": 10,
      "y": 3,
      "z": 21,
      "name": "Plant_Grass_Sharp"
    },
    {
      "x": 12,
      "y": 3,
      "z": 21,
      "name": "Plant_Grass_Sharp"
    },
    {
      "x": 15,
      "y": 3,
      "z": 21,
      "name": "Plant_Grass_Sharp"
    },
    {
      "x": 16,
      "y": 3,
      "z": 21,
      "name": "Plant_Grass_Sharp"
    },
    {
      "x": 4,
      "y": 3,
      "z": 22,
      "name": "Plant_Grass_Sharp"
    },
    {
      "x": 5,
      "y": 3,
      "z": 22,
      "name": "Plant_Grass_Sharp"
    },
    {
      "x": 2,
      "y": 4,
      "z": 5,
      "name": "Wood_Oak_Trunk"
    },
    {
      "x": 3,
      "y": 4,
      "z": 5,
      "name": "Wood_Pine_Planks"
    },
    {
      "x": 5,
      "y": 4,
      "z": 5,
      "name": "Wood_Pine_Planks"
    },
    {
      "x": 6,
      "y": 4,
      "z": 5,
      "name": "Wood_Oak_Trunk"
    },
    {
      "x": 7,
      "y": 4,
      "z": 5,
      "name": "Wood_Pine_Planks"
    },
    {
      "x": 9,
      "y": 4,
      "z": 5,
      "name": "Wood_Pine_Planks"
    },
    {
      "x": 10,
      "y": 4,
      "z": 5,
      "name": "Wood_Oak_Trunk"
    },
    {
      "x": 11,
      "y": 4,
      "z": 5,
      "name": "Wood_Pine_Planks"
    },
    {
      "x": 13,
      "y": 4,
      "z": 5,
      "name": "Wood_Pine_Planks"
    },
    {
      "x": 14,
      "y": 4,
      "z": 5,
      "name": "Wood_Oak_Trunk"
    },
    {
      "x": 2,
      "y": 4,
      "z": 6,
      "name": "Wood_Pine_Planks"
    },
    {
      "x": 3,
      "y": 4,
      "z": 6,
      "name": "Wood_Pine_Trunk"
    },
    {
      "x": 4,
      "y": 4,
      "z": 6,
      "name": "Wood_Pine_Trunk"
    },
    {
      "x": 5,
      "y": 4,
      "z": 6,
      "name": "Wood_Pine_Trunk"
    },
    {
      "x": 6,
      "y": 4,
      "z": 6,
      "name": "Rock_Stone_Brick"
    },
    {
      "x": 7,
      "y": 4,
      "z": 6,
      "name": "Rock_Stone_Brick"
    },
    {
      "x": 8,
      "y": 4,
      "z": 6,
      "name": "Wood_Oak_Planks"
    },
    {
      "x": 9,
      "y": 4,
      "z": 6,
      "name": "Rock_Stone_Brick"
    },
    {
      "x": 10,
      "y": 4,
      "z": 6,
      "name": "Rock_Stone_Brick"
    },
    {
      "x": 11,
      "y": 4,
      "z": 6,
      "name": "Wood_Pine_Trunk"
    },
    {
      "x": 12,
      "y": 4,
      "z": 6,
      "name": "Wood_Pine_Trunk"
    },
    {
      "x": 13,
      "y": 4,
      "z": 6,
      "name": "Wood_Pine_Trunk"
    },
    {
      "x": 14,
      "y": 4,
      "z": 6,
      "name": "Wood_Pine_Planks"
    },
    {
      "x": 3,
      "y": 4,
      "z": 7,
      "name": "Wood_Pine_Trunk"
    },
    {
      "x": 5,
      "y": 4,
      "z": 7,
      "name": "Wood_Pine_Planks"
    },
