{
  "version": 8,
  "blockIdVersion": 10,
  "anchorX": 0,
  "anchorY": 0,
  "anchorZ": 0,
  "blocks": [
    {
      "x": 0,
      "y": 0,
      "z": 0,
      "name": "Soil_Dirt"
    },
    {
      "x": 1,
      "y": 0,
      "z": 0,
      "name": "Soil_Dirt"
    },
    {
      "x": 2,
      "y": 0,
      "z": 0,
      "name": "Soil_Dirt"
    },
    {
      "x": 3,
      "y": 0,
      "z": 0,
      "name": "Soil_Dirt"
    },
    {
      "x": 4,
      "y": 0,
      "z": 0,
      "name": "Soil_Dirt"
    },
    {
      "x": 5,
      "y": 0,
      "z": 0,
      "name": "Soil_Dirt"
    },
    {
      "x": 6,
      "y": 0,
      "z": 0,
      "name": "Soil_Dirt"
    },
    {
      "x": 7,
      "y": 0,
      "z": 0,
      "name": "Soil_Dirt"
    },
    {
      "x": 8,
      "y": 0,
      "z": 0,
      "name": "Soil_Dirt"
    },
    {
      "x": 9,
      "y": 0,
      "z": 0,
      "name": "Soil_Dirt"
    },
    {
      "x": 10,
      "y": 0,
      "z": 0,
      "name": "Soil_Dirt"
    },
    {
      "x": 11,
      "y": 0,
      "z": 0,
      "name": "Soil_Dirt"
    },
    {
      "x": 12,
      "y": 0,
      "z": 0,
      "name": "Soil_Dirt"
    },
    {
      "x": 13,
      "y": 0,
      "z": 0,
      "name": "Soil_Dirt"
    },
    {
      "x": 14,
      "y": 0,
      "z": 0,
      "name": "Soil_Dirt"
    },
    {
      "x": 15,
      "y": 0,
      "z": 0,
      "name": "Soil_Dirt"
    },
    {
      "x": 16,
      "y": 0,
      "z": 0,
      "name": "Cloth_Block_Wool_Orange"
    },
    {
      "x": 0,
      "y": 0,
      "z": 1,
      "name": "Soil_Dirt"
    },
    {
      "x": 1,
      "y": 0,
      "z": 1,
      "name": "Soil_Dirt"
    },
    {
      "x": 2,
      "y": 0,
      "z": 1,
      "name": "Soil_Dirt"
    },
    {
      "x": 3,
      "y": 0,
      "z": 1,
      "name": "Soil_Dirt"
    },
    {
      "x": 4,
      "y": 0,
      "z": 1,
      "name": "Soil_Dirt"
    },
    {
      "x": 5,
      "y": 0,
      "z": 1,
      "name": "Soil_Dirt"
    },
    {
      "x": 6,
      "y": 0,
      "z": 1,
      "name": "Soil_Dirt"
    },
    {
      "x": 7,
      "y": 0,
      "z": 1,
      "name": "Soil_Dirt"
    },
    {
      "x": 8,
      "y": 0,
      "z": 1,
      "name": "Soil_Dirt"
    },
    {
      "x": 9,
      "y": 0,
      "z": 1,
      "name": "Soil_Dirt"
    },
    {
      "x": 10,
      "y": 0,
      "z": 1,
      "name": "Soil_Dirt"
    },
    {
      "x": 11,
      "y": 0,
      "z": 1,
      "name": "Soil_Dirt"
    },
    {
      "x": 12,
      "y": 0,
      "z": 1,
      "name": "Soil_Dirt"
    },
    {
      "x": 13,
      "y": 0,
      "z": 1,
      "name": "Soil_Dirt"
    },
    {
      "x": 14,
      "y": 0,
      "z": 1,
      "name": "Soil_Dirt"
    },
    {
      "x": 15,
      "y": 0,
      "z": 1,
      "name": "Soil_Dirt"
    },
    {
      "x": 16,
      "y": 0,
      "z": 1,
      "name": "Soil_Dirt"
    },
    {
      "x": 0,
      "y": 0,
      "z": 2,
      "name": "Soil_Dirt"
    },
    {
      "x": 1,
      "y": 0,
      "z": 2,
      "name": "Soil_Dirt"
    },
    {
      "x": 2,
      "y": 0,
      "z": 2,
      "name": "Soil_Dirt"
    },
    {
      "x": 3,
      "y": 0,
      "z": 2,
      "name": "Soil_Grass"
    },
    {
      "x": 4,
      "y": 0,
      "z": 2,
      "name": "Soil_Dirt"
    },
    {
      "x": 5,
      "y": 0,
      "z": 2,
      "name": "Soil_Dirt"
    },
    {
      "x": 6,
      "y": 0,
      "z": 2,
      "name": "Soil_Dirt"
    },
    {
      "x": 7,
      "y": 0,
      "z": 2,
      "name": "Soil_Dirt"
    },
    {
      "x": 8,
      "y": 0,
      "z": 2,
      "name": "Soil_Dirt"
    },
    {
      "x": 9,
      "y": 0,
      "z": 2,
      "name": "Soil_Dirt"
    },
    {
      "x": 10,
      "y": 0,
      "z": 2,
      "name": "Soil_Dirt"
    },
    {
      "x": 11,
      "y": 0,
      "z": 2,
      "name": "Soil_Grass"
    },
    {
      "x": 12,
      "y": 0,
      "z": 2,
      "name": "Soil_Dirt"
    },
    {
      "x": 13,
      "y": 0,
      "z": 2,
      "name": "Soil_Dirt"
    },
    {
      "x": 14,
      "y": 0,
      "z": 2,
      "name": "Soil_Dirt"
    },
    {
      "x": 15,
      "y": 0,
      "z": 2,
      "name": "Soil_Dirt"
    },
    {
      "x": 16,
      "y": 0,
      "z": 2,
      "name": "Soil_Dirt"
    },
    {
      "x": 0,
      "y": 0,
      "z": 3,
      "name": "Soil_Dirt"
    },
    {
      "x": 1,
      "y": 0,
      "z": 3,
      "name": "Soil_Dirt"
    },
    {
      "x": 2,
      "y": 0,
      "z": 3,
      "name": "Soil_Dirt"
    },
    {
      "x": 3,
      "y": 0,
      "z": 3,
      "name": "Soil_Dirt"
    },
    {
      "x": 4,
      "y": 0,
      "z": 3,
      "name": "Soil_Dirt"
    },
    {
      "x": 5,
      "y": 0,
      "z": 3,
      "name": "Soil_Dirt"
    },
    {
      "x": 6,
      "y": 0,
      "z": 3,
      "name": "Soil_Dirt"
    },
    {
      "x": 7,
      "y": 0,
      "z": 3,
      "name": "Soil_Dirt"
    },
    {
      "x": 8,
      "y": 0,
      "z": 3,
      "name": "Soil_Dirt"
    },
    {
      "x": 9,
      "y": 0,
      "z": 3,
      "name": "Soil_Dirt"
    },
    {
      "x": 10,
      "y": 0,
      "z": 3,
      "name": "Soil_Dirt"
    },
    {
      "x": 11,
      "y": 0,
      "z": 3,
      "name": "Soil_Dirt"
    },
    {
      "x": 12,
      "y": 0,
      "z": 3,
      "name": "Soil_Dirt"
    },
    {
      "x": 13,
      "y": 0,
      "z": 3,
      "name": "Soil_Dirt"
    },
    {
      "x": 14,
      "y": 0,
      "z": 3,
      "name": "Soil_Dirt"
    },
    {
      "x": 15,
      "y": 0,
      "z": 3,
      "name": "Soil_Dirt"
    },
    {
      "x": 16,
      "y": 0,
      "z": 3,
      "name": "Soil_Dirt"
    },
    {
      "x": 0,
      "y": 0,
      "z": 4,
      "name": "Soil_Dirt"
    },
    {
      "x": 1,
      "y": 0,
      "z": 4,
      "name": "Soil_Dirt"
    },
    {
      "x": 2,
      "y": 0,
      "z": 4,
      "name": "Soil_Dirt"
    },
    {
      "x": 3,
      "y": 0,
      "z": 4,
      "name": "Soil_Dirt"
    },
    {
      "x": 4,
      "y": 0,
      "z": 4,
      "name": "Soil_Dirt"
    },
    {
      "x": 5,
      "y": 0,
      "z": 4,
      "name": "Soil_Dirt"
    },
    {
      "x": 6,
      "y": 0,
      "z": 4,
      "name": "Soil_Dirt"
    },
    {
      "x": 7,
      "y": 0,
      "z": 4,
      "name": "Soil_Dirt"
    },
    {
      "x": 8,
      "y": 0,
      "z": 4,
      "name": "Soil_Dirt"
    },
    {
      "x": 9,
      "y": 0,
      "z": 4,
      "name": "Soil_Dirt"
    },
    {
      "x": 10,
      "y": 0,
      "z": 4,
      "name": "Soil_Dirt"
    },
    {
      "x": 11,
      "y": 0,
      "z": 4,
      "name": "Soil_Dirt"
    },
    {
      "x": 12,
      "y": 0,
      "z": 4,
      "name": "Soil_Dirt"
    },
    {
      "x": 13,
      "y": 0,
      "z": 4,
      "name": "Soil_Dirt"
    },
    {
      "x": 14,
      "y": 0,
      "z": 4,
      "name": "Soil_Dirt"
    },
    {
      "x": 15,
      "y": 0,
      "z": 4,
      "name": "Soil_Dirt"
    },
    {
      "x": 16,
      "y": 0,
      "z": 4,
      "name": "Soil_Dirt"
    },
    {
      "x": 0,
      "y": 0,
      "z": 5,
      "name": "Soil_Dirt"
    },
    {
      "x": 1,
      "y": 0,
      "z": 5,
      "name": "Soil_Dirt"
    },
    {
      "x": 2,
      "y": 0,
      "z": 5,
      "name": "Soil_Dirt"
    },
    {
      "x": 3,
      "y": 0,
      "z": 5,
      "name": "Soil_Dirt"
    },
    {
      "x": 4,
      "y": 0,
      "z": 5,
      "name": "Soil_Dirt"
    },
    {
      "x": 5,
      "y": 0,
      "z": 5,
      "name": "Soil_Dirt"
    },
    {
      "x": 6,
      "y": 0,
      "z": 5,
      "name": "Soil_Dirt"
    },
    {
      "x": 7,
      "y": 0,
      "z": 5,
      "name": "Soil_Dirt"
    },
    {
      "x": 8,
      "y": 0,
      "z": 5,
      "name": "Soil_Dirt"
    },
    {
      "x": 9,
      "y": 0,
      "z": 5,
      "name": "Soil_Dirt"
    },
    {
      "x": 10,
      "y": 0,
      "z": 5,
      "name": "Soil_Dirt"
    },
    {
      "x": 11,
      "y": 0,
      "z": 5,
      "name": "Soil_Dirt"
    },
    {
      "x": 12,
      "y": 0,
      "z": 5,
      "name": "Soil_Dirt"
    },
    {
      "x": 13,
      "y": 0,
      "z": 5,
      "name": "Soil_Dirt"
    },
    {
      "x": 14,
      "y": 0,
      "z": 5,
      "name": "Soil_Dirt"
    },
    {
      "x": 15,
      "y": 0,
      "z": 5,
      "name": "Soil_Dirt"
    },
    {
      "x": 16,
      "y": 0,
      "z": 5,
      "name": "Soil_Dirt"
    },
    {
      "x": 0,
      "y": 0,
      "z": 6,
      "name": "Soil_Dirt"
    },
    {
      "x": 1,
      "y": 0,
      "z": 6,
      "name": "Soil_Dirt"
    },
    {
      "x": 2,
      "y": 0,
      "z": 6,
      "name": "Soil_Dirt"
    },
    {
      "x": 3,
      "y": 0,
      "z": 6,
      "name": "Soil_Dirt"
    },
    {
      "x": 4,
      "y": 0,
      "z": 6,
      "name": "Soil_Dirt"
    },
    {
      "x": 5,
      "y": 0,
      "z": 6,
      "name": "Soil_Dirt"
    },
    {
      "x": 6,
      "y": 0,
      "z": 6,
      "name": "Soil_Dirt"
    },
    {
      "x": 7,
      "y": 0,
      "z": 6,
      "name": "Soil_Dirt"
    },
    {
      "x": 8,
      "y": 0,
      "z": 6,
      "name": "Soil_Dirt"
    },
    {
      "x": 9,
      "y": 0,
      "z": 6,
      "name": "Soil_Dirt"
    },
    {
      "x": 10,
      "y": 0,
      "z": 6,
      "name": "Soil_Dirt"
    },
    {
      "x": 11,
      "y": 0,
      "z": 6,
      "name": "Soil_Dirt"
    },
    {
      "x": 12,
      "y": 0,
      "z": 6,
      "name": "Soil_Dirt"
    },
    {
      "x": 13,
      "y": 0,
      "z": 6,
      "name": "Soil_Dirt"
    },
    {
      "x": 14,
      "y": 0,
      "z": 6,
      "name": "Soil_Dirt"
    },
    {
      "x": 15,
      "y": 0,
      "z": 6,
      "name": "Soil_Dirt"
    },
    {
      "x": 16,
      "y": 0,
      "z": 6,
      "name": "Soil_Dirt"
    },
    {
      "x": 0,
      "y": 0,
      "z": 7,
      "name": "Soil_Dirt"
    },
    {
      "x": 1,
      "y": 0,
      "z": 7,
      "name": "Soil_Dirt"
    },
    {
      "x": 2,
      "y": 0,
      "z": 7,
      "name": "Soil_Dirt"
    },
    {
      "x": 3,
      "y": 0,
      "z": 7,
      "name": "Soil_Dirt"
    },
    {
      "x": 4,
      "y": 0,
      "z": 7,
      "name": "Soil_Dirt"
    },
    {
      "x": 5,
      "y": 0,
      "z": 7,
      "name": "Soil_Dirt"
    },
    {
      "x": 6,
      "y": 0,
      "z": 7,
      "name": "Soil_Dirt"
    },
    {
      "x": 7,
      "y": 0,
      "z": 7,
      "name": "Soil_Dirt"
    },
    {
      "x": 8,
      "y": 0,
      "z": 7,
      "name": "Soil_Dirt"
    },
    {
      "x": 9,
      "y": 0,
      "z": 7,
      "name": "Soil_Dirt"
    },
    {
      "x": 10,
      "y": 0,
      "z": 7,
      "name": "Soil_Dirt"
    },
    {
      "x": 11,
      "y": 0,
      "z": 7,
      "name": "Soil_Dirt"
    },
    {
      "x": 12,
      "y": 0,
      "z": 7,
      "name": "Soil_Dirt"
    },
    {
      "x": 13,
      "y": 0,
      "z": 7,
      "name": "Soil_Dirt"
    },
    {
      "x": 14,
      "y": 0,
      "z": 7,
      "name": "Soil_Dirt"
    },
    {
      "x": 15,
      "y": 0,
      "z": 7,
      "name": "Soil_Dirt"
    },
    {
      "x": 16,
      "y": 0,
      "z": 7,
      "name": "Soil_Dirt"
    },
    {
      "x": 0,
      "y": 0,
      "z": 8,
      "name": "Soil_Dirt"
    },
    {
      "x": 1,
      "y": 0,
      "z": 8,
      "name": "Soil_Dirt"
    },
    {
      "x": 2,
      "y": 0,
      "z": 8,
      "name": "Soil_Dirt"
    },
    {
      "x": 3,
      "y": 0,
      "z": 8,
      "name": "Soil_Dirt"
    },
    {
      "x": 4,
      "y": 0,
      "z": 8,
      "name": "Soil_Dirt"
    },
    {
      "x": 5,
      "y": 0,
      "z": 8,
      "name": "Soil_Dirt"
    },
    {
      "x": 6,
      "y": 0,
      "z": 8,
      "name": "Soil_Dirt"
    },
    {
      "x": 7,
      "y": 0,
      "z": 8,
      "name": "Soil_Dirt"
    },
    {
      "x": 8,
      "y": 0,
      "z": 8,
      "name": "Soil_Dirt"
    },
    {
      "x": 9,
      "y": 0,
      "z": 8,
      "name": "Soil_Dirt"
    },
    {
      "x": 10,
      "y": 0,
      "z": 8,
      "name": "Soil_Dirt"
    },
    {
      "x": 11,
      "y": 0,
      "z": 8,
      "name": "Soil_Dirt"
    },
    {
      "x": 12,
      "y": 0,
      "z": 8,
      "name": "Soil_Dirt"
    },
    {
      "x": 13,
      "y": 0,
      "z": 8,
      "name": "Soil_Dirt"
    },
    {
      "x": 14,
      "y": 0,
      "z": 8,
      "name": "Soil_Dirt"
    },
    {
      "x": 15,
      "y": 0,
      "z": 8,
      "name": "Soil_Dirt"
    },
    {
      "x": 16,
      "y": 0,
      "z": 8,
      "name": "Soil_Dirt"
    },
    {
      "x": 0,
      "y": 0,
      "z": 9,
      "name": "Soil_Dirt"
    },
    {
      "x": 1,
      "y": 0,
      "z": 9,
      "name": "Soil_Dirt"
    },
    {
      "x": 2,
      "y": 0,
      "z": 9,
      "name": "Soil_Dirt"
    },
    {
      "x": 3,
      "y": 0,
      "z": 9,
      "name": "Soil_Dirt"
    },
    {
      "x": 4,
      "y": 0,
      "z": 9,
      "name": "Soil_Dirt"
    },
    {
      "x": 5,
      "y": 0,
      "z": 9,
      "name": "Soil_Dirt"
    },
    {
      "x": 6,
      "y": 0,
      "z": 9,
      "name": "Soil_Dirt"
    },
    {
      "x": 7,
      "y": 0,
      "z": 9,
      "name": "Soil_Dirt"
    },
    {
      "x": 8,
      "y": 0,
      "z": 9,
      "name": "Soil_Dirt"
    },
    {
      "x": 9,
      "y": 0,
      "z": 9,
      "name": "Soil_Dirt"
    },
    {
      "x": 10,
      "y": 0,
      "z": 9,
      "name": "Soil_Dirt"
    },
    {
      "x": 11,
      "y": 0,
      "z": 9,
      "name": "Soil_Dirt"
    },
    {
      "x": 12,
      "y": 0,
      "z": 9,
      "name": "Soil_Dirt"
    },
    {
      "x": 13,
      "y": 0,
      "z": 9,
      "name": "Soil_Dirt"
    },
    {
      "x": 14,
      "y": 0,
      "z": 9,
      "name": "Soil_Dirt"
    },
    {
      "x": 15,
      "y": 0,
      "z": 9,
      "name": "Soil_Dirt"
    },
    {
      "x": 16,
      "y": 0,
      "z": 9,
      "name": "Soil_Dirt"
    },
    {
      "x": 0,
      "y": 0,
      "z": 10,
      "name": "Soil_Dirt"
    },
    {
      "x": 1,
      "y": 0,
      "z": 10,
      "name": "Soil_Dirt"
    },
    {
      "x": 2,
      "y": 0,
      "z": 10,
      "name": "Soil_Dirt"
    },
    {
      "x": 3,
      "y": 0,
      "z": 10,
      "name": "Soil_Dirt"
    },
    {
      "x": 4,
      "y": 0,
      "z": 10,
      "name": "Soil_Dirt"
    },
    {
      "x": 5,
      "y": 0,
      "z": 10,
      "name": "Soil_Dirt"
    },
    {
      "x": 6,
      "y": 0,
      "z": 10,
      "name": "Soil_Dirt"
    },
    {
      "x": 7,
      "y": 0,
      "z": 10,
      "name": "Soil_Dirt"
    },
    {
      "x": 8,
      "y": 0,
      "z": 10,
      "name": "Soil_Dirt"
    },
    {
      "x": 9,
      "y": 0,
      "z": 10,
      "name": "Soil_Dirt"
    },
    {
      "x": 10,
      "y": 0,
      "z": 10,
      "name": "Soil_Dirt"
    },
    {
      "x": 11,
      "y": 0,
      "z": 10,
      "name": "Soil_Dirt"
    },
    {
      "x": 12,
      "y": 0,
      "z": 10,
      "name": "Soil_Dirt"
    },
    {
      "x": 13,
      "y": 0,
      "z": 10,
      "name": "Soil_Dirt"
    },
    {
      "x": 14,
      "y": 0,
      "z": 10,
      "name": "Soil_Dirt"
    },
    {
      "x": 15,
      "y": 0,
      "z": 10,
      "name": "Soil_Dirt"
    },
    {
      "x": 16,
      "y": 0,
      "z": 10,
      "name": "Soil_Dirt"
    },
    {
      "x": 0,
      "y": 0,
      "z": 11,
      "name": "Soil_Dirt"
    },
    {
      "x": 1,
      "y": 0,
      "z": 11,
      "name": "Soil_Dirt"
    },
    {
      "x": 2,
      "y": 0,
      "z": 11,
      "name": "Soil_Dirt"
    },
    {
      "x": 3,
      "y": 0,
      "z": 11,
      "name": "Soil_Dirt"
    },
    {
      "x": 4,
      "y": 0,
      "z": 11,
      "name": "Soil_Dirt"
    },
    {
      "x": 5,
      "y": 0,
      "z": 11,
      "name": "Soil_Dirt"
    },
    {
      "x": 6,
      "y": 0,
      "z": 11,
      "name": "Soil_Dirt"
    },
    {
      "x": 7,
      "y": 0,
      "z": 11,
      "name": "Soil_Dirt"
    },
    {
      "x": 8,
      "y": 0,
      "z": 11,
      "name": "Soil_Dirt"
    },
    {
      "x": 9,
      "y": 0,
      "z": 11,
      "name": "Soil_Dirt"
    },
    {
      "x": 10,
      "y": 0,
      "z": 11,
      "name": "Soil_Dirt"
    },
    {
      "x": 11,
      "y": 0,
      "z": 11,
      "name": "Soil_Dirt"
    },
    {
      "x": 12,
      "y": 0,
      "z": 11,
      "name": "Soil_Dirt"
    },
    {
      "x": 13,
      "y": 0,
      "z": 11,
      "name": "Soil_Dirt"
    },
    {
      "x": 14,
      "y": 0,
      "z": 11,
      "name": "Soil_Dirt"
    },
    {
      "x": 15,
      "y": 0,
      "z": 11,
      "name": "Soil_Dirt"
    },
    {
      "x": 16,
      "y": 0,
      "z": 11,
      "name": "Soil_Dirt"
    },
    {
      "x": 0,
      "y": 0,
      "z": 12,
      "name": "Soil_Dirt"
    },
    {
      "x": 1,
      "y": 0,
      "z": 12,
      "name": "Soil_Dirt"
    },
    {
      "x": 2,
      "y": 0,
      "z": 12,
      "name": "Soil_Dirt"
    },
    {
      "x": 3,
      "y": 0,
      "z": 12,
      "name": "Soil_Dirt"
    },
    {
      "x": 4,
      "y": 0,
      "z": 12,
      "name": "Soil_Dirt"
    },
    {
      "x": 5,
      "y": 0,
      "z": 12,
      "name": "Soil_Dirt"
    },
    {
      "x": 6,
      "y": 0,
      "z": 12,
      "name": "Soil_Dirt"
    },
    {
      "x": 7,
      "y": 0,
      "z": 12,
      "name": "Soil_Dirt"
    },
    {
      "x": 8,
      "y": 0,
      "z": 12,
      "name": "Soil_Dirt"
    },
    {
      "x": 9,
      "y": 0,
      "z": 12,
      "name": "Soil_Dirt"
    },
    {
      "x": 10,
      "y": 0,
      "z": 12,
      "name": "Soil_Dirt"
    },
    {
      "x": 11,
      "y": 0,
      "z": 12,
      "name": "Soil_Dirt"
    },
    {
      "x": 12,
      "y": 0,
      "z": 12,
      "name": "Soil_Dirt"
    },
    {
      "x": 13,
      "y": 0,
      "z": 12,
      "name": "Soil_Dirt"
    },
    {
      "x": 14,
      "y": 0,
      "z": 12,
      "name": "Soil_Dirt"
    },
    {
      "x": 15,
      "y": 0,
      "z": 12,
      "name": "Soil_Dirt"
    },
    {
      "x": 16,
      "y": 0,
      "z": 12,
      "name": "Soil_Dirt"
    },
    {
      "x": 0,
      "y": 0,
      "z": 13,
      "name": "Soil_Dirt"
    },
    {
      "x": 1,
      "y": 0,
      "z": 13,
      "name": "Soil_Dirt"
    },
    {
      "x": 2,
      "y": 0,
      "z": 13,
      "name": "Soil_Dirt"
    },
    {
      "x": 3,
      "y": 0,
      "z": 13,
      "name": "Soil_Dirt"
    },
    {
      "x": 4,
      "y": 0,
      "z": 13,
      "name": "Soil_Dirt"
    },
    {
      "x": 5,
      "y": 0,
      "z": 13,
      "name": "Soil_Dirt"
    },
    {
      "x": 6,
      "y": 0,
      "z": 13,
      "name": "Soil_Dirt"
    },
    {
      "x": 7,
      "y": 0,
      "z": 13,
      "name": "Soil_Dirt"
    },
    {
      "x": 8,
      "y": 0,
      "z": 13,
      "name": "Soil_Dirt"
    },
    {
      "x": 9,
      "y": 0,
      "z": 13,
      "name": "Soil_Dirt"
    },
    {
      "x": 10,
      "y": 0,
      "z": 13,
      "name": "Soil_Dirt"
    },
    {
      "x": 11,
      "y": 0,
      "z": 13,
      "name": "Soil_Dirt"
    },
    {
      "x": 12,
      "y": 0,
      "z": 13,
      "name": "Soil_Dirt"
    },
    {
      "x": 13,
      "y": 0,
      "z": 13,
      "name": "Soil_Dirt"
    },
    {
      "x": 14,
      "y": 0,
      "z": 13,
      "name": "Soil_Dirt"
    },
    {
      "x": 15,
      "y": 0,
      "z": 13,
      "name": "Soil_Dirt"
    },
    {
      "x": 16,
      "y": 0,
      "z": 13,
      "name": "Soil_Dirt"
    },
    {
      "x": 0,
      "y": 0,
      "z": 14,
      "name": "Soil_Dirt"
    },
    {
      "x": 1,
      "y": 0,
      "z": 14,
      "name": "Soil_Dirt"
    },
    {
      "x": 2,
      "y": 0,
      "z": 14,
      "name": "Soil_Dirt"
    },
    {
      "x": 3,
      "y": 0,
      "z": 14,
      "name": "Soil_Dirt"
    },
    {
      "x": 4,
      "y": 0,
      "z": 14,
      "name": "Soil_Dirt"
    },
    {
      "x": 5,
      "y": 0,
      "z": 14,
      "name": "Soil_Dirt"
    },
    {
      "x": 6,
      "y": 0,
      "z": 14,
      "name": "Soil_Dirt"
    },
    {
      "x": 7,
      "y": 0,
      "z": 14,
      "name": "Soil_Dirt"
    },
    {
      "x": 8,
      "y": 0,
      "z": 14,
      "name": "Soil_Dirt"
    },
    {
      "x": 9,
      "y": 0,
      "z": 14,
      "name": "Soil_Dirt"
    },
    {
      "x": 10,
      "y": 0,
      "z": 14,
      "name": "Soil_Dirt"
    },
    {
      "x": 11,
      "y": 0,
      "z": 14,
      "name": "Soil_Dirt"
    },
    {
      "x": 12,
      "y": 0,
      "z": 14,
      "name": "Soil_Dirt"
    },
    {
      "x": 13,
      "y": 0,
      "z": 14,
      "name": "Soil_Dirt"
    },
    {
      "x": 14,
      "y": 0,
      "z": 14,
      "name": "Soil_Dirt"
    },
    {
      "x": 15,
      "y": 0,
      "z": 14,
      "name": "Soil_Dirt"
    },
    {
      "x": 16,
      "y": 0,
      "z": 14,
      "name": "Soil_Dirt"
    },
    {
      "x": 0,
      "y": 0,
      "z": 15,
      "name": "Soil_Dirt"
    },
    {
      "x": 1,
      "y": 0,
      "z": 15,
      "name": "Soil_Dirt"
    },
    {
      "x": 2,
      "y": 0,
      "z": 15,
      "name": "Soil_Dirt"
    },
    {
      "x": 3,
      "y": 0,
      "z": 15,
      "name": "Soil_Dirt"
    },
    {
      "x": 4,
      "y": 0,
      "z": 15,
      "name": "Soil_Dirt"
    },
    {
      "x": 5,
      "y": 0,
      "z": 15,
      "name": "Soil_Dirt"
    },
    {
      "x": 6,
      "y": 0,
      "z": 15,
      "name": "Soil_Dirt"
    },
    {
      "x": 7,
      "y": 0,
      "z": 15,
      "name": "Soil_Dirt"
    },
    {
      "x": 8,
      "y": 0,
      "z": 15,
      "name": "Soil_Dirt"
    },
    {
      "x": 9,
      "y": 0,
      "z": 15,
      "name": "Soil_Dirt"
    },
    {
      "x": 10,
      "y": 0,
      "z": 15,
      "name": "Soil_Dirt"
    },
    {
      "x": 11,
      "y": 0,
      "z": 15,
      "name": "Soil_Dirt"
    },
    {
      "x": 12,
      "y": 0,
      "z": 15,
      "name": "Soil_Dirt"
    },
    {
      "x": 13,
      "y": 0,
      "z": 15,
      "name": "Soil_Dirt"
    },
    {
      "x": 14,
      "y": 0,
      "z": 15,
      "name": "Soil_Dirt"
    },
    {
      "x": 15,
      "y": 0,
      "z": 15,
      "name": "Soil_Dirt"
    },
    {
      "x": 16,
      "y": 0,
      "z": 15,
      "name": "Soil_Dirt"
    },
    {
      "x": 0,
      "y": 0,
      "z": 16,
      "name": "Soil_Dirt"
    },
    {
      "x": 1,
      "y": 0,
      "z": 16,
      "name": "Soil_Dirt"
    },
    {
      "x": 2,
      "y": 0,
      "z": 16,
      "name": "Soil_Dirt"
    },
    {
      "x": 3,
      "y": 0,
      "z": 16,
      "name": "Soil_Dirt"
    },
    {
      "x": 4,
      "y": 0,
      "z": 16,
      "name": "Soil_Dirt"
    },
    {
      "x": 5,
      "y": 0,
      "z": 16,
      "name": "Soil_Dirt"
    },
    {
      "x": 6,
      "y": 0,
      "z": 16,
      "name": "Soil_Dirt"
    },
    {
      "x": 7,
      "y": 0,
      "z": 16,
      "name": "Soil_Dirt"
    },
    {
      "x": 8,
      "y": 0,
      "z": 16,
      "name": "Soil_Dirt"
    },
    {
      "x": 9,
      "y": 0,
      "z": 16,
      "name": "Soil_Dirt"
    },
    {
      "x": 10,
      "y": 0,
      "z": 16,
      "name": "Soil_Dirt"
    },
    {
      "x": 11,
      "y": 0,
      "z": 16,
      "name": "Soil_Dirt"
    },
    {
      "x": 12,
      "y": 0,
      "z": 16,
      "name": "Soil_Dirt"
    },
    {
      "x": 13,
      "y": 0,
      "z": 16,
      "name": "Soil_Dirt"
    },
    {
      "x": 14,
      "y": 0,
      "z": 16,
      "name": "Soil_Dirt"
    },
    {
      "x": 15,
      "y": 0,
      "z": 16,
      "name": "Soil_Dirt"
    },
    {
      "x": 16,
      "y": 0,
      "z": 16,
      "name": "Soil_Dirt"
    },
    {
      "x": 0,
      "y": 0,
      "z": 17,
      "name": "Soil_Dirt"
    },
    {
      "x": 1,
      "y": 0,
      "z": 17,
      "name": "Soil_Dirt"
    },
    {
      "x": 2,
      "y": 0,
      "z": 17,
      "name": "Soil_Dirt"
    },
    {
      "x": 3,
      "y": 0,
      "z": 17,
      "name": "Soil_Dirt"
    },
    {
      "x": 4,
      "y": 0,
      "z": 17,
      "name": "Soil_Dirt"
    },
    {
      "x": 5,
      "y": 0,
      "z": 17,
      "name": "Soil_Dirt"
    },
    {
      "x": 6,
      "y": 0,
      "z": 17,
      "name": "Soil_Dirt"
    },
    {
      "x": 7,
      "y": 0,
      "z": 17,
      "name": "Soil_Dirt"
    },
    {
      "x": 8,
      "y": 0,
      "z": 17,
      "name": "Soil_Dirt"
    },
    {
      "x": 9,
      "y": 0,
      "z": 17,
      "name": "Soil_Dirt"
    },
    {
      "x": 10,
      "y": 0,
      "z": 17,
      "name": "Soil_Dirt"
    },
    {
      "x": 11,
      "y": 0,
      "z": 17,
      "name": "Soil_Dirt"
    },
    {
      "x": 12,
      "y": 0,
      "z": 17,
      "name": "Soil_Dirt"
    },
    {
      "x": 13,
      "y": 0,
      "z": 17,
      "name": "Soil_Dirt"
    },
    {
      "x": 14,
      "y": 0,
      "z": 17,
      "name": "Soil_Dirt"
    },
    {
      "x": 15,
      "y": 0,
      "z": 17,
      "name": "Soil_Dirt"
    },
    {
      "x": 16,
      "y": 0,
      "z": 17,
      "name": "Soil_Dirt"
    },
    {
      "x": 0,
      "y": 0,
      "z": 18,
      "name": "Soil_Dirt"
    },
    {
      "x": 1,
      "y": 0,
      "z": 18,
      "name": "Soil_Dirt"
    },
    {
      "x": 2,
      "y": 0,
      "z": 18,
      "name": "Soil_Dirt"
    },
    {
      "x": 3,
      "y": 0,
      "z": 18,
      "name": "Soil_Dirt"
    },
    {
      "x": 4,
      "y": 0,
      "z": 18,
      "name": "Soil_Dirt"
    },
    {
      "x": 5,
      "y": 0,
      "z": 18,
      "name": "Soil_Dirt"
    },
    {
      "x": 6,
      "y": 0,
      "z": 18,
      "name": "Soil_Dirt"
    },
    {
      "x": 7,
      "y": 0,
      "z": 18,
      "name": "Soil_Dirt"
    },
    {
      "x": 8,
      "y": 0,
      "z": 18,
      "name": "Soil_Dirt"
    },
    {
      "x": 9,
      "y": 0,
      "z": 18,
      "name": "Soil_Dirt"
    },
    {
      "x": 10,
      "y": 0,
      "z": 18,
      "name": "Soil_Dirt"
    },
    {
      "x": 11,
      "y": 0,
      "z": 18,
      "name": "Soil_Dirt"
    },
    {
      "x": 12,
      "y": 0,
      "z": 18,
      "name": "Soil_Dirt"
    },
    {
      "x": 13,
      "y": 0,
      "z": 18,
      "name": "Soil_Dirt"
    },
    {
      "x": 14,
      "y": 0,
      "z": 18,
      "name": "Soil_Dirt"
    },
    {
      "x": 15,
      "y": 0,
      "z": 18,
      "name": "Soil_Dirt"
    },
    {
      "x": 16,
      "y": 0,
      "z": 18,
      "name": "Soil_Dirt"
    },
    {
      "x": 0,
      "y": 0,
      "z": 19,
      "name": "Soil_Dirt"
    },
    {
      "x": 1,
      "y": 0,
      "z": 19,
      "name": "Soil_Dirt"
    },
    {
      "x": 2,
      "y": 0,
      "z": 19,
      "name": "Soil_Dirt"
    },
    {
      "x": 3,
      "y": 0,
      "z": 19,
      "name": "Soil_Dirt"
    },
    {
      "x": 4,
      "y": 0,
      "z": 19,
      "name": "Soil_Dirt"
    },
    {
      "x": 5,
      "y": 0,
      "z": 19,
      "name": "Soil_Dirt"
    },
    {
      "x": 6,
      "y": 0,
      "z": 19,
      "name": "Soil_Dirt"
    },
    {
      "x": 7,
      "y": 0,
      "z": 19,
      "name": "Soil_Dirt"
    },
    {
      "x": 8,
      "y": 0,
      "z": 19,
      "name": "Soil_Dirt"
    },
    {
      "x": 9,
      "y": 0,
      "z": 19,
      "name": "Soil_Dirt"
    },
    {
      "x": 10,
      "y": 0,
      "z": 19,
      "name": "Soil_Dirt"
    },
    {
      "x": 11,
      "y": 0,
      "z": 19,
      "name": "Soil_Dirt"
    },
    {
      "x": 12,
      "y": 0,
      "z": 19,
      "name": "Soil_Dirt"
    },
    {
      "x": 13,
      "y": 0,
      "z": 19,
      "name": "Soil_Dirt"
    },
    {
      "x": 14,
      "y": 0,
      "z": 19,
      "name": "Soil_Dirt"
    },
    {
      "x": 15,
      "y": 0,
      "z": 19,
      "name": "Soil_Dirt"
    },
    {
      "x": 16,
      "y": 0,
      "z": 19,
      "name": "Soil_Dirt"
    },
    {
      "x": 0,
      "y": 0,
      "z": 20,
      "name": "Soil_Dirt"
    },
    {
      "x": 1,
      "y": 0,
      "z": 20,
      "name": "Soil_Dirt"
    },
    {
      "x": 2,
      "y": 0,
      "z": 20,
      "name": "Soil_Dirt"
    },
    {
      "x": 3,
      "y": 0,
      "z": 20,
      "name": "Soil_Dirt"
    },
    {
      "x": 4,
      "y": 0,
      "z": 20,
      "name": "Soil_Dirt"
    },
    {
      "x": 5,
      "y": 0,
      "z": 20,
      "name": "Soil_Dirt"
    },
    {
      "x": 6,
      "y": 0,
      "z": 20,
      "name": "Soil_Dirt"
    },
    {
      "x": 7,
      "y": 0,
      "z": 20,
      "name": "Soil_Dirt"
    },
    {
      "x": 8,
      "y": 0,
      "z": 20,
      "name": "Soil_Dirt"
    },
    {
      "x": 9,
      "y": 0,
      "z": 20,
      "name": "Soil_Dirt"
    },
    {
      "x": 10,
      "y": 0,
      "z": 20,
      "name": "Soil_Dirt"
    },
    {
      "x": 11,
      "y": 0,
      "z": 20,
      "name": "Soil_Dirt"
    },
    {
      "x": 12,
      "y": 0,
      "z": 20,
      "name": "Soil_Dirt"
    },
    {
      "x": 13,
      "y": 0,
      "z": 20,
      "name": "Soil_Dirt"
    },
    {
      "x": 14,
      "y": 0,
      "z": 20,
      "name": "Soil_Dirt"
    },
    {
      "x": 15,
      "y": 0,
      "z": 20,
      "name": "Soil_Dirt"
    },
    {
      "x": 16,
      "y": 0,
      "z": 20,
      "name": "Soil_Dirt"
    },
    {
      "x": 0,
      "y": 0,
      "z": 21,
      "name": "Soil_Dirt"
    },
    {
      "x": 1,
      "y": 0,
      "z": 21,
      "name": "Soil_Dirt"
    },
    {
      "x": 2,
      "y": 0,
      "z": 21,
      "name": "Soil_Dirt"
    },
    {
      "x": 3,
      "y": 0,
      "z": 21,
      "name": "Soil_Dirt"
    },
    {
      "x": 4,
      "y": 0,
      "z": 21,
      "name": "Soil_Dirt"
    },
    {
      "x": 5,
      "y": 0,
      "z": 21,
      "name": "Soil_Dirt"
    },
    {
      "x": 6,
      "y": 0,
      "z": 21,
      "name": "Soil_Dirt"
    },
    {
      "x": 7,
      "y": 0,
      "z": 21,
      "name": "Soil_Dirt"
    },
    {
      "x": 8,
      "y": 0,
      "z": 21,
      "name": "Soil_Dirt"
    },
    {
      "x": 9,
      "y": 0,
      "z": 21,
      "name": "Soil_Dirt"
    },
    {
      "x": 10,
      "y": 0,
      "z": 21,
      "name": "Soil_Dirt"
    },
    {
      "x": 11,
      "y": 0,
      "z": 21,
      "name": "Soil_Dirt"
    },
    {
      "x": 12,
      "y": 0,
      "z": 21,
      "name": "Soil_Dirt"
    },
    {
      "x": 13,
      "y": 0,
      "z": 21,
      "name": "Soil_Dirt"
    },
    {
      "x": 14,
      "y": 0,
      "z": 21,
      "name": "Soil_Dirt"
    },
    {
      "x": 15,
      "y": 0,
      "z": 21,
      "name": "Soil_Dirt"
    },
    {
      "x": 16,
      "y": 0,
      "z": 21,
      "name": "Soil_Dirt"
    },
    {
      "x": 0,
      "y": 0,
      "z": 22,
      "name": "Soil_Dirt"
    },
    {
      "x": 1,
      "y": 0,
      "z": 22,
      "name": "Soil_Dirt"
    },
    {
      "x": 2,
      "y": 0,
      "z": 22,
      "name": "Soil_Dirt"
    },
    {
      "x": 3,
      "y": 0,
      "z": 22,
      "name": "Soil_Dirt"
    },
    {
      "x": 4,
      "y": 0,
      "z": 22,
      "name": "Soil_Dirt"
    },
    {
      "x": 5,
      "y": 0,
      "z": 22,
      "name": "Soil_Dirt"
    },
    {
      "x": 6,
      "y": 0,
      "z": 22,
      "name": "Soil_Dirt"
    },
    {
      "x": 7,
      "y": 0,
      "z": 22,
      "name": "Soil_Dirt"
    },
    {
      "x": 8,
      "y": 0,
      "z": 22,
      "name": "Soil_Dirt"
    },
    {
      "x": 9,
      "y": 0,
      "z": 22,
      "name": "Soil_Dirt"
    },
    {
      "x": 10,
      "y": 0,
      "z": 22,
      "name": "Soil_Dirt"
    },
    {
      "x": 11,
      "y": 0,
      "z": 22,
      "name": "Soil_Dirt"
    },
    {
      "x": 12,
      "y": 0,
      "z": 22,
      "name": "Soil_Dirt"
    },
    {
      "x": 13,
      "y": 0,
      "z": 22,
      "name": "Soil_Dirt"
    },
    {
      "x": 14,
      "y": 0,
      "z": 22,
      "name": "Soil_Dirt"
    },
    {
      "x": 15,
      "y": 0,
      "z": 22,
      "name": "Soil_Dirt"
    },
    {
      "x": 16,
      "y": 0,
      "z": 22,
      "name": "Soil_Dirt"
    },
    {
      "x": 0,
      "y": 1,
      "z": 0,
      "name": "Soil_Grass"
    },
    {
      "x": 1,
      "y": 1,
      "z": 0,
      "name": "Soil_Grass"
    },
    {
      "x": 2,
      "y": 1,
      "z": 0,
      "name": "Soil_Grass"
    },
    {
      "x": 3,
      "y": 1,
      "z": 0,
      "name": "Soil_Grass"
    },
    {
      "x": 4,
      "y": 1,
      "z": 0,
      "name": "Soil_Dirt_Burnt"
    },
    {
      "x": 5,
      "y": 1,
      "z": 0,
      "name": "Soil_Dirt_Burnt"
    },
    {
      "x": 6,
      "y": 1,
      "z": 0,
      "name": "Soil_Pathway"
    },
    {
      "x": 7,
      "y": 1,
      "z": 0,
      "name": "Soil_Pathway"
    },
    {
      "x": 8,
      "y": 1,
      "z": 0,
      "name": "Soil_Pathway"
    },
    {
      "x": 9,
      "y": 1,
      "z": 0,
      "name": "Soil_Grass"
    },
    {
      "x": 10,
      "y": 1,
      "z": 0,
      "name": "Soil_Dirt_Burnt"
    },
    {
      "x": 11,
      "y": 1,
      "z": 0,
      "name": "Soil_Grass"
    },
    {
      "x": 12,
      "y": 1,
      "z": 0,
      "name": "Soil_Grass"
    },
    {
      "x": 14,
      "y": 1,
      "z": 0,
      "name": "Soil_Grass"
    },
    {
      "x": 15,
      "y": 1,
      "z": 0,
      "name": "Soil_Grass"
    },
    {
      "x": 0,
      "y": 1,
      "z": 1,
      "name": "Soil_Grass"
    },
    {
      "x": 1,
      "y": 1,
      "z": 1,
      "name": "Soil_Grass"
    },
    {
      "x": 2,
      "y": 1,
      "z": 1,
      "name": "Soil_Grass"
    },
    {
      "x": 3,
      "y": 1,
      "z": 1,
      "name": "Soil_Grass"
    },
    {
      "x": 4,
      "y": 1,
      "z": 1,
      "name": "Rock_Stone_Cobble_Mossy_Half"
    },
    {
      "x": 5,
      "y": 1,
      "z": 1,
      "name": "Soil_Grass"
    },
    {
      "x": 6,
      "y": 1,
      "z": 1,
      "name": "Soil_Dirt_Burnt"
    },
    {
      "x": 7,
      "y": 1,
      "z": 1,
      "name": "Soil_Pathway"
    },
    {
      "x": 8,
      "y": 1,
      "z": 1,
      "name": "Soil_Pathway"
    },
    {
      "x": 9,
      "y": 1,
      "z": 1,
      "name": "Soil_Grass"
    },
    {
      "x": 10,
      "y": 1,
      "z": 1,
      "name": "Rock_Stone_Cobble_Mossy_Half"
    },
    {
      "x": 11,
      "y": 1,
      "z": 1,
      "name": "Rock_Stone_Cobble_Mossy_Half"
    },
    {
      "x": 12,
      "y": 1,
      "z": 1,
      "name": "Soil_Grass"
    },
    {
      "x": 13,
      "y": 1,
      "z": 1,
      "name": "Soil_Dirt"
    },
    {
      "x": 15,
      "y": 1,
      "z": 1,
      "name": "Soil_Grass"
    },
    {
      "x": 16,
      "y": 1,
      "z": 1,
      "name": "Soil_Grass"
    },
    {
      "x": 0,
      "y": 1,
      "z": 2,
      "name": "Soil_Dirt_Burnt"
    },
    {
      "x": 1,
      "y": 1,
      "z": 2,
      "name": "Soil_Grass"
    },
    {
      "x": 2,
      "y": 1,
      "z": 2,
      "name": "Soil_Dirt_Burnt"
    },
    {
      "x": 3,
      "y": 1,
      "z": 2,
      "name": "Rock_Stone_Cobble_Mossy_Half"
    },
    {
      "x": 4,
      "y": 1,
      "z": 2,
      "name": "Soil_Grass"
    },
    {
      "x": 5,
      "y": 1,
      "z": 2,
      "name": "Soil_Grass"
    },
    {
      "x": 6,
      "y": 1,
      "z": 2,
      "name": "Soil_Grass"
    },
    {
      "x": 7,
      "y": 1,
      "z": 2,
      "name": "Soil_Pathway"
    },
    {
      "x": 8,
      "y": 1,
      "z": 2,
      "name": "Soil_Pathway"
    },
    {
      "x": 9,
      "y": 1,
      "z": 2,
      "name": "Soil_Dirt_Burnt"
    },
    {
      "x": 10,
      "y": 1,
      "z": 2,
      "name": "Soil_Dirt_Burnt"
    },
    {
      "x": 11,
      "y": 1,
      "z": 2,
      "name": "Rock_Stone_Cobble_Mossy_Half"
    },
    {
      "x": 12,
      "y": 1,
      "z": 2,
      "name": "Soil_Grass"
    },
    {
      "x": 13,
      "y": 1,
      "z": 2,
      "name": "Soil_Grass"
    },
    {
      "x": 14,
      "y": 1,
      "z": 2,
      "name": "Soil_Grass"
    },
    {
      "x": 15,
      "y": 1,
      "z": 2,
      "name": "Soil_Grass"
    },
    {
      "x": 16,
      "y": 1,
      "z": 2,
      "name": "Soil_Grass"
    },
    {
      "x": 0,
      "y": 1,
      "z": 3,
      "name": "Soil_Grass"
    },
    {
      "x": 1,
      "y": 1,
      "z": 3,
      "name": "Soil_Grass"
    },
    {
      "x": 2,
      "y": 1,
      "z": 3,
      "name": "Soil_Dirt_Burnt"
    },
    {
      "x": 3,
      "y": 1,
      "z": 3,
      "name": "Soil_Dirt_Burnt"
    },
    {
      "x": 4,
      "y": 1,
      "z": 3,
      "name": "Soil_Grass"
    },
    {
      "x": 5,
      "y": 1,
      "z": 3,
      "name": "Soil_Dirt_Burnt"
    },
    {
      "x": 6,
      "y": 1,
      "z": 3,
      "name": "Soil_Dirt_Burnt"
    },
    {
      "x": 7,
      "y": 1,
      "z": 3,
      "name": "Soil_Dirt_Burnt"
    },
    {
      "x": 8,
      "y": 1,
      "z": 3,
      "name": "Soil_Dirt_Burnt"
    },
    {
      "x": 9,
      "y": 1,
      "z": 3,
      "name": "Soil_Dirt_Burnt"
    },
    {
      "x": 10,
      "y": 1,
      "z": 3,
      "name": "Soil_Dirt_Burnt"
    },
    {
      "x": 11,
      "y": 1,
      "z": 3,
      "name": "Soil_Dirt_Burnt"
    },
    {
      "x": 12,
      "y": 1,
      "z": 3,
      "name": "Soil_Grass"
    },
    {
      "x": 13,
      "y": 1,
      "z": 3,
      "name": "Soil_Dirt_Burnt"
    },
    {
      "x": 14,
      "y": 1,
      "z": 3,
      "name": "Soil_Dirt_Burnt"
    },
    {
      "x": 15,
      "y": 1,
      "z": 3,
      "name": "Soil_Dirt_Burnt"
    },
    {
      "x": 16,
      "y": 1,
      "z": 3,
      "name": "Soil_Grass"
    },
    {
      "x": 0,
      "y": 1,
      "z": 4,
      "name": "Soil_Dirt_Burnt"
    },
    {
      "x": 1,
      "y": 1,
      "z": 4,
      "name": "Soil_Dirt_Burnt"
    },
    {
      "x": 2,
      "y": 1,
      "z": 4,
      "name": "Wood_Oak_Trunk"
    },
    {
      "x": 3,
      "y": 1,
      "z": 4,
      "name": "Soil_Dirt_Burnt"
    },
    {
      "x": 4,
      "y": 1,
      "z": 4,
      "name": "Soil_Grass"
    },
    {
      "x": 5,
      "y": 1,
      "z": 4,
      "name": "Soil_Dirt_Burnt"
    },
    {
      "x": 6,
      "y": 1,
      "z": 4,
      "name": "Wood_Oak_Trunk"
    },
    {
      "x": 8,
      "y": 1,
      "z": 4,
      "name": "Soil_Dirt_Burnt"
    },
    {
      "x": 10,
      "y": 1,
      "z": 4,
      "name": "Wood_Oak_Trunk"
    },
    {
      "x": 11,
      "y": 1,
      "z": 4,
      "name": "Soil_Dirt_Burnt"
    },
    {
      "x": 12,
      "y": 1,
      "z": 4,
      "name": "Soil_Dirt_Burnt"
    },
    {
      "x": 13,
      "y": 1,
      "z": 4,
      "name": "Soil_Dirt_Burnt"
    },
    {
      "x": 14,
      "y": 1,
      "z": 4,
      "name": "Wood_Oak_Trunk"
    },
    {
      "x": 15,
      "y": 1,
      "z": 4,
      "name": "Soil_Dirt_Burnt"
    },
    {
      "x": 16,
      "y": 1,
      "z": 4,
      "name": "Soil_Grass"
    },
    {
      "x": 0,
      "y": 1,
      "z": 5,
      "name": "Soil_Grass"
    },
    {
      "x": 1,
      "y": 1,
      "z": 5,
      "name": "Wood_Oak_Trunk"
    },
    {
      "x": 2,
      "y": 1,
      "z": 5,
      "name": "Wood_Oak_Trunk"
    },
    {
      "x": 3,
      "y": 1,
      "z": 5,
      "name": "Cloth_Block_Wool_Cyan"
    },
    {
      "x": 4,
      "y": 1,
      "z": 5,
      "name": "Cloth_Block_Wool_White"
    },
    {
      "x": 5,
      "y": 1,
      "z": 5,
      "name": "Cloth_Block_Wool_Cyan"
    },
    {
      "x": 6,
      "y": 1,
      "z": 5,
      "name": "Wood_Oak_Trunk"
    },
    {
      "x": 7,
      "y": 1,
      "z": 5,
      "name": "Cloth_Block_Wool_Cyan"
    },
    {
      "x": 8,
      "y": 1,
      "z": 5,
      "name": "Cloth_Block_Wool_White"
    },
    {
      "x": 9,
      "y": 1,
      "z": 5,
      "name": "Cloth_Block_Wool_Cyan"
    },
    {
      "x": 10,
      "y": 1,
      "z": 5,
      "name": "Wood_Oak_Trunk"
    },
    {
      "x": 11,
      "y": 1,
      "z": 5,
      "name": "Cloth_Block_Wool_Cyan"
    },
    {
      "x": 12,
      "y": 1,
      "z": 5,
      "name": "Cloth_Block_Wool_White"
    },
    {
      "x": 13,
      "y": 1,
      "z": 5,
      "name": "Cloth_Block_Wool_Cyan"
    },
    {
      "x": 14,
      "y": 1,
      "z": 5,
      "name": "Wood_Oak_Trunk"
    },
    {
      "x": 15,
      "y": 1,
      "z": 5,
      "name": "Wood_Oak_Trunk"
    },
    {
      "x": 16,
      "y": 1,
      "z": 5,
      "name": "Soil_Dirt_Burnt"
    },
    {
      "x": 0,
      "y": 1,
      "z": 6,
      "name": "Soil_Dirt_Burnt"
    },
    {
      "x": 1,
      "y": 1,
      "z": 6,
      "name": "Soil_Dirt_Burnt"
    },
    {
      "x": 2,
      "y": 1,
      "z": 6,
      "name": "Cloth_Block_Wool_Cyan"
    },
    {
      "x": 3,
      "y": 1,
      "z": 6,
      "name": "Wood_Darkwood_Planks"
    },
    {
      "x": 4,
      "y": 1,
      "z": 6,
      "name": "Wood_Darkwood_Planks"
    },
    {
      "x": 5,
      "y": 1,
      "z": 6,
      "name": "Wood_Darkwood_Planks"
    },
    {
      "x": 6,
      "y": 1,
      "z": 6,
      "name": "Wood_Darkwood_Planks"
    },
    {
      "x": 7,
      "y": 1,
      "z": 6,
      "name": "Wood_Darkwood_Planks"
    },
    {
      "x": 8,
      "y": 1,
      "z": 6,
      "name": "Wood_Darkwood_Planks"
    },
    {
      "x": 9,
      "y": 1,
      "z": 6,
      "name": "Wood_Darkwood_Planks"
    },
    {
      "x": 10,
      "y": 1,
      "z": 6,
      "name": "Wood_Darkwood_Planks"
    },
    {
      "x": 11,
      "y": 1,
      "z": 6,
      "name": "Wood_Darkwood_Planks"
    },
    {
      "x": 12,
      "y": 1,
      "z": 6,
      "name": "Wood_Darkwood_Planks"
    },
    {
      "x": 13,
      "y": 1,
      "z": 6,
      "name": "Wood_Darkwood_Planks"
    },
    {
      "x": 14,
      "y": 1,
      "z": 6,
      "name": "Cloth_Block_Wool_Cyan"
    },
    {
      "x": 15,
      "y": 1,
      "z": 6,
      "name": "Soil_Dirt_Burnt"
    },
    {
      "x": 16,
      "y": 1,
      "z": 6,
      "name": "Soil_Dirt_Burnt"
    },
    {
      "x": 0,
      "y": 1,
      "z": 7,
      "name": "Soil_Grass"
    },
    {
      "x": 1,
      "y": 1,
      "z": 7,
      "name": "Soil_Grass"
    },
    {
      "x": 2,
      "y": 1,
      "z": 7,
      "name": "Cloth_Block_Wool_White"
    },
    {
      "x": 3,
      "y": 1,
      "z": 7,
      "name": "Wood_Darkwood_Planks"
    },
    {
      "x": 4,
      "y": 1,
      "z": 7,
      "name": "Wood_Darkwood_Planks"
    },
    {
      "x": 5,
      "y": 1,
      "z": 7,
      "name": "Wood_Darkwood_Planks"
    },
    {
      "x": 6,
      "y": 1,
      "z": 7,
      "name": "Wood_Darkwood_Planks"
    },
    {
      "x": 7,
      "y": 1,
      "z": 7,
      "name": "Wood_Darkwood_Planks"
    },
    {
      "x": 8,
      "y": 1,
      "z": 7,
      "name": "Wood_Darkwood_Planks"
    },
    {
      "x": 9,
      "y": 1,
      "z": 7,
      "name": "Wood_Darkwood_Planks"
    },
    {
      "x": 10,
      "y": 1,
      "z": 7,
      "name": "Wood_Darkwood_Planks"
    },
    {
      "x": 11,
      "y": 1,
      "z": 7,
      "name": "Wood_Darkwood_Planks"
    },
    {
      "x": 12,
      "y": 1,
      "z": 7,
      "name": "Wood_Darkwood_Planks"
    },
    {
      "x": 13,
      "y": 1,
      "z": 7,
      "name": "Wood_Darkwood_Planks"
    },
    {
      "x": 14,
      "y": 1,
      "z": 7,
      "name": "Cloth_Block_Wool_White"
    },
    {
      "x": 15,
      "y": 1,
      "z": 7,
      "name": "Soil_Dirt_Burnt"
    },
    {
      "x": 16,
      "y": 1,
      "z": 7,
      "name": "Soil_Dirt_Burnt"
    },
    {
      "x": 0,
      "y": 1,
      "z": 8,
      "name": "Soil_Dirt_Burnt"
    },
    {
      "x": 1,
      "y": 1,
      "z": 8,
      "name": "Soil_Grass"
    },
    {
      "x": 2,
      "y": 1,
      "z": 8,
      "name": "Cloth_Block_Wool_Cyan"
    },
    {
      "x": 3,
      "y": 1,
      "z": 8,
      "name": "Wood_Darkwood_Planks"
    },
    {
      "x": 4,
      "y": 1,
      "z": 8,
      "name": "Wood_Darkwood_Planks"
    },
    {
      "x": 5,
      "y": 1,
      "z": 8,
      "name": "Wood_Darkwood_Planks"
    },
    {
      "x": 6,
      "y": 1,
      "z": 8,
      "name": "Wood_Darkwood_Planks"
    },
    {
      "x": 7,
      "y": 1,
      "z": 8,
      "name": "Wood_Darkwood_Planks"
    },
    {
      "x": 8,
      "y": 1,
      "z": 8,
      "name": "Wood_Darkwood_Planks"
    },
    {
      "x": 9,
      "y": 1,
      "z": 8,
      "name": "Wood_Darkwood_Planks"
    },
    {
      "x": 10,
      "y": 1,
      "z": 8,
      "name": "Wood_Darkwood_Planks"
    },
    {
      "x": 11,
      "y": 1,
      "z": 8,
      "name": "Wood_Darkwood_Planks"
    },
    {
      "x": 12,
      "y": 1,
      "z": 8,
      "name": "Wood_Darkwood_Planks"
    },
    {
      "x": 13,
      "y": 1,
      "z": 8,
      "name": "Wood_Darkwood_Planks"
    },
    {
      "x": 14,
      "y": 1,
      "z": 8,
      "name": "Cloth_Block_Wool_Cyan"
    },
    {
      "x": 15,
      "y": 1,
      "z": 8,
      "name": "Soil_Dirt_Burnt"
    },
    {
      "x": 16,
      "y": 1,
      "z": 8,
      "name": "Soil_Dirt_Burnt"
    },
    {
      "x": 0,
      "y": 1,
      "z": 9,
      "name": "Soil_Grass"
    },
    {
      "x": 1,
      "y": 1,
      "z": 9,
      "name": "Wood_Oak_Trunk"
    },
    {
      "x": 2,
      "y": 1,
      "z": 9,
      "name": "Wood_Oak_Trunk"
    },
    {
      "x": 3,
      "y": 1,
      "z": 9,
      "name": "Wood_Darkwood_Planks"
    },
    {
      "x": 4,
      "y": 1,
      "z": 9,
      "name": "Wood_Darkwood_Planks"
    },
    {
      "x": 5,
      "y": 1,
      "z": 9,
      "name": "Wood_Darkwood_Planks"
    },
    {
      "x": 6,
      "y": 1,
      "z": 9,
      "name": "Wood_Darkwood_Planks"
    },
    {
      "x": 7,
      "y": 1,
      "z": 9,
      "name": "Wood_Darkwood_Planks"
    },
    {
      "x": 8,
      "y": 1,
      "z": 9,
      "name": "Wood_Darkwood_Planks"
    },
    {
      "x": 9,
      "y": 1,
      "z": 9,
      "name": "Wood_Darkwood_Planks"
    },
    {
      "x": 10,
      "y": 1,
      "z": 9,
      "name": "Wood_Darkwood_Planks"
    },
    {
      "x": 11,
      "y": 1,
      "z": 9,
      "name": "Wood_Darkwood_Planks"
    },
    {
      "x": 12,
      "y": 1,
      "z": 9,
      "name": "Wood_Darkwood_Planks"
    },
    {
      "x": 13,
      "y": 1,
      "z": 9,
      "name": "Wood_Darkwood_Planks"
    },
    {
      "x": 14,
      "y": 1,
      "z": 9,
      "name": "Wood_Oak_Trunk"
    },
    {
      "x": 15,
      "y": 1,
      "z": 9,
      "name": "Wood_Oak_Trunk"
    },
    {
      "x": 16,
      "y": 1,
      "z": 9,
      "name": "Soil_Dirt_Burnt"
    },
    {
      "x": 0,
      "y": 1,
      "z": 10,
      "name": "Soil_Grass"
    },
    {
      "x": 1,
      "y": 1,
      "z": 10,
      "name": "Soil_Dirt_Burnt"
    },
    {
      "x": 2,
      "y": 1,
      "z": 10,
      "name": "Cloth_Block_Wool_Cyan"
    },
    {
      "x": 3,
      "y": 1,
      "z": 10,
      "name": "Wood_Darkwood_Planks"
    },
    {
      "x": 4,
      "y": 1,
      "z": 10,
      "name": "Wood_Darkwood_Planks"
    },
    {
      "x": 5,
      "y": 1,
      "z": 10,
      "name": "Wood_Darkwood_Planks"
    },
    {
      "x": 6,
      "y": 1,
      "z": 10,
      "name": "Wood_Darkwood_Planks"
    },
    {
      "x": 7,
      "y": 1,
      "z": 10,
      "name": "Wood_Darkwood_Planks"
    },
    {
      "x": 8,
      "y": 1,
      "z": 10,
      "name": "Wood_Darkwood_Planks"
    },
    {
      "x": 9,
      "y": 1,
      "z": 10,
      "name": "Wood_Darkwood_Planks"
    },
    {
      "x": 10,
      "y": 1,
      "z": 10,
      "name": "Wood_Darkwood_Planks"
    },
    {
      "x": 11,
      "y": 1,
      "z": 10,
      "name": "Wood_Darkwood_Planks"
    },
    {
      "x": 12,
      "y": 1,
      "z": 10,
      "name": "Wood_Darkwood_Planks"
    },
    {
      "x": 13,
      "y": 1,
      "z": 10,
      "name": "Wood_Darkwood_Planks"
    },
    {
      "x": 14,
      "y": 1,
      "z": 10,
      "name": "Cloth_Block_Wool_Cyan"
    },
    {
      "x": 15,
      "y": 1,
      "z": 10,
      "name": "Soil_Dirt_Burnt"
    },
    {
      "x": 16,
      "y": 1,
      "z": 10,
      "name": "Soil_Dirt_Burnt"
    },
    {
      "x": 0,
      "y": 1,
      "z": 11,
      "name": "Soil_Dirt_Burnt"
    },
    {
      "x": 1,
      "y": 1,
      "z": 11,
      "name": "Soil_Dirt_Burnt"
    },
    {
      "x": 2,
      "y": 1,
      "z": 11,
      "name": "Cloth_Block_Wool_White"
    },
    {
      "x": 3,
      "y": 1,
      "z": 11,
      "name": "Wood_Darkwood_Planks"
    },
    {
      "x": 4,
      "y": 1,
      "z": 11,
      "name": "Wood_Darkwood_Planks"
    },
    {
      "x": 5,
      "y": 1,
      "z": 11,
      "name": "Wood_Darkwood_Planks"
    },
    {
      "x": 6,
      "y": 1,
      "z": 11,
      "name": "Wood_Darkwood_Planks"
    },
    {
      "x": 7,
      "y": 1,
      "z": 11,
      "name": "Wood_Darkwood_Planks"
    },
    {
      "x": 8,
      "y": 1,
      "z": 11,
      "name": "Wood_Darkwood_Planks"
    },
    {
      "x": 9,
      "y": 1,
      "z": 11,
      "name": "Wood_Darkwood_Planks"
    },
    {
      "x": 10,
      "y": 1,
      "z": 11,
      "name": "Wood_Darkwood_Planks"
    },
    {
      "x": 11,
      "y": 1,
      "z": 11,
      "name": "Wood_Darkwood_Planks"
    },
    {
      "x": 12,
      "y": 1,
      "z": 11,
      "name": "Wood_Darkwood_Planks"
    },
    {
      "x": 13,
      "y": 1,
      "z": 11,
      "name": "Wood_Darkwood_Planks"
    },
    {
      "x": 14,
      "y": 1,
      "z": 11,
      "name": "Cloth_Block_Wool_White"
    },
    {
      "x": 15,
      "y": 1,
      "z": 11,
      "name": "Soil_Dirt_Burnt"
    },
    {
      "x": 16,
      "y": 1,
      "z": 11,
      "name": "Soil_Dirt_Burnt"
    },
    {
      "x": 0,
      "y": 1,
      "z": 12,
      "name": "Soil_Dirt_Burnt"
    },
    {
      "x": 1,
      "y": 1,
      "z": 12,
      "name": "Soil_Dirt_Burnt"
    },
    {
      "x": 2,
      "y": 1,
      "z": 12,
      "name": "Cloth_Block_Wool_Cyan"
    },
    {
      "x": 3,
      "y": 1,
      "z": 12,
      "name": "Wood_Darkwood_Planks"
    },
    {
      "x": 4,
      "y": 1,
      "z": 12,
      "name": "Wood_Darkwood_Planks"
    },
    {
      "x": 5,
      "y": 1,
      "z": 12,
      "name": "Wood_Darkwood_Planks"
    },
    {
      "x": 6,
      "y": 1,
      "z": 12,
      "name": "Wood_Darkwood_Planks"
    },
    {
      "x": 7,
      "y": 1,
      "z": 12,
      "name": "Wood_Darkwood_Planks"
    },
    {
      "x": 8,
      "y": 1,
      "z": 12,
      "name": "Wood_Darkwood_Planks"
    },
    {
      "x": 9,
      "y": 1,
      "z": 12,
      "name": "Wood_Darkwood_Planks"
    },
    {
      "x": 10,
      "y": 1,
      "z": 12,
      "name": "Wood_Darkwood_Planks"
    },
    {
      "x": 11,
      "y": 1,
      "z": 12,
      "name": "Wood_Darkwood_Planks"
    },
    {
      "x": 12,
      "y": 1,
      "z": 12,
      "name": "Wood_Darkwood_Planks"
    },
    {
      "x": 13,
      "y": 1,
      "z": 12,
      "name": "Wood_Darkwood_Planks"
    },
    {
      "x": 14,
      "y": 1,
      "z": 12,
      "name": "Cloth_Block_Wool_Cyan"
    },
    {
      "x": 15,
      "y": 1,
      "z": 12,
      "name": "Soil_Grass"
    },
    {
      "x": 16,
      "y": 1,
      "z": 12,
      "name": "Soil_Grass"
    },
    {
      "x": 0,
      "y": 1,
      "z": 13,
      "name": "Soil_Grass"
    },
    {
      "x": 1,
      "y": 1,
      "z": 13,
      "name": "Wood_Oak_Trunk"
    },
    {
      "x": 2,
      "y": 1,
      "z": 13,
      "name": "Wood_Oak_Trunk"
    },
    {
      "x": 3,
      "y": 1,
      "z": 13,
      "name": "Wood_Darkwood_Planks"
    },
    {
      "x": 4,
      "y": 1,
      "z": 13,
      "name": "Wood_Darkwood_Planks"
    },
    {
      "x": 5,
      "y": 1,
      "z": 13,
      "name": "Wood_Darkwood_Planks"
    },
    {
      "x": 6,
      "y": 1,
      "z": 13,
      "name": "Wood_Darkwood_Planks"
    },
    {
      "x": 7,
      "y": 1,
      "z": 13,
      "name": "Wood_Darkwood_Planks"
    },
    {
      "x": 8,
      "y": 1,
      "z": 13,
      "name": "Wood_Darkwood_Planks"
    },
    {
      "x": 9,
      "y": 1,
      "z": 13,
      "name": "Wood_Darkwood_Planks"
    },
    {
      "x": 10,
      "y": 1,
      "z": 13,
      "name": "Wood_Darkwood_Planks"
    },
    {
      "x": 11,
      "y": 1,
      "z": 13,
      "name": "Wood_Darkwood_Planks"
    },
    {
      "x": 12,
      "y": 1,
      "z": 13,
      "name": "Wood_Darkwood_Planks"
    },
    {
      "x": 13,
      "y": 1,
      "z": 13,
      "name": "Wood_Darkwood_Planks"
    },
    {
      "x": 14,
      "y": 1,
      "z": 13,
      "name": "Wood_Oak_Trunk"
    },
    {
      "x": 15,
      "y": 1,
      "z": 13,
      "name": "Wood_Oak_Trunk"
    },
    {
      "x": 16,
      "y": 1,
      "z": 13,
      "name": "Soil_Dirt_Burnt"
    },
    {
      "x": 0,
      "y": 1,
      "z": 14,
      "name": "Soil_Grass"
    },
    {
      "x": 1,
      "y": 1,
      "z": 14,
      "name": "Soil_Grass"
    },
    {
      "x": 2,
      "y": 1,
      "z": 14,
      "name": "Cloth_Block_Wool_Cyan"
    },
    {
      "x": 3,
      "y": 1,
      "z": 14,
      "name": "Wood_Darkwood_Planks"
    },
    {
      "x": 4,
      "y": 1,
      "z": 14,
      "name": "Wood_Darkwood_Planks"
    },
    {
      "x": 5,
      "y": 1,
      "z": 14,
      "name": "Wood_Darkwood_Planks"
    },
    {
      "x": 6,
      "y": 1,
      "z": 14,
      "name": "Wood_Darkwood_Planks"
    },
    {
      "x": 7,
      "y": 1,
      "z": 14,
      "name": "Wood_Darkwood_Planks"
    },
    {
      "x": 8,
      "y": 1,
      "z": 14,
      "name": "Wood_Darkwood_Planks"
    },
    {
      "x": 9,
      "y": 1,
      "z": 14,
      "name": "Wood_Darkwood_Planks"
    },
    {
      "x": 10,
      "y": 1,
      "z": 14,
      "name": "Wood_Darkwood_Planks"
    },
    {
      "x": 11,
      "y": 1,
      "z": 14,
      "name": "Wood_Darkwood_Planks"
    },
    {
      "x": 12,
      "y": 1,
      "z": 14,
      "name": "Wood_Darkwood_Planks"
    },
    {
      "x": 13,
      "y": 1,
      "z": 14,
      "name": "Wood_Darkwood_Planks"
    },
    {
      "x": 14,
      "y": 1,
      "z": 14,
      "name": "Cloth_Block_Wool_Cyan"
    },
    {
      "x": 15,
      "y": 1,
      "z": 14,
      "name": "Soil_Dirt_Burnt"
    },
    {
      "x": 16,
      "y": 1,
      "z": 14,
      "name": "Soil_Dirt_Burnt"
    },
    {
      "x": 0,
      "y": 1,
      "z": 15,
      "name": "Soil_Dirt_Burnt"
    },
    {
      "x": 1,
      "y": 1,
      "z": 15,
      "name": "Soil_Grass"
    },
    {
      "x": 2,
      "y": 1,
      "z": 15,
      "name": "Cloth_Block_Wool_White"
    },
    {
      "x": 3,
      "y": 1,
      "z": 15,
      "name": "Wood_Darkwood_Planks"
    },
    {
      "x": 4,
      "y": 1,
      "z": 15,
      "name": "Wood_Darkwood_Planks"
    },
    {
      "x": 5,
      "y": 1,
      "z": 15,
      "name": "Wood_Darkwood_Planks"
    },
    {
      "x": 6,
      "y": 1,
      "z": 15,
      "name": "Wood_Darkwood_Planks"
    },
    {
      "x": 7,
      "y": 1,
      "z": 15,
      "name": "Wood_Darkwood_Planks"
    },
    {
      "x": 8,
      "y": 1,
      "z": 15,
      "name": "Wood_Darkwood_Planks"
    },
    {
      "x": 9,
      "y": 1,
      "z": 15,
      "name": "Wood_Darkwood_Planks"
    },
    {
      "x": 10,
      "y": 1,
      "z": 15,
      "name": "Wood_Darkwood_Planks"
    },
    {
      "x": 11,
      "y": 1,
      "z": 15,
      "name": "Wood_Darkwood_Planks"
    },
    {
      "x": 12,
      "y": 1,
      "z": 15,
      "name": "Wood_Darkwood_Planks"
    },
    {
      "x": 13,
      "y": 1,
      "z": 15,
      "name": "Wood_Darkwood_Planks"
    },
    {
      "x": 14,
      "y": 1,
      "z": 15,
      "name": "Cloth_Block_Wool_White"
    },
    {
      "x": 15,
      "y": 1,
      "z": 15,
      "name": "Soil_Dirt_Burnt"
    },
    {
      "x": 16,
      "y": 1,
      "z": 15,
      "name": "Soil_Dirt_Burnt"
    },
    {
      "x": 0,
      "y": 1,
      "z": 16,
      "name": "Soil_Dirt_Burnt"
    },
    {
      "x": 1,
      "y": 1,
      "z": 16,
      "name": "Soil_Dirt_Burnt"
    },
    {
      "x": 2,
      "y": 1,
      "z": 16,
      "name": "Cloth_Block_Wool_Cyan"
    },
    {
      "x": 3,
      "y": 1,
      "z": 16,
      "name": "Wood_Darkwood_Planks"
    },
    {
      "x": 4,
      "y": 1,
      "z": 16,
      "name": "Wood_Darkwood_Planks"
    },
    {
      "x": 5,
      "y": 1,
      "z": 16,
      "name": "Wood_Darkwood_Planks"
    },
    {
      "x": 6,
      "y": 1,
      "z": 16,
      "name": "Wood_Darkwood_Planks"
    },
    {
      "x": 7,
      "y": 1,
      "z": 16,
      "name": "Wood_Darkwood_Planks"
    },
    {
      "x": 8,
      "y": 1,
      "z": 16,
      "name": "Wood_Darkwood_Planks"
    },
    {
      "x": 9,
      "y": 1,
      "z": 16,
      "name": "Wood_Darkwood_Planks"
    },
    {
      "x": 10,
      "y": 1,
      "z": 16,
      "name": "Wood_Darkwood_Planks"
    },
    {
      "x": 11,
      "y": 1,
      "z": 16,
      "name": "Wood_Darkwood_Planks"
    },
    {
      "x": 12,
      "y": 1,
      "z": 16,
      "name": "Wood_Darkwood_Planks"
    },
    {
      "x": 13,
      "y": 1,
      "z": 16,
      "name": "Wood_Darkwood_Planks"
    },
    {
      "x": 14,
      "y": 1,
      "z": 16,
      "name": "Cloth_Block_Wool_Cyan"
    },
    {
      "x": 15,
      "y": 1,
      "z": 16,
      "name": "Soil_Dirt_Burnt"
    },
    {
      "x": 16,
      "y": 1,
      "z": 16,
      "name": "Soil_Dirt_Burnt"
    },
    {
      "x": 0,
      "y": 1,
      "z": 17,
      "name": "Soil_Grass"
    },
    {
      "x": 1,
      "y": 1,
      "z": 17,
      "name": "Wood_Oak_Trunk"
    },
    {
      "x": 2,
      "y": 1,
      "z": 17,
      "name": "Wood_Oak_Trunk"
    },
    {
      "x": 3,
      "y": 1,
      "z": 17,
      "name": "Cloth_Block_Wool_Cyan"
    },
    {
      "x": 4,
      "y": 1,
      "z": 17,
      "name": "Cloth_Block_Wool_White"
    },
    {
      "x": 5,
      "y": 1,
      "z": 17,
      "name": "Cloth_Block_Wool_Cyan"
    },
    {
      "x": 6,
      "y": 1,
      "z": 17,
      "name": "Wood_Oak_Trunk"
    },
    {
      "x": 7,
      "y": 1,
      "z": 17,
      "name": "Cloth_Block_Wool_Cyan"
    },
    {
      "x": 8,
      "y": 1,
      "z": 17,
      "name": "Cloth_Block_Wool_White"
    },
    {
      "x": 9,
      "y": 1,
      "z": 17,
      "name": "Cloth_Block_Wool_Cyan"
    },
    {
      "x": 10,
      "y": 1,
      "z": 17,
      "name": "Wood_Oak_Trunk"
    },
    {
      "x": 11,
      "y": 1,
      "z": 17,
      "name": "Cloth_Block_Wool_Cyan"
    },
    {
      "x": 12,
      "y": 1,
      "z": 17,
      "name": "Cloth_Block_Wool_White"
    },
    {
      "x": 13,
      "y": 1,
      "z": 17,
      "name": "Cloth_Block_Wool_Cyan"
    },
    {
      "x": 14,
      "y": 1,
      "z": 17,
      "name": "Wood_Oak_Trunk"
    },
    {
      "x": 15,
      "y": 1,
      "z": 17,
      "name": "Wood_Oak_Trunk"
    },
    {
      "x": 16,
      "y": 1,
      "z": 17,
      "name": "Soil_Dirt_Burnt"
    },
    {
      "x": 0,
      "y": 1,
      "z": 18,
      "name": "Soil_Dirt_Burnt"
    },
    {
      "x": 1,
      "y": 1,
      "z": 18,
      "name": "Soil_Grass"
    },
    {
      "x": 2,
      "y": 1,
      "z": 18,
      "name": "Wood_Oak_Trunk"
    },
    {
      "x": 3,
      "y": 1,
      "z": 18,
      "name": "Soil_Dirt_Burnt"
    },
    {
      "x": 4,
      "y": 1,
      "z": 18,
      "name": "Soil_Grass"
    },
    {
      "x": 5,
      "y": 1,
      "z": 18,
      "name": "Soil_Dirt_Burnt"
    },
    {
      "x": 6,
      "y": 1,
      "z": 18,
      "name": "Soil_Dirt_Burnt"
    },
    {
      "x": 7,
      "y": 1,
      "z": 18,
      "name": "Soil_Grass"
    },
    {
      "x": 8,
      "y": 1,
      "z": 18,
      "name": "Soil_Grass"
    },
    {
      "x": 9,
      "y": 1,
      "z": 18,
      "name": "Soil_Dirt_Burnt"
    },
    {
      "x": 10,
      "y": 1,
      "z": 18,
      "name": "Wood_Oak_Trunk"
    },
    {
      "x": 11,
      "y": 1,
      "z": 18,
      "name": "Soil_Dirt_Burnt"
    },
    {
      "x": 12,
      "y": 1,
      "z": 18,
      "name": "Soil_Dirt_Burnt"
    },
    {
      "x": 13,
      "y": 1,
      "z": 18,
      "name": "Soil_Dirt_Burnt"
    },
    {
      "x": 14,
      "y": 1,
      "z": 18,
      "name": "Wood_Oak_Trunk"
    },
    {
      "x": 15,
      "y": 1,
      "z": 18,
      "name": "Soil_Grass"
    },
    {
      "x": 16,
      "y": 1,
      "z": 18,
      "name": "Soil_Dirt_Burnt"
    },
    {
      "x": 0,
      "y": 1,
      "z": 19,
      "name": "Soil_Dirt_Burnt"
    },
    {
      "x": 1,
      "y": 1,
      "z": 19,
      "name": "Soil_Dirt_Burnt"
    },
    {
      "x": 2,
      "y": 1,
      "z": 19,
      "name": "Soil_Dirt_Burnt"
    },
    {
      "x": 3,
      "y": 1,
      "z": 19,
      "name": "Soil_Grass"
    },
    {
      "x": 4,
      "y": 1,
      "z": 19,
      "name": "Soil_Dirt_Burnt"
    },
    {
      "x": 5,
      "y": 1,
      "z": 19,
      "name": "Soil_Dirt_Burnt"
    },
    {
      "x": 6,
      "y": 1,
      "z": 19,
      "name": "Soil_Dirt_Burnt"
    },
    {
      "x": 7,
      "y": 1,
      "z": 19,
      "name": "Soil_Dirt_Burnt"
    },
    {
      "x": 8,
      "y": 1,
      "z": 19,
      "name": "Soil_Grass"
    },
    {
      "x": 9,
      "y": 1,
      "z": 19,
      "name": "Soil_Dirt_Burnt"
    },
    {
      "x": 10,
      "y": 1,
      "z": 19,
      "name": "Soil_Dirt_Burnt"
    },
    {
      "x": 11,
      "y": 1,
      "z": 19,
      "name": "Soil_Dirt_Burnt"
    },
    {
      "x": 12,
      "y": 1,
      "z": 19,
      "name": "Soil_Grass"
    },
    {
      "x": 13,
      "y": 1,
      "z": 19,
      "name": "Soil_Dirt_Burnt"
    },
    {
      "x": 14,
      "y": 1,
      "z": 19,
      "name": "Soil_Dirt_Burnt"
    },
    {
      "x": 15,
      "y": 1,
      "z": 19,
      "name": "Soil_Dirt_Burnt"
    },
    {
      "x": 16,
      "y": 1,
      "z": 19,
      "name": "Soil_Grass"
    },
    {
      "x": 0,
      "y": 1,
      "z": 20,
      "name": "Soil_Grass"
    },
    {
      "x": 1,
      "y": 1,
      "z": 20,
      "name": "Soil_Grass"
    },
    {
      "x": 2,
      "y": 1,
      "z": 20,
      "name": "Soil_Dirt_Burnt"
    },
    {
      "x": 3,
      "y": 1,
      "z": 20,
      "name": "Soil_Grass"
    },
    {
      "x": 4,
      "y": 1,
      "z": 20,
      "name": "Soil_Dirt_Burnt"
    },
    {
      "x": 5,
      "y": 1,
      "z": 20,
      "name": "Soil_Grass"
    },
    {
      "x": 6,
      "y": 1,
      "z": 20,
      "name": "Soil_Grass"
    },
    {
      "x": 7,
      "y": 1,
      "z": 20,
      "name": "Soil_Grass"
    },
    {
      "x": 8,
      "y": 1,
      "z": 20,
      "name": "Soil_Grass"
    },
    {
      "x": 9,
      "y": 1,
      "z": 20,
      "name": "Soil_Dirt_Burnt"
    },
    {
      "x": 10,
      "y": 1,
      "z": 20,
      "name": "Soil_Grass"
    },
    {
      "x": 11,
      "y": 1,
      "z": 20,
      "name": "Soil_Dirt_Burnt"
    },
    {
      "x": 12,
      "y": 1,
      "z": 20,
      "name": "Soil_Dirt_Burnt"
    },
    {
      "x": 13,
      "y": 1,
      "z": 20,
      "name": "Soil_Grass"
    },
    {
      "x": 14,
      "y": 1,
      "z": 20,
      "name": "Soil_Dirt_Burnt"
    },
    {
      "x": 15,
      "y": 1,
      "z": 20,
      "name": "Soil_Grass"
    },
    {
      "x": 16,
      "y": 1,
      "z": 20,
      "name": "Soil_Dirt_Burnt"
    },
    {
      "x": 0,
      "y": 1,
      "z": 21,
      "name": "Soil_Grass"
    },
    {
      "x": 1,
      "y": 1,
      "z": 21,
      "name": "Soil_Grass"
    },
    {
      "x": 2,
      "y": 1,
      "z": 21,
      "name": "Soil_Grass"
    },
    {
      "x": 3,
      "y": 1,
      "z": 21,
      "name": "Soil_Dirt_Burnt"
    },
    {
      "x": 4,
      "y": 1,
      "z": 21,
      "name": "Soil_Grass"
    },
    {
      "x": 5,
      "y": 1,
      "z": 21,
      "name": "Soil_Grass"
    },
    {
      "x": 6,
      "y": 1,
      "z": 21,
      "name": "Soil_Grass"
    },
    {
      "x": 7,
      "y": 1,
      "z": 21,
      "name": "Soil_Dirt_Burnt"
    },
    {
      "x": 8,
      "y": 1,
      "z": 21,
      "name": "Soil_Dirt_Burnt"
    },
    {
      "x": 9,
      "y": 1,
      "z": 21,
      "name": "Soil_Grass"
    },
    {
      "x": 10,
      "y": 1,
      "z": 21,
      "name": "Soil_Grass"
    },
    {
      "x": 11,
      "y": 1,
      "z": 21,
      "name": "Soil_Grass"
    },
    {
      "x": 12,
      "y": 1,
      "z": 21,
      "name": "Soil_Grass"
    },
    {
      "x": 13,
      "y": 1,
      "z": 21,
      "name": "Soil_Grass"
    },
    {
      "x": 14,
      "y": 1,
      "z": 21,
      "name": "Soil_Grass"
    },
    {
      "x": 15,
      "y": 1,
      "z": 21,
      "name": "Soil_Grass"
    },
    {
      "x": 16,
      "y": 1,
      "z": 21,
      "name": "Soil_Grass"
    },
    {
      "x": 0,
      "y": 1,
      "z": 22,
      "name": "Soil_Grass"
    },
    {
      "x": 1,
      "y": 1,
      "z": 22,
      "name": "Soil_Grass"
    },
    {
      "x": 2,
      "y": 1,
      "z": 22,
      "name": "Soil_Grass"
    },
    {
      "x": 3,
      "y": 1,
      "z": 22,
      "name": "Soil_Grass"
    },
    {
      "x": 4,
      "y": 1,
      "z": 22,
      "name": "Soil_Grass"
    },
    {
      "x": 5,
      "y": 1,
      "z": 22,
      "name": "Soil_Grass"
    },
    {
      "x": 6,
      "y": 1,
      "z": 22,
      "name": "Soil_Grass"
    },
    {
      "x": 7,
      "y": 1,
      "z": 22,
      "name": "Soil_Grass"
    },
    {
      "x": 8,
      "y": 1,
      "z": 22,
      "name": "Soil_Grass"
    },
    {
      "x": 9,
      "y": 1,
      "z": 22,
      "name": "Soil_Grass"
    },
    {
      "x": 10,
      "y": 1,
      "z": 22,
      "name": "Soil_Grass"
    },
    {
      "x": 11,
      "y": 1,
      "z": 22,
      "name": "Soil_Grass"
    },
    {
      "x": 12,
      "y": 1,
      "z": 22,
      "name": "Soil_Grass"
    },
    {
      "x": 13,
      "y": 1,
      "z": 22,
      "name": "Soil_Grass"
    },
    {
      "x": 14,
      "y": 1,
      "z": 22,
      "name": "Soil_Grass"
    },
    {
      "x": 15,
      "y": 1,
      "z": 22,
      "name": "Soil_Grass"
    },
    {
      "x": 16,
      "y": 1,
      "z": 22,
      "name": "Soil_Grass"
    },
    {
      "x": 0,
      "y": 2,
      "z": 0,
      "name": "Plant_Flower_Common_White2"
    },
    {
      "x": 1,
      "y": 2,
      "z": 0,
      "name": "Rock_Stone_Brick"
    },
    {
      "x": 2,
      "y": 2,
      "z": 0,
      "name": "Rock_Stone_Brick"
    },
    {
      "x": 12,
      "y": 2,
      "z": 0,
      "name": "Rock_Stone_Brick"
    },
    {
      "x": 0,
      "y": 2,
      "z": 1,
      "name": "Rock_Stone_Brick"
    },
    {
      "x": 2,
      "y": 2,
      "z": 1,
      "name": "Plant_Flower_Common_White2"
    },
    {
      "x": 3,
      "y": 2,
      "z": 1,
      "name": "Rock_Stone_Brick"
    },
    {
      "x": 9,
      "y": 2,
      "z": 1,
      "name": "Rock_Stone_Brick"
    },
    {
      "x": 13,
      "y": 2,
      "z": 1,
      "name": "Rock_Stone_Cobble_Mossy_Half"
    },
    {
      "x": 15,
      "y": 2,
      "z": 1,
      "name": "Rock_Stone_Brick"
    },
    {
      "x": 16,
      "y": 2,
      "z": 1,
      "name": "Rock_Stone_Brick"
    },
    {
      "x": 1,
      "y": 2,
      "z": 2,
      "name": "Rock_Stone_Brick"
    },
    {
      "x": 14,
      "y": 2,
      "z": 2,
      "name": "*Plant_Crop_Berry_Block_State_Definitions_StageFinal"
    },
    {
      "x": 16,
      "y": 2,
      "z": 2,
      "name": "Rock_Stone_Brick"
    },
    {
      "x": 2,
      "y": 2,
      "z": 3,
      "name": "Plant_Leaves_Beech"
    },
    {
      "x": 6,
      "y": 2,
      "z": 3,
      "name": "*Plant_Crop_Berry_Block_State_Definitions_StageFinal"
    },
    {
      "x": 12,
      "y": 2,
      "z": 3,
      "name": "*Plant_Crop_Berry_Block_State_Definitions_StageFinal"
    },
    {
      "x": 13,
      "y": 2,
      "z": 3,
      "name": "Plant_Leaves_Beech"
    },
    {
      "x": 14,
      "y": 2,
      "z": 3,
      "name": "Plant_Grass_Sharp_Wild"
    },
    {
      "x": 1,
      "y": 2,
      "z": 4,
      "name": "Plant_Flower_Tall_Pink"
    },
    {
      "x": 2,
      "y": 2,
      "z": 4,
      "name": "Wood_Oak_Trunk"
    },
    {
      "x": 3,
      "y": 2,
      "z": 4,
      "name": "Plant_Leaves_Beech"
    },
    {
      "x": 4,
      "y": 2,
      "z": 4,
      "name": "Plant_Grass_Sharp_Wild"
    },
    {
      "x": 5,
      "y": 2,
      "z": 4,
      "name": "*Plant_Crop_Berry_Block_State_Definitions_StageFinal"
    },
    {
      "x": 6,
      "y": 2,
      "z": 4,
      "name": "Wood_Oak_Trunk"
    },
    {
      "x": 10,
      "y": 2,
      "z": 4,
      "name": "Wood_Oak_Trunk"
    },
    {
      "x": 11,
      "y": 2,
      "z": 4,
      "name": "Plant_Grass_Sharp_Wild"
    },
    {
      "x": 12,
      "y": 2,
      "z": 4,
      "name": "Plant_Leaves_Beech"
    },
    {
      "x": 13,
      "y": 2,
      "z": 4,
      "name": "Plant_Leaves_Beech"
    },
    {
      "x": 14,
      "y": 2,
      "z": 4,
      "name": "Wood_Oak_Trunk"
    },
    {
      "x": 15,
      "y": 2,
      "z": 4,
      "name": "Plant_Leaves_Beech"
    },
    {
      "x": 16,
      "y": 2,
      "z": 4,
      "name": "Plant_Flower_Common_White2"
    },
    {
      "x": 0,
      "y": 2,
      "z": 5,
      "name": "*Plant_Crop_Berry_Block_State_Definitions_StageFinal"
    },
    {
      "x": 1,
      "y": 2,
      "z": 5,
      "name": "Wood_Oak_Trunk"
    },
    {
      "x": 2,
      "y": 2,
      "z": 5,
      "name": "Wood_Oak_Trunk"
    },
    {
      "x": 3,
      "y": 2,
      "z": 5,
      "name": "Rock_Stone_Brick"
    },
    {
      "x": 4,
      "y": 2,
      "z": 5,
      "name": "Rock_Stone_Brick"
    },
    {
      "x": 5,
      "y": 2,
      "z": 5,
      "name": "Rock_Stone_Brick"
    },
    {
      "x": 6,
      "y": 2,
      "z": 5,
      "name": "Wood_Oak_Trunk"
    },
    {
      "x": 7,
      "y": 2,
      "z": 5,
      "name": "Wood_Darkwood_Planks"
    },
    {
      "x": 8,
      "y": 2,
      "z": 5,
      "name": "Wood_Darkwood_Planks"
    },
    {
      "x": 9,
      "y": 2,
      "z": 5,
      "name": "Wood_Darkwood_Planks"
    },
    {
      "x": 10,
      "y": 2,
      "z": 5,
      "name": "Wood_Oak_Trunk"
    },
    {
      "x": 11,
      "y": 2,
      "z": 5,
      "name": "Rock_Stone_Brick"
    },
    {
      "x": 12,
      "y": 2,
      "z": 5,
      "name": "Rock_Stone_Brick"
    },
    {
      "x": 13,
      "y": 2,
      "z": 5,
      "name": "Rock_Stone_Brick"
    },
    {
      "x": 14,
      "y": 2,
      "z": 5,
      "name": "Wood_Oak_Trunk"
    },
    {
      "x": 15,
      "y": 2,
      "z": 5,
      "name": "Wood_Oak_Trunk"
    },
    {
      "x": 1,
      "y": 2,
      "z": 6,
      "name": "Plant_Flower_Tall_Pink"
    },
    {
      "x": 2,
      "y": 2,
      "z": 6,
      "name": "Rock_Stone_Brick"
    },
    {
      "x": 3,
      "y": 2,
      "z": 6,
      "name": "Wood_Darkwood_Planks"
    },
    {
      "x": 4,
      "y": 2,
      "z": 6,
      "name": "Wood_Darkwood_Planks"
    },
    {
      "x": 5,
      "y": 2,
      "z": 6,
      "name": "Wood_Darkwood_Planks"
    },
    {
      "x": 6,
      "y": 2,
      "z": 6,
      "name": "Wood_Darkwood_Planks"
    },
    {
      "x": 7,
      "y": 2,
      "z": 6,
      "name": "Wood_Darkwood_Planks"
    },
    {
      "x": 8,
      "y": 2,
      "z": 6,
      "name": "Wood_Darkwood_Planks"
    },
    {
      "x": 9,
      "y": 2,
      "z": 6,
      "name": "Wood_Darkwood_Planks"
    },
    {
      "x": 10,
      "y": 2,
      "z": 6,
      "name": "Wood_Darkwood_Planks"
    },
    {
      "x": 11,
      "y": 2,
      "z": 6,
      "name": "Wood_Darkwood_Planks"
    },
    {
      "x": 12,
      "y": 2,
      "z": 6,
      "name": "Wood_Darkwood_Planks"
    },
    {
      "x": 13,
      "y": 2,
      "z": 6,
      "name": "Wood_Darkwood_Planks"
    },
    {
      "x": 14,
      "y": 2,
      "z": 6,
      "name": "Rock_Stone_Brick"
    },
    {
      "x": 1,
      "y": 2,
      "z": 7,
      "name": "Plant_Leaves_Beech"
    },
    {
      "x": 2,
      "y": 2,
      "z": 7,
      "name": "Rock_Stone_Brick"
    },
    {
      "x": 3,
      "y": 2,
      "z": 7,
      "name": "Wood_Darkwood_Planks"
    },
    {
      "x": 4,
      "y": 2,
      "z": 7,
      "name": "Wood_Darkwood_Planks"
    },
    {
      "x": 5,
      "y": 2,
      "z": 7,
      "name": "Wood_Darkwood_Planks"
    },
    {
      "x": 6,
      "y": 2,
      "z": 7,
      "name": "Wood_Darkwood_Planks"
    },
    {
      "x": 7,
      "y": 2,
      "z": 7,
      "name": "Wood_Darkwood_Planks"
    },
    {
      "x": 8,
      "y": 2,
      "z": 7,
      "name": "Wood_Darkwood_Planks"
    },
    {
      "x": 9,
      "y": 2,
      "z": 7,
      "name": "Wood_Darkwood_Planks"
    },
    {
      "x": 10,
      "y": 2,
      "z": 7,
      "name": "Wood_Darkwood_Planks"
    },
    {
      "x": 11,
      "y": 2,
      "z": 7,
      "name": "Wood_Darkwood_Planks"
    },
    {
      "x": 12,
      "y": 2,
      "z": 7,
      "name": "Wood_Darkwood_Planks"
    },
    {
      "x": 13,
      "y": 2,
      "z": 7,
      "name": "Wood_Darkwood_Planks"
    },
    {
      "x": 14,
      "y": 2,
      "z": 7,
      "name": "Rock_Stone_Brick"
    },
    {
      "x": 0,
      "y": 2,
      "z": 8,
      "name": "Plant_Crop_Mana1"
    },
    {
      "x": 1,
      "y": 2,
      "z": 8,
      "name": "Plant_Leaves_Beech"
    },
    {
      "x": 2,
      "y": 2,
      "z": 8,
      "name": "Rock_Stone_Brick"
    },
    {
      "x": 3,
      "y": 2,
      "z": 8,
      "name": "Wood_Darkwood_Planks"
    },
    {
      "x": 4,
      "y": 2,
      "z": 8,
      "name": "Wood_Darkwood_Planks"
    },
    {
      "x": 5,
      "y": 2,
      "z": 8,
      "name": "Wood_Darkwood_Planks"
    },
    {
      "x": 6,
      "y": 2,
      "z": 8,
      "name": "Wood_Darkwood_Planks"
    },
    {
      "x": 7,
      "y": 2,
      "z": 8,
      "name": "Wood_Darkwood_Planks"
    },
    {
      "x": 8,
      "y": 2,
      "z": 8,
      "name": "Wood_Darkwood_Planks"
    },
    {
      "x": 9,
      "y": 2,
      "z": 8,
      "name": "Wood_Darkwood_Planks"
    },
    {
      "x": 10,
      "y": 2,
      "z": 8,
      "name": "Wood_Darkwood_Planks"
    },
    {
      "x": 11,
      "y": 2,
      "z": 8,
      "name": "Wood_Darkwood_Planks"
    },
    {
      "x": 12,
      "y": 2,
      "z": 8,
      "name": "Wood_Darkwood_Planks"
    },
    {
      "x": 13,
      "y": 2,
      "z": 8,
      "name": "Wood_Darkwood_Planks"
    },
    {
      "x": 14,
      "y": 2,
      "z": 8,
      "name": "Rock_Stone_Brick"
    },
    {
      "x": 15,
      "y": 2,
      "z": 8,
      "name": "Plant_Grass_Sharp_Wild"
    },
    {
      "x": 0,
      "y": 2,
      "z": 9,
      "name": "Plant_Leaves_Beech"
    },
    {
      "x": 1,
      "y": 2,
      "z": 9,
      "name": "Wood_Oak_Trunk"
    },
    {
      "x": 2,
      "y": 2,
      "z": 9,
      "name": "Wood_Oak_Trunk"
    },
    {
      "x": 3,
      "y": 2,
      "z": 9,
      "name": "Wood_Darkwood_Planks"
    },
    {
      "x": 4,
      "y": 2,
      "z": 9,
      "name": "Wood_Darkwood_Planks"
    },
    {
      "x": 5,
      "y": 2,
      "z": 9,
      "name": "Wood_Darkwood_Planks"
    },
    {
      "x": 6,
      "y": 2,
      "z": 9,
      "name": "Wood_Darkwood_Planks"
    },
    {
      "x": 7,
      "y": 2,
      "z": 9,
      "name": "Wood_Darkwood_Planks"
    },
    {
      "x": 8,
      "y": 2,
      "z": 9,
      "name": "Wood_Darkwood_Planks"
    },
    {
      "x": 9,
      "y": 2,
      "z": 9,
      "name": "Wood_Darkwood_Planks"
    },
    {
      "x": 10,
      "y": 2,
      "z": 9,
      "name": "Wood_Darkwood_Planks"
    },
    {
      "x": 11,
      "y": 2,
      "z": 9,
      "name": "Wood_Darkwood_Planks"
    },
    {
      "x": 12,
      "y": 2,
      "z": 9,
      "name": "Wood_Darkwood_Planks"
    },
    {
      "x": 13,
      "y": 2,
      "z": 9,
      "name": "Wood_Darkwood_Planks"
    },
    {
      "x": 14,
      "y": 2,
      "z": 9,
      "name": "Wood_Oak_Trunk"
    },
    {
      "x": 15,
      "y": 2,
      "z": 9,
      "name": "Wood_Oak_Trunk"
    },
    {
      "x": 16,
      "y": 2,
      "z": 9,
      "name": "Plant_Leaves_Beech"
    },
    {
      "x": 1,
      "y": 2,
      "z": 10,
      "name": "Plant_Grass_Sharp_Wild"
    },
    {
      "x": 2,
      "y": 2,
      "z": 10,
      "name": "Rock_Stone_Brick"
    },
    {
      "x": 3,
      "y": 2,
      "z": 10,
      "name": "Wood_Darkwood_Planks"
    },
    {
      "x": 4,
      "y": 2,
      "z": 10,
      "name": "Wood_Darkwood_Planks"
    },
    {
      "x": 5,
      "y": 2,
      "z": 10,
      "name": "Wood_Darkwood_Planks"
    },
    {
      "x": 6,
      "y": 2,
      "z": 10,
      "name": "Wood_Darkwood_Planks"
    },
    {
      "x": 7,
      "y": 2,
      "z": 10,
      "name": "Wood_Darkwood_Planks"
    },
    {
      "x": 8,
      "y": 2,
      "z": 10,
      "name": "Wood_Darkwood_Planks"
    },
    {
      "x": 9,
      "y": 2,
      "z": 10,
      "name": "Wood_Darkwood_Planks"
    },
    {
      "x": 10,
      "y": 2,
      "z": 10,
      "name": "Wood_Darkwood_Planks"
    },
    {
      "x": 11,
      "y": 2,
      "z": 10,
      "name": "Wood_Darkwood_Planks"
    },
    {
      "x": 12,
      "y": 2,
      "z": 10,
      "name": "Wood_Darkwood_Planks"
    },
    {
      "x": 13,
      "y": 2,
      "z": 10,
      "name": "Wood_Darkwood_Planks"
    },
    {
      "x": 14,
      "y": 2,
      "z": 10,
      "name": "Rock_Stone_Brick"
    },
    {
      "x": 15,
      "y": 2,
      "z": 10,
      "name": "Plant_Leaves_Beech"
    },
    {
      "x": 1,
      "y": 2,
      "z": 11,
      "name": "*Plant_Crop_Berry_Block_State_Definitions_StageFinal"
    },
    {
      "x": 2,
      "y": 2,
      "z": 11,
      "name": "Rock_Stone_Brick"
    },
    {
      "x": 3,
      "y": 2,
      "z": 11,
      "name": "Wood_Darkwood_Planks"
    },
    {
      "x": 4,
      "y": 2,
      "z": 11,
      "name": "Wood_Darkwood_Planks"
    },
    {
      "x": 5,
      "y": 2,
      "z": 11,
      "name": "Wood_Darkwood_Planks"
    },
    {
      "x": 6,
      "y": 2,
      "z": 11,
      "name": "Wood_Darkwood_Planks"
    },
    {
      "x": 7,
      "y": 2,
      "z": 11,
      "name": "Wood_Darkwood_Planks"
    },
    {
      "x": 8,
      "y": 2,
      "z": 11,
      "name": "Wood_Darkwood_Planks"
    },
    {
      "x": 9,
      "y": 2,
      "z": 11,
      "name": "Wood_Darkwood_Planks"
    },
    {
      "x": 10,
      "y": 2,
      "z": 11,
      "name": "Wood_Darkwood_Planks"
    },
    {
      "x": 11,
      "y": 2,
      "z": 11,
      "name": "Wood_Darkwood_Planks"
    },
    {
      "x": 12,
      "y": 2,
      "z": 11,
      "name": "Wood_Darkwood_Planks"
    },
    {
      "x": 13,
      "y": 2,
      "z": 11,
      "name": "Wood_Darkwood_Planks"
    },
    {
      "x": 14,
      "y": 2,
      "z": 11,
      "name": "Rock_Stone_Brick"
    },
    {
      "x": 2,
      "y": 2,
      "z": 12,
      "name": "Rock_Stone_Brick"
    },
    {
      "x": 3,
      "y": 2,
      "z": 12,
      "name": "Wood_Darkwood_Planks"
    },
    {
      "x": 4,
      "y": 2,
      "z": 12,
      "name": "Wood_Darkwood_Planks"
    },
    {
      "x": 5,
      "y": 2,
      "z": 12,
      "name": "Wood_Darkwood_Planks"
    },
    {
      "x": 6,
      "y": 2,
      "z": 12,
      "name": "Wood_Darkwood_Planks"
    },
    {
      "x": 7,
      "y": 2,
      "z": 12,
      "name": "Wood_Darkwood_Planks"
    },
    {
      "x": 8,
      "y": 2,
      "z": 12,
      "name": "Wood_Darkwood_Planks"
    },
    {
      "x": 9,
      "y": 2,
      "z": 12,
      "name": "Wood_Darkwood_Planks"
    },
    {
      "x": 10,
      "y": 2,
      "z": 12,
      "name": "Wood_Darkwood_Planks"
    },
    {
      "x": 11,
      "y": 2,
      "z": 12,
      "name": "Wood_Darkwood_Planks"
    },
    {
      "x": 12,
      "y": 2,
      "z": 12,
      "name": "Wood_Darkwood_Planks"
    },
    {
      "x": 13,
      "y": 2,
      "z": 12,
      "name": "Wood_Darkwood_Planks"
    },
    {
      "x": 14,
      "y": 2,
      "z": 12,
      "name": "Rock_Stone_Brick"
    },
    {
      "x": 15,
      "y": 2,
      "z": 12,
      "name": "Plant_Crop_Mana1"
    },
    {
      "x": 0,
      "y": 2,
      "z": 13,
      "name": "Plant_Leaves_Beech"
    },
    {
      "x": 1,
      "y": 2,
      "z": 13,
      "name": "Wood_Oak_Trunk"
    },
    {
      "x": 2,
      "y": 2,
      "z": 13,
      "name": "Wood_Oak_Trunk"
    },
    {
      "x": 3,
      "y": 2,
      "z": 13,
      "name": "Wood_Darkwood_Planks"
    },
    {
      "x": 4,
      "y": 2,
      "z": 13,
      "name": "Wood_Darkwood_Planks"
    },
    {
      "x": 5,
      "y": 2,
      "z": 13,
      "name": "Wood_Darkwood_Planks"
    },
    {
      "x": 6,
      "y": 2,
      "z": 13,
      "name": "Wood_Darkwood_Planks"
    },
    {
      "x": 7,
      "y": 2,
      "z": 13,
      "name": "Wood_Darkwood_Planks"
    },
    {
      "x": 8,
      "y": 2,
      "z": 13,
      "name": "Wood_Darkwood_Planks"
    },
    {
      "x": 9,
      "y": 2,
      "z": 13,
      "name": "Wood_Darkwood_Planks"
    },
    {
      "x": 10,
      "y": 2,
      "z": 13,
      "name": "Wood_Darkwood_Planks"
    },
    {
      "x": 11,
      "y": 2,
      "z": 13,
      "name": "Wood_Darkwood_Planks"
    },
    {
      "x": 12,
      "y": 2,
      "z": 13,
      "name": "Wood_Darkwood_Planks"
    },
    {
      "x": 13,
      "y": 2,
      "z": 13,
      "name": "Wood_Darkwood_Planks"
    },
    {
      "x": 14,
      "y": 2,
      "z": 13,
      "name": "Wood_Oak_Trunk"
    },
    {
      "x": 15,
      "y": 2,
      "z": 13,
      "name": "Wood_Oak_Trunk"
    },
    {
      "x": 0,
      "y": 2,
      "z": 14,
      "name": "Plant_Flower_Tall_Pink"
    },
    {
      "x": 1,
      "y": 2,
      "z": 14,
      "name": "Plant_Leaves_Beech"
    },
    {
      "x": 2,
      "y": 2,
      "z": 14,
      "name": "Rock_Stone_Brick"
    },
    {
      "x": 3,
      "y": 2,
      "z": 14,
      "name": "Wood_Darkwood_Planks"
    },
    {
      "x": 4,
      "y": 2,
      "z": 14,
      "name": "Wood_Darkwood_Planks"
    },
    {
      "x": 5,
      "y": 2,
      "z": 14,
      "name": "Wood_Darkwood_Planks"
    },
    {
      "x": 6,
      "y": 2,
      "z": 14,
      "name": "Wood_Darkwood_Planks"
    },
    {
      "x": 7,
      "y": 2,
      "z": 14,
      "name": "Wood_Darkwood_Planks"
    },
    {
      "x": 8,
      "y": 2,
      "z": 14,
      "name": "Wood_Darkwood_Planks"
    },
    {
      "x": 9,
      "y": 2,
      "z": 14,
      "name": "Wood_Darkwood_Planks"
    },
    {
      "x": 10,
      "y": 2,
      "z": 14,
      "name": "Wood_Darkwood_Planks"
    },
    {
      "x": 11,
      "y": 2,
      "z": 14,
      "name": "Wood_Darkwood_Planks"
    },
    {
      "x": 12,
      "y": 2,
      "z": 14,
      "name": "Wood_Darkwood_Planks"
    },
    {
      "x": 13,
      "y": 2,
      "z": 14,
      "name": "Wood_Darkwood_Planks"
    },
    {
      "x": 14,
      "y": 2,
      "z": 14,
      "name": "Rock_Stone_Brick"
    },
    {
      "x": 1,
      "y": 2,
      "z": 15,
      "name": "Plant_Flower_Tall_Pink"
    },
    {
      "x": 2,
      "y": 2,
      "z": 15,
      "name": "Rock_Stone_Brick"
    },
    {
      "x": 3,
      "y": 2,
      "z": 15,
      "name": "Wood_Darkwood_Planks"
    },
    {
      "x": 4,
      "y": 2,
      "z": 15,
      "name": "Wood_Darkwood_Planks"
    },
    {
      "x": 5,
      "y": 2,
      "z": 15,
      "name": "Wood_Darkwood_Planks"
    },
    {
      "x": 6,
      "y": 2,
      "z": 15,
      "name": "Wood_Darkwood_Planks"
    },
    {
      "x": 7,
      "y": 2,
      "z": 15,
      "name": "Wood_Darkwood_Planks"
    },
    {
      "x": 8,
      "y": 2,
      "z": 15,
      "name": "Wood_Darkwood_Planks"
    },
    {
      "x": 9,
      "y": 2,
      "z": 15,
      "name": "Wood_Darkwood_Planks"
    },
    {
      "x": 10,
      "y": 2,
      "z": 15,
      "name": "Wood_Darkwood_Planks"
    },
    {
      "x": 11,
      "y": 2,
      "z": 15,
      "name": "Wood_Darkwood_Planks"
    },
    {
      "x": 12,
      "y": 2,
      "z": 15,
      "name": "Wood_Darkwood_Planks"
    },
    {
      "x": 13,
      "y": 2,
      "z": 15,
      "name": "Wood_Darkwood_Planks"
    },
    {
      "x": 14,
      "y": 2,
      "z": 15,
      "name": "Rock_Stone_Brick"
    },
    {
      "x": 15,
      "y": 2,
      "z": 15,
      "name": "Plant_Flower_Tall_Pink"
    },
    {
      "x": 1,
      "y": 2,
      "z": 16,
      "name": "*Plant_Crop_Berry_Block_State_Definitions_StageFinal"
    },
    {
      "x": 2,
      "y": 2,
      "z": 16,
      "name": "Rock_Stone_Brick"
    },
    {
      "x": 3,
      "y": 2,
      "z": 16,
      "name": "Wood_Darkwood_Planks"
    },
    {
      "x": 4,
      "y": 2,
      "z": 16,
      "name": "Wood_Darkwood_Planks"
    },
    {
      "x": 5,
      "y": 2,
      "z": 16,
      "name": "Wood_Darkwood_Planks"
    },
    {
      "x": 6,
      "y": 2,
      "z": 16,
      "name": "Wood_Darkwood_Planks"
    },
    {
      "x": 7,
      "y": 2,
      "z": 16,
      "name": "Wood_Darkwood_Planks"
    },
    {
      "x": 8,
      "y": 2,
      "z": 16,
      "name": "Wood_Darkwood_Planks"
    },
    {
      "x": 9,
      "y": 2,
      "z": 16,
      "name": "Wood_Darkwood_Planks"
    },
    {
      "x": 10,
      "y": 2,
      "z": 16,
      "name": "Wood_Darkwood_Planks"
    },
    {
      "x": 11,
      "y": 2,
      "z": 16,
      "name": "Wood_Darkwood_Planks"
    },
    {
      "x": 12,
      "y": 2,
      "z": 16,
      "name": "Wood_Darkwood_Planks"
    },
    {
      "x": 13,
      "y": 2,
      "z": 16,
      "name": "Wood_Darkwood_Planks"
    },
    {
      "x": 14,
      "y": 2,
      "z": 16,
      "name": "Rock_Stone_Brick"
    },
    {
      "x": 15,
      "y": 2,
      "z": 16,
      "name": "Plant_Leaves_Beech"
    },
    {
      "x": 1,
      "y": 2,
      "z": 17,
      "name": "Wood_Oak_Trunk"
    },
    {
      "x": 2,
      "y": 2,
      "z": 17,
      "name": "Wood_Oak_Trunk"
    },
    {
      "x": 3,
      "y": 2,
      "z": 17,
      "name": "Rock_Stone_Brick"
    },
    {
      "x": 4,
      "y": 2,
      "z": 17,
      "name": "Rock_Stone_Brick"
    },
    {
      "x": 5,
      "y": 2,
      "z": 17,
      "name": "Rock_Stone_Brick"
    },
    {
      "x": 6,
      "y": 2,
      "z": 17,
      "name": "Wood_Oak_Trunk"
    },
    {
      "x": 7,
      "y": 2,
      "z": 17,
      "name": "Rock_Stone_Brick"
    },
    {
      "x": 8,
      "y": 2,
      "z": 17,
      "name": "Rock_Stone_Brick"
    },
    {
      "x": 9,
      "y": 2,
      "z": 17,
      "name": "Rock_Stone_Brick"
    },
    {
      "x": 10,
      "y": 2,
      "z": 17,
      "name": "Wood_Oak_Trunk"
    },
    {
      "x": 11,
      "y": 2,
      "z": 17,
      "name": "Rock_Stone_Brick"
    },
    {
      "x": 12,
      "y": 2,
      "z": 17,
      "name": "Rock_Stone_Brick"
    },
    {
      "x": 13,
      "y": 2,
      "z": 17,
      "name": "Rock_Stone_Brick"
    },
    {
      "x": 14,
      "y": 2,
      "z": 17,
      "name": "Wood_Oak_Trunk"
    },
    {
      "x": 15,
      "y": 2,
      "z": 17,
      "name": "Wood_Oak_Trunk"
    },
    {
      "x": 16,
      "y": 2,
      "z": 17,
      "name": "Plant_Leaves_Beech"
    },
    {
      "x": 1,
      "y": 2,
      "z": 18,
      "name": "*Plant_Crop_Berry_Block_State_Definitions_StageFinal"
    },
    {
      "x": 2,
      "y": 2,
      "z": 18,
      "name": "Wood_Oak_Trunk"
    },
    {
      "x": 3,
      "y": 2,
      "z": 18,
      "name": "Plant_Leaves_Beech"
    },
    {
      "x": 4,
      "y": 2,
      "z": 18,
      "name": "Plant_Flower_Tall_Pink"
    },
    {
      "x": 6,
      "y": 2,
      "z": 18,
      "name": "Wood_Oak_Trunk"
    },
    {
      "x": 7,
      "y": 2,
      "z": 18,
      "name": "Plant_Leaves_Beech"
    },
    {
      "x": 9,
      "y": 2,
      "z": 18,
      "name": "Plant_Flower_Tall_Pink"
    },
    {
      "x": 10,
      "y": 2,
      "z": 18,
      "name": "Wood_Oak_Trunk"
    },
    {
      "x": 11,
      "y": 2,
      "z": 18,
      "name": "Plant_Grass_Sharp_Wild"
    },
    {
      "x": 12,
      "y": 2,
      "z": 18,
      "name": "*Plant_Crop_Berry_Block_State_Definitions_StageFinal"
    },
    {
      "x": 14,
      "y": 2,
      "z": 18,
      "name": "Wood_Oak_Trunk"
    },
    {
      "x": 15,
      "y": 2,
      "z": 18,
      "name": "Plant_Leaves_Beech"
    },
    {
      "x": 2,
      "y": 2,
      "z": 19,
      "name": "Plant_Grass_Sharp_Wild"
    },
    {
      "x": 6,
      "y": 2,
      "z": 19,
      "name": "Plant_Leaves_Beech"
    },
    {
      "x": 7,
      "y": 2,
      "z": 19,
      "name": "Plant_Grass_Sharp_Wild"
    },
    {
      "x": 10,
      "y": 2,
      "z": 19,
      "name": "*Plant_Crop_Berry_Block_State_Definitions_StageFinal"
    },
    {
      "x": 16,
      "y": 2,
      "z": 19,
      "name": "Rock_Stone_Brick"
    },
    {
      "x": 0,
      "y": 2,
      "z": 20,
      "name": "Plant_Grass_Sharp_Wild"
    },
    {
      "x": 1,
      "y": 2,
      "z": 20,
      "name": "Plant_Grass_Sharp_Wild"
    },
    {
      "x": 3,
      "y": 2,
      "z": 20,
      "name": "Rock_Stone_Brick"
    },
    {
      "x": 5,
      "y": 2,
      "z": 20,
      "name": "Rock_Stone_Brick"
    },
    {
      "x": 6,
      "y": 2,
      "z": 20,
      "name": "*Plant_Crop_Berry_Block_State_Definitions_StageFinal"
    },
    {
      "x": 10,
      "y": 2,
      "z": 20,
      "name": "Rock_Stone_Brick"
    },
    {
      "x": 13,
      "y": 2,
      "z": 20,
      "name": "Rock_Stone_Brick"
    },
    {
      "x": 15,
      "y": 2,
      "z": 20,
      "name": "Plant_Flower_Common_White2"
    },
    {
      "x": 0,
      "y": 2,
      "z": 21,
      "name": "Plant_Grass_Sharp_Wild"
    },
    {
      "x": 1,
      "y": 2,
      "z": 21,
      "name": "Rock_Stone_Brick"
    },
    {
      "x": 2,
      "y": 2,
      "z": 21,
      "name": "Rock_Stone_Brick"
    },
    {
      "x": 4,
      "y": 2,
      "z": 21,
      "name": "Rock_Stone_Brick"
    },
    {
      "x": 5,
      "y": 2,
      "z": 21,
      "name": "Plant_Grass_Sharp_Wild"
    },
    {
      "x": 6,
      "y": 2,
      "z": 21,
      "name": "Rock_Stone_Brick"
    },
    {
      "x": 9,
      "y": 2,
      "z": 21,
      "name": "Rock_Stone_Brick"
    },
    {
      "x": 10,
      "y": 2,
      "z": 21,
      "name": "Plant_Grass_Sharp_Wild"
    },
    {
      "x": 11,
      "y": 2,
      "z": 21,
      "name": "Rock_Stone_Brick"
    },
    {
      "x": 12,
      "y": 2,
      "z": 21,
      "name": "Plant_Grass_Sharp_Wild"
    },
    {
      "x": 14,
      "y": 2,
      "z": 21,
      "name": "Rock_Stone_Brick"
    },
    {
      "x": 15,
      "y": 2,
      "z": 21,
      "name": "Plant_Grass_Sharp_Wild"
    },
    {
      "x": 16,
      "y": 2,
      "z": 21,
      "name": "Plant_Grass_Sharp_Wild"
    },
    {
      "x": 0,
      "y": 2,
      "z": 22,
      "name": "Plant_Flower_Common_Cyan2"
    },
    {
      "x": 2,
      "y": 2,
      "z": 22,
      "name": "Rock_Stone_Brick"
    },
    {
      "x": 3,
      "y": 2,
      "z": 22,
      "name": "Rock_Stone_Brick"
    },
    {
      "x": 4,
      "y": 2,
      "z": 22,
      "name": "Plant_Grass_Sharp_Wild"
    },
    {
      "x": 5,
      "y": 2,
      "z": 22,
      "name": "Plant_Grass_Sharp_Wild"
    },
    {
      "x": 6,
      "y": 2,
      "z": 22,
      "name": "Rock_Stone_Brick"
    },
    {
      "x": 8,
      "y": 2,
      "z": 22,
      "name": "Rock_Stone_Brick"
    },
    {
      "x": 9,
      "y": 2,
      "z": 22,
      "name": "Rock_Stone_Brick"
    },
    {
      "x": 10,
      "y": 2,
      "z": 22,
      "name": "Rock_Stone_Brick"
    },
    {
      "x": 11,
      "y": 2,
      "z": 22,
      "name": "Rock_Stone_Brick"
    },
    {
      "x": 12,
      "y": 2,
      "z": 22,
      "name": "Rock_Stone_Brick"
    },
    {
      "x": 13,
      "y": 2,
      "z": 22,
      "name": "Rock_Stone_Brick"
    },
    {
      "x": 14,
      "y": 2,
      "z": 22,
      "name": "Rock_Stone_Brick"
    },
    {
      "x": 15,
      "y": 2,
      "z": 22,
      "name": "Rock_Stone_Brick"
    },
    {
      "x": 14,
      "y": 3,
      "z": 3,
      "name": "Plant_Grass_Sharp_Wild"
    },
    {
      "x": 1,
      "y": 3,
      "z": 4,
      "name": "Plant_Flower_Tall_Pink"
    },
    {
      "x": 2,
      "y": 3,
      "z": 4,
      "name": "Wood_Oak_Trunk"
    },
    {
      "x": 4,
      "y": 3,
      "z": 4,
      "name": "Plant_Grass_Sharp_Wild"
    },
    {
      "x": 6,
      "y": 3,
      "z": 4,
      "name": "Wood_Oak_Trunk"
    },
    {
      "x": 10,
      "y": 3,
      "z": 4,
      "name": "Wood_Oak_Trunk"
    },
    {
      "x": 11,
      "y": 3,
      "z": 4,
      "name": "Plant_Grass_Sharp_Wild"
    },
    {
      "x": 13,
      "y": 3,
      "z": 4,
      "name": "Plant_Leaves_Beech"
    },
    {
      "x": 14,
      "y": 3,
      "z": 4,
      "name": "Wood_Oak_Trunk"
    },
    {
      "x": 1,
      "y": 3,
      "z": 5,
      "name": "Wood_Oak_Trunk"
    },
    {
      "x": 2,
      "y": 3,
      "z": 5,
      "name": "Wood_Oak_Trunk"
    },
    {
      "x": 6,
      "y": 3,
      "z": 5,
      "name": "Wood_Oak_Trunk"
    },
    {
      "x": 7,
      "y": 3,
      "z": 5,
      "name": "Furniture_Crude_Trapdoor"
    },
    {
      "x": 9,
      "y": 3,
      "z": 5,
      "name": "Furniture_Crude_Trapdoor"
    },
    {
      "x": 10,
      "y": 3,
      "z": 5,
      "name": "Wood_Oak_Trunk"
    },
    {
      "x": 14,
      "y": 3,
      "z": 5,
      "name": "Wood_Oak_Trunk"
    },
    {
      "x": 15,
      "y": 3,
      "z": 5,
      "name": "Wood_Oak_Trunk"
    },
    {
      "x": 1,
      "y": 3,
      "z": 6,
      "name": "Plant_Flower_Tall_Pink"
    },
    {
      "x": 3,
      "y": 3,
      "z": 6,
      "name": "Wood_Beech_Trunk_Full"
    },
    {
      "x": 4,
      "y": 3,
      "z": 6,
      "name": "Wood_Beech_Trunk_Full"
    },
    {
      "x": 5,
      "y": 3,
      "z": 6,
      "name": "Wood_Beech_Trunk_Full"
    },
    {
      "x": 6,
      "y": 3,
      "z": 6,
      "name": "Rock_Stone_Brick"
    },
    {
      "x": 7,
      "y": 3,
      "z": 6,
      "name": "Furniture_Tavern_Trapdoor"
    },
    {
      "x": 8,
      "y": 3,
      "z": 6,
      "name": "*Furniture_Village_Door_State_Definitions_CloseDoorOut"
    },
    {
      "x": 9,
      "y": 3,
      "z": 6,
      "name": "Furniture_Tavern_Trapdoor"
    },
    {
      "x": 10,
      "y": 3,
      "z": 6,
      "name": "Rock_Stone_Brick"
    },
    {
      "x": 11,
      "y": 3,
      "z": 6,
      "name": "Wood_Beech_Trunk_Full"
    },
    {
      "x": 12,
      "y": 3,
      "z": 6,
      "name": "Wood_Beech_Trunk_Full"
    },
    {
      "x": 13,
      "y": 3,
      "z": 6,
      "name": "Wood_Beech_Trunk_Full"
    },
    {
      "x": 3,
      "y": 3,
      "z": 7,
      "name": "Wood_Beech_Trunk_Full"
    },
    {
      "x": 5,
      "y": 3,
      "z": 7,
      "name": "Furniture_Ancient_Crate"
    },
    {
      "x": 11,
      "y": 3,
      "z": 7,
      "name": "Rock_Stone_Brick"
    },
    {
      "x": 13,
      "y": 3,
      "z": 7,
      "name": "Wood_Beech_Trunk_Full"
    },
    {
      "x": 0,
      "y": 3,
      "z": 8,
      "name": "Plant_Crop_Mana1"
    },
    {
      "x": 1,
      "y": 3,
      "z": 8,
      "name": "Plant_Leaves_Beech"
    },
    {
      "x": 3,
      "y": 3,
      "z": 8,
      "name": "Wood_Beech_Trunk_Full"
    },
    {
      "x": 4,
      "y": 3,
      "z": 8,
      "name": "Wood_Beech_Trunk_Full"
    },
    {
      "x": 12,
      "y": 3,
      "z": 8,
      "name": "Wood_Beech_Trunk_Full"
    },
    {
      "x": 13,
      "y": 3,
      "z": 8,
      "name": "Wood_Beech_Trunk_Full"
    },
    {
      "x": 15,
      "y": 3,
      "z": 8,
      "name": "Plant_Grass_Sharp_Wild"
    },
    {
      "x": 1,
      "y": 3,
      "z": 9,
      "name": "Wood_Oak_Trunk"
    },
    {
      "x": 2,
      "y": 3,
      "z": 9,
      "name": "Wood_Oak_Trunk"
    },
    {
      "x": 3,
      "y": 3,
      "z": 9,
      "name": "Wood_Beech_Trunk_Full"
    },
    {
      "x": 5,
      "y": 3,
      "z": 9,
      "name": "Wood_Darkwood_Planks"
    },
    {
      "x": 11,
      "y": 3,
      "z": 9,
      "name": "Furniture_Tavern_Planter"
    },
    {
      "x": 13,
      "y": 3,
      "z": 9,
      "name": "Wood_Beech_Trunk_Full"
    },
    {
      "x": 14,
      "y": 3,
      "z": 9,
      "name": "Wood_Oak_Trunk"
    },
    {
      "x": 15,
      "y": 3,
      "z": 9,
      "name": "Wood_Oak_Trunk"
    },
    {
      "x": 1,
      "y": 3,
      "z": 10,
      "name": "Plant_Grass_Sharp_Wild"
    },
    {
      "x": 3,
      "y": 3,
      "z": 10,
      "name": "Wood_Beech_Trunk_Full"
    },
    {
      "x": 4,
      "y": 3,
      "z": 10,
      "name": "Wood_Beech_Trunk_Full"
    },
    {
      "x": 12,
      "y": 3,
      "z": 10,
      "name": "Wood_Beech_Trunk_Full"
    },
    {
      "x": 13,
      "y": 3,
      "z": 10,
      "name": "Wood_Beech_Trunk_Full"
    },
    {
      "x": 3,
      "y": 3,
      "z": 11,
      "name": "Wood_Beech_Trunk_Full"
    },
    {
      "x": 5,
      "y": 3,
      "z": 11,
      "name": "Rock_Stone_Brick"
    },
    {
      "x": 11,
      "y": 3,
      "z": 11,
      "name": "Rock_Stone_Brick"
    },
    {
      "x": 13,
      "y": 3,
      "z": 11,
      "name": "Wood_Beech_Trunk_Full"
    },
    {
      "x": 3,
      "y": 3,
      "z": 12,
      "name": "Wood_Beech_Trunk_Full"
    },
    {
      "x": 4,
      "y": 3,
      "z": 12,
      "name": "Wood_Beech_Trunk_Full"
    },
    {
      "x": 12,
      "y": 3,
      "z": 12,
      "name": "Wood_Beech_Trunk_Full"
    },
    {
      "x": 13,
      "y": 3,
      "z": 12,
      "name": "Wood_Beech_Trunk_Full"
    },
    {
      "x": 15,
      "y": 3,
      "z": 12,
      "name": "Plant_Crop_Mana1"
    },
    {
      "x": 1,
      "y": 3,
      "z": 13,
      "name": "Wood_Oak_Trunk"
    },
    {
      "x": 2,
      "y": 3,
      "z": 13,
      "name": "Wood_Oak_Trunk"
    },
    {
      "x": 3,
      "y": 3,
      "z": 13,
      "name": "Wood_Beech_Trunk_Full"
    },
    {
      "x": 5,
      "y": 3,
      "z": 13,
      "name": "Wood_Darkwood_Planks"
    },
    {
      "x": 11,
      "y": 3,
      "z": 13,
      "name": "Wood_Darkwood_Planks"
    },
    {
      "x": 13,
      "y": 3,
      "z": 13,
      "name": "Wood_Beech_Trunk_Full"
    },
    {
      "x": 14,
      "y": 3,
      "z": 13,
      "name": "Wood_Oak_Trunk"
    },
    {
      "x": 15,
      "y": 3,
      "z": 13,
      "name": "Wood_Oak_Trunk"
    },
    {
      "x": 0,
      "y": 3,
      "z": 14,
      "name": "Plant_Flower_Tall_Pink"
    },
    {
      "x": 3,
      "y": 3,
      "z": 14,
      "name": "Wood_Beech_Trunk_Full"
    },
    {
      "x": 4,
      "y": 3,
      "z": 14,
      "name": "Wood_Beech_Trunk_Full"
    },
    {
      "x": 12,
      "y": 3,
      "z": 14,
      "name": "Wood_Beech_Trunk_Full"
    },
    {
      "x": 13,
      "y": 3,
      "z": 14,
      "name": "Wood_Beech_Trunk_Full"
    },
    {
      "x": 1,
      "y": 3,
      "z": 15,
      "name": "Plant_Flower_Tall_Pink"
    },
    {
      "x": 3,
      "y": 3,
      "z": 15,
      "name": "Wood_Beech_Trunk_Full"
    },
    {
      "x": 5,
      "y": 3,
      "z": 15,
      "name": "Rock_Stone_Brick"
    },
    {
      "x": 11,
      "y": 3,
      "z": 15,
      "name": "Rock_Stone_Brick"
    },
    {
      "x": 13,
      "y": 3,
      "z": 15,
      "name": "Wood_Beech_Trunk_Full"
    },
    {
