{
  "version": 8,
  "blockIdVersion": 10,
  "anchorX": 0,
  "anchorY": 0,
  "anchorZ": 0,
  "blocks": [
    {
      "x": 0,
      "y": 0,
      "z": 0,
      "name": "Rock_Stone"
    },
    {
      "x": 1,
      "y": 0,
      "z": 0,
      "name": "Rock_Stone"
    },
    {
      "x": 2,
      "y": 0,
      "z": 0,
      "name": "Rock_Stone"
    },
    {
      "x": 3,
      "y": 0,
      "z": 0,
      "name": "Rock_Stone"
    },
    {
      "x": 4,
      "y": 0,
      "z": 0,
      "name": "Rock_Stone"
    },
    {
      "x": 5,
      "y": 0,
      "z": 0,
      "name": "Rock_Stone"
    },
    {
      "x": 6,
      "y": 0,
      "z": 0,
      "name": "Rock_Stone"
    },
    {
      "x": 0,
      "y": 0,
      "z": 1,
      "name": "Rock_Stone"
    },
    {
      "x": 1,
      "y": 0,
      "z": 1,
      "name": "Rock_Stone"
    },
    {
      "x": 2,
      "y": 0,
      "z": 1,
      "name": "Rock_Stone"
    },
    {
      "x": 3,
      "y": 0,
      "z": 1,
      "name": "Rock_Stone"
    },
    {
      "x": 4,
      "y": 0,
      "z": 1,
      "name": "Rock_Stone"
    },
    {
      "x": 5,
      "y": 0,
      "z": 1,
      "name": "Rock_Stone"
    },
    {
      "x": 6,
      "y": 0,
      "z": 1,
      "name": "Rock_Stone"
    },
    {
      "x": 0,
      "y": 0,
      "z": 2,
      "name": "Rock_Stone"
    },
    {
      "x": 1,
      "y": 0,
      "z": 2,
      "name": "Rock_Stone"
    },
    {
      "x": 2,
      "y": 0,
      "z": 2,
      "name": "Rock_Stone"
    },
    {
      "x": 3,
      "y": 0,
      "z": 2,
      "name": "Rock_Stone"
    },
    {
      "x": 4,
      "y": 0,
      "z": 2,
      "name": "Rock_Stone"
    },
    {
      "x": 5,
      "y": 0,
      "z": 2,
      "name": "Rock_Stone"
    },
    {
      "x": 6,
      "y": 0,
      "z": 2,
      "name": "Rock_Stone"
    },
    {
      "x": 0,
      "y": 0,
      "z": 3,
      "name": "Rock_Stone"
    },
    {
      "x": 1,
      "y": 0,
      "z": 3,
      "name": "Rock_Stone"
    },
    {
      "x": 2,
      "y": 0,
      "z": 3,
      "name": "Rock_Stone"
    },
    {
      "x": 3,
      "y": 0,
      "z": 3,
      "name": "Rock_Stone"
    },
    {
      "x": 4,
      "y": 0,
      "z": 3,
      "name": "Rock_Stone"
    },
    {
      "x": 5,
      "y": 0,
      "z": 3,
      "name": "Rock_Stone"
    },
    {
      "x": 6,
      "y": 0,
      "z": 3,
      "name": "Rock_Stone"
    },
    {
      "x": 0,
      "y": 0,
      "z": 4,
      "name": "Rock_Stone"
    },
    {
      "x": 1,
      "y": 0,
      "z": 4,
      "name": "Rock_Stone"
    },
    {
      "x": 2,
      "y": 0,
      "z": 4,
      "name": "Rock_Stone"
    },
    {
      "x": 3,
      "y": 0,
      "z": 4,
      "name": "Rock_Stone"
    },
    {
      "x": 4,
      "y": 0,
      "z": 4,
      "name": "Rock_Stone"
    },
    {
      "x": 5,
      "y": 0,
      "z": 4,
      "name": "Rock_Stone"
    },
    {
      "x": 6,
      "y": 0,
      "z": 4,
      "name": "Rock_Stone"
    },
    {
      "x": 0,
      "y": 0,
      "z": 5,
      "name": "Rock_Stone"
    },
    {
      "x": 1,
      "y": 0,
      "z": 5,
      "name": "Rock_Stone"
    },
    {
      "x": 2,
      "y": 0,
      "z": 5,
      "name": "Rock_Stone"
    },
    {
      "x": 3,
      "y": 0,
      "z": 5,
      "name": "Rock_Stone"
    },
    {
      "x": 4,
      "y": 0,
      "z": 5,
      "name": "Rock_Stone"
    },
    {
      "x": 5,
      "y": 0,
      "z": 5,
      "name": "Rock_Stone"
    },
    {
      "x": 6,
      "y": 0,
      "z": 5,
      "name": "Rock_Stone"
    },
    {
      "x": 0,
      "y": 0,
      "z": 6,
      "name": "Rock_Stone"
    },
    {
      "x": 1,
      "y": 0,
      "z": 6,
      "name": "Rock_Stone"
    },
    {
      "x": 2,
      "y": 0,
      "z": 6,
      "name": "Rock_Stone"
    },
    {
      "x": 3,
      "y": 0,
      "z": 6,
      "name": "Rock_Stone"
    },
    {
      "x": 4,
      "y": 0,
      "z": 6,
      "name": "Rock_Stone"
    },
    {
      "x": 5,
      "y": 0,
      "z": 6,
      "name": "Rock_Stone"
    },
    {
      "x": 6,
      "y": 0,
      "z": 6,
      "name": "Rock_Stone"
    },
    {
      "x": 0,
      "y": 1,
      "z": 0,
      "name": "Soil_Dirt"
    },
    {
      "x": 1,
      "y": 1,
      "z": 0,
      "name": "Soil_Dirt"
    },
    {
      "x": 2,
      "y": 1,
      "z": 0,
      "name": "Soil_Dirt"
    },
    {
      "x": 3,
      "y": 1,
      "z": 0,
      "name": "Soil_Dirt"
    },
    {
      "x": 4,
      "y": 1,
      "z": 0,
      "name": "Soil_Dirt"
    },
    {
      "x": 5,
      "y": 1,
      "z": 0,
      "name": "Soil_Dirt"
    },
    {
      "x": 6,
      "y": 1,
      "z": 0,
      "name": "Soil_Dirt"
    },
    {
      "x": 0,
      "y": 1,
      "z": 1,
      "name": "Soil_Dirt"
    },
    {
      "x": 1,
      "y": 1,
      "z": 1,
      "name": "Soil_Dirt"
    },
    {
      "x": 2,
      "y": 1,
      "z": 1,
      "name": "Soil_Dirt"
    },
    {
      "x": 3,
      "y": 1,
      "z": 1,
      "name": "Soil_Dirt"
    },
    {
      "x": 4,
      "y": 1,
      "z": 1,
      "name": "Soil_Dirt"
    },
    {
      "x": 5,
      "y": 1,
      "z": 1,
      "name": "Soil_Dirt"
    },
    {
      "x": 6,
      "y": 1,
      "z": 1,
      "name": "Soil_Dirt"
    },
    {
      "x": 0,
      "y": 1,
      "z": 2,
      "name": "Soil_Dirt"
    },
    {
      "x": 1,
      "y": 1,
      "z": 2,
      "name": "Soil_Dirt"
    },
    {
      "x": 2,
      "y": 1,
      "z": 2,
      "name": "Soil_Dirt"
    },
    {
      "x": 3,
      "y": 1,
      "z": 2,
      "name": "Soil_Dirt"
    },
    {
      "x": 4,
      "y": 1,
      "z": 2,
      "name": "Soil_Dirt"
    },
    {
      "x": 5,
      "y": 1,
      "z": 2,
      "name": "Soil_Dirt"
    },
    {
      "x": 6,
      "y": 1,
      "z": 2,
      "name": "Soil_Dirt"
    },
    {
      "x": 0,
      "y": 1,
      "z": 3,
      "name": "Soil_Dirt"
    },
    {
      "x": 1,
      "y": 1,
      "z": 3,
      "name": "Soil_Dirt"
    },
    {
      "x": 2,
      "y": 1,
      "z": 3,
      "name": "Soil_Dirt"
    },
    {
      "x": 3,
      "y": 1,
      "z": 3,
      "name": "Soil_Dirt"
    },
    {
      "x": 4,
      "y": 1,
      "z": 3,
      "name": "Soil_Dirt"
    },
    {
      "x": 5,
      "y": 1,
      "z": 3,
      "name": "Soil_Dirt"
    },
    {
      "x": 6,
      "y": 1,
      "z": 3,
      "name": "Soil_Dirt"
    },
    {
      "x": 0,
      "y": 1,
      "z": 4,
      "name": "Soil_Dirt"
    },
    {
      "x": 1,
      "y": 1,
      "z": 4,
      "name": "Soil_Dirt"
    },
    {
      "x": 2,
      "y": 1,
      "z": 4,
      "name": "Soil_Dirt"
    },
    {
      "x": 3,
      "y": 1,
      "z": 4,
      "name": "Soil_Dirt"
    },
    {
      "x": 4,
      "y": 1,
      "z": 4,
      "name": "Soil_Dirt"
    },
    {
      "x": 5,
      "y": 1,
      "z": 4,
      "name": "Soil_Dirt"
    },
    {
      "x": 6,
      "y": 1,
      "z": 4,
      "name": "Soil_Dirt"
    },
    {
      "x": 0,
      "y": 1,
      "z": 5,
      "name": "Soil_Dirt"
    },
    {
      "x": 1,
      "y": 1,
      "z": 5,
      "name": "Soil_Dirt"
    },
    {
      "x": 2,
      "y": 1,
      "z": 5,
      "name": "Soil_Dirt"
    },
    {
      "x": 3,
      "y": 1,
      "z": 5,
      "name": "Soil_Dirt"
    },
    {
      "x": 4,
      "y": 1,
      "z": 5,
      "name": "Soil_Dirt"
    },
    {
      "x": 5,
      "y": 1,
      "z": 5,
      "name": "Soil_Dirt"
    },
    {
      "x": 6,
      "y": 1,
      "z": 5,
      "name": "Soil_Dirt"
    },
    {
      "x": 0,
      "y": 1,
      "z": 6,
      "name": "Soil_Dirt"
    },
    {
      "x": 1,
      "y": 1,
      "z": 6,
      "name": "Soil_Dirt"
    },
    {
      "x": 2,
      "y": 1,
      "z": 6,
      "name": "Soil_Dirt"
    },
    {
      "x": 3,
      "y": 1,
      "z": 6,
      "name": "Soil_Dirt"
    },
    {
      "x": 4,
      "y": 1,
      "z": 6,
      "name": "Soil_Dirt"
    },
    {
      "x": 5,
      "y": 1,
      "z": 6,
      "name": "Soil_Dirt"
    },
    {
      "x": 6,
      "y": 1,
      "z": 6,
      "name": "Soil_Dirt"
    },
    {
      "x": 0,
      "y": 2,
      "z": 0,
      "name": "Soil_Grass"
    },
    {
      "x": 1,
      "y": 2,
      "z": 0,
      "name": "Soil_Grass"
    },
    {
      "x": 2,
      "y": 2,
      "z": 0,
      "name": "Soil_Grass"
    },
    {
      "x": 3,
      "y": 2,
      "z": 0,
      "name": "Soil_Grass"
    },
    {
      "x": 4,
      "y": 2,
      "z": 0,
      "name": "Soil_Grass"
    },
    {
      "x": 5,
      "y": 2,
      "z": 0,
      "name": "Soil_Grass"
    },
    {
      "x": 6,
      "y": 2,
      "z": 0,
      "name": "Soil_Grass"
    },
    {
      "x": 0,
      "y": 2,
      "z": 1,
      "name": "Soil_Grass"
    },
    {
      "x": 1,
      "y": 2,
      "z": 1,
      "name": "Soil_Grass"
    },
    {
      "x": 2,
      "y": 2,
      "z": 1,
      "name": "Soil_Grass"
    },
    {
      "x": 3,
      "y": 2,
      "z": 1,
      "name": "Soil_Grass"
    },
    {
      "x": 4,
      "y": 2,
      "z": 1,
      "name": "Soil_Grass"
    },
    {
      "x": 5,
      "y": 2,
      "z": 1,
      "name": "Soil_Grass"
    },
    {
      "x": 6,
      "y": 2,
      "z": 1,
      "name": "Soil_Grass"
    },
    {
      "x": 0,
      "y": 2,
      "z": 2,
      "name": "Soil_Grass"
    },
    {
      "x": 1,
      "y": 2,
      "z": 2,
      "name": "Soil_Grass"
    },
    {
      "x": 2,
      "y": 2,
      "z": 2,
      "name": "Soil_Grass"
    },
    {
      "x": 3,
      "y": 2,
      "z": 2,
      "name": "Soil_Grass"
    },
    {
      "x": 4,
      "y": 2,
      "z": 2,
      "name": "Soil_Grass"
    },
    {
      "x": 5,
      "y": 2,
      "z": 2,
      "name": "Soil_Grass"
    },
    {
      "x": 6,
      "y": 2,
      "z": 2,
      "name": "Soil_Grass"
    },
    {
      "x": 0,
      "y": 2,
      "z": 3,
      "name": "Soil_Grass"
    },
    {
      "x": 1,
      "y": 2,
      "z": 3,
      "name": "Soil_Grass"
    },
    {
      "x": 2,
      "y": 2,
      "z": 3,
      "name": "Soil_Grass"
    },
    {
      "x": 3,
      "y": 2,
      "z": 3,
      "name": "Soil_Grass"
    },
    {
      "x": 4,
      "y": 2,
      "z": 3,
      "name": "Soil_Grass"
    },
    {
      "x": 5,
      "y": 2,
      "z": 3,
      "name": "Soil_Grass"
    },
    {
      "x": 6,
      "y": 2,
      "z": 3,
      "name": "Soil_Grass"
    },
    {
      "x": 0,
      "y": 2,
      "z": 4,
      "name": "Soil_Grass"
    },
    {
      "x": 1,
      "y": 2,
      "z": 4,
      "name": "Soil_Grass"
    },
    {
      "x": 2,
      "y": 2,
      "z": 4,
      "name": "Soil_Grass"
    },
    {
      "x": 3,
      "y": 2,
      "z": 4,
      "name": "Soil_Grass"
    },
    {
      "x": 4,
      "y": 2,
      "z": 4,
      "name": "Soil_Grass"
    },
    {
      "x": 5,
      "y": 2,
      "z": 4,
      "name": "Soil_Grass"
    },
    {
      "x": 6,
      "y": 2,
      "z": 4,
      "name": "Soil_Grass"
    },
    {
      "x": 0,
      "y": 2,
      "z": 5,
      "name": "Soil_Grass"
    },
    {
      "x": 1,
      "y": 2,
      "z": 5,
      "name": "Soil_Grass"
    },
    {
      "x": 2,
      "y": 2,
      "z": 5,
      "name": "Soil_Grass"
    },
    {
      "x": 3,
      "y": 2,
      "z": 5,
      "name": "Soil_Grass"
    },
    {
      "x": 4,
      "y": 2,
      "z": 5,
      "name": "Soil_Grass"
    },
    {
      "x": 5,
      "y": 2,
      "z": 5,
      "name": "Soil_Grass"
    },
    {
      "x": 6,
      "y": 2,
      "z": 5,
      "name": "Soil_Grass"
    },
    {
      "x": 0,
      "y": 2,
      "z": 6,
      "name": "Soil_Grass"
    },
    {
      "x": 1,
      "y": 2,
      "z": 6,
      "name": "Soil_Grass"
    },
    {
      "x": 2,
      "y": 2,
      "z": 6,
      "name": "Soil_Grass"
    },
    {
      "x": 3,
      "y": 2,
      "z": 6,
      "name": "Soil_Grass"
    },
    {
      "x": 4,
      "y": 2,
      "z": 6,
      "name": "Soil_Grass"
    },
    {
      "x": 5,
      "y": 2,
      "z": 6,
      "name": "Soil_Grass"
    },
    {
      "x": 6,
      "y": 2,
      "z": 6,
      "name": "Soil_Grass"
    }
  ],
  "fluids": []
}